Workbook
Name Agency_List: [1]Control!$H$17:$H$19
Name BUControlSheet_CurrencySelections: [2]Control!$A$19:$A$20
Name BUControlSheet_FormulaSelections: [2]Control!$A$16:$A$17
Name BUControlSheet_RevisionSelections: [2]Control!$A$21:$A$22
Name BUControlSheet_ScaleSelections: [2]Control!$J$35:$J$36
Name Coordinator_List: [1]Control!$J$20:$J$21
Name Country: [3]Control!$C$1
Name ctylist: #REF!
Name ctylist: #REF!
Name ctylist: #REF!
Name ctylist: #REF!
Name ctylist: #REF!
Name ctylist: #REF!
Name ctylist: #REF!
Name Currency_Def: [1]Control!$BA$330:$BA$487
Name DelKreditor: #REF!,#REF!
Name DelKreditor: #REF!,#REF!
Name DelKreditor: #REF!,#REF!
Name DelKreditor: #REF!,#REF!
Name delstr: #REF!,#REF!,#REF!
Name delstr: #REF!,#REF!,#REF!
Name delstr: #REF!,#REF!,#REF!
Name delstr: #REF!,#REF!,#REF!
Name DELVD: #REF!,#REF!,#REF!,#REF!,#REF!,#REF!,#REF!,#REF!,#REF!,#REF!,#REF!,#REF!,#REF!,#REF!,#REF!,#REF!,#REF!
Name DELVD: #REF!,#REF!,#REF!,#REF!,#REF!,#REF!,#REF!,#REF!,#REF!,#REF!,#REF!,#REF!,#REF!,#REF!,#REF!,#REF!,#REF!
Name DELVD: #REF!,#REF!,#REF!,#REF!,#REF!,#REF!,#REF!,#REF!,#REF!,#REF!,#REF!,#REF!,#REF!,#REF!,#REF!,#REF!,#REF!
Name DELVD: #REF!,#REF!,#REF!,#REF!,#REF!,#REF!,#REF!,#REF!,#REF!,#REF!,#REF!,#REF!,#REF!,#REF!,#REF!,#REF!,#REF!
Name DelVd1: #REF!,#REF!,#REF!,#REF!,#REF!,#REF!,#REF!,#REF!,#REF!,#REF!,#REF!,#REF!
Name DelVd1: #REF!,#REF!,#REF!,#REF!,#REF!,#REF!,#REF!,#REF!,#REF!,#REF!,#REF!,#REF!
Name DelVd1: #REF!,#REF!,#REF!,#REF!,#REF!,#REF!,#REF!,#REF!,#REF!,#REF!,#REF!,#REF!
Name DelVd1: #REF!,#REF!,#REF!,#REF!,#REF!,#REF!,#REF!,#REF!,#REF!,#REF!,#REF!,#REF!
Name DelZaim: #REF!
Name DelZaim: #REF!
Name DelZaim: #REF!
Name DelZaim: #REF!
Name fullpilot: #REF!
Name fullpilot: #REF!
Name fullpilot: #REF!
Name fullpilot: #REF!
Name fullpilot: #REF!
Name fullpilot: #REF!
Name fullpilot: #REF!
Name IIPpilot: #REF!
Name IIPpilot: #REF!
Name IIPpilot: #REF!
Name IIPpilot: #REF!
Name IIPpilot: #REF!
Name IIPpilot: #REF!
Name IIPpilot: #REF!
Name pilot: #REF!
Name pilot: #REF!
Name pilot: #REF!
Name pilot: #REF!
Name pilot: #REF!
Name pilot: #REF!
Name pilot: #REF!
Name Range_DownloadAnnual: [2]Control!$C$4
Name Range_DownloadMonth: [2]Control!$C$2
Name Range_DownloadQuarter: [2]Control!$C$3
Name Range_DSTNotes: #REF!

Sheet Sheet2
A1: Date Initialisation | B1: Date needed | C1: External Debt interpolated
A2: 36892 | B2: =TEXT(A2,"yyyy-mm-01") -> 2001-01-01 | C2: =VLOOKUP(B2,'Final Cle'!$C$2:$D$103,2,FALSE) -> 12634.572
A3: =EDATE(A2,1) -> 36923 | B3: =TEXT(A3,"yyyy-mm-01") -> 2001-02-01 | C3: {=INDEX($C:$C,MATCH(ROW()-MOD(ROW()-ROW($C$2),3),ROW($C:$C),0))+(B3-INDEX($B:$B,MATCH(ROW()-MOD(ROW()-ROW($C$2),3),ROW($C:$C),0)))/(INDEX($B:$B,MATCH(ROW()-MOD(ROW()-ROW($C$2),3),ROW($C:$C),0)+3)-INDEX($B:$B,MATCH(ROW()-MOD(ROW()-ROW($C$2),3),ROW($C:$C),0)))*(INDEX($C:$C,MATCH(ROW()-MOD(ROW()-ROW($C$2),3),ROW($C:$C),0)+3)-INDEX($C:$C,MATCH(ROW()-MOD(ROW()-ROW($C$2),3),ROW($C:$C),0)))} -> 12754.627
A4: =EDATE(A3,1) -> 36951 | B4: =TEXT(A4,"yyyy-mm-01") -> 2001-03-01 | C4: {=INDEX($C:$C,MATCH(ROW()-MOD(ROW()-ROW($C$2),3),ROW($C:$C),0))+(B4-INDEX($B:$B,MATCH(ROW()-MOD(ROW()-ROW($C$2),3),ROW($C:$C),0)))/(INDEX($B:$B,MATCH(ROW()-MOD(ROW()-ROW($C$2),3),ROW($C:$C),0)+3)-INDEX($B:$B,MATCH(ROW()-MOD(ROW()-ROW($C$2),3),ROW($C:$C),0)))*(INDEX($C:$C,MATCH(ROW()-MOD(ROW()-ROW($C$2),3),ROW($C:$C),0)+3)-INDEX($C:$C,MATCH(ROW()-MOD(ROW()-ROW($C$2),3),ROW($C:$C),0)))} -> 12863.063
A5: =EDATE(A4,1) -> 36982 | B5: =TEXT(A5,"yyyy-mm-01") -> 2001-04-01 | C5: =VLOOKUP(B5,'Final Cle'!$C$2:$D$103,2,FALSE) -> 12983.117
A6: =EDATE(A5,1) -> 37012 | B6: =TEXT(A6,"yyyy-mm-01") -> 2001-05-01 | C6: {=INDEX($C:$C,MATCH(ROW()-MOD(ROW()-ROW($C$2),3),ROW($C:$C),0))+(B6-INDEX($B:$B,MATCH(ROW()-MOD(ROW()-ROW($C$2),3),ROW($C:$C),0)))/(INDEX($B:$B,MATCH(ROW()-MOD(ROW()-ROW($C$2),3),ROW($C:$C),0)+3)-INDEX($B:$B,MATCH(ROW()-MOD(ROW()-ROW($C$2),3),ROW($C:$C),0)))*(INDEX($C:$C,MATCH(ROW()-MOD(ROW()-ROW($C$2),3),ROW($C:$C),0)+3)-INDEX($C:$C,MATCH(ROW()-MOD(ROW()-ROW($C$2),3),ROW($C:$C),0)))} -> 13167.24
A7: =EDATE(A6,1) -> 37043 | B7: =TEXT(A7,"yyyy-mm-01") -> 2001-06-01 | C7: {=INDEX($C:$C,MATCH(ROW()-MOD(ROW()-ROW($C$2),3),ROW($C:$C),0))+(B7-INDEX($B:$B,MATCH(ROW()-MOD(ROW()-ROW($C$2),3),ROW($C:$C),0)))/(INDEX($B:$B,MATCH(ROW()-MOD(ROW()-ROW($C$2),3),ROW($C:$C),0)+3)-INDEX($B:$B,MATCH(ROW()-MOD(ROW()-ROW($C$2),3),ROW($C:$C),0)))*(INDEX($C:$C,MATCH(ROW()-MOD(ROW()-ROW($C$2),3),ROW($C:$C),0)+3)-INDEX($C:$C,MATCH(ROW()-MOD(ROW()-ROW($C$2),3),ROW($C:$C),0)))} -> 13357.502
A8: =EDATE(A7,1) -> 37073 | B8: =TEXT(A8,"yyyy-mm-01") -> 2001-07-01 | C8: =VLOOKUP(B8,'Final Cle'!$C$2:$D$103,2,FALSE) -> 13541.625
A9: =EDATE(A8,1) -> 37104 | B9: =TEXT(A9,"yyyy-mm-01") -> 2001-08-01 | C9: {=INDEX($C:$C,MATCH(ROW()-MOD(ROW()-ROW($C$2),3),ROW($C:$C),0))+(B9-INDEX($B:$B,MATCH(ROW()-MOD(ROW()-ROW($C$2),3),ROW($C:$C),0)))/(INDEX($B:$B,MATCH(ROW()-MOD(ROW()-ROW($C$2),3),ROW($C:$C),0)+3)-INDEX($B:$B,MATCH(ROW()-MOD(ROW()-ROW($C$2),3),ROW($C:$C),0)))*(INDEX($C:$C,MATCH(ROW()-MOD(ROW()-ROW($C$2),3),ROW($C:$C),0)+3)-INDEX($C:$C,MATCH(ROW()-MOD(ROW()-ROW($C$2),3),ROW($C:$C),0)))} -> 13810.262
A10: =EDATE(A9,1) -> 37135 | B10: =TEXT(A10,"yyyy-mm-01") -> 2001-09-01 | C10: {=INDEX($C:$C,MATCH(ROW()-MOD(ROW()-ROW($C$2),3),ROW($C:$C),0))+(B10-INDEX($B:$B,MATCH(ROW()-MOD(ROW()-ROW($C$2),3),ROW($C:$C),0)))/(INDEX($B:$B,MATCH(ROW()-MOD(ROW()-ROW($C$2),3),ROW($C:$C),0)+3)-INDEX($B:$B,MATCH(ROW()-MOD(ROW()-ROW($C$2),3),ROW($C:$C),0)))*(INDEX($C:$C,MATCH(ROW()-MOD(ROW()-ROW($C$2),3),ROW($C:$C),0)+3)-INDEX($C:$C,MATCH(ROW()-MOD(ROW()-ROW($C$2),3),ROW($C:$C),0)))} -> 14078.899
A11: =EDATE(A10,1) -> 37165 | B11: =TEXT(A11,"yyyy-mm-01") -> 2001-10-01 | C11: =VLOOKUP(B11,'Final Cle'!$C$2:$D$103,2,FALSE) -> 14338.871
A12: =EDATE(A11,1) -> 37196 | B12: =TEXT(A12,"yyyy-mm-01") -> 2001-11-01 | C12: {=INDEX($C:$C,MATCH(ROW()-MOD(ROW()-ROW($C$2),3),ROW($C:$C),0))+(B12-INDEX($B:$B,MATCH(ROW()-MOD(ROW()-ROW($C$2),3),ROW($C:$C),0)))/(INDEX($B:$B,MATCH(ROW()-MOD(ROW()-ROW($C$2),3),ROW($C:$C),0)+3)-INDEX($B:$B,MATCH(ROW()-MOD(ROW()-ROW($C$2),3),ROW($C:$C),0)))*(INDEX($C:$C,MATCH(ROW()-MOD(ROW()-ROW($C$2),3),ROW($C:$C),0)+3)-INDEX($C:$C,MATCH(ROW()-MOD(ROW()-ROW($C$2),3),ROW($C:$C),0)))} -> 14564.401
A13: =EDATE(A12,1) -> 37226 | B13: =TEXT(A13,"yyyy-mm-01") -> 2001-12-01 | C13: {=INDEX($C:$C,MATCH(ROW()-MOD(ROW()-ROW($C$2),3),ROW($C:$C),0))+(B13-INDEX($B:$B,MATCH(ROW()-MOD(ROW()-ROW($C$2),3),ROW($C:$C),0)))/(INDEX($B:$B,MATCH(ROW()-MOD(ROW()-ROW($C$2),3),ROW($C:$C),0)+3)-INDEX($B:$B,MATCH(ROW()-MOD(ROW()-ROW($C$2),3),ROW($C:$C),0)))*(INDEX($C:$C,MATCH(ROW()-MOD(ROW()-ROW($C$2),3),ROW($C:$C),0)+3)-INDEX($C:$C,MATCH(ROW()-MOD(ROW()-ROW($C$2),3),ROW($C:$C),0)))} -> 14782.656
A14: =EDATE(A13,1) -> 37257 | B14: =TEXT(A14,"yyyy-mm-01") -> 2002-01-01 | C14: =VLOOKUP(B14,'Final Cle'!$C$2:$D$103,2,FALSE) -> 15008.185
A15: =EDATE(A14,1) -> 37288 | B15: =TEXT(A15,"yyyy-mm-01") -> 2002-02-01 | C15: {=INDEX($C:$C,MATCH(ROW()-MOD(ROW()-ROW($C$2),3),ROW($C:$C),0))+(B15-INDEX($B:$B,MATCH(ROW()-MOD(ROW()-ROW($C$2),3),ROW($C:$C),0)))/(INDEX($B:$B,MATCH(ROW()-MOD(ROW()-ROW($C$2),3),ROW($C:$C),0)+3)-INDEX($B:$B,MATCH(ROW()-MOD(ROW()-ROW($C$2),3),ROW($C:$C),0)))*(INDEX($C:$C,MATCH(ROW()-MOD(ROW()-ROW($C$2),3),ROW($C:$C),0)+3)-INDEX($C:$C,MATCH(ROW()-MOD(ROW()-ROW($C$2),3),ROW($C:$C),0)))} -> 15131.944
A16: =EDATE(A15,1) -> 37316 | B16: =TEXT(A16,"yyyy-mm-01") -> 2002-03-01 | C16: {=INDEX($C:$C,MATCH(ROW()-MOD(ROW()-ROW($C$2),3),ROW($C:$C),0))+(B16-INDEX($B:$B,MATCH(ROW()-MOD(ROW()-ROW($C$2),3),ROW($C:$C),0)))/(INDEX($B:$B,MATCH(ROW()-MOD(ROW()-ROW($C$2),3),ROW($C:$C),0)+3)-INDEX($B:$B,MATCH(ROW()-MOD(ROW()-ROW($C$2),3),ROW($C:$C),0)))*(INDEX($C:$C,MATCH(ROW()-MOD(ROW()-ROW($C$2),3),ROW($C:$C),0)+3)-INDEX($C:$C,MATCH(ROW()-MOD(ROW()-ROW($C$2),3),ROW($C:$C),0)))} -> 15243.726
A17: =EDATE(A16,1) -> 37347 | B17: =TEXT(A17,"yyyy-mm-01") -> 2002-04-01 | C17: =VLOOKUP(B17,'Final Cle'!$C$2:$D$103,2,FALSE) -> 15367.485
A18: =EDATE(A17,1) -> 37377 | B18: =TEXT(A18,"yyyy-mm-01") -> 2002-05-01 | C18: {=INDEX($C:$C,MATCH(ROW()-MOD(ROW()-ROW($C$2),3),ROW($C:$C),0))+(B18-INDEX($B:$B,MATCH(ROW()-MOD(ROW()-ROW($C$2),3),ROW($C:$C),0)))/(INDEX($B:$B,MATCH(ROW()-MOD(ROW()-ROW($C$2),3),ROW($C:$C),0)+3)-INDEX($B:$B,MATCH(ROW()-MOD(ROW()-ROW($C$2),3),ROW($C:$C),0)))*(INDEX($C:$C,MATCH(ROW()-MOD(ROW()-ROW($C$2),3),ROW($C:$C),0)+3)-INDEX($C:$C,MATCH(ROW()-MOD(ROW()-ROW($C$2),3),ROW($C:$C),0)))} -> 15658.315
A19: =EDATE(A18,1) -> 37408 | B19: =TEXT(A19,"yyyy-mm-01") -> 2002-06-01 | C19: {=INDEX($C:$C,MATCH(ROW()-MOD(ROW()-ROW($C$2),3),ROW($C:$C),0))+(B19-INDEX($B:$B,MATCH(ROW()-MOD(ROW()-ROW($C$2),3),ROW($C:$C),0)))/(INDEX($B:$B,MATCH(ROW()-MOD(ROW()-ROW($C$2),3),ROW($C:$C),0)+3)-INDEX($B:$B,MATCH(ROW()-MOD(ROW()-ROW($C$2),3),ROW($C:$C),0)))*(INDEX($C:$C,MATCH(ROW()-MOD(ROW()-ROW($C$2),3),ROW($C:$C),0)+3)-INDEX($C:$C,MATCH(ROW()-MOD(ROW()-ROW($C$2),3),ROW($C:$C),0)))} -> 15958.839
A20: =EDATE(A19,1) -> 37438 | B20: =TEXT(A20,"yyyy-mm-01") -> 2002-07-01 | C20: =VLOOKUP(B20,'Final Cle'!$C$2:$D$103,2,FALSE) -> 16249.669
A21: =EDATE(A20,1) -> 37469 | B21: =TEXT(A21,"yyyy-mm-01") -> 2002-08-01 | C21: {=INDEX($C:$C,MATCH(ROW()-MOD(ROW()-ROW($C$2),3),ROW($C:$C),0))+(B21-INDEX($B:$B,MATCH(ROW()-MOD(ROW()-ROW($C$2),3),ROW($C:$C),0)))/(INDEX($B:$B,MATCH(ROW()-MOD(ROW()-ROW($C$2),3),ROW($C:$C),0)+3)-INDEX($B:$B,MATCH(ROW()-MOD(ROW()-ROW($C$2),3),ROW($C:$C),0)))*(INDEX($C:$C,MATCH(ROW()-MOD(ROW()-ROW($C$2),3),ROW($C:$C),0)+3)-INDEX($C:$C,MATCH(ROW()-MOD(ROW()-ROW($C$2),3),ROW($C:$C),0)))} -> 16548.372
A22: =EDATE(A21,1) -> 37500 | B22: =TEXT(A22,"yyyy-mm-01") -> 2002-09-01 | C22: {=INDEX($C:$C,MATCH(ROW()-MOD(ROW()-ROW($C$2),3),ROW($C:$C),0))+(B22-INDEX($B:$B,MATCH(ROW()-MOD(ROW()-ROW($C$2),3),ROW($C:$C),0)))/(INDEX($B:$B,MATCH(ROW()-MOD(ROW()-ROW($C$2),3),ROW($C:$C),0)+3)-INDEX($B:$B,MATCH(ROW()-MOD(ROW()-ROW($C$2),3),ROW($C:$C),0)))*(INDEX($C:$C,MATCH(ROW()-MOD(ROW()-ROW($C$2),3),ROW($C:$C),0)+3)-INDEX($C:$C,MATCH(ROW()-MOD(ROW()-ROW($C$2),3),ROW($C:$C),0)))} -> 16847.075
A23: =EDATE(A22,1) -> 37530 | B23: =TEXT(A23,"yyyy-mm-01") -> 2002-10-01 | C23: =VLOOKUP(B23,'Final Cle'!$C$2:$D$103,2,FALSE) -> 17136.142
A24: =EDATE(A23,1) -> 37561 | B24: =TEXT(A24,"yyyy-mm-01") -> 2002-11-01 | C24: {=INDEX($C:$C,MATCH(ROW()-MOD(ROW()-ROW($C$2),3),ROW($C:$C),0))+(B24-INDEX($B:$B,MATCH(ROW()-MOD(ROW()-ROW($C$2),3),ROW($C:$C),0)))/(INDEX($B:$B,MATCH(ROW()-MOD(ROW()-ROW($C$2),3),ROW($C:$C),0)+3)-INDEX($B:$B,MATCH(ROW()-MOD(ROW()-ROW($C$2),3),ROW($C:$C),0)))*(INDEX($C:$C,MATCH(ROW()-MOD(ROW()-ROW($C$2),3),ROW($C:$C),0)+3)-INDEX($C:$C,MATCH(ROW()-MOD(ROW()-ROW($C$2),3),ROW($C:$C),0)))} -> 17472.64
A25: =EDATE(A24,1) -> 37591 | B25: =TEXT(A25,"yyyy-mm-01") -> 2002-12-01 | C25: {=INDEX($C:$C,MATCH(ROW()-MOD(ROW()-ROW($C$2),3),ROW($C:$C),0))+(B25-INDEX($B:$B,MATCH(ROW()-MOD(ROW()-ROW($C$2),3),ROW($C:$C),0)))/(INDEX($B:$B,MATCH(ROW()-MOD(ROW()-ROW($C$2),3),ROW($C:$C),0)+3)-INDEX($B:$B,MATCH(ROW()-MOD(ROW()-ROW($C$2),3),ROW($C:$C),0)))*(INDEX($C:$C,MATCH(ROW()-MOD(ROW()-ROW($C$2),3),ROW($C:$C),0)+3)-INDEX($C:$C,MATCH(ROW()-MOD(ROW()-ROW($C$2),3),ROW($C:$C),0)))} -> 17798.283
A26: =EDATE(A25,1) -> 37622 | B26: =TEXT(A26,"yyyy-mm-01") -> 2003-01-01 | C26: =VLOOKUP(B26,'Final Cle'!$C$2:$D$103,2,FALSE) -> 18134.781
A27: =EDATE(A26,1) -> 37653 | B27: =TEXT(A27,"yyyy-mm-01") -> 2003-02-01 | C27: {=INDEX($C:$C,MATCH(ROW()-MOD(ROW()-ROW($C$2),3),ROW($C:$C),0))+(B27-INDEX($B:$B,MATCH(ROW()-MOD(ROW()-ROW($C$2),3),ROW($C:$C),0)))/(INDEX($B:$B,MATCH(ROW()-MOD(ROW()-ROW($C$2),3),ROW($C:$C),0)+3)-INDEX($B:$B,MATCH(ROW()-MOD(ROW()-ROW($C$2),3),ROW($C:$C),0)))*(INDEX($C:$C,MATCH(ROW()-MOD(ROW()-ROW($C$2),3),ROW($C:$C),0)+3)-INDEX($C:$C,MATCH(ROW()-MOD(ROW()-ROW($C$2),3),ROW($C:$C),0)))} -> 18341.031
A28: =EDATE(A27,1) -> 37681 | B28: =TEXT(A28,"yyyy-mm-01") -> 2003-03-01 | C28: {=INDEX($C:$C,MATCH(ROW()-MOD(ROW()-ROW($C$2),3),ROW($C:$C),0))+(B28-INDEX($B:$B,MATCH(ROW()-MOD(ROW()-ROW($C$2),3),ROW($C:$C),0)))/(INDEX($B:$B,MATCH(ROW()-MOD(ROW()-ROW($C$2),3),ROW($C:$C),0)+3)-INDEX($B:$B,MATCH(ROW()-MOD(ROW()-ROW($C$2),3),ROW($C:$C),0)))*(INDEX($C:$C,MATCH(ROW()-MOD(ROW()-ROW($C$2),3),ROW($C:$C),0)+3)-INDEX($C:$C,MATCH(ROW()-MOD(ROW()-ROW($C$2),3),ROW($C:$C),0)))} -> 18527.321
A29: =EDATE(A28,1) -> 37712 | B29: =TEXT(A29,"yyyy-mm-01") -> 2003-04-01 | C29: =VLOOKUP(B29,'Final Cle'!$C$2:$D$103,2,FALSE) -> 18733.571
A30: =EDATE(A29,1) -> 37742 | B30: =TEXT(A30,"yyyy-mm-01") -> 2003-05-01 | C30: {=INDEX($C:$C,MATCH(ROW()-MOD(ROW()-ROW($C$2),3),ROW($C:$C),0))+(B30-INDEX($B:$B,MATCH(ROW()-MOD(ROW()-ROW($C$2),3),ROW($C:$C),0)))/(INDEX($B:$B,MATCH(ROW()-MOD(ROW()-ROW($C$2),3),ROW($C:$C),0)+3)-INDEX($B:$B,MATCH(ROW()-MOD(ROW()-ROW($C$2),3),ROW($C:$C),0)))*(INDEX($C:$C,MATCH(ROW()-MOD(ROW()-ROW($C$2),3),ROW($C:$C),0)+3)-INDEX($C:$C,MATCH(ROW()-MOD(ROW()-ROW($C$2),3),ROW($C:$C),0)))} -> 19165.289
A31: =EDATE(A30,1) -> 37773 | B31: =TEXT(A31,"yyyy-mm-01") -> 2003-06-01 | C31: {=INDEX($C:$C,MATCH(ROW()-MOD(ROW()-ROW($C$2),3),ROW($C:$C),0))+(B31-INDEX($B:$B,MATCH(ROW()-MOD(ROW()-ROW($C$2),3),ROW($C:$C),0)))/(INDEX($B:$B,MATCH(ROW()-MOD(ROW()-ROW($C$2),3),ROW($C:$C),0)+3)-INDEX($B:$B,MATCH(ROW()-MOD(ROW()-ROW($C$2),3),ROW($C:$C),0)))*(INDEX($C:$C,MATCH(ROW()-MOD(ROW()-ROW($C$2),3),ROW($C:$C),0)+3)-INDEX($C:$C,MATCH(ROW()-MOD(ROW()-ROW($C$2),3),ROW($C:$C),0)))} -> 19611.398
A32: =EDATE(A31,1) -> 37803 | B32: =TEXT(A32,"yyyy-mm-01") -> 2003-07-01 | C32: =VLOOKUP(B32,'Final Cle'!$C$2:$D$103,2,FALSE) -> 20043.117
A33: =EDATE(A32,1) -> 37834 | B33: =TEXT(A33,"yyyy-mm-01") -> 2003-08-01 | C33: {=INDEX($C:$C,MATCH(ROW()-MOD(ROW()-ROW($C$2),3),ROW($C:$C),0))+(B33-INDEX($B:$B,MATCH(ROW()-MOD(ROW()-ROW($C$2),3),ROW($C:$C),0)))/(INDEX($B:$B,MATCH(ROW()-MOD(ROW()-ROW($C$2),3),ROW($C:$C),0)+3)-INDEX($B:$B,MATCH(ROW()-MOD(ROW()-ROW($C$2),3),ROW($C:$C),0)))*(INDEX($C:$C,MATCH(ROW()-MOD(ROW()-ROW($C$2),3),ROW($C:$C),0)+3)-INDEX($C:$C,MATCH(ROW()-MOD(ROW()-ROW($C$2),3),ROW($C:$C),0)))} -> 20574.292
A34: =EDATE(A33,1) -> 37865 | B34: =TEXT(A34,"yyyy-mm-01") -> 2003-09-01 | C34: {=INDEX($C:$C,MATCH(ROW()-MOD(ROW()-ROW($C$2),3),ROW($C:$C),0))+(B34-INDEX($B:$B,MATCH(ROW()-MOD(ROW()-ROW($C$2),3),ROW($C:$C),0)))/(INDEX($B:$B,MATCH(ROW()-MOD(ROW()-ROW($C$2),3),ROW($C:$C),0)+3)-INDEX($B:$B,MATCH(ROW()-MOD(ROW()-ROW($C$2),3),ROW($C:$C),0)))*(INDEX($C:$C,MATCH(ROW()-MOD(ROW()-ROW($C$2),3),ROW($C:$C),0)+3)-INDEX($C:$C,MATCH(ROW()-MOD(ROW()-ROW($C$2),3),ROW($C:$C),0)))} -> 21105.468
A35: =EDATE(A34,1) -> 37895 | B35: =TEXT(A35,"yyyy-mm-01") -> 2003-10-01 | C35: =VLOOKUP(B35,'Final Cle'!$C$2:$D$103,2,FALSE) -> 21619.509
A36: =EDATE(A35,1) -> 37926 | B36: =TEXT(A36,"yyyy-mm-01") -> 2003-11-01 | C36: {=INDEX($C:$C,MATCH(ROW()-MOD(ROW()-ROW($C$2),3),ROW($C:$C),0))+(B36-INDEX($B:$B,MATCH(ROW()-MOD(ROW()-ROW($C$2),3),ROW($C:$C),0)))/(INDEX($B:$B,MATCH(ROW()-MOD(ROW()-ROW($C$2),3),ROW($C:$C),0)+3)-INDEX($B:$B,MATCH(ROW()-MOD(ROW()-ROW($C$2),3),ROW($C:$C),0)))*(INDEX($C:$C,MATCH(ROW()-MOD(ROW()-ROW($C$2),3),ROW($C:$C),0)+3)-INDEX($C:$C,MATCH(ROW()-MOD(ROW()-ROW($C$2),3),ROW($C:$C),0)))} -> 22114.762
A37: =EDATE(A36,1) -> 37956 | B37: =TEXT(A37,"yyyy-mm-01") -> 2003-12-01 | C37: {=INDEX($C:$C,MATCH(ROW()-MOD(ROW()-ROW($C$2),3),ROW($C:$C),0))+(B37-INDEX($B:$B,MATCH(ROW()-MOD(ROW()-ROW($C$2),3),ROW($C:$C),0)))/(INDEX($B:$B,MATCH(ROW()-MOD(ROW()-ROW($C$2),3),ROW($C:$C),0)+3)-INDEX($B:$B,MATCH(ROW()-MOD(ROW()-ROW($C$2),3),ROW($C:$C),0)))*(INDEX($C:$C,MATCH(ROW()-MOD(ROW()-ROW($C$2),3),ROW($C:$C),0)+3)-INDEX($C:$C,MATCH(ROW()-MOD(ROW()-ROW($C$2),3),ROW($C:$C),0)))} -> 22594.04
A38: =EDATE(A37,1) -> 37987 | B38: =TEXT(A38,"yyyy-mm-01") -> 2004-01-01 | C38: =VLOOKUP(B38,'Final Cle'!$C$2:$D$103,2,FALSE) -> 23089.293
A39: =EDATE(A38,1) -> 38018 | B39: =TEXT(A39,"yyyy-mm-01") -> 2004-02-01 | C39: {=INDEX($C:$C,MATCH(ROW()-MOD(ROW()-ROW($C$2),3),ROW($C:$C),0))+(B39-INDEX($B:$B,MATCH(ROW()-MOD(ROW()-ROW($C$2),3),ROW($C:$C),0)))/(INDEX($B:$B,MATCH(ROW()-MOD(ROW()-ROW($C$2),3),ROW($C:$C),0)+3)-INDEX($B:$B,MATCH(ROW()-MOD(ROW()-ROW($C$2),3),ROW($C:$C),0)))*(INDEX($C:$C,MATCH(ROW()-MOD(ROW()-ROW($C$2),3),ROW($C:$C),0)+3)-INDEX($C:$C,MATCH(ROW()-MOD(ROW()-ROW($C$2),3),ROW($C:$C),0)))} -> 23488.112
A40: =EDATE(A39,1) -> 38047 | B40: =TEXT(A40,"yyyy-mm-01") -> 2004-03-01 | C40: {=INDEX($C:$C,MATCH(ROW()-MOD(ROW()-ROW($C$2),3),ROW($C:$C),0))+(B40-INDEX($B:$B,MATCH(ROW()-MOD(ROW()-ROW($C$2),3),ROW($C:$C),0)))/(INDEX($B:$B,MATCH(ROW()-MOD(ROW()-ROW($C$2),3),ROW($C:$C),0)+3)-INDEX($B:$B,MATCH(ROW()-MOD(ROW()-ROW($C$2),3),ROW($C:$C),0)))*(INDEX($C:$C,MATCH(ROW()-MOD(ROW()-ROW($C$2),3),ROW($C:$C),0)+3)-INDEX($C:$C,MATCH(ROW()-MOD(ROW()-ROW($C$2),3),ROW($C:$C),0)))} -> 23861.202
...

Sheet Final Cle
A1: Date | B1: ='1. standard presentation'!A4 -> External debt | C1: Date | D1: =B1 -> External debt
A2: 36892 | B2: {=TRANSPOSE('1. standard presentation'!C4:CZ4)} -> 12634.572 | C2: =TEXT(A2,"yyyy-mm-01") -> 2001-01-01 | D2: =B2 -> 12634.572
A3: 36982 | B3: 12983.117 | C3: =TEXT(A3,"yyyy-mm-01") -> 2001-04-01 | D3: =B3 -> 12983.117
A4: 37073 | B4: 13541.625 | C4: =TEXT(A4,"yyyy-mm-01") -> 2001-07-01 | D4: =B4 -> 13541.625
A5: 37165 | B5: 14338.871 | C5: =TEXT(A5,"yyyy-mm-01") -> 2001-10-01 | D5: =B5 -> 14338.871
A6: 37257 | B6: 15008.185 | C6: =TEXT(A6,"yyyy-mm-01") -> 2002-01-01 | D6: =B6 -> 15008.185
A7: 37347 | B7: 15367.485 | C7: =TEXT(A7,"yyyy-mm-01") -> 2002-04-01 | D7: =B7 -> 15367.485
A8: 37438 | B8: 16249.669 | C8: =TEXT(A8,"yyyy-mm-01") -> 2002-07-01 | D8: =B8 -> 16249.669
A9: 37530 | B9: 17136.142 | C9: =TEXT(A9,"yyyy-mm-01") -> 2002-10-01 | D9: =B9 -> 17136.142
A10: 37622 | B10: 18134.781 | C10: =TEXT(A10,"yyyy-mm-01") -> 2003-01-01 | D10: =B10 -> 18134.781
A11: 37712 | B11: 18733.571 | C11: =TEXT(A11,"yyyy-mm-01") -> 2003-04-01 | D11: =B11 -> 18733.571
A12: 37803 | B12: 20043.117 | C12: =TEXT(A12,"yyyy-mm-01") -> 2003-07-01 | D12: =B12 -> 20043.117
A13: 37895 | B13: 21619.509 | C13: =TEXT(A13,"yyyy-mm-01") -> 2003-10-01 | D13: =B13 -> 21619.509
A14: 37987 | B14: 23089.293 | C14: =TEXT(A14,"yyyy-mm-01") -> 2004-01-01 | D14: =B14 -> 23089.293
... A103: 46113 | B103: 182778.24 | C103: =TEXT(A103,"yyyy-mm-01") -> 2026-04-01 | D103: =B103 -> 182778.24

Sheet Final Cleaned
A1: date | B1: kz_extdebt_m
A2: ='Final Cle'!C2 -> 2001-01-01 | B2: ='Final Cle'!D2 -> 12634.572
A3: ='Final Cle'!C3 -> 2001-04-01 | B3: ='Final Cle'!D3 -> 12983.117
A4: ='Final Cle'!C4 -> 2001-07-01 | B4: ='Final Cle'!D4 -> 13541.625
A5: ='Final Cle'!C5 -> 2001-10-01 | B5: ='Final Cle'!D5 -> 14338.871
A6: ='Final Cle'!C6 -> 2002-01-01 | B6: ='Final Cle'!D6 -> 15008.185
A7: ='Final Cle'!C7 -> 2002-04-01 | B7: ='Final Cle'!D7 -> 15367.485
A8: ='Final Cle'!C8 -> 2002-07-01 | B8: ='Final Cle'!D8 -> 16249.669
A9: ='Final Cle'!C9 -> 2002-10-01 | B9: ='Final Cle'!D9 -> 17136.142
A10: ='Final Cle'!C10 -> 2003-01-01 | B10: ='Final Cle'!D10 -> 18134.781
A11: ='Final Cle'!C11 -> 2003-04-01 | B11: ='Final Cle'!D11 -> 18733.571
A12: ='Final Cle'!C12 -> 2003-07-01 | B12: ='Final Cle'!D12 -> 20043.117
A13: ='Final Cle'!C13 -> 2003-10-01 | B13: ='Final Cle'!D13 -> 21619.509
... A103: ='Final Cle'!C103 -> 2026-04-01 | B103: ='Final Cle'!D103 -> 182778.24

Sheet Metadata
A1: Name of the Statistical Indicator | B1: External Debt of Kazakhstan
A2: Responsible institution | B2: The National Bank of the Republic of Kazakhstan
A3: Unit of measurement | B3: Million US dollars
A4: Frequency | B4: Quarterly
A5: History of the Indicator | B5: Since 2001
A6: Definition of the Indicator | B6: External Debt indicators
A7: Data | B7: Aggregated statistical and administrative data
A8: Methodology for Calculation | B8: The methodological and conceptual framework for the compilation of external debt statistics is the joint document of international organizations "External Debt Statistics: a Guide for compilers and users", "Public Sector Debt Statistics in an expanded definition: a guide for compilers and users", as well as the sixth edition of the "Balance of Payments and International Investment Position Guide" of the International Monetary Fund (BPM6)
A9: Source of the Indicator | B9: Statistical and administrative reports of banks, professional participants of the securities market, other financial and non-financial organizations, including branches of foreign companies and government agencies, administrative reports of individuals, financial statements of individual organizations, accounting data of the National Bank of Kazakhstan and reports of the global custodian on the assets of the National Fund.
A10: Methodological Explanations | B10: https://nationalbank.kz/en/news/metodologicheskiy-kommentariy/7348
A11: Related Publications | B11: https://nationalbank.kz/en/news/platezhnyy-balans/rubrics/2358
A12: Useful Links | B12: https://nationalbank.kz/en/news/vneshniy-dolg https://data.nationalbank.kz/
A13: Date of Last Update | B13: 46213
A14: Date of Next Update | B14: 46295
A15: Responsible Structural Division | B15: Balance of Payments Department
A16: Responsible Officer | B16: Aigul Kassymova
A17: Telephone Number | B17: +7 (7172) 77 55 10
A18: E-mail | B18: kasimova@nationalbank.kz
A19: Terms of use | B19: Users without conclusion of the contract with the National Bank of the Republic of Kazakhstan have the right to use official statistical information Use of data, including its reuse, is permitted free of charge, in perpetuity, and without territorial restrictions. Users are granted the right to: - reproduce, copy, and distribute information, subject to mandatory citation of the source; - publish and integrate data with other information; - use data for software development and other applications.

Sheet Content
A2: External Debt of the Republic of Kazakhstan as of April 1st, 2026
A4: Content:
A5: Sheet 1. | B5: Standard presentation
A6: Sheet 2. | B6: Analytical presentation
A7: Sheet 3. | B7: Absolute and comparative indicators
A8: Sheet 4. | B8: Reconciliation of positions and flows of the external debt
A9: Sheet 5. | B9: Net external debt
A10: Sheet 6. | B10: Debt securities (issued by residents and belonging to non-residents) by the location of the issue

Sheet 1. standard presentation
A1: External debt: standard presentation
A2: mln.US dollars
B3: Row's code | C3: 01.01.2001 | D3: 01.04.2001 | E3: 01.07.2001 | F3: 01.10.2001 | G3: 01.01.2002 | H3: 01.04.2002 | I3: 01.07.2002 | J3: 01.10.2002 | K3: 01.01.2003 | L3: 01.04.2003 | M3: 01.07.2003 | N3: 01.10.2003 | O3: 01.01.2004 | P3: 01.04.2004 | Q3: 01.07.2004 | R3: 01.10.2004 | S3: 01.01.2005 | T3: 01.04.2005 | U3: 01.07.2005 | V3: 01.10.2005 | W3: 01.01.2006 | X3: 01.04.2006 | Y3: 01.07.2006 | Z3: 01.10.2006 | AA3: 01.01.2007 | AB3: 01.04.2007 | AC3: 01.07.2007 | AD3: 01.10.2007 | AE3: 01.01.2008 | AF3: 01.04.2008 | AG3: 01.07.2008 | AH3: 01.10.2008 | AI3: 01.01.2009 | AJ3: 01.04.2009 | AK3: 01.07.2009 | AL3: 01.10.2009 | AM3: 01.01.2010 | AN3: 01.04.2010 | AO3: 01.07.2010 | AP3: 01.10.2010 | AQ3: 01.01.2011 | AR3: 01.04.2011 | AS3: 01.07.2011 | AT3: 01.10.2011 | AU3: 01.01.2012 | AV3: 01.04.2012 | AW3: 01.07.2012 | AX3: 01.10.2012 | AY3: 01.01.2013 | AZ3: 01.04.2013 | BA3: 01.07.2013 | BB3: 01.10.2013 | BC3: 01.01.2014 | BD3: 01.04.2014 | BE3: 01.07.2014 | BF3: 01.10.2014 | BG3: 01.01.2015 | BH3: 01.04.2015 | BI3: 01.07.2015 | BJ3: 01.10.2015 | BK3: 01.01.2016 | BL3: 01.04.2016 | BM3: 01.07.2016 | BN3: 01.10.2016 | BO3: 01.01.2017 | BP3: 01.04.2017 | BQ3: 01.07.2017 | BR3: 01.10.2017 | BS3: 01.01.2018 | BT3: 01.04.2018 | BU3: 01.07.2018 | BV3: 01.10.2018 | BW3: 01.01.2019 | BX3: 01.04.2019 | BY3: 01.07.2019 | BZ3: 01.10.2019 | CA3: 01.01.2020 | CB3: 01.04.2020 | CC3: 01.07.2020 | CD3: 01.10.2020 | CE3: 01.01.2021 | CF3: 01.04.2021 | CG3: 01.07.2021 | CH3: 01.10.2021 | CI3: 01.01.2022 | CJ3: 01.04.2022 | CK3: 01.07.2022 | CL3: 01.10.2022 | CM3: 01.01.2023 | CN3: 01.04.2023 | CO3: 01.07.2023 | CP3: 01.10.2023 | CQ3: 01.01.2024 | CR3: 01.04.2024 | CS3: 01.07.2024 | CT3: 01.10.2024 | CU3: 01.01.2025 | CV3: 01.04.2025 | CW3: 01.07.2025 | CX3: 01.10.2025 | CY3: 01.01.2026 | CZ3: 01.04.2026
A4: External debt | B4: 1=2+3= 4+18+32+45+65 | C4: 12634.572 | D4: 12983.117 | E4: 13541.625 | F4: 14338.871 | G4: 15008.185 | H4: 15367.485 | I4: 16249.669 | J4: 17136.142 | K4: 18134.781 | L4: 18733.571 | M4: 20043.117 | N4: 21619.509 | O4: 23089.293 | P4: 24260.021 | Q4: 25732.896 | R4: 27150.57 | S4: 32723.731 | T4: 34256.104 | U4: 35724.692 | V4: 38277.611 | W4: 43428.528 | X4: 48369.473 | Y4: 53969.645 | Z4: 60146.599 | AA4: 74014.09 | AB4: 81905.913 | AC4: 92367.909 | AD4: 94248.343 | AE4: 96893.004 | AF4: 98877.328 | AG4: 101204.66 | AH4: 105995.33 | AI4: 107933.38 | AJ4: 104803.67 | AK4: 106675.74 | AL4: 111527.94 | AM4: 112866.89 | AN4: 110861.49 | AO4: 113619.66 | AP4: 111518.69 | AQ4: 118222.76 | AR4: 123359.16 | AS4: 124897.28 | AT4: 123708.36 | AU4: 125320.78 | AV4: 129154.05 | AW4: 132535.86 | AX4: 134414.12 | AY4: 136918.22 | AZ4: 139691.46 | BA4: 145554.8 | BB4: 148162.71 | BC4: 150032.87 | BD4: 151504.68 | BE4: 155583.92 | BF4: 155674.88 | BG4: 157114.53 | BH4: 154065.71 | BI4: 155281.01 | BJ4: 155284.28 | BK4: 153006.61 | BL4: 153335.14 | BM4: 159864.39 | BN4: 164849.21 | BO4: 163528.49 | BP4: 165292.7 | BQ4: 167774.33 | BR4: 168847.75 | BS4: 167482.72 | BT4: 167755.6 | BU4: 165679.6 | BV4: 162643.83 | BW4: 160331.29 | BX4: 160238.82 | BY4: 160393.97 | BZ4: 160328.62 | CA4: 159544.22 | CB4: 155466.74 | CC4: 160585.79 | CD4: 161706.54 | CE4: 163980.07 | CF4: 163955.09 | CG4: 166483.08 | CH4: 165761.72 | CI4: 164131.07 | CJ4: 159896.77 | CK4: 164152.25 | CL4: 161096.2 | CM4: 161144.27 | CN4: 162813.97 | CO4: 162802.62 | CP4: 163809.5 | CQ4: 163711.96 | CR4: 163952.93 | CS4: 166853.1 | CT4: 166367.06 | CU4: 164677.5 | CV4: 170037.8 | CW4: 172547.08 | CX4: 171558.26 | CY4: 181841.59 | CZ4: 182778.24
A5: Short-term | B5: 2=5+19+33+47 | C5: 960.83644 | D5: 911.25592 | E5: 1138.6412 | F5: 1175.2842 | G5: 1340.1748 | H5: 1286.2567 | I5: 1302.8472 | J5: 1574.6118 | K5: 2046.2267 | L5: 2010.2172 | M5: 2072.5811 | N5: 2377.8123 | O5: 3170.7262 | P5: 2987.7319 | Q5: 3183.6475 | R5: 3286.6231 | S5: 3864.49 | T5: 4200.7061 | U5: 4631.3713 | V5: 5606.5683 | W5: 8102.4299 | X5: 8501.9101 | Y5: 9323.9373 | Z5: 8500.6954 | AA5: 12445.218 | AB5: 11304.022 | AC5: 14887.811 | AD5: 10631.068 | AE5: 11529.681 | AF5: 11483.766 | AG5: 10399.217 | AH5: 10318.871 | AI5: 9486.7669 | AJ5: 7645.767 | AK5: 8165.2547 | AL5: 7713.4861 | AM5: 6985.1371 | AN5: 7559.4129 | AO5: 6952.0543 | AP5: 7087.0754 | AQ5: 8864.4948 | AR5: 11006.615 | AS5: 9619.8061 | AT5: 7689.5421 | AU5: 7867.2054 | AV5: 7533.4188 | AW5: 8079.0231 | AX5: 7922.3727 | AY5: 9086.3352 | AZ5: 8322.4151 | BA5: 8328.2724 | BB5: 9186.0426 | BC5: 9468.0696 | BD5: 9277.9631 | BE5: 9867.1725 | BF5: 9291.2238 | BG5: 9713.7711 | BH5: 8085.0413 | BI5: 7796.8116 | BJ5: 6429.2748 | BK5: 6260.3316 | BL5: 6238.1279 | BM5: 6326.146 | BN5: 6733.0899 | BO5: 6560.2863 | BP5: 7052.3174 | BQ5: 7193.6603 | BR5: 7407.5321 | BS5: 7489.1819 | BT5: 8306.197 | BU5: 8085.9598 | BV5: 8157.0621 | BW5: 8150.4561 | BX5: 8197.3064 | BY5: 8290.6416 | BZ5: 8225.3025 | CA5: 8801.1863 | CB5: 8347.7253 | CC5: 8894.1643 | CD5: 9151.283 | CE5: 9481.0146 | CF5: 10955.212 | CG5: 12243.771 | CH5: 11585.003 | CI5: 12009.62 | CJ5: 11720.057 | CK5: 14150.405 | CL5: 15527.76 | CM5: 16335.689 | CN5: 17256.953 | CO5: 17200.649 | CP5: 18225.459 | CQ5: 19389.554 | CR5: 19132.3 | CS5: 20633.718 | CT5: 21269.029 | CU5: 19468.737 | CV5: 21617.707 | CW5: 22418.968 | CX5: 20927.888 | CY5: 21688.322 | CZ5: 23576.213
A6: Long-term | B6: 3=11+25+39+53+65 | C6: 11673.736 | D6: 12071.861 | E6: 12402.984 | F6: 13163.587 | G6: 13668.011 | H6: 14081.229 | I6: 14946.821 | J6: 15561.53 | K6: 16088.554 | L6: 16723.354 | M6: 17970.536 | N6: 19241.697 | O6: 19918.566 | P6: 21272.289 | Q6: 22549.248 | R6: 23863.947 | S6: 28859.241 | T6: 30055.397 | U6: 31093.321 | V6: 32671.043 | W6: 35326.098 | X6: 39867.563 | Y6: 44645.708 | Z6: 51645.904 | AA6: 61568.872 | AB6: 70601.891 | AC6: 77480.097 | AD6: 83617.275 | AE6: 85363.323 | AF6: 87393.562 | AG6: 90805.446 | AH6: 95676.459 | AI6: 98446.611 | AJ6: 97157.906 | AK6: 98510.486 | AL6: 103814.45 | AM6: 105881.75 | AN6: 103302.08 | AO6: 106667.6 | AP6: 104431.62 | AQ6: 109358.27 | AR6: 112352.54 | AS6: 115277.47 | AT6: 116018.82 | AU6: 117453.57 | AV6: 121620.64 | AW6: 124456.84 | AX6: 126491.74 | AY6: 127831.88 | AZ6: 131369.05 | BA6: 137226.53 | BB6: 138976.67 | BC6: 140564.8 | BD6: 142226.72 | BE6: 145716.75 | BF6: 146383.66 | BG6: 147400.76 | BH6: 145980.66 | BI6: 147484.19 | BJ6: 148855 | BK6: 146746.28 | BL6: 147097.02 | BM6: 153538.25 | BN6: 158116.12 | BO6: 156968.21 | BP6: 158240.38 | BQ6: 160580.67 | BR6: 161440.22 | BS6: 159993.53 | BT6: 159449.4 | BU6: 157593.64 | BV6: 154486.76 | BW6: 152180.84 | BX6: 152041.51 | BY6: 152103.33 | BZ6: 152103.32 | CA6: 150743.03 | CB6: 147119.02 | CC6: 151691.63 | CD6: 152555.25 | CE6: 154499.06 | CF6: 152999.88 | CG6: 154239.31 | CH6: 154176.72 | CI6: 152121.45 | CJ6: 148176.72 | CK6: 150001.84 | CL6: 145568.44 | CM6: 144808.58 | CN6: 145557.02 | CO6: 145601.97 | CP6: 145584.04 | CQ6: 144322.41 | CR6: 144820.63 | CS6: 146219.38 | CT6: 145098.04 | CU6: 145208.76 | CV6: 148420.09 | CW6: 150128.12 | CX6: 150630.37 | CY6: 160153.27 | CZ6: 159202.03
A7: General Government | B7: 4=5+11 | C7: 2825.1976 | D7: 2744.974 | E7: 2712.002 | F7: 2727.47 | G7: 2694.025 | H7: 2490.5336 | I7: 2472.8143 | J7: 2439.4797 | K7: 2334.0095 | L7: 2400.7822 | M7: 2404.6542 | N7: 2459.0988 | O7: 2552.3441 | P7: 2704.8274 | Q7: 2702.0244 | R7: 2716.7994 | S7: 2496.1174 | T7: 2348.1019 | U7: 2062.4565 | V7: 2058.5873 | W7: 1478.9213 | X7: 1495.2886 | Y7: 1507.0701 | Z7: 1450.3088 | AA7: 1495.1813 | AB7: 1468.0315 | AC7: 1422.5411 | AD7: 1483.659 | AE7: 1491.5012 | AF7: 1559.5994 | AG7: 1541.9171 | AH7: 1603.6395 | AI7: 1641.9025 | AJ7: 1572.43 | AK7: 1584.5043 | AL7: 1639.3944 | AM7: 2218.0983 | AN7: 2264.2314 | AO7: 2352.0124 | AP7: 3492.2507 | AQ7: 3800.2919 | AR7: 3797.4067 | AS7: 3975.9498 | AT7: 4223.0944 | AU7: 4487.4154 | AV7: 4418.6391 | AW7: 4450.1104 | AX7: 4554.0234 | AY7: 4855.1224 | AZ7: 4756.4511 | BA7: 4827.6286 | BB7: 4978.8035 | BC7: 5217.5756 | BD7: 5066.2462 | BE7: 5045.1768 | BF7: 5116.6368 | BG7: 7333.7497 | BH7: 7105.9885 | BI7: 7005.6957 | BJ7: 10319.729 | BK7: 11313.193 | BL7: 11337.067 | BM7: 12696.818 | BN7: 12698.964 | BO7: 12092.075 | BP7: 12170.192 | BQ7: 12145.184 | BR7: 12313.301 | BS7: 12067.476 | BT7: 11137.89 | BU7: 10690.4 | BV7: 10651.472 | BW7: 11554.788 | BX7: 11488.784 | BY7: 11888.719 | BZ7: 12793.613 | CA7: 12417.6 | CB7: 11428.362 | CC7: 11834.52 | CD7: 12295.063 | CE7: 13885.041 | CF7: 14471.581 | CG7: 15682.086 | CH7: 15936.662 | CI7: 15859.324 | CJ7: 14153.244 | CK7: 14283.313 | CL7: 12939.095 | CM7: 13389.992 | CN7: 12857.149 | CO7: 12686.181 | CP7: 12610.291 | CQ7: 11809.413 | CR7: 11227.058 | CS7: 10883.271 | CT7: 11660.378 | CU7: 12773.497 | CV7: 12526.665 | CW7: 12475.636 | CX7: 14035.644 | CY7: 15999.525 | CZ7: 16541.489
A8: Short-term | B8: 5=6+7+8+9+10 | C8: 0.4876 | D8: 0 | E8: 0 | F8: 0 | G8: 0 | H8: 0 | I8: 0 | J8: 0 | K8: 0 | L8: 0 | M8: 0 | N8: 0 | O8: 0 | P8: 0 | Q8: 0 | R8: 0 | S8: 0 | T8: 0 | U8: 0 | V8: 0 | W8: 0 | X8: 0 | Y8: 0 | Z8: 0 | AA8: 0 | AB8: 0 | AC8: 0 | AD8: 0 | AE8: 0 | AF8: 0 | AG8: 18.778108 | AH8: 35.336123 | AI8: 9.0254202e-05 | AJ8: 0 | AK8: 0 | AL8: 0 | AM8: 0 | AN8: 0 | AO8: 0 | AP8: 0 | AQ8: 0 | AR8: 8.0159595 | AS8: 55.584976 | AT8: 99.675935 | AU8: 7.8760593 | AV8: 0.10207803 | AW8: 0.10164985 | AX8: 0.101 | AY8: 0.101 | AZ8: 0.101 | BA8: 0 | BB8: 0 | BC8: 0 | BD8: 0 | BE8: 0 | BF8: 0.905 | BG8: 1.23 | BH8: 25.615611 | BI8: 25.207576 | BJ8: 16.096868 | BK8: 21.651824 | BL8: 21.632227 | BM8: 15.877645 | BN8: 15.880973 | BO8: 13.61159 | BP8: 11.598057 | BQ8: 14.030109 | BR8: 16.915808 | BS8: 19.309576 | BT8: 17.587462 | BU8: 21.548471 | BV8: 23.058446 | BW8: 17.908613 | BX8: 17.773797 | BY8: 17.441582 | BZ8: 15.606123 | CA8: 14.929188 | CB8: 16.917969 | CC8: 18.888595 | CD8: 22.039426 | CE8: 24.613437 | CF8: 29.455581 | CG8: 32.246166 | CH8: 28.994734 | CI8: 24.301409 | CJ8: 30.411785 | CK8: 35.659143 | CL8: 35.089092 | CM8: 55.365297 | CN8: 59.579994 | CO8: 54.364503 | CP8: 114.65215 | CQ8: 115.77272 | CR8: 121.67959 | CS8: 120.49025 | CT8: 245.2924 | CU8: 183.63558 | CV8: 185.62672 | CW8: 157.56755 | CX8: 145.88062 | CY8: 118.60584 | CZ8: 127.4558
A9: Currency and deposits | B9: 6 | C9: 0 | D9: 0 | E9: 0 | F9: 0 | G9: 0 | H9: 0 | I9: 0 | J9: 0 | K9: 0 | L9: 0 | M9: 0 | N9: 0 | O9: 0 | P9: 0 | Q9: 0 | R9: 0 | S9: 0 | T9: 0 | U9: 0 | V9: 0 | W9: 0 | X9: 0 | Y9: 0 | Z9: 0 | AA9: 0 | AB9: 0 | AC9: 0 | AD9: 0 | AE9: 0 | AF9: 0 | AG9: 0 | AH9: 0 | AI9: 0 | AJ9: 0 | AK9: 0 | AL9: 0 | AM9: 0 | AN9: 0 | AO9: 0 | AP9: 0 | AQ9: 0 | AR9: 0 | AS9: 0 | AT9: 0 | AU9: 0 | AV9: 0 | AW9: 0 | AX9: 0 | AY9: 0 | AZ9: 0 | BA9: 0 | BB9: 0 | BC9: 0 | BD9: 0 | BE9: 0 | BF9: 0 | BG9: 0 | BH9: 0 | BI9: 0 | BJ9: 0 | BK9: 0 | BL9: 0 | BM9: 0 | BN9: 0 | BO9: 0 | BP9: 0 | BQ9: 0 | BR9: 0 | BS9: 0 | BT9: 0 | BU9: 0 | BV9: 0 | BW9: 0 | BX9: 0 | BY9: 0 | BZ9: 0 | CA9: 0 | CB9: 0 | CC9: 0 | CD9: 0 | CE9: 0 | CF9: 0 | CG9: 0 | CH9: 0 | CI9: 0 | CJ9: 0 | CK9: 0 | CL9: 0 | CM9: 0 | CN9: 0 | CO9: 0 | CP9: 0 | CQ9: 0 | CR9: 0 | CS9: 0 | CT9: 0 | CU9: 0 | CV9: 0 | CW9: 0 | CX9: 0 | CY9: 0 | CZ9: 0
A10: Debt securities1 | B10: 7 | C10: 0.4876 | D10: 0 | E10: 0 | F10: 0 | G10: 0 | H10: 0 | I10: 0 | J10: 0 | K10: 0 | L10: 0 | M10: 0 | N10: 0 | O10: 0 | P10: 0 | Q10: 0 | R10: 0 | S10: 0 | T10: 0 | U10: 0 | V10: 0 | W10: 0 | X10: 0 | Y10: 0 | Z10: 0 | AA10: 0 | AB10: 0 | AC10: 0 | AD10: 0 | AE10: 0 | AF10: 0 | AG10: 18.778108 | AH10: 35.336123 | AI10: 9.0254202e-05 | AJ10: 0 | AK10: 0 | AL10: 0 | AM10: 0 | AN10: 0 | AO10: 0 | AP10: 0 | AQ10: 0 | AR10: 7.9149595 | AS10: 55.483976 | AT10: 99.574935 | AU10: 7.7750593 | AV10: 0.0010780267 | AW10: 0.00064984607 | AX10: 0 | AY10: 0 | AZ10: 0 | BA10: 0 | BB10: 0 | BC10: 0 | BD10: 0 | BE10: 0 | BF10: 0 | BG10: 0 | BH10: 0 | BI10: 0 | BJ10: 0 | BK10: 0 | BL10: 0 | BM10: 0 | BN10: 0 | BO10: 0 | BP10: 0 | BQ10: 0 | BR10: 0 | BS10: 0 | BT10: 0 | BU10: 0 | BV10: 0 | BW10: 0 | BX10: 0 | BY10: 0 | BZ10: 0 | CA10: 0 | CB10: 0 | CC10: 0 | CD10: 0 | CE10: 0 | CF10: 0 | CG10: 0 | CH10: 0 | CI10: 0 | CJ10: 0 | CK10: 0 | CL10: 0 | CM10: 0 | CN10: 0 | CO10: 0 | CP10: 0 | CQ10: 0 | CR10: 0 | CS10: 0 | CT10: 0 | CU10: 0 | CV10: 0 | CW10: 0 | CX10: 0 | CY10: 0 | CZ10: 0
A11: Loans | B11: 8 | C11: 0 | D11: 0 | E11: 0 | F11: 0 | G11: 0 | H11: 0 | I11: 0 | J11: 0 | K11: 0 | L11: 0 | M11: 0 | N11: 0 | O11: 0 | P11: 0 | Q11: 0 | R11: 0 | S11: 0 | T11: 0 | U11: 0 | V11: 0 | W11: 0 | X11: 0 | Y11: 0 | Z11: 0 | AA11: 0 | AB11: 0 | AC11: 0 | AD11: 0 | AE11: 0 | AF11: 0 | AG11: 0 | AH11: 0 | AI11: 0 | AJ11: 0 | AK11: 0 | AL11: 0 | AM11: 0 | AN11: 0 | AO11: 0 | AP11: 0 | AQ11: 0 | AR11: 0 | AS11: 0 | AT11: 0 | AU11: 0 | AV11: 0 | AW11: 0 | AX11: 0 | AY11: 0 | AZ11: 0 | BA11: 0 | BB11: 0 | BC11: 0 | BD11: 0 | BE11: 0 | BF11: 0 | BG11: 0 | BH11: 0 | BI11: 0 | BJ11: 0 | BK11: 0 | BL11: 0 | BM11: 0 | BN11: 0 | BO11: 0 | BP11: 0 | BQ11: 0 | BR11: 0 | BS11: 0 | BT11: 0 | BU11: 0 | BV11: 0 | BW11: 0 | BX11: 0 | BY11: 0 | BZ11: 0 | CA11: 0 | CB11: 0 | CC11: 0 | CD11: 0 | CE11: 0 | CF11: 0 | CG11: 0 | CH11: 0 | CI11: 0 | CJ11: 0 | CK11: 0 | CL11: 0 | CM11: 0 | CN11: 0 | CO11: 0 | CP11: 0 | CQ11: 0 | CR11: 0 | CS11: 0 | CT11: 0 | CU11: 0 | CV11: 0 | CW11: 0 | CX11: 0 | CY11: 0 | CZ11: 0
A12: Trade credit and advances | B12: 9 | C12: 0 | D12: 0 | E12: 0 | F12: 0 | G12: 0 | H12: 0 | I12: 0 | J12: 0 | K12: 0 | L12: 0 | M12: 0 | N12: 0 | O12: 0 | P12: 0 | Q12: 0 | R12: 0 | S12: 0 | T12: 0 | U12: 0 | V12: 0 | W12: 0 | X12: 0 | Y12: 0 | Z12: 0 | AA12: 0 | AB12: 0 | AC12: 0 | AD12: 0 | AE12: 0 | AF12: 0 | AG12: 0 | AH12: 0 | AI12: 0 | AJ12: 0 | AK12: 0 | AL12: 0 | AM12: 0 | AN12: 0 | AO12: 0 | AP12: 0 | AQ12: 0 | AR12: 0.101 | AS12: 0.101 | AT12: 0.101 | AU12: 0.101 | AV12: 0.101 | AW12: 0.101 | AX12: 0.101 | AY12: 0.101 | AZ12: 0.101 | BA12: 0 | BB12: 0 | BC12: 0 | BD12: 0 | BE12: 0 | BF12: 0.905 | BG12: 1.23 | BH12: 25.615611 | BI12: 25.207576 | BJ12: 16.096868 | BK12: 21.651824 | BL12: 21.632227 | BM12: 15.877645 | BN12: 15.880973 | BO12: 13.61159 | BP12: 11.598057 | BQ12: 14.030109 | BR12: 16.915808 | BS12: 19.309576 | BT12: 17.587462 | BU12: 21.548471 | BV12: 23.058446 | BW12: 17.908613 | BX12: 17.773797 | BY12: 17.441582 | BZ12: 15.606123 | CA12: 14.929188 | CB12: 16.917969 | CC12: 18.888595 | CD12: 22.039426 | CE12: 24.613437 | CF12: 29.455581 | CG12: 32.246166 | CH12: 28.994734 | CI12: 24.301409 | CJ12: 30.287085 | CK12: 35.606903 | CL12: 34.896362 | CM12: 55.126057 | CN12: 59.434404 | CO12: 54.363893 | CP12: 49.501147 | CQ12: 50.621716 | CR12: 56.528585 | CS12: 55.339245 | CT12: 131.2894 | CU12: 69.772582 | CV12: 71.763715 | CW12: 43.704551 | CX12: 63.648616 | CY12: 39.030835 | CZ12: 47.8808
A13: Other debt liabilities | B13: 10 | C13: 0 | D13: 0 | E13: 0 | F13: 0 | G13: 0 | H13: 0 | I13: 0 | J13: 0 | K13: 0 | L13: 0 | M13: 0 | N13: 0 | O13: 0 | P13: 0 | Q13: 0 | R13: 0 | S13: 0 | T13: 0 | U13: 0 | V13: 0 | W13: 0 | X13: 0 | Y13: 0 | Z13: 0 | AA13: 0 | AB13: 0 | AC13: 0 | AD13: 0 | AE13: 0 | AF13: 0 | AG13: 0 | AH13: 0 | AI13: 0 | AJ13: 0 | AK13: 0 | AL13: 0 | AM13: 0 | AN13: 0 | AO13: 0 | AP13: 0 | AQ13: 0 | AR13: 0 | AS13: 0 | AT13: 0 | AU13: 0 | AV13: 0 | AW13: 0 | AX13: 0 | AY13: 0 | AZ13: 0 | BA13: 0 | BB13: 0 | BC13: 0 | BD13: 0 | BE13: 0 | BF13: 0 | BG13: 0 | BH13: 0 | BI13: 0 | BJ13: 0 | BK13: 0 | BL13: 0 | BM13: 0 | BN13: 0 | BO13: 0 | BP13: 0 | BQ13: 0 | BR13: 0 | BS13: 0 | BT13: 0 | BU13: 0 | BV13: 0 | BW13: 0 | BX13: 0 | BY13: 0 | BZ13: 0 | CA13: 0 | CB13: 0 | CC13: 0 | CD13: 0 | CE13: 0 | CF13: 0 | CG13: 0 | CH13: 0 | CI13: 0 | CJ13: 0.1247 | CK13: 0.05224 | CL13: 0.19273 | CM13: 0.23924 | CN13: 0.14559 | CO13: 0.00061 | CP13: 65.151 | CQ13: 65.151 | CR13: 65.151 | CS13: 65.151 | CT13: 114.003 | CU13: 113.863 | CV13: 113.863 | CW13: 113.863 | CX13: 82.232 | CY13: 79.575 | CZ13: 79.575
A14: Long-term | B14: 11=12+13+14+15+16+17 | C14: 2824.71 | D14: 2744.974 | E14: 2712.002 | F14: 2727.47 | G14: 2694.025 | H14: 2490.5336 | I14: 2472.8143 | J14: 2439.4797 | K14: 2334.0095 | L14: 2400.7822 | M14: 2404.6542 | N14: 2459.0988 | O14: 2552.3441 | P14: 2704.8274 | Q14: 2702.0244 | R14: 2716.7994 | S14: 2496.1174 | T14: 2348.1019 | U14: 2062.4565 | V14: 2058.5873 | W14: 1478.9213 | X14: 1495.2886 | Y14: 1507.0701 | Z14: 1450.3088 | AA14: 1495.1813 | AB14: 1468.0315 | AC14: 1422.5411 | AD14: 1483.659 | AE14: 1491.5012 | AF14: 1559.5994 | AG14: 1523.139 | AH14: 1568.3033 | AI14: 1641.9024 | AJ14: 1572.43 | AK14: 1584.5043 | AL14: 1639.3944 | AM14: 2218.0983 | AN14: 2264.2314 | AO14: 2352.0124 | AP14: 3492.2507 | AQ14: 3800.2919 | AR14: 3789.3908 | AS14: 3920.3648 | AT14: 4123.4184 | AU14: 4479.5393 | AV14: 4418.5371 | AW14: 4450.0088 | AX14: 4553.9224 | AY14: 4855.0214 | AZ14: 4756.3501 | BA14: 4827.6286 | BB14: 4978.8035 | BC14: 5217.5756 | BD14: 5066.2462 | BE14: 5045.1768 | BF14: 5115.7318 | BG14: 7332.5197 | BH14: 7080.3729 | BI14: 6980.4881 | BJ14: 10303.633 | BK14: 11291.541 | BL14: 11315.435 | BM14: 12680.941 | BN14: 12683.083 | BO14: 12078.463 | BP14: 12158.594 | BQ14: 12131.154 | BR14: 12296.385 | BS14: 12048.166 | BT14: 11120.303 | BU14: 10668.851 | BV14: 10628.414 | BW14: 11536.88 | BX14: 11471.01 | BY14: 11871.277 | BZ14: 12778.007 | CA14: 12402.671 | CB14: 11411.444 | CC14: 11815.631 | CD14: 12273.023 | CE14: 13860.428 | CF14: 14442.126 | CG14: 15649.84 | CH14: 15907.667 | CI14: 15835.023 | CJ14: 14122.832 | CK14: 14247.654 | CL14: 12904.006 | CM14: 13334.626 | CN14: 12797.569 | CO14: 12631.817 | CP14: 12495.639 | CQ14: 11693.64 | CR14: 11105.379 | CS14: 10762.781 | CT14: 11415.086 | CU14: 12589.862 | CV14: 12341.038 | CW14: 12318.068 | CX14: 13889.763 | CY14: 15880.919 | CZ14: 16414.033
A15: Special Drawing Rights | B15: 12 | C15: 0 | D15: 0 | E15: 0 | F15: 0 | G15: 0 | H15: 0 | I15: 0 | J15: 0 | K15: 0 | L15: 0 | M15: 0 | N15: 0 | O15: 0 | P15: 0 | Q15: 0 | R15: 0 | S15: 0 | T15: 0 | U15: 0 | V15: 0 | W15: 0 | X15: 0 | Y15: 0 | Z15: 0 | AA15: 0 | AB15: 0 | AC15: 0 | AD15: 0 | AE15: 0 | AF15: 0 | AG15: 0 | AH15: 0 | AI15: 0 | AJ15: 0 | AK15: 0 | AL15: 0 | AM15: 0 | AN15: 0 | AO15: 0 | AP15: 0 | AQ15: 0 | AR15: 0 | AS15: 0 | AT15: 0 | AU15: 0 | AV15: 0 | AW15: 0 | AX15: 0 | AY15: 0 | AZ15: 0 | BA15: 0 | BB15: 0 | BC15: 0 | BD15: 0 | BE15: 0 | BF15: 0 | BG15: 0 | BH15: 0 | BI15: 0 | BJ15: 0 | BK15: 0 | BL15: 0 | BM15: 0 | BN15: 0 | BO15: 0 | BP15: 0 | BQ15: 0 | BR15: 0 | BS15: 0 | BT15: 0 | BU15: 0 | BV15: 0 | BW15: 0 | BX15: 0 | BY15: 0 | BZ15: 0 | CA15: 0 | CB15: 0 | CC15: 0 | CD15: 0 | CE15: 0 | CF15: 0 | CG15: 0 | CH15: 0 | CI15: 0 | CJ15: 0 | CK15: 0 | CL15: 0 | CM15: 0 | CN15: 0 | CO15: 0 | CP15: 0 | CQ15: 0 | CR15: 0 | CS15: 0 | CT15: 0 | CU15: 0 | CV15: 0 | CW15: 0 | CX15: 0 | CY15: 0 | CZ15: 0
A16: Currency and deposits | B16: 13 | C16: 0 | D16: 0 | E16: 0 | F16: 0 | G16: 0 | H16: 0 | I16: 0 | J16: 0 | K16: 0 | L16: 0 | M16: 0 | N16: 0 | O16: 0 | P16: 0 | Q16: 0 | R16: 0 | S16: 0 | T16: 0 | U16: 0 | V16: 0 | W16: 0 | X16: 0 | Y16: 0 | Z16: 0 | AA16: 0 | AB16: 0 | AC16: 0 | AD16: 0 | AE16: 0 | AF16: 0 | AG16: 0 | AH16: 0 | AI16: 0 | AJ16: 0 | AK16: 0 | AL16: 0 | AM16: 0 | AN16: 0 | AO16: 0 | AP16: 0 | AQ16: 0 | AR16: 0 | AS16: 0 | AT16: 0 | AU16: 0 | AV16: 0 | AW16: 0 | AX16: 0 | AY16: 0 | AZ16: 0 | BA16: 0 | BB16: 0 | BC16: 0 | BD16: 0 | BE16: 0 | BF16: 0 | BG16: 0 | BH16: 0 | BI16: 0 | BJ16: 0 | BK16: 0 | BL16: 0 | BM16: 0 | BN16: 0 | BO16: 0 | BP16: 0 | BQ16: 0 | BR16: 0 | BS16: 0 | BT16: 0 | BU16: 0 | BV16: 0 | BW16: 0 | BX16: 0 | BY16: 0 | BZ16: 0 | CA16: 0 | CB16: 0 | CC16: 0 | CD16: 0 | CE16: 0 | CF16: 0 | CG16: 0 | CH16: 0 | CI16: 0 | CJ16: 0 | CK16: 0 | CL16: 0 | CM16: 0 | CN16: 0 | CO16: 0 | CP16: 0 | CQ16: 0 | CR16: 0 | CS16: 0 | CT16: 0 | CU16: 0 | CV16: 0 | CW16: 0 | CX16: 0 | CY16: 0 | CZ16: 0
A17: Debt securities1 | B17: 14 | C17: 547.74695 | D17: 512.43295 | E17: 483.29695 | F17: 459.16395 | G17: 445.01995 | H17: 254.7956 | I17: 217.52367 | J17: 180.25788 | K17: 39.959364 | L17: 79.414107 | M17: 82.632462 | N17: 70.697765 | O17: 129.09901 | P17: 298.18191 | Q17: 326.56373 | R17: 334.59686 | S17: 113.41741 | T17: 114.15187 | U17: 78.625291 | V17: 67.924 | W17: 52.296113 | X17: 49.458611 | Y17: 32.034055 | Z17: 36.643762 | AA17: 53.099314 | AB17: 116.83855 | AC17: 68.750061 | AD17: 93.575008 | AE17: 60.305237 | AF17: 54.272434 | AG17: 53.579967 | AH17: 65.681337 | AI17: 23.758383 | AJ17: 0.04002642 | AK17: 0.040276577 | AL17: 0.053381915 | AM17: 0.020275007 | AN17: 0.020447284 | AO17: 13.583399 | AP17: 41.198712 | AQ17: 49.128928 | AR17: 49.682772 | AS17: 120.97278 | AT17: 94.633416 | AU17: 23.84531 | AV17: 38.966055 | AW17: 21.20079 | AX17: 21.126852 | AY17: 14.082394 | AZ17: 14.073058 | BA17: 13.997626 | BB17: 13.818123 | BC17: 14.670562 | BD17: 0.67424742 | BE17: 0.66880994 | BF17: 0.7237915 | BG17: 1887.6487 | BH17: 1870.0769 | BI17: 1768.8731 | BJ17: 5007.8306 | BK17: 5038.0111 | BL17: 5074.1779 | BM17: 5367.7023 | BN17: 5330.8793 | BO17: 4713.741 | BP17: 4836.9393 | BQ17: 4862.3772 | BR17: 5062.5497 | BS17: 4799.689 | BT17: 3935.6645 | BU17: 3576.3571 | BV17: 3620.4005 | BW17: 4554.2838 | BX17: 4832.8628 | BY17: 5250.1014 | BZ17: 6466.8687 | CA17: 6133.3972 | CB17: 5479.4081 | CC17: 5941.8814 | CD17: 6728.7103 | CE17: 7202.6667 | CF17: 7108.6939 | CG17: 8361.3753 | CH17: 8739.0258 | CI17: 8748.7327 | CJ17: 7187.6953 | CK17: 7527.4053 | CL17: 6417.2894 | CM17: 6336.2198 | CN17: 5843.9892 | CO17: 5765.5349 | CP17: 5909.3294 | CQ17: 5135.1758 | CR17: 4852.5003 | CS17: 4618.3102 | CT17: 5371.279 | CU17: 5537.9237 | CV17: 5458.1685 | CW17: 5407.2427 | CX17: 7168.8222 | CY17: 9311.9151 | CZ17: 10078.12
A18: Loans | B18: 15 | C18: 2271.963 | D18: 2227.541 | E18: 2223.705 | F18: 2263.306 | G18: 2247.335 | H18: 2235.738 | I18: 2255.2906 | J18: 2259.2219 | K18: 2294.0501 | L18: 2321.3681 | M18: 2322.0217 | N18: 2388.401 | O18: 2423.2451 | P18: 2406.6455 | Q18: 2375.4607 | R18: 2382.2025 | S18: 2382.7 | T18: 2233.95 | U18: 1983.8312 | V18: 1990.6633 | W18: 1426.6252 | X18: 1445.83 | Y18: 1475.036 | Z18: 1413.665 | AA18: 1442.082 | AB18: 1351.193 | AC18: 1353.791 | AD18: 1390.084 | AE18: 1431.196 | AF18: 1505.327 | AG18: 1469.559 | AH18: 1502.622 | AI18: 1618.144 | AJ18: 1572.39 | AK18: 1584.464 | AL18: 1639.341 | AM18: 2218.078 | AN18: 2264.211 | AO18: 2338.429 | AP18: 3451.052 | AQ18: 3751.163 | AR18: 3739.708 | AS18: 3799.392 | AT18: 4028.785 | AU18: 4455.694 | AV18: 4379.571 | AW18: 4428.808 | AX18: 4532.7955 | AY18: 4840.939 | AZ18: 4642.204 | BA18: 4712.937 | BB18: 4863.6864 | BC18: 5101.001 | BD18: 4997.238 | BE18: 4968.992 | BF18: 5039.636 | BG18: 5369.667 | BH18: 5168.858 | BI18: 5169.326 | BJ18: 5256.45 | BK18: 6214.542 | BL18: 6238.422 | BM18: 7310.97 | BN18: 7350.505 | BO18: 7363.583 | BP18: 7321.655 | BQ18: 7268.777 | BR18: 7233.8352 | BS18: 7248.477 | BT18: 7184.638 | BU18: 7092.494 | BV18: 7008.013 | BW18: 6982.596 | BX18: 6638.147 | BY18: 6621.176 | BZ18: 6311.138 | CA18: 6269.274 | CB18: 5932.036 | CC18: 5873.75 | CD18: 5544.313 | CE18: 6657.761 | CF18: 7333.432 | CG18: 7288.465 | CH18: 7168.641 | CI18: 7086.2901 | CJ18: 6935.137 | CK18: 6720.249 | CL18: 6486.7168 | CM18: 6998.4066 | CN18: 6953.5798 | CO18: 6866.282 | CP18: 6586.3095 | CQ18: 6558.4647 | CR18: 6252.8784 | CS18: 6144.4705 | CT18: 6043.8068 | CU18: 7051.9381 | CV18: 6882.8699 | CW18: 6910.8256 | CX18: 6720.9407 | CY18: 6569.0038 | CZ18: 6335.9127
A19: Trade credit and advances | B19: 16 | C19: 0 | D19: 0 | E19: 0 | F19: 0 | G19: 0 | H19: 0 | I19: 0 | J19: 0 | K19: 0 | L19: 0 | M19: 0 | N19: 0 | O19: 0 | P19: 0 | Q19: 0 | R19: 0 | S19: 0 | T19: 0 | U19: 0 | V19: 0 | W19: 0 | X19: 0 | Y19: 0 | Z19: 0 | AA19: 0 | AB19: 0 | AC19: 0 | AD19: 0 | AE19: 0 | AF19: 0 | AG19: 0 | AH19: 0 | AI19: 0 | AJ19: 0 | AK19: 0 | AL19: 0 | AM19: 0 | AN19: 0 | AO19: 0 | AP19: 0 | AQ19: 0 | AR19: 0 | AS19: 0 | AT19: 0 | AU19: 0 | AV19: 0 | AW19: 0 | AX19: 0 | AY19: 0 | AZ19: 0 | BA19: 0 | BB19: 0 | BC19: 0 | BD19: 0 | BE19: 0 | BF19: 0 | BG19: 0 | BH19: 1.361 | BI19: 2.49 | BJ19: 0 | BK19: 0 | BL19: 0 | BM19: 0 | BN19: 0 | BO19: 0 | BP19: 0 | BQ19: 0 | BR19: 0 | BS19: 0 | BT19: 0 | BU19: 0 | BV19: 0 | BW19: 0 | BX19: 0 | BY19: 0 | BZ19: 0 | CA19: 0 | CB19: 0 | CC19: 0 | CD19: 0 | CE19: 0 | CF19: 0 | CG19: 0 | CH19: 0 | CI19: 0 | CJ19: 0 | CK19: 0 | CL19: 0 | CM19: 0 | CN19: 0 | CO19: 0 | CP19: 0 | CQ19: 0 | CR19: 0 | CS19: 0 | CT19: 0 | CU19: 0 | CV19: 0 | CW19: 0 | CX19: 0 | CY19: 0 | CZ19: 0
A20: Other debt liabilities | B20: 17 | C20: 5 | D20: 5 | E20: 5 | F20: 5 | G20: 1.67 | H20: 0 | I20: 0 | J20: 0 | K20: 0 | L20: 0 | M20: 0 | N20: 0 | O20: 0 | P20: 0 | Q20: 0 | R20: 0 | S20: 0 | T20: 0 | U20: 0 | V20: 0 | W20: 0 | X20: 0 | Y20: 0 | Z20: 0 | AA20: 0 | AB20: 0 | AC20: 0 | AD20: 0 | AE20: 0 | AF20: 0 | AG20: 0 | AH20: 0 | AI20: 0 | AJ20: 0 | AK20: 0 | AL20: 0 | AM20: 0 | AN20: 0 | AO20: 0 | AP20: 0 | AQ20: 0 | AR20: 0 | AS20: 0 | AT20: 0 | AU20: 0 | AV20: 0 | AW20: 0 | AX20: 0 | AY20: 0 | AZ20: 100.073 | BA20: 100.694 | BB20: 101.299 | BC20: 101.904 | BD20: 68.334 | BE20: 75.516 | BF20: 75.372 | BG20: 75.204 | BH20: 40.077 | BI20: 39.799 | BJ20: 39.352 | BK20: 38.98834 | BL20: 2.83534 | BM20: 2.26834 | BN20: 1.699 | BO20: 1.139 | BP20: 0 | BQ20: 0 | BR20: 0 | BS20: 0 | BT20: 0 | BU20: 0 | BV20: 0 | BW20: 0 | BX20: 0 | BY20: 0 | BZ20: 0 | CA20: 0 | CB20: 0 | CC20: 0 | CD20: 0 | CE20: 0 | CF20: 0 | CG20: 0 | CH20: 0 | CI20: 0 | CJ20: 0 | CK20: 0 | CL20: 0 | CM20: 0 | CN20: 0 | CO20: 0 | CP20: 0 | CQ20: 0 | CR20: 0 | CS20: 0 | CT20: 0 | CU20: 0 | CV20: 0 | CW20: 0 | CX20: 0 | CY20: 0 | CZ20: 0
A21: Central Bank | B21: 18=19+25 | C21: 1.9033932 | D21: 2.2474933 | E21: 2.1631109 | F21: 2.2500286 | G21: 2.2576278 | H21: 2.2348776 | I21: 2.2502304 | J21: 2.4100151 | K21: 2.4799209 | L21: 2.3697076 | M21: 2.5523562 | N21: 2.7067686 | O21: 2.3852402 | P21: 2.4832399 | Q21: 3.9371407 | R21: 3.5785977 | S21: 3.4659552 | T21: 14.893957 | U21: 86.050029 | V21: 132.3594 | W21: 103.54233 | X21: 244.2004 | Y21: 115.76938 | Z21: 193.55753 | AA21: 1076.8435 | AB21: 2081.2404 | AC21: 3144.1831 | AD21: 934.49078 | AE21: 106.89344 | AF21: 106.9963 | AG21: 32.379064 | AH21: 36.622303 | AI21: 12.127684 | AJ21: 2.4714349 | AK21: 175.72762 | AL21: 607.08723 | AM21: 1017.4874 | AN21: 1355.8633 | AO21: 1016.6219 | AP21: 693.58583 | AQ21: 1000.6498 | AR21: 3501.4632 | AS21: 2547.7319 | AT21: 684.29285 | AU21: 563.25744 | AV21: 657.80673 | AW21: 539.19785 | AX21: 549.96369 | AY21: 618.884 | AZ21: 537.84997 | BA21: 535.60042 | BB21: 557.76952 | BC21: 546.7 | BD21: 870.42072 | BE21: 805.71878 | BF21: 857.4888 | BG21: 953.65208 | BH21: 760.26513 | BI21: 779.21428 | BJ21: 875.29489 | BK21: 898.82369 | BL21: 892.03691 | BM21: 893.99357 | BN21: 739.38577 | BO21: 756.29982 | BP21: 1120.3822 | BQ21: 1097.8499 | BR21: 869.73808 | BS21: 926.31534 | BT21: 1899.1809 | BU21: 1188.5697 | BV21: 774.57793 | BW21: 770.39637 | BX21: 938.78931 | BY21: 759.41161 | BZ21: 634.03784 | CA21: 891.10116 | CB21: 949.8852 | CC21: 825.9092 | CD21: 805.59551 | CE21: 1329.3693 | CF21: 1835.9915 | CG21: 1714.6907 | CH21: 3051.342 | CI21: 2535.7666 | CJ21: 2519.3343 | CK21: 2214.3143 | CL21: 2043.6277 | CM21: 2171.8023 | CN21: 2217.8953 | CO21: 2065.0931 | CP21: 2097.6294 | CQ21: 2233.0697 | CR21: 2094.1758 | CS21: 2035.9904 | CT21: 2204.0123 | CU21: 2469.9652 | CV21: 2212.7413 | CW21: 2205.8534 | CX21: 2165.8445 | CY21: 2594.4324 | CZ21: 2381.7913
A22: Short-term | B22: 19=20+21+22+23+24 | C22: 0.00067820069 | D22: 0.34477827 | E22: 0.2603959 | F22: 0.34731359 | G22: 0.35491278 | H22: 0.33216264 | I22: 0.34751538 | J22: 0.50730013 | K22: 0.57720587 | L22: 0.46699263 | M22: 0.64964117 | N22: 0.80405357 | O22: 0.49800151 | P22: 0.58052494 | Q22: 2.0344257 | R22: 1.6758827 | S22: 1.5632402 | T22: 12.991242 | U22: 84.147314 | V22: 130.45669 | W22: 101.63961 | X22: 242.29769 | Y22: 113.86667 | Z22: 191.65481 | AA22: 1074.9408 | AB22: 2079.3377 | AC22: 3142.2804 | AD22: 932.58806 | AE22: 104.99072 | AF22: 105.09359 | AG22: 30.476349 | AH22: 34.719588 | AI22: 10.224969 | AJ22: 0.56871988 | AK22: 173.82491 | AL22: 63.969698 | AM22: 479.72176 | AN22: 832.21661 | AO22: 508.68771 | AP22: 159.14999 | AQ22: 470.43413 | AR22: 2957.5946 | AS22: 1997.8349 | AT22: 144.65787 | AU22: 36.329465 | AV22: 123.74641 | AW22: 15.326959 | AX22: 18.109901 | AY22: 88.063119 | AZ22: 20.453459 | BA22: 16.21121 | BB22: 28.447459 | BC22: 10.695178 | BD22: 333.09817 | BE22: 268.29026 | BF22: 115.90368 | BG22: 215.57358 | BH22: 12.532547 | BI22: 10.929881 | BJ22: 79.911277 | BK22: 75.954131 | BL22: 104.73457 | BM22: 169.3658 | BN22: 178.52901 | BO22: 242.53662 | BP22: 626.94322 | BQ22: 593.74221 | BR22: 368.29924 | BS22: 421.75315 | BT22: 1388.1652 | BU22: 694.51427 | BV22: 286.4923 | BW22: 286.24097 | BX22: 455.5703 | BY22: 275.48976 | BZ22: 159.09733 | CA22: 409.70703 | CB22: 472.75556 | CC22: 345.58138 | CD22: 315.71116 | CE22: 828.02566 | CF22: 1342.7691 | CG22: 1218.0262 | CH22: 989.87803 | CI22: 494.63373 | CJ22: 501.93911 | CK22: 270.38519 | CL22: 182.81149 | CM22: 230.88555 | CN22: 255.29493 | CO22: 119.74808 | CP22: 185.16305 | CQ22: 276.35476 | CR22: 164.0574 | CS22: 118.15329 | CT22: 227.87528 | CU22: 567.97818 | CV22: 279.38265 | CW22: 202.92557 | CX22: 168.50423 | CY22: 595.37327 | CZ22: 401.57727
A23: Currency and deposits | B23: 20 | C23: 0.00067820069 | D23: 0.34477827 | E23: 0.2603959 | F23: 0.2582803 | G23: 0.1732344 | H23: 0.040352246 | I23: 0.11829737 | J23: 0.11720569 | K23: 0.11634905 | L23: 0.11943731 | M23: 0.11943731 | N23: 0.11943731 | O23: 0.11943731 | P23: 0.10105687 | Q23: 0.17614348 | R23: 0.077985859 | S23: 0.31388906 | T23: 0.08149617 | U23: 0.83146959 | V23: 0 | W23: 1.0001249 | X23: 0.75513222 | Y23: 19.749069 | Z23: 0.30014091 | AA23: 0.77467723 | AB23: 0.24030479 | AC23: 0.048959815 | AD23: 0.0015720404 | AE23: 0.010947184 | AF23: 0.0092259439 | AG23: 0.022352953 | AH23: 0.022693149 | AI23: 0.27273972 | AJ23: 0.56871988 | AK23: 169.14639 | AL23: 63.969698 | AM23: 103.59101 | AN23: 91.01704 | AO23: 41.115525 | AP23: 73.73935 | AQ23: 239.54028 | AR23: 432.94524 | AS23: 140.21561 | AT23: 13.538227 | AU23: 16.484451 | AV23: 119.67325 | AW23: 11.899516 | AX23: 15.348304 | AY23: 88.051092 | AZ23: 16.790878 | BA23: 11.721053 | BB23: 24.389399 | BC23: 6.6751331 | BD23: 327.05747 | BE23: 258.96951 | BF23: 110.309 | BG23: 209.2746 | BH23: 6.1969299 | BI23: 3.980762 | BJ23: 73.504304 | BK23: 70.916354 | BL23: 99.662189 | BM23: 105.22314 | BN23: 50.195931 | BO23: 17.186079 | BP23: 16.837046 | BQ23: 18.406813 | BR23: 15.343369 | BS23: 10.575614 | BT23: 7.1823114 | BU23: 4.9193451 | BV23: 5.7710657 | BW23: 6.9245681 | BX23: 5.5473189 | BY23: 4.1301489 | BZ23: 4.660437 | CA23: 3.8512206 | CB23: 4.8349365 | CC23: 4.4461222 | CD23: 5.3882441 | CE23: 2.6300656 | CF23: 4.8996795 | CG23: 72.970479 | CH23: 4.2893759 | CI23: 7.8965182 | CJ23: 255.14151 | CK23: 11.266757 | CL23: 11.148138 | CM23: 12.802021 | CN23: 10.388588 | CO23: 13.577331 | CP23: 13.022969 | CQ23: 249.74479 | CR23: 13.372578 | CS23: 113.22014 | CT23: 98.15124 | CU23: 365.413 | CV23: 96.865134 | CW23: 191.52151 | CX23: 162.20343 | CY23: 294.142 | CZ23: 140.88421
A24: Debt securities1 | B24: 21 | C24: 0 | D24: 0 | E24: 0 | F24: 0.033649289 | G24: 0 | H24: 0 | I24: 0 | J24: 0 | K24: 0 | L24: 0 | M24: 0 | N24: 0 | O24: 0 | P24: 0 | Q24: 0 | R24: 0 | S24: 0 | T24: 10.181763 | U24: 82.273446 | V24: 127.15004 | W24: 99.77385 | X24: 240.4823 | Y24: 91.85036 | Z24: 190.16858 | AA24: 1072.9653 | AB24: 2077.9874 | AC24: 3141.7294 | AD24: 932.31864 | AE24: 104.77186 | AF24: 104.86823 | AG24: 30.260612 | AH24: 34.550747 | AI24: 9.9522293 | AJ24: 0 | AK24: 4.6785159 | AL24: 0 | AM24: 376.13075 | AN24: 741.19957 | AO24: 467.57218 | AP24: 85.41064 | AQ24: 230.89384 | AR24: 2524.6494 | AS24: 1857.6193 | AT24: 131.11965 | AU24: 19.845013 | AV24: 0 | AW24: 0 | AX24: 0 | AY24: 0 | AZ24: 0 | BA24: 1.3188262 | BB24: 0 | BC24: 0 | BD24: 0 | BE24: 0 | BF24: 0 | BG24: 0 | BH24: 0 | BI24: 0 | BJ24: 0 | BK24: 0 | BL24: 0 | BM24: 60.421529 | BN24: 120.83496 | BO24: 220.78125 | BP24: 605.96871 | BQ24: 572.70106 | BR24: 350.21461 | BS24: 408.12084 | BT24: 1376.9217 | BU24: 685.46183 | BV24: 276.30602 | BW24: 275.3117 | BX24: 445.75856 | BY24: 267.28404 | BZ24: 150.62053 | CA24: 401.60773 | CB24: 463.17143 | CC24: 335.57822 | CD24: 305.18777 | CE24: 821.18942 | CF24: 1333.183 | CG24: 1140.3331 | CH24: 980.7527 | CI24: 483.30177 | CJ24: 242.91583 | CK24: 254.41541 | CL24: 166.54201 | CM24: 214.42808 | CN24: 240.80188 | CO24: 101.92158 | CP24: 168.17438 | CQ24: 22.865471 | CR24: 146.51904 | CS24: 0 | CT24: 124.88023 | CU24: 198.65563 | CV24: 178.05088 | CW24: 6.1657771 | CX24: 0 | CY24: 295.69847 | CZ24: 253.8005
A25: Loans | B25: 22 | C25: 0 | D25: 0 | E25: 0 | F25: 0 | G25: 0 | H25: 0 | I25: 0 | J25: 0 | K25: 0 | L25: 0 | M25: 0 | N25: 0 | O25: 0 | P25: 0 | Q25: 0 | R25: 0 | S25: 0 | T25: 0 | U25: 0 | V25: 0 | W25: 0 | X25: 0 | Y25: 0 | Z25: 0 | AA25: 0 | AB25: 0 | AC25: 0 | AD25: 0 | AE25: 0 | AF25: 0 | AG25: 0 | AH25: 0 | AI25: 0 | AJ25: 0 | AK25: 0 | AL25: 0 | AM25: 0 | AN25: 0 | AO25: 0 | AP25: 0 | AQ25: 0 | AR25: 0 | AS25: 0 | AT25: 0 | AU25: 0 | AV25: 0 | AW25: 0 | AX25: 0 | AY25: 0 | AZ25: 0 | BA25: 0 | BB25: 0 | BC25: 0 | BD25: 0 | BE25: 0 | BF25: 0 | BG25: 0 | BH25: 0 | BI25: 0 | BJ25: 0 | BK25: 0 | BL25: 0 | BM25: 0 | BN25: 0 | BO25: 0 | BP25: 0 | BQ25: 0 | BR25: 0 | BS25: 0 | BT25: 0 | BU25: 0 | BV25: 0 | BW25: 0 | BX25: 0 | BY25: 0 | BZ25: 0 | CA25: 0 | CB25: 0 | CC25: 0 | CD25: 0 | CE25: 0 | CF25: 0 | CG25: 0 | CH25: 0 | CI25: 0 | CJ25: 0 | CK25: 0 | CL25: 0 | CM25: 0 | CN25: 0 | CO25: 0 | CP25: 0 | CQ25: 0 | CR25: 0 | CS25: 0 | CT25: 0 | CU25: 0 | CV25: 0 | CW25: 0 | CX25: 0 | CY25: 0 | CZ25: 0
A26: Trade credit and advances | B26: 23 | C26: 0 | D26: 0 | E26: 0 | F26: 0 | G26: 0 | H26: 0 | I26: 0 | J26: 0 | K26: 0 | L26: 0 | M26: 0 | N26: 0 | O26: 0 | P26: 0 | Q26: 0 | R26: 0 | S26: 0 | T26: 0 | U26: 0 | V26: 0 | W26: 0 | X26: 0 | Y26: 0 | Z26: 0 | AA26: 0 | AB26: 0 | AC26: 0 | AD26: 0 | AE26: 0 | AF26: 0 | AG26: 0 | AH26: 0 | AI26: 0 | AJ26: 0 | AK26: 0 | AL26: 0 | AM26: 0 | AN26: 0 | AO26: 0 | AP26: 0 | AQ26: 0 | AR26: 0 | AS26: 0 | AT26: 0 | AU26: 0 | AV26: 4.073155 | AW26: 3.4274431 | AX26: 2.7615975 | AY26: 0.012026682 | AZ26: 0 | BA26: 0 | BB26: 0 | BC26: 0 | BD26: 0 | BE26: 0 | BF26: 0 | BG26: 0 | BH26: 0 | BI26: 0 | BJ26: 0 | BK26: 0 | BL26: 0 | BM26: 0 | BN26: 0 | BO26: 0 | BP26: 4.1374662 | BQ26: 2.6343374 | BR26: 2.7412522 | BS26: 3.0566954 | BT26: 4.0611806 | BU26: 4.133103 | BV26: 4.4152113 | BW26: 4.0047021 | BX26: 4.2644172 | BY26: 4.0755653 | BZ26: 3.8163618 | CA26: 4.248081 | CB26: 4.7491982 | CC26: 5.5570325 | CD26: 5.135151 | CE26: 4.2061706 | CF26: 4.6863834 | CG26: 4.7226225 | CH26: 4.835949 | CI26: 3.4354432 | CJ26: 3.881775 | CK26: 4.703022 | CL26: 5.1213407 | CM26: 3.6554498 | CN26: 4.1044663 | CO26: 4.2491632 | CP26: 3.9657061 | CQ26: 3.744495 | CR26: 4.1657809 | CS26: 4.9331472 | CT26: 4.8438047 | CU26: 3.9095495 | CV26: 4.4666437 | CW26: 5.2382857 | CX26: 6.3008034 | CY26: 5.5327994 | CZ26: 6.8925595
A27: Other debt liabilities | B27: 24 | C27: 0 | D27: 0 | E27: 0 | F27: 0.055384 | G27: 0.18167838 | H27: 0.29181039 | I27: 0.229218 | J27: 0.39009444 | K27: 0.46085682 | L27: 0.34755532 | M27: 0.53020387 | N27: 0.68461626 | O27: 0.37856421 | P27: 0.47946807 | Q27: 1.8582822 | R27: 1.5978969 | S27: 1.2493511 | T27: 2.7279822 | U27: 1.0423986 | V27: 3.3066452 | W27: 0.86563863 | X27: 1.0602599 | Y27: 2.2672402 | Z27: 1.1860901 | AA27: 1.2007778 | AB27: 1.1099426 | AC27: 0.50204387 | AD27: 0.26785095 | AE27: 0.20791816 | AF27: 0.21613463 | AG27: 0.19338334 | AH27: 0.14614862 | AI27: 0 | AJ27: 0 | AK27: 0 | AL27: 0 | AM27: 0 | AN27: 0 | AO27: 0 | AP27: 0 | AQ27: 0 | AR27: 0 | AS27: 0 | AT27: 0 | AU27: 0 | AV27: 0 | AW27: 0 | AX27: 0 | AY27: 0 | AZ27: 3.662581 | BA27: 3.1713307 | BB27: 4.0580594 | BC27: 4.020045 | BD27: 6.040697 | BE27: 9.3207539 | BF27: 5.5946833 | BG27: 6.2989781 | BH27: 6.3356168 | BI27: 6.9491187 | BJ27: 6.4069727 | BK27: 5.0377767 | BL27: 5.0723777 | BM27: 3.7211367 | BN27: 7.4981189 | BO27: 4.5692991 | BP27: 0 | BQ27: 0 | BR27: 0 | BS27: 0 | BT27: 0 | BU27: 0 | BV27: 0 | BW27: 0 | BX27: 0 | BY27: 0 | BZ27: 0 | CA27: 0 | CB27: 0 | CC27: 0 | CD27: 0 | CE27: 0 | CF27: 0 | CG27: 0 | CH27: 0 | CI27: 0 | CJ27: 0 | CK27: 0 | CL27: 0 | CM27: 0 | CN27: 0 | CO27: 0 | CP27: 0 | CQ27: 0 | CR27: 0 | CS27: 0 | CT27: 0 | CU27: 0 | CV27: 0 | CW27: 0 | CX27: 0 | CY27: 0 | CZ27: 0
