Workbook

Sheet Monetary aggregates
A1: Monetary aggregates*, bln rbls | B1: Dec, 1992 | C1: Jan, 1993 | D1: Feb, 1993 | E1: Mar, 1993 | F1: Apr, 1993 | G1: May, 1993 | H1: Jun, 1993 | I1: Jul, 1993 | J1: Aug, 1993 | K1: Sep, 1993 | L1: Oct, 1993 | M1: Nov, 1993 | N1: Dec, 1993 | O1: Jan, 1994 | P1: Feb, 1994 | Q1: Mar, 1994 | R1: Apr, 1994 | S1: May, 1994 | T1: Jun, 1994 | U1: Jul, 1994 | V1: Aug, 1994 | W1: Sep, 1994 | X1: Oct, 1994 | Y1: Nov, 1994 | Z1: Dec, 1994 | AA1: Jan, 1995 | AB1: Feb, 1995 | AC1: Mar, 1995 | AD1: Apr, 1995 | AE1: May, 1995 | AF1: Jun, 1995 | AG1: Jul, 1995 | AH1: Aug, 1995 | AI1: Sep, 1995 | AJ1: Oct, 1995 | AK1: Nov, 1995 | AL1: Dec, 1995 | AM1: Jan, 1996 | AN1: Feb, 1996 | AO1: Mar, 1996 | AP1: Apr, 1996 | AQ1: May, 1996 | AR1: Jun, 1996 | AS1: Jul, 1996 | AT1: Aug, 1996 | AU1: Sep, 1996 | AV1: Oct, 1996 | AW1: Nov, 1996 | AX1: Dec, 1996 | AY1: Jan, 1997 | AZ1: Feb, 1997 | BA1: Mar, 1997 | BB1: Apr, 1997 | BC1: May, 1997 | BD1: Jun, 1997 | BE1: Jul, 1997 | BF1: Aug, 1997 | BG1: Sep, 1997 | BH1: Oct, 1997 | BI1: Nov, 1997 | BJ1: Dec, 1997 | BK1: Jan, 1998 | BL1: Feb, 1998 | BM1: Mar, 1998 | BN1: Apr, 1998 | BO1: May, 1998 | BP1: Jun, 1998 | BQ1: Jul, 1998 | BR1: Aug, 1998 | BS1: Sep, 1998 | BT1: Oct, 1998 | BU1: Nov, 1998 | BV1: Dec, 1998 | BW1: Jan, 1999 | BX1: Feb, 1999 | BY1: Mar, 1999 | BZ1: Apr, 1999 | CA1: May, 1999 | CB1: Jun, 1999 | CC1: Jul, 1999 | CD1: Aug, 1999 | CE1: Sep, 1999 | CF1: Oct, 1999 | CG1: Nov, 1999 | CH1: Dec, 1999 | CI1: Jan, 2000 | CJ1: Feb, 2000 | CK1: Mar, 2000 | CL1: Apr, 2000 | CM1: May, 2000 | CN1: Jun, 2000 | CO1: Jul, 2000 | CP1: Aug, 2000 | CQ1: Sep, 2000 | CR1: Oct, 2000 | CS1: Nov, 2000 | CT1: Dec, 2000 | CU1: Jan, 2001 | CV1: Feb, 2001 | CW1: Mar, 2001 | CX1: Apr, 2001 | CY1: May, 2001 | CZ1: Jun, 2001 | DA1: Jul, 2001 | DB1: Aug, 2001 | DC1: Sep, 2001 | DD1: Oct, 2001 | DE1: Nov, 2001 | DF1: Dec, 2001 | DG1: Jan, 2002 | DH1: Feb, 2002 | DI1: Mar, 2002 | DJ1: Apr, 2002 | DK1: May, 2002 | DL1: Jun, 2002 | DM1: Jul, 2002 | DN1: Aug, 2002 | DO1: Sep, 2002 | DP1: Oct, 2002 | DQ1: Nov, 2002 | DR1: Dec, 2002 | DS1: Jan, 2003 | DT1: Feb, 2003 | DU1: Mar, 2003 | DV1: Apr, 2003 | DW1: May, 2003 | DX1: Jun, 2003 | DY1: Jul, 2003 | DZ1: Aug, 2003 | EA1: Sep, 2003 | EB1: Oct, 2003 | EC1: Nov, 2003 | ED1: Dec, 2003 | EE1: Jan, 2004 | EF1: Feb, 2004 | EG1: Mar, 2004 | EH1: Apr, 2004 | EI1: May, 2004 | EJ1: Jun, 2004 | EK1: Jul, 2004 | EL1: Aug, 2004 | EM1: Sep, 2004 | EN1: Oct, 2004 | EO1: Nov, 2004 | EP1: Dec, 2004 | EQ1: Jan, 2005 | ER1: Feb, 2005 | ES1: Mar, 2005 | ET1: Apr, 2005 | EU1: May, 2005 | EV1: Jun, 2005 | EW1: Jul, 2005 | EX1: Aug, 2005 | EY1: Sep, 2005 | EZ1: Oct, 2005 | FA1: Nov, 2005 | FB1: Dec, 2005 | FC1: Jan, 2006 | FD1: Feb, 2006 | FE1: Mar, 2006 | FF1: Apr, 2006 | FG1: May, 2006 | FH1: Jun, 2006 | FI1: Jul, 2006 | FJ1: Aug, 2006 | FK1: Sep, 2006 | FL1: Oct, 2006 | FM1: Nov, 2006 | FN1: Dec, 2006 | FO1: Jan, 2007 | FP1: Feb, 2007 | FQ1: Mar, 2007 | FR1: Apr, 2007 | FS1: May, 2007 | FT1: Jun, 2007 | FU1: Jul, 2007 | FV1: Aug, 2007 | FW1: Sep, 2007 | FX1: Oct, 2007 | FY1: Nov, 2007 | FZ1: Dec, 2007 | GA1: Jan, 2008 | GB1: Feb, 2008 | GC1: Mar, 2008 | GD1: Apr, 2008 | GE1: May, 2008 | GF1: Jun, 2008 | GG1: Jul, 2008 | GH1: Aug, 2008 | GI1: Sep, 2008 | GJ1: Oct, 2008 | GK1: Nov, 2008 | GL1: Dec, 2008 | GM1: Jan, 2009 | GN1: Feb, 2009 | GO1: Mar, 2009 | GP1: Apr, 2009 | GQ1: May, 2009 | GR1: Jun, 2009 | GS1: Jul, 2009 | GT1: Aug, 2009 | GU1: Sep, 2009 | GV1: Oct, 2009 | GW1: Nov, 2009 | GX1: Dec, 2009 | GY1: Jan, 2010 | GZ1: Feb, 2010 | HA1: Mar, 2010 | HB1: Apr, 2010 | HC1: May, 2010 | HD1: Jun, 2010 | HE1: Jul, 2010 | HF1: Aug, 2010 | HG1: Sep, 2010 | HH1: Oct, 2010 | HI1: Nov, 2010 | HJ1: Dec, 2010 | HK1: Jan, 2011 | HL1: Feb, 2011 | HM1: Mar, 2011 | HN1: Apr, 2011 | HO1: May, 2011 | HP1: Jun, 2011 | HQ1: Jul, 2011 | HR1: Aug, 2011 | HS1: Sep, 2011 | HT1: Oct, 2011 | HU1: Nov, 2011 | HV1: Dec, 2011 | HW1: Jan, 2012 | HX1: Feb, 2012 | HY1: Mar, 2012 | HZ1: Apr, 2012 | IA1: May, 2012 | IB1: Jun, 2012 | IC1: Jul, 2012 | ID1: Aug, 2012 | IE1: Sep, 2012 | IF1: Oct, 2012 | IG1: Nov, 2012 | IH1: Dec, 2012 | II1: Jan, 2013 | IJ1: Feb, 2013 | IK1: Mar, 2013 | IL1: Apr, 2013 | IM1: May, 2013 | IN1: Jun, 2013 | IO1: Jul, 2013 | IP1: Aug, 2013 | IQ1: Sep, 2013 | IR1: Oct, 2013 | IS1: Nov, 2013 | IT1: Dec, 2013 | IU1: Jan, 2014 | IV1: Feb, 2014 | IW1: Mar, 2014 | IX1: Apr, 2014 | IY1: May, 2014 | IZ1: Jun, 2014 | JA1: Jul, 2014 | JB1: Aug, 2014 | JC1: Sep, 2014 | JD1: Oct, 2014 | JE1: Nov, 2014 | JF1: Dec, 2014 | JG1: Jan, 2015 | JH1: Feb, 2015 | JI1: Mar, 2015 | JJ1: Apr, 2015 | JK1: May, 2015 | JL1: Jun, 2015 | JM1: Jul, 2015 | JN1: Aug, 2015 | JO1: Sep, 2015 | JP1: Oct, 2015 | JQ1: Nov, 2015 | JR1: Dec, 2015 | JS1: Jan, 2016 | JT1: Feb, 2016 | JU1: Mar, 2016 | JV1: Apr, 2016 | JW1: May, 2016 | JX1: Jun, 2016 | JY1: Jul, 2016 | JZ1: Aug, 2016 | KA1: Sep, 2016 | KB1: Oct, 2016 | KC1: Nov, 2016 | KD1: Dec, 2016 | KE1: Jan, 2017 | KF1: Feb, 2017 | KG1: Mar, 2017 | KH1: Apr, 2017 | KI1: May, 2017 | KJ1: Jun, 2017 | KK1: Jul, 2017 | KL1: Aug, 2017 | KM1: Sep, 2017 | KN1: Oct, 2017 | KO1: Nov, 2017 | KP1: Dec, 2017 | KQ1: Jan, 2018 | KR1: Feb, 2018 | KS1: Mar, 2018 | KT1: Apr, 2018 | KU1: May, 2018 | KV1: Jun, 2018 | KW1: Jul, 2018 | KX1: Aug, 2018 | KY1: Sep, 2018 | KZ1: Oct, 2018 | LA1: Nov, 2018 | LB1: Dec, 2018 | LC1: Jan, 2019 | LD1: Feb, 2019 | LE1: Mar, 2019 | LF1: Apr, 2019 | LG1: May, 2019 | LH1: Jun, 2019 | LI1: Jul, 2019 | LJ1: Aug, 2019 | LK1: Sep, 2019 | LL1: Oct, 2019 | LM1: Nov, 2019 | LN1: Dec, 2019 | LO1: Jan, 2020 | LP1: Feb, 2020 | LQ1: Mar, 2020 | LR1: Apr, 2020 | LS1: May, 2020 | LT1: Jun, 2020 | LU1: Jul, 2020 | LV1: Aug, 2020 | LW1: Sep, 2020 | LX1: Oct, 2020 | LY1: Nov, 2020 | LZ1: Dec, 2020 | MA1: Jan, 2021 | MB1: Feb, 2021 | MC1: Mar, 2021 | MD1: Apr, 2021 | ME1: May, 2021 | MF1: Jun, 2021 | MG1: Jul, 2021 | MH1: Aug, 2021 | MI1: Sep, 2021 | MJ1: Oct, 2021 | MK1: Nov, 2021 | ML1: Dec, 2021 | MM1: Jan, 2022 | MN1: Feb, 2022 | MO1: Mar, 2022 | MP1: Apr, 2022 | MQ1: May, 2022 | MR1: Jun, 2022 | MS1: Jul, 2022 | MT1: Aug, 2022 | MU1: Sep, 2022 | MV1: Oct, 2022 | MW1: Nov, 2022 | MX1: Dec, 2022 | MY1: Jan, 2023 | MZ1: Feb, 2023 | NA1: Mar, 2023 | NB1: Apr, 2023 | NC1: May, 2023 | ND1: Jun, 2023 | NE1: Jul, 2023 | NF1: Aug, 2023 | NG1: Sep, 2023 | NH1: Oct, 2023 | NI1: Nov, 2023 | NJ1: Dec, 2023 | NK1: Jan, 2024 | NL1: Feb, 2024 | NM1: Mar, 2024 | NN1: Apr, 2024 | NO1: May, 2024 | NP1: Jun, 2024 | NQ1: Jul, 2024 | NR1: Aug, 2024 | NS1: Sep, 2024 | NT1: Oct, 2024 | NU1: Nov, 2024 | NV1: Dec, 2024 | NW1: Jan, 2025 | NX1: Feb, 2025 | NY1: Mar, 2025 | NZ1: Apr, 2025 | OA1: May, 2025 | OB1: Jun, 2025 | OC1: Jul, 2025 | OD1: Aug, 2025 | OE1: Sep, 2025 | OF1: Oct, 2025 | OG1: Nov, 2025 | OH1: Dec, 2025 | OI1: Jan, 2026 | OJ1: Feb, 2026 | OK1: Mar, 2026 | OL1: Apr, 2026 | OM1: May, 2026 | ON1: Jun, 2026 | OO1: Jul, 2026
A2: Monetary aggregate М0 | B2: 1.7 | C2: 1.9 | D2: 2.3 | E2: 2.6 | F2: 3.3 | G2: 4 | H2: 5.1 | I2: 6.3 | J2: 7.3 | K2: 8.4 | L2: 9.8 | M2: 11 | N2: 13.3 | O2: 13 | P2: 14.6 | Q2: 15.9 | R2: 19.4 | S2: 20.7 | T2: 23.8 | U2: 27 | V2: 27.9 | W2: 30 | X2: 30.5 | Y2: 31.9 | Z2: 36.5 | AA2: 30.7 | AB2: 33.3 | AC2: 35 | AD2: 41.8 | AE2: 45.9 | AF2: 55 | AG2: 59.6 | AH2: 63.2 | AI2: 66.7 | AJ2: 67.3 | AK2: 71.4 | AL2: 80.8 | AM2: 75.4 | AN2: 80.4 | AO2: 86.7 | AP2: 93.1 | AQ2: 93.7 | AR2: 104.4 | AS2: 102.8 | AT2: 101.1 | AU2: 96.2 | AV2: 94.4 | AW2: 95.8 | AX2: 103.8 | AY2: 96.4 | AZ2: 102.1 | BA2: 105.2 | BB2: 115.2 | BC2: 120.4 | BD2: 136.9 | BE2: 140.4 | BF2: 141.6 | BG2: 134.9 | BH2: 135.8 | BI2: 128.8 | BJ2: 130.3 | BK2: 116.6 | BL2: 120.3 | BM2: 119 | BN2: 128.5 | BO2: 129.7 | BP2: 129.7 | BQ2: 129.2 | BR2: 133.2 | BS2: 154 | BT2: 166.3 | BU2: 167.1 | BV2: 187.7 | BW2: 177.9 | BX2: 180.6 | BY2: 174 | BZ2: 195.1 | CA2: 205.1 | CB2: 216.2 | CC2: 218 | CD2: 216 | CE2: 212.6 | CF2: 221.8 | CG2: 218.9 | CH2: 266.1 | CI2: 232.5 | CJ2: 241.6 | CK2: 251.1 | CL2: 278.7 | CM2: 288.9 | CN2: 321.4 | CO2: 333.7 | CP2: 341.2 | CQ2: 350.5 | CR2: 349.3 | CS2: 357.9 | CT2: 418.9 | CU2: 379.7 | CV2: 387.6 | CW2: 399 | CX2: 435 | CY2: 438 | CZ2: 474.3 | DA2: 490.3 | DB2: 506.8 | DC2: 530.6 | DD2: 531 | DE2: 526.8 | DF2: 583.8 | DG2: 532.9 | DH2: 543.1 | DI2: 552.7 | DJ2: 609.9 | DK2: 607.2 | DL2: 645.7 | DM2: 659.5 | DN2: 678.8 | DO2: 672.3 | DP2: 675.6 | DQ2: 690.4 | DR2: 763.2 | DS2: 708.9 | DT2: 730.8 | DU2: 749.5 | DV2: 822.3 | DW2: 855.5 | DX2: 917 | DY2: 940.9 | DZ2: 966.3 | EA2: 957.1 | EB2: 975.8 | EC2: 1002.1 | ED2: 1147 | EE2: 1130.6 | EF2: 1164.1 | EG2: 1165.5 | EH2: 1230.1 | EI2: 1220.5 | EJ2: 1276.1 | EK2: 1315 | EL2: 1290.6 | EM2: 1293.7 | EN2: 1310.3 | EO2: 1332.7 | EP2: 1534.8 | EQ2: 1425.2 | ER2: 1444.1 | ES2: 1481.7 | ET2: 1565.8 | EU2: 1582.3 | EV2: 1650.7 | EW2: 1701.8 | EX2: 1703.3 | EY2: 1740.7 | EZ2: 1752 | FA2: 1765.8 | FB2: 2009.2 | FC2: 1875.6 | FD2: 1890.1 | FE2: 1928.8 | FF2: 2027.8 | FG2: 2096.9 | FH2: 2233.4 | FI2: 2290.3 | FJ2: 2351.6 | FK2: 2400.8 | FL2: 2402.2 | FM2: 2450.7 | FN2: 2785.2 | FO2: 2630.1 | FP2: 2682 | FQ2: 2741.2 | FR2: 2859.4 | FS2: 2896.6 | FT2: 3027.5 | FU2: 3087 | FV2: 3170.6 | FW2: 3220.9 | FX2: 3259.1 | FY2: 3373.4 | FZ2: 3702.2 | GA2: 3465.7 | GB2: 3487.6 | GC2: 3475.5 | GD2: 3601.4 | GE2: 3656.2 | GF2: 3724.9 | GG2: 3807.2 | GH2: 3887.4 | GI2: 3904.2 | GJ2: 3962.2 | GK2: 3793.1 | GL2: 3794.8 | GM2: 3312.7 | GN2: 3301.6 | GO2: 3278.3 | GP2: 3410.1 | GQ2: 3461.9 | GR2: 3522.5 | GS2: 3550.1 | GT2: 3506.6 | GU2: 3485.6 | GV2: 3566.7 | GW2: 3600.1 | GX2: 4038.1 | GY2: 3873.3 | GZ2: 3950 | HA2: 3986.1 | HB2: 4181 | HC2: 4240.3 | HD2: 4367.7 | HE2: 4467.3 | HF2: 4477.8 | HG2: 4524.5 | HH2: 4590 | HI2: 4621.5 | HJ2: 5062.7 | HK2: 4830.7 | HL2: 4898 | HM2: 4918.2 | HN2: 5071.3 | HO2: 5079.8 | HP2: 5192.2 | HQ2: 5306.6 | HR2: 5343 | HS2: 5420.4 | HT2: 5420.1 | HU2: 5475.2 | HV2: 5938.6 | HW2: 5670.7 | HX2: 5713 | HY2: 5704.3 | HZ2: 5831.5 | IA2: 5856.4 | IB2: 6003.9 | IC2: 5976.3 | ID2: 5980 | IE2: 5969.2 | IF2: 5931.3 | IG2: 5975.4 | IH2: 6430.1 | II2: 6078.9 | IJ2: 6140.9 | IK2: 6181.4 | IL2: 6353.5 | IM2: 6348.8 | IN2: 6470.3 | IO2: 6480.1 | IP2: 6509.8 | IQ2: 6414.4 | IR2: 6419 | IS2: 6564.1 | IT2: 6985.6 | IU2: 6663.1 | IV2: 6699.9 | IW2: 6608.2 | IX2: 6776.8 | IY2: 6763.1 | IZ2: 6762.2 | JA2: 6871.2 | JB2: 6964.1 | JC2: 6959.3 | JD2: 6907.6 | JE2: 6920 | JF2: 7171.5 | JG2: 6700.3 | JH2: 6671.9 | JI2: 6540.9 | JJ2: 6619.6 | JK2: 6576.8 | JL2: 6659.5 | JM2: 6759.5 | JN2: 6785.7 | JO2: 6744.9 | JP2: 6786.9 | JQ2: 6786.6 | JR2: 7239.1 | JS2: 7055.1 | JT2: 7149.8 | JU2: 7142.9 | JV2: 7301.5 | JW2: 7296.8 | JX2: 7372.7 | JY2: 7462.4 | JZ2: 7438.5 | KA2: 7412.2 | KB2: 7339.1 | KC2: 7317.2 | KD2: 7714.8 | KE2: 7543.7 | KF2: 7587.4 | KG2: 7610.3 | KH2: 7775.3 | KI2: 7813.3 | KJ2: 7946.9 | KK2: 8034.2 | KL2: 8066.8 | KM2: 8088.7 | KN2: 8070.7 | KO2: 8073.1 | KP2: 8446 | KQ2: 8162.6 | KR2: 8300 | KS2: 8441.6 | KT2: 8711.3 | KU2: 8771 | KV2: 8945.5 | KW2: 9052.2 | KX2: 9149.1 | KY2: 9137.8 | KZ2: 9047.6 | LA2: 8980.1 | LB2: 9339 | LC2: 8988.8 | LD2: 9028.7 | LE2: 8980.5 | LF2: 9112.7 | LG2: 9109.7 | LH2: 9192.8 | LI2: 9253.1 | LJ2: 9367.6 | LK2: 9411.9 | LL2: 9354.6 | LM2: 9394 | LN2: 9658.4 | LO2: 9489 | LP2: 9670.8 | LQ2: 10241 | LR2: 10912 | LS2: 11209.3 | LT2: 11516.4 | LU2: 11817.8 | LV2: 11951.3 | LW2: 12072.8 | LX2: 12157.7 | LY2: 12134.6 | LZ2: 12523.9 | MA2: 12429.1 | MB2: 12538.1 | MC2: 12569.7 | MD2: 12859.9 | ME2: 12752.3 | MF2: 12786.5 | MG2: 12938.7 | MH2: 12969.4 | MI2: 13087.2 | MJ2: 13020.6 | MK2: 12954.2 | ML2: 13200.4 | MM2: 13026.9 | MN2: 13913.4 | MO2: 13834.3 | MP2: 13518.4 | MQ2: 13233.5 | MR2: 13293.1 | MS2: 13390.8 | MT2: 13481.8 | MU2: 14175 | MV2: 14669.8 | MW2: 14740.3 | MX2: 15435.7 | MY2: 15361.2 | MZ2: 15576.6 | NA2: 15819.6 | NB2: 16242 | NC2: 16485.5 | ND2: 16920.5 | NE2: 17246 | NF2: 17377.5 | NG2: 17349.6 | NH2: 17214.1 | NI2: 16873 | NJ2: 17134 | NK2: 16756.4 | NL2: 16708.8 | NM2: 16622.3 | NN2: 16738.2 | NO2: 16750.9 | NP2: 16705.8 | NQ2: 16782.1 | NR2: 16801.4 | NS2: 16797.4 | NT2: 16795.7 | NU2: 16730.6 | NV2: 17274 | NW2: 16807.3 | NX2: 16635.3 | NY2: 16396.8 | NZ2: 16539.3 | OA2: 16506.8 | OB2: 16701.5 | OC2: 16938.9 | OD2: 17154.3 | OE2: 17275.9 | OF2: 17406.2 | OG2: 17488.3 | OH2: 18234.2 | OI2: 17853.9 | OJ2: 18095.2 | OK2: 18390.6 | OL2: 19002.1 | OM2: 19390.8 | ON2: 19793.9 | OO2: 20366.4
A3: Transferable deposits in rubles | CT3: 450.5 | CU3: 426.1 | CV3: 433.8 | CW3: 453.5 | CX3: 478.3 | CY3: 495.9 | CZ3: 507.2 | DA3: 518.3 | DB3: 527.2 | DC3: 536.7 | DD3: 547.2 | DE3: 524.7 | DF3: 600.2 | DG3: 538.9 | DH3: 534 | DI3: 548.3 | DJ3: 530.7 | DK3: 592.1 | DL3: 603.5 | DM3: 604.5 | DN3: 596.2 | DO3: 621.8 | DP3: 635.4 | DQ3: 643.1 | DR3: 728.1 | DS3: 674.1 | DT3: 696.1 | DU3: 752.5 | DV3: 754.5 | DW3: 813.5 | DX3: 888.1 | DY3: 849.7 | DZ3: 860.3 | EA3: 897.4 | EB3: 858.7 | EC3: 879.5 | ED3: 1018.1 | EE3: 976.4 | EF3: 1010.5 | EG3: 1055.9 | EH3: 1002.2 | EI3: 1040.5 | EJ3: 1120.4 | EK3: 1038.8 | EL3: 1060.1 | EM3: 1101 | EN3: 1108.7 | EO3: 1181 | EP3: 1296.7 | EQ3: 1230.3 | ER3: 1296.9 | ES3: 1356.4 | ET3: 1318.3 | EU3: 1361.7 | EV3: 1468.6 | EW3: 1434.3 | EX3: 1509.6 | EY3: 1603.8 | EZ3: 1560 | FA3: 1620.6 | FB3: 1829.4 | FC3: 1755.9 | FD3: 1768.7 | FE3: 1898.1 | FF3: 1896 | FG3: 2075.2 | FH3: 2206.2 | FI3: 2177 | FJ3: 2258.5 | FK3: 2421.3 | FL3: 2329.5 | FM3: 2405 | FN3: 2779 | FO3: 2640.5 | FP3: 2658.8 | FQ3: 2993.2 | FR3: 3257.9 | FS3: 3792.1 | FT3: 3612.4 | FU3: 3547.9 | FV3: 3602.4 | FW3: 3831.2 | FX3: 3408.3 | FY3: 3501 | FZ3: 3868 | GA3: 3833.5 | GB3: 3764.1 | GC3: 3921 | GD3: 3624.3 | GE3: 3806.4 | GF3: 4136.8 | GG3: 3927.9 | GH3: 4037 | GI3: 4103.5 | GJ3: 3638.2 | GK3: 3772.7 | GL3: 3858.6 | GM3: 3325.5 | GN3: 3254.6 | GO3: 3304.9 | GP3: 3276.3 | GQ3: 3455.3 | GR3: 3679.6 | GS3: 3538.5 | GT3: 3678.2 | GU3: 3819.7 | GV3: 3742.1 | GW3: 3876.2 | GX3: 4287.6 | GY3: 4168.2 | GZ3: 4275.4 | HA3: 4352.1 | HB3: 4335.8 | HC3: 4527.3 | HD3: 4681.4 | HE3: 4602.8 | HF3: 4763.7 | HG3: 4922.6 | HH3: 4884.9 | HI3: 5106.3 | HJ3: 5797.1 | HK3: 5574.7 | HL3: 5650 | HM3: 5571.2 | HN3: 5435.6 | HO3: 5492.6 | HP3: 5769.2 | HQ3: 5656.1 | HR3: 5755.1 | HS3: 5938.8 | HT3: 5710.7 | HU3: 5878.9 | HV3: 6818.3 | HW3: 6525.5 | HX3: 6485.8 | HY3: 6505.7 | HZ3: 6325.7 | IA3: 6358.7 | IB3: 6563.2 | IC3: 6405.5 | ID3: 6195.7 | IE3: 6362.3 | IF3: 6247.1 | IG3: 6326.2 | IH3: 7264 | II3: 7028.6 | IJ3: 7049.2 | IK3: 7212.1 | IL3: 6919.9 | IM3: 7035.1 | IN3: 7513.3 | IO3: 7522.5 | IP3: 7334 | IQ3: 7426.8 | IR3: 7259.9 | IS3: 7506 | IT3: 8526.3 | IU3: 8031.8 | IV3: 8271.5 | IW3: 8134.9 | IX3: 7999.7 | IY3: 7937.1 | IZ3: 8177.3 | JA3: 7920.1 | JB3: 7820.2 | JC3: 7787.7 | JD3: 7352.5 | JE3: 7801 | JF3: 8170 | JG3: 8254.9 | JH3: 8249.1 | JI3: 8208.9 | JJ3: 8134 | JK3: 8246.3 | JL3: 8364.8 | JM3: 8204 | JN3: 8392.8 | JO3: 8236.3 | JP3: 8001.6 | JQ3: 8462.9 | JR3: 9276.4 | JS3: 8852.2 | JT3: 8943.8 | JU3: 9259.1 | JV3: 9009 | JW3: 9439.4 | JX3: 9477.4 | JY3: 9184.8 | JZ3: 9258.9 | KA3: 9111.5 | KB3: 9155.2 | KC3: 9266.7 | KD3: 9927.6 | KE3: 9782.1 | KF3: 9909.6 | KG3: 9695.9 | KH3: 9512.5 | KI3: 9872.6 | KJ3: 10093.5 | KK3: 10024.2 | KL3: 10010 | KM3: 9920.4 | KN3: 10067.4 | KO3: 10294.9 | KP3: 11062.8 | KQ3: 10702.4 | KR3: 10950.2 | KS3: 10905.2 | KT3: 11048.5 | KU3: 11307.3 | KV3: 11658.9 | KW3: 11618.5 | KX3: 11448.4 | KY3: 11437 | KZ3: 11438.7 | LA3: 11594 | LB3: 12285.1 | LC3: 11761.5 | LD3: 11917.5 | LE3: 11830.4 | LF3: 12062.7 | LG3: 11980.3 | LH3: 12524.8 | LI3: 12492.2 | LJ3: 12588.4 | LK3: 13018.3 | LL3: 12782.3 | LM3: 13135.4 | LN3: 14203.3 | LO3: 13868.8 | LP3: 14353.4 | LQ3: 14895.4 | LR3: 15079.4 | LS3: 15262.1 | LT3: 16300.9 | LU3: 16270.4 | LV3: 17076.1 | LW3: 17440.6 | LX3: 17464.6 | LY3: 18260.2 | LZ3: 19261.7 | MA3: 19091.2 | MB3: 19619.8 | MC3: 19628.5 | MD3: 20170.4 | ME3: 20524.4 | MF3: 20967.2 | MG3: 20580.5 | MH3: 20790.9 | MI3: 20851.1 | MJ3: 20781.1 | MK3: 21590.4 | ML3: 22808.3 | MM3: 22870.1 | MN3: 23335 | MO3: 21038.4 | MP3: 20751 | MQ3: 21486.9 | MR3: 23164.8 | MS3: 24254.9 | MT3: 25533.8 | MU3: 26426.6 | MV3: 26653.1 | MW3: 26744.3 | MX3: 28582.8 | MY3: 29603.3 | MZ3: 30044.4 | NA3: 29530.7 | NB3: 29516.9 | NC3: 31033.9 | ND3: 31527 | NE3: 32271.2 | NF3: 32333.3 | NG3: 31635 | NH3: 31415.9 | NI3: 31010.3 | NJ3: 32551.8 | NK3: 31838.8 | NL3: 32659.9 | NM3: 32715.6 | NN3: 33381.3 | NO3: 33236.2 | NP3: 33570.7 | NQ3: 34316.2 | NR3: 33795 | NS3: 34034.3 | NT3: 32796.2 | NU3: 31799.2 | NV3: 34441.5 | NW3: 34257.5 | NX3: 34951.4 | NY3: 34738.1 | NZ3: 34491.7 | OA3: 34875.1 | OB3: 35709.9 | OC3: 35597.2 | OD3: 35728 | OE3: 35743.9 | OF3: 36023.6 | OG3: 36439.6 | OH3: 37679.9 | OI3: 37034 | OJ3: 38550.8 | OK3: 38960 | OL3: 39823.6 | OM3: 40634.3 | ON3: 41519.1 | OO3: 41024.1
A4: Transferable deposits of other financial corporations | CT4: 12.8 | CU4: 15 | CV4: 12 | CW4: 15.4 | CX4: 11.7 | CY4: 15.7 | CZ4: 14.5 | DA4: 12.3 | DB4: 12.3 | DC4: 15.1 | DD4: 16.5 | DE4: 16 | DF4: 21.1 | DG4: 15.7 | DH4: 17.3 | DI4: 21.2 | DJ4: 16.1 | DK4: 22.4 | DL4: 21.2 | DM4: 20.7 | DN4: 17.7 | DO4: 25.6 | DP4: 24.2 | DQ4: 23.5 | DR4: 39.5 | DS4: 20.7 | DT4: 22 | DU4: 36.1 | DV4: 27.9 | DW4: 30 | DX4: 75.9 | DY4: 31.6 | DZ4: 32.1 | EA4: 52.2 | EB4: 35.1 | EC4: 33.4 | ED4: 74.9 | EE4: 54.9 | EF4: 58.5 | EG4: 82 | EH4: 59.3 | EI4: 47 | EJ4: 96.7 | EK4: 51 | EL4: 46.8 | EM4: 62.5 | EN4: 56 | EO4: 63.8 | EP4: 99.5 | EQ4: 74.5 | ER4: 78 | ES4: 86.2 | ET4: 66.1 | EU4: 59.5 | EV4: 99.6 | EW4: 70.2 | EX4: 80.7 | EY4: 119.7 | EZ4: 92 | FA4: 91.4 | FB4: 144 | FC4: 111 | FD4: 109.8 | FE4: 137.6 | FF4: 117.1 | FG4: 139.4 | FH4: 175.5 | FI4: 121.1 | FJ4: 135.3 | FK4: 174.4 | FL4: 124 | FM4: 122.4 | FN4: 187.7 | FO4: 164.4 | FP4: 164.3 | FQ4: 225.9 | FR4: 177.2 | FS4: 182.5 | FT4: 246.8 | FU4: 178.8 | FV4: 165.9 | FW4: 241.9 | FX4: 222 | FY4: 188.3 | FZ4: 250.8 | GA4: 232.9 | GB4: 205.4 | GC4: 274.4 | GD4: 208.2 | GE4: 229.2 | GF4: 288.2 | GG4: 207 | GH4: 209.3 | GI4: 310 | GJ4: 206.2 | GK4: 401.2 | GL4: 306.7 | GM4: 246.3 | GN4: 227.1 | GO4: 239.2 | GP4: 213.7 | GQ4: 229.1 | GR4: 288.9 | GS4: 288.4 | GT4: 324.1 | GU4: 332 | GV4: 305 | GW4: 228.6 | GX4: 234.5 | GY4: 234.2 | GZ4: 289.5 | HA4: 287.6 | HB4: 276.5 | HC4: 291.1 | HD4: 322 | HE4: 308.6 | HF4: 308.4 | HG4: 338.5 | HH4: 314.8 | HI4: 321.6 | HJ4: 317 | HK4: 344.4 | HL4: 331.3 | HM4: 404 | HN4: 322.5 | HO4: 334.3 | HP4: 383.4 | HQ4: 338.4 | HR4: 350.3 | HS4: 413.6 | HT4: 325.9 | HU4: 337.6 | HV4: 346.4 | HW4: 339.6 | HX4: 321.1 | HY4: 401.9 | HZ4: 304.4 | IA4: 253.2 | IB4: 365.6 | IC4: 284.8 | ID4: 232.5 | IE4: 345.2 | IF4: 232.8 | IG4: 235.9 | IH4: 323.6 | II4: 385.1 | IJ4: 380.6 | IK4: 522.3 | IL4: 332.6 | IM4: 320.5 | IN4: 484.7 | IO4: 494.1 | IP4: 462.9 | IQ4: 475.4 | IR4: 452.9 | IS4: 469.3 | IT4: 531.5 | IU4: 501.8 | IV4: 516.4 | IW4: 485 | IX4: 498.5 | IY4: 514.6 | IZ4: 492.4 | JA4: 476 | JB4: 441.2 | JC4: 405.6 | JD4: 372.3 | JE4: 424.2 | JF4: 441.2 | JG4: 431.4 | JH4: 316.4 | JI4: 429.4 | JJ4: 733.5 | JK4: 661.7 | JL4: 540.6 | JM4: 552.6 | JN4: 525.5 | JO4: 496.3 | JP4: 481.5 | JQ4: 524.9 | JR4: 532.8 | JS4: 558.2 | JT4: 616.6 | JU4: 906.7 | JV4: 706.9 | JW4: 785.3 | JX4: 621.8 | JY4: 700.4 | JZ4: 686.7 | KA4: 652.8 | KB4: 593.5 | KC4: 637.2 | KD4: 549 | KE4: 621.2 | KF4: 598.2 | KG4: 751.3 | KH4: 637.2 | KI4: 667.2 | KJ4: 644.5 | KK4: 635.4 | KL4: 626.5 | KM4: 577.7 | KN4: 633.5 | KO4: 628 | KP4: 654.5 | KQ4: 744.1 | KR4: 627.5 | KS4: 641.3 | KT4: 612.9 | KU4: 590.3 | KV4: 661.8 | KW4: 554.7 | KX4: 539 | KY4: 546.9 | KZ4: 561.9 | LA4: 552.6 | LB4: 480.1 | LC4: 531.9 | LD4: 486.3 | LE4: 525.2 | LF4: 488 | LG4: 484.7 | LH4: 476.3 | LI4: 509.2 | LJ4: 500.7 | LK4: 509.6 | LL4: 490.8 | LM4: 500.5 | LN4: 511.8 | LO4: 520.5 | LP4: 546.3 | LQ4: 535.7 | LR4: 471.2 | LS4: 492.9 | LT4: 503 | LU4: 518.5 | LV4: 586.6 | LW4: 574 | LX4: 557.3 | LY4: 616 | LZ4: 508.7 | MA4: 564.1 | MB4: 599.5 | MC4: 560.2 | MD4: 564.8 | ME4: 611.5 | MF4: 568.1 | MG4: 586 | MH4: 599 | MI4: 602.1 | MJ4: 681.2 | MK4: 701.6 | ML4: 651.1 | MM4: 716.9 | MN4: 852.3 | MO4: 776.9 | MP4: 700 | MQ4: 715 | MR4: 787.6 | MS4: 765.2 | MT4: 1031.3 | MU4: 765.8 | MV4: 813.9 | MW4: 923.1 | MX4: 922 | MY4: 1062.4 | MZ4: 971.8 | NA4: 891.6 | NB4: 905.5 | NC4: 1050 | ND4: 1151 | NE4: 1143.2 | NF4: 1206.4 | NG4: 1181.8 | NH4: 1228.5 | NI4: 1290 | NJ4: 1253.6 | NK4: 1384.4 | NL4: 1350.5 | NM4: 1320 | NN4: 1364.1 | NO4: 1444.2 | NP4: 1475.9 | NQ4: 1549.2 | NR4: 1485 | NS4: 1580.6 | NT4: 1558.1 | NU4: 1468.3 | NV4: 1422.2 | NW4: 1587.4 | NX4: 1538 | NY4: 1517.1 | NZ4: 1473.7 | OA4: 1430.2 | OB4: 1518.2 | OC4: 1436.6 | OD4: 1582.6 | OE4: 1464.4 | OF4: 1544.8 | OG4: 1514.1 | OH4: 1427.2 | OI4: 1605.3 | OJ4: 1572.6 | OK4: 1581.4 | OL4: 1537.2 | OM4: 1510.4 | ON4: 1805.2 | OO4: 1791.3
A5: Transferable deposits of non-financial corporations | CT5: 337.3 | CU5: 312.1 | CV5: 319.1 | CW5: 330 | CX5: 351.4 | CY5: 362.8 | CZ5: 367.1 | DA5: 375.5 | DB5: 381 | DC5: 382.5 | DD5: 394.1 | DE5: 385.7 | DF5: 464.1 | DG5: 418.2 | DH5: 411.1 | DI5: 423 | DJ5: 405.9 | DK5: 458.1 | DL5: 464.4 | DM5: 463.3 | DN5: 460 | DO5: 476.9 | DP5: 492.6 | DQ5: 497 | DR5: 554.6 | DS5: 525 | DT5: 540.1 | DU5: 577.9 | DV5: 578.4 | DW5: 628.7 | DX5: 646.1 | DY5: 645.3 | DZ5: 652.9 | EA5: 668.1 | EB5: 647.3 | EC5: 662.2 | ED5: 738.1 | EE5: 715.9 | EF5: 733.3 | EG5: 749.5 | EH5: 706.8 | EI5: 754.5 | EJ5: 778.6 | EK5: 753.1 | EL5: 786.3 | EM5: 819.9 | EN5: 838.2 | EO5: 900 | EP5: 944.7 | EQ5: 914.3 | ER5: 967 | ES5: 1007.4 | ET5: 971.8 | EU5: 1018.3 | EV5: 1067.5 | EW5: 1048.6 | EX5: 1114.4 | EY5: 1165.9 | EZ5: 1152 | FA5: 1206.3 | FB5: 1304 | FC5: 1282.4 | FD5: 1279.6 | FE5: 1366.4 | FF5: 1353 | FG5: 1497.7 | FH5: 1549.6 | FI5: 1568.3 | FJ5: 1626.5 | FK5: 1738 | FL5: 1702.6 | FM5: 1768.7 | FN5: 1962.8 | FO5: 1907.9 | FP5: 1891.8 | FQ5: 2156 | FR5: 2429.2 | FS5: 2948.5 | FT5: 2646.2 | FU5: 2634.6 | FV5: 2693.1 | FW5: 2828.8 | FX5: 2437.6 | FY5: 2528.9 | FZ5: 2693 | GA5: 2751.3 | GB5: 2688.7 | GC5: 2767.4 | GD5: 2485.9 | GE5: 2622.3 | GF5: 2836.3 | GG5: 2703.1 | GH5: 2789.5 | GI5: 2815.6 | GJ5: 2586.2 | GK5: 2543.9 | GL5: 2645.5 | GM5: 2299 | GN5: 2219.4 | GO5: 2279.8 | GP5: 2228.9 | GQ5: 2373.8 | GR5: 2475.7 | GS5: 2335.6 | GT5: 2463.3 | GU5: 2594.6 | GV5: 2528.7 | GW5: 2721.4 | GX5: 2919.3 | GY5: 2908 | GZ5: 2916.8 | HA5: 2997.8 | HB5: 2914.1 | HC5: 3060.5 | HD5: 3092.8 | HE5: 2992.3 | HF5: 3168 | HG5: 3291.8 | HH5: 3265 | HI5: 3458.4 | HJ5: 3837.6 | HK5: 3760.3 | HL5: 3798.5 | HM5: 3643.4 | HN5: 3471.7 | HO5: 3533.2 | HP5: 3613 | HQ5: 3513.1 | HR5: 3641.2 | HS5: 3742.5 | HT5: 3621 | HU5: 3767.2 | HV5: 4305.4 | HW5: 4276 | HX5: 4204 | HY5: 4154.8 | HZ5: 3970.9 | IA5: 4076 | IB5: 4006.5 | IC5: 3976.7 | ID5: 3811.3 | IE5: 3877.9 | IF5: 3953.9 | IG5: 3944.9 | IH5: 4357.8 | II5: 4440 | IJ5: 4390.4 | IK5: 4359.1 | IL5: 4083 | IM5: 4295.4 | IN5: 4436.3 | IO5: 4472 | IP5: 4337.8 | IQ5: 4451.8 | IR5: 4366.8 | IS5: 4528.9 | IT5: 4981.1 | IU5: 5019.7 | IV5: 5173.4 | IW5: 5133 | IX5: 4799.6 | IY5: 4789.1 | IZ5: 4949.6 | JA5: 4726.5 | JB5: 4619.9 | JC5: 4717.8 | JD5: 4316.5 | JE5: 4704 | JF5: 4966 | JG5: 5462.6 | JH5: 5481.6 | JI5: 5369.6 | JJ5: 4800.8 | JK5: 5017.8 | JL5: 5151.1 | JM5: 4915 | JN5: 5229.2 | JO5: 5104.3 | JP5: 4914.4 | JQ5: 5310.7 | JR5: 5472.9 | JS5: 5554.3 | JT5: 5500.9 | JU5: 5517.6 | JV5: 5278.8 | JW5: 5584.7 | JX5: 5597.5 | JY5: 5219.6 | JZ5: 5306.9 | KA5: 5192.4 | KB5: 5364.6 | KC5: 5444.9 | KD5: 5684.2 | KE5: 5767.5 | KF5: 5803.8 | KG5: 5450.5 | KH5: 5288.1 | KI5: 5597 | KJ5: 5547.2 | KK5: 5465.2 | KL5: 5500.2 | KM5: 5469.5 | KN5: 5601.8 | KO5: 5767.2 | KP5: 5842.4 | KQ5: 5897.1 | KR5: 5965.5 | KS5: 5884.6 | KT5: 5733.3 | KU5: 5956.9 | KV5: 5955.8 | KW5: 5963.6 | KX5: 5825.1 | KY5: 5851.8 | KZ5: 5732.6 | LA5: 6080.3 | LB5: 6104.4 | LC5: 6197.3 | LD5: 6227.2 | LE5: 6141.6 | LF5: 5997.8 | LG5: 5980.3 | LH5: 6274.2 | LI5: 6245.1 | LJ5: 6281.7 | LK5: 6632.1 | LL5: 6428.2 | LM5: 6598 | LN5: 6821.2 | LO5: 7004.4 | LP5: 7177.6 | LQ5: 7525.5 | LR5: 7173.4 | LS5: 7250.3 | LT5: 7713.8 | LU5: 7528.9 | LV5: 8034.1 | LW5: 8150.1 | LX5: 8099.2 | LY5: 8553.5 | LZ5: 8404.3 | MA5: 8860.8 | MB5: 9078 | MC5: 8982 | MD5: 8631.1 | ME5: 9198.1 | MF5: 9497.3 | MG5: 8923.6 | MH5: 9157.3 | MI5: 9187.4 | MJ5: 9052.2 | MK5: 9860 | ML5: 10275.2 | MM5: 11157.5 | MN5: 11766 | MO5: 11712.1 | MP5: 11210.5 | MQ5: 11929.4 | MR5: 12168.2 | MS5: 12994.7 | MT5: 13588.6 | MU5: 14228.7 | MV5: 14263.4 | MW5: 13867.7 | MX5: 13645.3 | MY5: 15630.1 | MZ5: 15510.1 | NA5: 14732.3 | NB5: 14332.1 | NC5: 15225.9 | ND5: 14761.4 | NE5: 15049.1 | NF5: 15410.6 | NG5: 15198.4 | NH5: 15232.4 | NI5: 15234.2 | NJ5: 15244.3 | NK5: 15375.7 | NL5: 15575.9 | NM5: 15458.5 | NN5: 15940.3 | NO5: 15011.9 | NP5: 14965 | NQ5: 15323.5 | NR5: 15074.7 | NS5: 15337.1 | NT5: 14868.5 | NU5: 14663.6 | NV5: 15488 | NW5: 16191.9 | NX5: 16623.2 | NY5: 16420.7 | NZ5: 15449.2 | OA5: 15900 | OB5: 16137.5 | OC5: 15827.2 | OD5: 15786.4 | OE5: 15870.7 | OF5: 16086.9 | OG5: 16735.8 | OH5: 15874.3 | OI5: 16662.6 | OJ5: 17387.5 | OK5: 17363.2 | OL5: 17285.3 | OM5: 18275.4 | ON5: 18535.2 | OO5: 17748.5
A6: Transferable deposits of households | CT6: 100.4 | CU6: 99 | CV6: 102.6 | CW6: 108.1 | CX6: 115.1 | CY6: 117.4 | CZ6: 125.6 | DA6: 130.5 | DB6: 133.9 | DC6: 139 | DD6: 136.6 | DE6: 122.9 | DF6: 115 | DG6: 105 | DH6: 105.6 | DI6: 104.1 | DJ6: 108.7 | DK6: 111.5 | DL6: 117.9 | DM6: 120.6 | DN6: 118.4 | DO6: 119.3 | DP6: 118.6 | DQ6: 122.6 | DR6: 134.1 | DS6: 128.4 | DT6: 134.1 | DU6: 138.6 | DV6: 148.1 | DW6: 154.8 | DX6: 166.1 | DY6: 172.8 | DZ6: 175.3 | EA6: 177.1 | EB6: 176.3 | EC6: 183.9 | ED6: 205.1 | EE6: 205.6 | EF6: 218.7 | EG6: 224.3 | EH6: 236.1 | EI6: 239 | EJ6: 245.1 | EK6: 234.7 | EL6: 227 | EM6: 218.6 | EN6: 214.6 | EO6: 217.3 | EP6: 252.6 | EQ6: 241.4 | ER6: 251.8 | ES6: 262.8 | ET6: 280.4 | EU6: 283.8 | EV6: 301.6 | EW6: 315.5 | EX6: 314.5 | EY6: 318.2 | EZ6: 316.1 | FA6: 323 | FB6: 381.4 | FC6: 362.4 | FD6: 379.3 | FE6: 394.1 | FF6: 425.8 | FG6: 438.1 | FH6: 481.1 | FI6: 487.7 | FJ6: 496.7 | FK6: 508.9 | FL6: 502.9 | FM6: 513.9 | FN6: 628.5 | FO6: 568.2 | FP6: 602.7 | FQ6: 611.3 | FR6: 651.5 | FS6: 661.1 | FT6: 719.4 | FU6: 734.5 | FV6: 743.4 | FW6: 760.5 | FX6: 748.7 | FY6: 783.7 | FZ6: 924.2 | GA6: 849.3 | GB6: 870 | GC6: 879.2 | GD6: 930.1 | GE6: 954.8 | GF6: 1012.4 | GG6: 1017.8 | GH6: 1038.1 | GI6: 978 | GJ6: 845.7 | GK6: 827.6 | GL6: 906.4 | GM6: 780.2 | GN6: 808.1 | GO6: 785.9 | GP6: 833.6 | GQ6: 852.4 | GR6: 914.9 | GS6: 914.5 | GT6: 890.8 | GU6: 893.2 | GV6: 908.5 | GW6: 926.2 | GX6: 1133.8 | GY6: 1026 | GZ6: 1069.1 | HA6: 1066.7 | HB6: 1145.2 | HC6: 1175.6 | HD6: 1266.6 | HE6: 1301.8 | HF6: 1287.3 | HG6: 1292.3 | HH6: 1305.2 | HI6: 1326.3 | HJ6: 1642.4 | HK6: 1470 | HL6: 1520.2 | HM6: 1523.7 | HN6: 1641.5 | HO6: 1625.1 | HP6: 1772.8 | HQ6: 1804.6 | HR6: 1763.5 | HS6: 1782.7 | HT6: 1763.8 | HU6: 1774.1 | HV6: 2166.5 | HW6: 1909.9 | HX6: 1960.7 | HY6: 1949 | HZ6: 2050.3 | IA6: 2029.5 | IB6: 2191.1 | IC6: 2144 | ID6: 2151.9 | IE6: 2139.3 | IF6: 2060.4 | IG6: 2145.4 | IH6: 2582.6 | II6: 2203.4 | IJ6: 2278.2 | IK6: 2330.6 | IL6: 2504.3 | IM6: 2419.2 | IN6: 2592.4 | IO6: 2556.4 | IP6: 2533.3 | IQ6: 2499.6 | IR6: 2440.2 | IS6: 2507.8 | IT6: 3013.8 | IU6: 2510.3 | IV6: 2581.8 | IW6: 2516.9 | IX6: 2701.6 | IY6: 2633.4 | IZ6: 2735.2 | JA6: 2717.6 | JB6: 2759.1 | JC6: 2664.3 | JD6: 2663.7 | JE6: 2672.8 | JF6: 2762.8 | JG6: 2360.9 | JH6: 2451.1 | JI6: 2410 | JJ6: 2599.7 | JK6: 2566.9 | JL6: 2673.1 | JM6: 2736.4 | JN6: 2638.1 | JO6: 2635.7 | JP6: 2605.7 | JQ6: 2627.3 | JR6: 3270.7 | JS6: 2739.7 | JT6: 2826.3 | JU6: 2834.9 | JV6: 3023.3 | JW6: 3069.3 | JX6: 3258.2 | JY6: 3264.8 | JZ6: 3265.3 | KA6: 3266.3 | KB6: 3197.1 | KC6: 3184.6 | KD6: 3694.4 | KE6: 3393.4 | KF6: 3507.6 | KG6: 3494.1 | KH6: 3587.2 | KI6: 3608.4 | KJ6: 3901.9 | KK6: 3923.6 | KL6: 3883.3 | KM6: 3873.1 | KN6: 3832.1 | KO6: 3899.7 | KP6: 4565.9 | KQ6: 4061.1 | KR6: 4357.2 | KS6: 4379.3 | KT6: 4702.2 | KU6: 4760.1 | KV6: 5041.3 | KW6: 5100.2 | KX6: 5084.2 | KY6: 5038.3 | KZ6: 5144.1 | LA6: 4961.1 | LB6: 5700.5 | LC6: 5032.3 | LD6: 5204 | LE6: 5163.6 | LF6: 5576.9 | LG6: 5515.3 | LH6: 5774.4 | LI6: 5737.9 | LJ6: 5805.9 | LK6: 5876.7 | LL6: 5863.4 | LM6: 6036.9 | LN6: 6870.2 | LO6: 6343.8 | LP6: 6629.4 | LQ6: 6834.2 | LR6: 7434.7 | LS6: 7518.8 | LT6: 8084.1 | LU6: 8223 | LV6: 8455.4 | LW6: 8716.5 | LX6: 8808.1 | LY6: 9090.7 | LZ6: 10348.7 | MA6: 9666.2 | MB6: 9942.3 | MC6: 10086.3 | MD6: 10974.5 | ME6: 10714.8 | MF6: 10901.8 | MG6: 11070.9 | MH6: 11034.6 | MI6: 11061.6 | MJ6: 11047.7 | MK6: 11028.7 | ML6: 11882 | MM6: 10995.8 | MN6: 10716.7 | MO6: 8549.5 | MP6: 8840.5 | MQ6: 8842.5 | MR6: 10208.9 | MS6: 10495 | MT6: 10913.9 | MU6: 11432.1 | MV6: 11575.9 | MW6: 11953.5 | MX6: 14015.5 | MY6: 12910.9 | MZ6: 13562.5 | NA6: 13906.7 | NB6: 14279.3 | NC6: 14758 | ND6: 15614.7 | NE6: 16078.8 | NF6: 15716.3 | NG6: 15254.8 | NH6: 14955 | NI6: 14486.1 | NJ6: 16053.9 | NK6: 15078.7 | NL6: 15733.5 | NM6: 15937.1 | NN6: 16076.8 | NO6: 16780.1 | NP6: 17129.8 | NQ6: 17443.5 | NR6: 17235.3 | NS6: 17116.6 | NT6: 16369.5 | NU6: 15667.2 | NV6: 17531.2 | NW6: 16478.2 | NX6: 16790.2 | NY6: 16800.3 | NZ6: 17568.8 | OA6: 17544.9 | OB6: 18054.3 | OC6: 18333.3 | OD6: 18359 | OE6: 18408.8 | OF6: 18391.9 | OG6: 18189.7 | OH6: 20378.4 | OI6: 18766.1 | OJ6: 19590.7 | OK6: 20015.4 | OL6: 21001.1 | OM6: 20848.5 | ON6: 21178.6 | OO6: 21484.3
A7: - interest-bearing deposits | MK7: 5935.6 | ML7: 6089.7 | MM7: 5883.2 | MN7: 5485.6 | MO7: 4263.3 | MP7: 4363.1 | MQ7: 4472.2 | MR7: 5206.7 | MS7: 5460.7 | MT7: 5706.4 | MU7: 5868.3 | MV7: 6046 | MW7: 6464.6 | MX7: 7541.8 | MY7: 7279.1 | MZ7: 7580 | NA7: 7739 | NB7: 8049.6 | NC7: 8443.7 | ND7: 8834 | NE7: 9125.4 | NF7: 8852.3 | NG7: 8546.6 | NH7: 8511.2 | NI7: 8084.7 | NJ7: 8383 | NK7: 9316.3 | NL7: 9637.4 | NM7: 9683.2 | NN7: 10009.6 | NO7: 10334.4 | NP7: 10524.8 | NQ7: 10870.5 | NR7: 10593.7 | NS7: 10456.7 | NT7: 9809.5 | NU7: 9102.5 | NV7: 10291.4 | NW7: 10014.5 | NX7: 10093.6 | NY7: 10253.1 | NZ7: 10932.8 | OA7: 10933.7 | OB7: 11309.4 | OC7: 11540.8 | OD7: 11495.1 | OE7: 11628.8 | OF7: 11719.3 | OG7: 11501.1 | OH7: 12602.4 | OI7: 12090.8 | OJ7: 12655.2 | OK7: 13070.3 | OL7: 13901.9 | OM7: 13525.9 | ON7: 13809.7 | OO7: 14109.4
A8: -non-interest-bearing deposits | MK8: 5093.1 | ML8: 5792.3 | MM8: 5112.7 | MN8: 5231 | MO8: 4286.2 | MP8: 4477.4 | MQ8: 4370.3 | MR8: 5002.2 | MS8: 5034.3 | MT8: 5207.5 | MU8: 5563.8 | MV8: 5529.9 | MW8: 5488.9 | MX8: 6473.7 | MY8: 5631.8 | MZ8: 5982.5 | NA8: 6167.7 | NB8: 6229.7 | NC8: 6314.2 | ND8: 6780.7 | NE8: 6953.4 | NF8: 6864 | NG8: 6708.2 | NH8: 6443.8 | NI8: 6401.4 | NJ8: 7670.9 | NK8: 5762.3 | NL8: 6096.1 | NM8: 6253.8 | NN8: 6067.2 | NO8: 6445.7 | NP8: 6605 | NQ8: 6573 | NR8: 6641.6 | NS8: 6660 | NT8: 6560 | NU8: 6564.7 | NV8: 7239.8 | NW8: 6463.7 | NX8: 6696.6 | NY8: 6547.2 | NZ8: 6636 | OA8: 6611.2 | OB8: 6744.9 | OC8: 6792.5 | OD8: 6863.9 | OE8: 6780 | OF8: 6672.6 | OG8: 6688.6 | OH8: 7776 | OI8: 6675.3 | OJ8: 6935.5 | OK8: 6945.1 | OL8: 7099.2 | OM8: 7322.6 | ON8: 7369 | OO8: 7374.9
A9: Monetary aggregate М1 | CT9: 869.4 | CU9: 805.8 | CV9: 821.3 | CW9: 852.5 | CX9: 913.3 | CY9: 933.9 | CZ9: 981.5 | DA9: 1008.6 | DB9: 1034 | DC9: 1067.3 | DD9: 1078.2 | DE9: 1051.5 | DF9: 1184 | DG9: 1071.8 | DH9: 1077.1 | DI9: 1101 | DJ9: 1140.5 | DK9: 1199.3 | DL9: 1249.2 | DM9: 1264 | DN9: 1275 | DO9: 1294.1 | DP9: 1311 | DQ9: 1333.5 | DR9: 1491.4 | DS9: 1383 | DT9: 1426.9 | DU9: 1502 | DV9: 1576.8 | DW9: 1669 | DX9: 1805.1 | DY9: 1790.6 | DZ9: 1826.5 | EA9: 1854.5 | EB9: 1834.6 | EC9: 1881.6 | ED9: 2165.1 | EE9: 2107 | EF9: 2174.6 | EG9: 2221.4 | EH9: 2232.3 | EI9: 2261 | EJ9: 2396.5 | EK9: 2353.8 | EL9: 2350.7 | EM9: 2394.7 | EN9: 2419 | EO9: 2513.7 | EP9: 2831.5 | EQ9: 2655.5 | ER9: 2741 | ES9: 2838.1 | ET9: 2884.1 | EU9: 2943.9 | EV9: 3119.4 | EW9: 3136.1 | EX9: 3212.9 | EY9: 3344.5 | EZ9: 3312.1 | FA9: 3386.4 | FB9: 3838.6 | FC9: 3631.5 | FD9: 3658.7 | FE9: 3827 | FF9: 3923.7 | FG9: 4172.2 | FH9: 4439.6 | FI9: 4467.3 | FJ9: 4610.1 | FK9: 4822.1 | FL9: 4731.7 | FM9: 4855.6 | FN9: 5564.2 | FO9: 5270.6 | FP9: 5340.7 | FQ9: 5734.3 | FR9: 6117.3 | FS9: 6688.8 | FT9: 6639.9 | FU9: 6634.9 | FV9: 6773 | FW9: 7052 | FX9: 6667.4 | FY9: 6874.3 | FZ9: 7570.2 | GA9: 7299.2 | GB9: 7251.7 | GC9: 7396.5 | GD9: 7225.7 | GE9: 7462.6 | GF9: 7861.7 | GG9: 7735.1 | GH9: 7924.4 | GI9: 8007.7 | GJ9: 7600.4 | GK9: 7565.8 | GL9: 7653.4 | GM9: 6638.2 | GN9: 6556.2 | GO9: 6583.2 | GP9: 6686.4 | GQ9: 6917.2 | GR9: 7202.1 | GS9: 7088.6 | GT9: 7184.8 | GU9: 7305.3 | GV9: 7308.8 | GW9: 7476.3 | GX9: 8325.7 | GY9: 8041.5 | GZ9: 8225.4 | HA9: 8338.2 | HB9: 8516.8 | HC9: 8767.6 | HD9: 9049.1 | HE9: 9070.1 | HF9: 9241.5 | HG9: 9447.1 | HH9: 9474.9 | HI9: 9727.8 | HJ9: 10859.8 | HK9: 10405.4 | HL9: 10548 | HM9: 10489.4 | HN9: 10506.9 | HO9: 10572.4 | HP9: 10961.4 | HQ9: 10962.7 | HR9: 11098.1 | HS9: 11359.2 | HT9: 11130.8 | HU9: 11354.1 | HV9: 12756.9 | HW9: 12196.2 | HX9: 12198.8 | HY9: 12210 | HZ9: 12157.2 | IA9: 12215.1 | IB9: 12567.1 | IC9: 12381.8 | ID9: 12175.7 | IE9: 12331.5 | IF9: 12178.4 | IG9: 12301.6 | IH9: 13694.1 | II9: 13107.5 | IJ9: 13190.1 | IK9: 13393.5 | IL9: 13273.4 | IM9: 13383.9 | IN9: 13983.6 | IO9: 14002.6 | IP9: 13843.8 | IQ9: 13841.2 | IR9: 13678.9 | IS9: 14070.1 | IT9: 15511.9 | IU9: 14694.9 | IV9: 14971.4 | IW9: 14743.1 | IX9: 14776.5 | IY9: 14700.2 | IZ9: 14939.5 | JA9: 14791.3 | JB9: 14784.3 | JC9: 14747 | JD9: 14260.1 | JE9: 14721 | JF9: 15341.4 | JG9: 14955.2 | JH9: 14921 | JI9: 14749.8 | JJ9: 14753.7 | JK9: 14823 | JL9: 15024.3 | JM9: 14963.6 | JN9: 15178.5 | JO9: 14981.2 | JP9: 14788.5 | JQ9: 15249.5 | JR9: 16515.6 | JS9: 15907.3 | JT9: 16093.6 | JU9: 16402 | JV9: 16310.4 | JW9: 16736.1 | JX9: 16850.1 | JY9: 16647.2 | JZ9: 16697.4 | KA9: 16523.7 | KB9: 16494.3 | KC9: 16583.9 | KD9: 17642.4 | KE9: 17325.8 | KF9: 17497 | KG9: 17306.2 | KH9: 17287.8 | KI9: 17685.9 | KJ9: 18040.5 | KK9: 18058.4 | KL9: 18076.8 | KM9: 18009.1 | KN9: 18138.2 | KO9: 18368 | KP9: 19508.9 | KQ9: 18865 | KR9: 19250.2 | KS9: 19346.8 | KT9: 19759.8 | KU9: 20078.2 | KV9: 20604.4 | KW9: 20670.8 | KX9: 20597.4 | KY9: 20574.8 | KZ9: 20486.2 | LA9: 20574.1 | LB9: 21624.1 | LC9: 20750.3 | LD9: 20946.2 | LE9: 20810.8 | LF9: 21175.4 | LG9: 21090 | LH9: 21717.7 | LI9: 21745.3 | LJ9: 21956 | LK9: 22430.2 | LL9: 22136.9 | LM9: 22529.4 | LN9: 23861.7 | LO9: 23357.8 | LP9: 24024.2 | LQ9: 25136.4 | LR9: 25991.4 | LS9: 26471.4 | LT9: 27817.3 | LU9: 28088.2 | LV9: 29027.4 | LW9: 29513.5 | LX9: 29622.3 | LY9: 30394.8 | LZ9: 31785.6 | MA9: 31520.3 | MB9: 32157.9 | MC9: 32198.2 | MD9: 33030.3 | ME9: 33276.7 | MF9: 33753.7 | MG9: 33519.2 | MH9: 33760.3 | MI9: 33938.3 | MJ9: 33801.7 | MK9: 34544.6 | ML9: 36008.7 | MM9: 35897 | MN9: 37248.3 | MO9: 34872.8 | MP9: 34269.4 | MQ9: 34720.4 | MR9: 36457.9 | MS9: 37645.8 | MT9: 39015.6 | MU9: 40601.7 | MV9: 41323 | MW9: 41484.6 | MX9: 44018.5 | MY9: 44964.6 | MZ9: 45621 | NA9: 45350.3 | NB9: 45758.8 | NC9: 47519.4 | ND9: 48447.6 | NE9: 49517.1 | NF9: 49710.8 | NG9: 48984.6 | NH9: 48630 | NI9: 47883.4 | NJ9: 49685.7 | NK9: 48595.1 | NL9: 49368.8 | NM9: 49338 | NN9: 50119.4 | NO9: 49987.1 | NP9: 50276.5 | NQ9: 51098.3 | NR9: 50596.4 | NS9: 50831.7 | NT9: 49591.9 | NU9: 48529.8 | NV9: 51715.5 | NW9: 51064.8 | NX9: 51586.7 | NY9: 51134.9 | NZ9: 51031.1 | OA9: 51381.9 | OB9: 52411.4 | OC9: 52536.1 | OD9: 52882.4 | OE9: 53019.8 | OF9: 53429.8 | OG9: 53927.9 | OH9: 55914.1 | OI9: 54887.9 | OJ9: 56646 | OK9: 57350.6 | OL9: 58825.6 | OM9: 60025.2 | ON9: 61312.9 | OO9: 61390.5
A10: Other deposits in rubles | CT10: 281.2 | CU10: 284.2 | CV10: 297.2 | CW10: 307.2 | CX10: 307.2 | CY10: 308.8 | CZ10: 319.8 | DA10: 328.8 | DB10: 340.5 | DC10: 354.2 | DD10: 371.6 | DE10: 396.7 | DF10: 425.4 | DG10: 439.4 | DH10: 455.7 | DI10: 473.1 | DJ10: 490.2 | DK10: 500.9 | DL10: 514.9 | DM10: 526.2 | DN10: 549.3 | DO10: 563.2 | DP10: 589 | DQ10: 610.4 | DR10: 639.2 | DS10: 650.3 | DT10: 687.1 | DU10: 716.4 | DV10: 749.3 | DW10: 778.2 | DX10: 814.2 | DY10: 847.7 | DZ10: 868.8 | EA10: 889.5 | EB10: 919 | EC10: 953.6 | ED10: 1040.1 | EE10: 1096.3 | EF10: 1148.9 | EG10: 1188.4 | EH10: 1241.9 | EI10: 1253.9 | EJ10: 1274.4 | EK10: 1272.9 | EL10: 1299.1 | EM10: 1322.8 | EN10: 1368.7 | EO10: 1414.8 | EP10: 1522.4 | EQ10: 1524.4 | ER10: 1559.7 | ES10: 1624.7 | ET10: 1693.4 | EU10: 1733.7 | EV10: 1796 | EW10: 1838.2 | EX10: 1905.3 | EY10: 1930.4 | EZ10: 1984.4 | FA10: 2030.7 | FB10: 2193.5 | FC10: 2190.6 | FD10: 2241 | FE10: 2321.1 | FF10: 2409.7 | FG10: 2491.3 | FH10: 2617.6 | FI10: 2732.3 | FJ10: 2807.3 | FK10: 2905 | FL10: 3011.7 | FM10: 3118.8 | FN10: 3406.6 | FO10: 3404.2 | FP10: 3532.6 | FQ10: 3647.4 | FR10: 3847 | FS10: 3984.2 | FT10: 4187.5 | FU10: 4253.5 | FV10: 4355.5 | FW10: 4409.8 | FX10: 4714.8 | FY10: 4881.6 | FZ10: 5298.7 | GA10: 5210.5 | GB10: 5411.2 | GC10: 5577.3 | GD10: 5718.7 | GE10: 5850.2 | GF10: 5979.5 | GG10: 6107.5 | GH10: 6272.2 | GI10: 6037.9 | GJ10: 5572.7 | GK10: 5273.5 | GL10: 5322.4 | GM10: 4792.7 | GN10: 4908.9 | GO10: 4998.4 | GP10: 5152.2 | GQ10: 5414.4 | GR10: 5448.3 | GS10: 5529.5 | GT10: 5612.4 | GU10: 5796.7 | GV10: 6068.1 | GW10: 6237 | GX10: 6941.9 | GY10: 6862.6 | GZ10: 7011 | HA10: 7301.2 | HB10: 7581.8 | HC10: 7703 | HD10: 7851.8 | HE10: 7993.2 | HF10: 8196.1 | HG10: 8243 | HH10: 8373.4 | HI10: 8537.2 | HJ10: 9152 | HK10: 8902.3 | HL10: 8988.7 | HM10: 9299.3 | HN10: 9513.9 | HO10: 9588.5 | HP10: 9760.5 | HQ10: 9865.4 | HR10: 9963.8 | HS10: 10121.3 | HT10: 10235.8 | HU10: 10565.9 | HV10: 11447.9 | HW10: 11152.9 | HX10: 11343.7 | HY10: 11537.7 | HZ10: 11766.6 | IA10: 11821.2 | IB10: 11894 | IC10: 11924.5 | ID10: 12108.5 | IE10: 12106.2 | IF10: 12266.5 | IG10: 12439.4 | IH10: 13470.6 | II10: 13241.2 | IJ10: 13578.2 | IK10: 13805.2 | IL10: 14103.7 | IM10: 14209.6 | IN10: 14228.6 | IO10: 14441.3 | IP10: 14656.2 | IQ10: 14511.3 | IR10: 14597.5 | IS10: 14803.2 | IT10: 15643.7 | IU10: 15166.2 | IV10: 15197.5 | IW10: 14776.3 | IX10: 15102.6 | IY10: 15190.6 | IZ10: 15132.3 | JA10: 15387 | JB10: 15554.4 | JC10: 15550.6 | JD10: 15571.1 | JE10: 15420.9 | JF10: 16274.3 | JG10: 16078.3 | JH10: 16303.8 | JI10: 16278.6 | JJ10: 16943.2 | JK10: 16997.3 | JL10: 16912 | JM10: 17082.4 | JN10: 17078.8 | JO10: 17071.3 | JP10: 17372.5 | JQ10: 17493.9 | JR10: 18664.1 | JS10: 18027.7 | JT10: 18216.1 | JU10: 18286.7 | JV10: 18793.1 | JW10: 18906.8 | JX10: 19006.7 | JY10: 19384 | JZ10: 19448.2 | KA10: 19625 | KB10: 19556.7 | KC10: 19849 | KD10: 20775.2 | KE10: 20691.3 | KF10: 20965.6 | KG10: 21249.3 | KH10: 21376.3 | KI10: 21537.2 | KJ10: 21582.6 | KK10: 21217.9 | KL10: 21342.9 | KM10: 21563.2 | KN10: 21529.5 | KO10: 21746.4 | KP10: 22933.3 | KQ10: 22733.1 | KR10: 22796.1 | KS10: 23029.3 | KT10: 23362.8 | KU10: 23179.7 | KV10: 23522.4 | KW10: 23240.7 | KX10: 23772.8 | KY10: 23679.1 | KZ10: 23733.4 | LA10: 24318.6 | LB10: 25485.2 | LC10: 24972.9 | LD10: 25268.5 | LE10: 25330.5 | LF10: 25262.1 | LG10: 25646.9 | LH10: 25631.7 | LI10: 25607.2 | LJ10: 25630.7 | LK10: 25836.8 | LL10: 25947.1 | LM10: 26667.5 | LN10: 27798.6 | LO10: 27265.5 | LP10: 27290.2 | LQ10: 27190.7 | LR10: 26960.4 | LS10: 26596 | LT10: 26575.3 | LU10: 26598.6 | LV10: 26266.4 | LW10: 26511.5 | LX10: 26248.8 | LY10: 25727.8 | LZ10: 26866.5 | MA10: 26077.6 | MB10: 26020.4 | MC10: 26064.4 | MD10: 26175.5 | ME10: 25917.4 | MF10: 25830.2 | MG10: 25860.6 | MH10: 26056.7 | MI10: 26667.8 | MJ10: 27012.1 | MK10: 27768 | ML10: 30244.2 | MM10: 29413.3 | MN10: 29411.4 | MO10: 33330.8 | MP10: 34205.9 | MQ10: 34273 | MR10: 33165.4 | MS10: 33179.6 | MT10: 34317.7 | MU10: 34495.2 | MV10: 34313.5 | MW10: 35387.6 | MX10: 38369.5 | MY10: 37257.1 | MZ10: 38334.9 | NA10: 39462.8 | NB10: 38877.2 | NC10: 38678 | ND10: 38829.2 | NE10: 38776.9 | NF10: 40400.1 | NG10: 41612.7 | NH10: 42504.7 | NI10: 44663.5 | NJ10: 48699.6 | NK10: 49221.5 | NL10: 50053.3 | NM10: 50257.8 | NN10: 52988 | NO10: 52531.9 | NP10: 53280.7 | NQ10: 53253 | NR10: 55646.3 | NS10: 56803.1 | NT10: 59355.9 | NU10: 62495.4 | NV10: 65540.9 | NW10: 65513 | NX10: 66110.9 | NY10: 65364.1 | NZ10: 66506.1 | OA10: 66829.5 | OB10: 66677.3 | OC10: 67501.1 | OD10: 68684.5 | OE10: 68240.8 | OF10: 69635.8 | OG10: 70787.8 | OH10: 73714.6 | OI10: 72965.9 | OJ10: 74425.7 | OK10: 72873.6 | OL10: 73163.6 | OM10: 73608.1 | ON10: 73535.3 | OO10: 74292.9
A11: Other deposits of other financial corporations | CT11: 5.8 | CU11: 7 | CV11: 7.9 | CW11: 7.8 | CX11: 8.4 | CY11: 8.3 | CZ11: 9.3 | DA11: 7.5 | DB11: 7.9 | DC11: 8.4 | DD11: 10 | DE11: 9.8 | DF11: 10 | DG11: 11 | DH11: 10.6 | DI11: 11.4 | DJ11: 11 | DK11: 11.3 | DL11: 11.7 | DM11: 12 | DN11: 12.4 | DO11: 13.2 | DP11: 13.2 | DQ11: 13.7 | DR11: 14.6 | DS11: 14.3 | DT11: 14.8 | DU11: 13.4 | DV11: 13.4 | DW11: 13.3 | DX11: 13.6 | DY11: 17 | DZ11: 18.3 | EA11: 18 | EB11: 19.8 | EC11: 21.5 | ED11: 20.2 | EE11: 23.7 | EF11: 25.4 | EG11: 26.7 | EH11: 30 | EI11: 29.4 | EJ11: 28.9 | EK11: 34.6 | EL11: 37.4 | EM11: 35.5 | EN11: 39.5 | EO11: 39.5 | EP11: 60 | EQ11: 58.6 | ER11: 46.4 | ES11: 46.9 | ET11: 53.8 | EU11: 54.6 | EV11: 50.9 | EW11: 60.1 | EX11: 57.1 | EY11: 57.4 | EZ11: 58.5 | FA11: 57.5 | FB11: 86 | FC11: 69.7 | FD11: 71.5 | FE11: 75.8 | FF11: 77.8 | FG11: 81.1 | FH11: 84.7 | FI11: 93.5 | FJ11: 96.6 | FK11: 96.8 | FL11: 100.4 | FM11: 103.4 | FN11: 111.3 | FO11: 97.1 | FP11: 109.3 | FQ11: 114.2 | FR11: 129.9 | FS11: 133.4 | FT11: 140.2 | FU11: 134 | FV11: 143.1 | FW11: 152.3 | FX11: 162.2 | FY11: 172.4 | FZ11: 206.9 | GA11: 213.5 | GB11: 223.1 | GC11: 221 | GD11: 272.1 | GE11: 294.3 | GF11: 311.4 | GG11: 322.2 | GH11: 326.6 | GI11: 304.6 | GJ11: 303.5 | GK11: 308.7 | GL11: 429.2 | GM11: 402.1 | GN11: 430 | GO11: 426.6 | GP11: 382.1 | GQ11: 421.4 | GR11: 392.7 | GS11: 371.6 | GT11: 408.8 | GU11: 432.7 | GV11: 461.6 | GW11: 467.2 | GX11: 503.6 | GY11: 476.4 | GZ11: 427.8 | HA11: 430.9 | HB11: 488.9 | HC11: 465 | HD11: 471.4 | HE11: 487.8 | HF11: 499.8 | HG11: 511.3 | HH11: 509 | HI11: 500.1 | HJ11: 520.3 | HK11: 500.2 | HL11: 499.6 | HM11: 485.1 | HN11: 525.6 | HO11: 525.7 | HP11: 531.6 | HQ11: 567.8 | HR11: 577.4 | HS11: 608.7 | HT11: 645.1 | HU11: 696.6 | HV11: 745.9 | HW11: 737.4 | HX11: 800.2 | HY11: 835.6 | HZ11: 886.2 | IA11: 876 | IB11: 877.5 | IC11: 929.5 | ID11: 992.2 | IE11: 988.9 | IF11: 1000.5 | IG11: 1021.3 | IH11: 1097.2 | II11: 975.5 | IJ11: 987.9 | IK11: 1099.2 | IL11: 1133.7 | IM11: 1114.6 | IN11: 1170.1 | IO11: 1177.1 | IP11: 1216.9 | IQ11: 1205.2 | IR11: 1211.8 | IS11: 1210.7 | IT11: 1213.4 | IU11: 1189.9 | IV11: 1191.3 | IW11: 1172.2 | IX11: 1196.2 | IY11: 1195.1 | IZ11: 1187.4 | JA11: 1271.8 | JB11: 1255.3 | JC11: 1251.6 | JD11: 1271 | JE11: 1275.1 | JF11: 1294.7 | JG11: 1331.5 | JH11: 1337.5 | JI11: 1317.1 | JJ11: 1556.8 | JK11: 1586.7 | JL11: 1584.4 | JM11: 1482.5 | JN11: 1459.7 | JO11: 1445.1 | JP11: 1413 | JQ11: 1349.3 | JR11: 1385.2 | JS11: 1349.4 | JT11: 1324.7 | JU11: 1370.5 | JV11: 1475.7 | JW11: 1424.9 | JX11: 1417.6 | JY11: 1376.1 | JZ11: 1412.4 | KA11: 1423.9 | KB11: 1473.8 | KC11: 1353.3 | KD11: 1379.8 | KE11: 1363.4 | KF11: 1391.5 | KG11: 1376.9 | KH11: 1414.1 | KI11: 1345.9 | KJ11: 1274.1 | KK11: 1207.7 | KL11: 1229.9 | KM11: 1215.1 | KN11: 1198.7 | KO11: 1188.7 | KP11: 1319.2 | KQ11: 1321.3 | KR11: 1334.9 | KS11: 1290.6 | KT11: 1337.3 | KU11: 1326.3 | KV11: 1273 | KW11: 1212.1 | KX11: 1206.8 | KY11: 1243.6 | KZ11: 1301.8 | LA11: 1407.8 | LB11: 1309.4 | LC11: 1450.1 | LD11: 1507.8 | LE11: 1444.1 | LF11: 1430.6 | LG11: 1503.2 | LH11: 1451 | LI11: 1460.1 | LJ11: 1509.8 | LK11: 1475.6 | LL11: 1515.5 | LM11: 1595.3 | LN11: 1557.1 | LO11: 1613.3 | LP11: 1622 | LQ11: 1633.7 | LR11: 1723.2 | LS11: 1629.9 | LT11: 1539.4 | LU11: 1719.6 | LV11: 1679.8 | LW11: 1706.4 | LX11: 1747.8 | LY11: 1729.7 | LZ11: 1766.5 | MA11: 1763.8 | MB11: 1778.9 | MC11: 1833.7 | MD11: 1892.2 | ME11: 1842.7 | MF11: 1896.3 | MG11: 1816.4 | MH11: 1873.7 | MI11: 2011.4 | MJ11: 1960.2 | MK11: 2015.9 | ML11: 2295.9 | MM11: 2169 | MN11: 2169.2 | MO11: 2258.9 | MP11: 2258.9 | MQ11: 2250.9 | MR11: 2219.1 | MS11: 2286.3 | MT11: 2327.4 | MU11: 2589.4 | MV11: 2590.3 | MW11: 2650.2 | MX11: 2859.6 | MY11: 3114.6 | MZ11: 3430.1 | NA11: 4022.7 | NB11: 3313.9 | NC11: 3097.7 | ND11: 3268.2 | NE11: 3275.6 | NF11: 3378.5 | NG11: 3268 | NH11: 3366.7 | NI11: 3610.3 | NJ11: 3783.2 | NK11: 4151 | NL11: 4342.7 | NM11: 4304.5 | NN11: 4200.2 | NO11: 4558.7 | NP11: 4531.8 | NQ11: 4443.9 | NR11: 4899 | NS11: 5048.2 | NT11: 5284.9 | NU11: 5928.9 | NV11: 5856.7 | NW11: 5929.6 | NX11: 5878.6 | NY11: 5683.2 | NZ11: 5495.5 | OA11: 5554.5 | OB11: 5649.3 | OC11: 5685.6 | OD11: 5758.7 | OE11: 5825.6 | OF11: 5693.2 | OG11: 5774 | OH11: 6014.5 | OI11: 6125.7 | OJ11: 6227.1 | OK11: 6308.3 | OL11: 6201.5 | OM11: 6322.6 | ON11: 6191 | OO11: 6254.7
A12: Other deposits of non-financial corporations | CT12: 65.3 | CU12: 59.2 | CV12: 65.5 | CW12: 70.3 | CX12: 63.3 | CY12: 59.6 | CZ12: 65.6 | DA12: 70.5 | DB12: 73.6 | DC12: 75.8 | DD12: 73.9 | DE12: 75.2 | DF12: 76.1 | DG12: 67.7 | DH12: 66.9 | DI12: 69.3 | DJ12: 70.8 | DK12: 72.7 | DL12: 74.8 | DM12: 71.8 | DN12: 80.5 | DO12: 80.1 | DP12: 83.5 | DQ12: 87.1 | DR12: 99.1 | DS12: 88.6 | DT12: 94.7 | DU12: 100.7 | DV12: 108.3 | DW12: 110.5 | DX12: 115.6 | DY12: 119.5 | DZ12: 116.5 | EA12: 123.7 | EB12: 122.7 | EC12: 118.7 | ED12: 137.6 | EE12: 124.5 | EF12: 132.5 | EG12: 137.2 | EH12: 159.7 | EI12: 158.9 | EJ12: 164.9 | EK12: 164.7 | EL12: 173.6 | EM12: 174.2 | EN12: 186.3 | EO12: 192.5 | EP12: 216.1 | EQ12: 195.8 | ER12: 204.2 | ES12: 222.1 | ET12: 239.9 | EU12: 249.5 | EV12: 281.6 | EW12: 279.8 | EX12: 312.9 | EY12: 296.1 | EZ12: 315.3 | FA12: 318 | FB12: 358.7 | FC12: 345.2 | FD12: 338.9 | FE12: 356.7 | FF12: 388.2 | FG12: 400.3 | FH12: 457.6 | FI12: 499.6 | FJ12: 500.6 | FK12: 534.3 | FL12: 563.7 | FM12: 585 | FN12: 693.2 | FO12: 640.9 | FP12: 671.1 | FQ12: 697.2 | FR12: 788.4 | FS12: 850.6 | FT12: 967.3 | FU12: 954.4 | FV12: 962.4 | FW12: 931 | FX12: 1164.2 | FY12: 1227.5 | FZ12: 1450.6 | GA12: 1325.3 | GB12: 1462.1 | GC12: 1559.1 | GD12: 1556 | GE12: 1589.8 | GF12: 1620.1 | GG12: 1667.6 | GH12: 1735.2 | GI12: 1569.5 | GJ12: 1429.8 | GK12: 1292.8 | GL12: 1388.4 | GM12: 1059.5 | GN12: 1113.7 | GO12: 1131.2 | GP12: 1226.3 | GQ12: 1338.5 | GR12: 1310.7 | GS12: 1354.2 | GT12: 1354.3 | GU12: 1436.6 | GV12: 1540.7 | GW12: 1561.2 | GX12: 1964.7 | GY12: 1781.3 | GZ12: 1788.6 | HA12: 1886 | HB12: 1911.3 | HC12: 1911.8 | HD12: 1913.2 | HE12: 1892.5 | HF12: 1956.1 | HG12: 1882 | HH12: 1885.7 | HI12: 1893.7 | HJ12: 2220.8 | HK12: 1897.2 | HL12: 1857.7 | HM12: 2078.6 | HN12: 2157.3 | HO12: 2159.5 | HP12: 2243.5 | HQ12: 2211 | HR12: 2236.7 | HS12: 2334.9 | HT12: 2374.8 | HU12: 2521.8 | HV12: 3017.8 | HW12: 2639.6 | HX12: 2652.2 | HY12: 2691.9 | HZ12: 2726.2 | IA12: 2704.5 | IB12: 2684.2 | IC12: 2615.1 | ID12: 2642.4 | IE12: 2588.3 | IF12: 2609.7 | IG12: 2620.5 | IH12: 3234.1 | II12: 2952.1 | IJ12: 3081.8 | IK12: 3014.1 | IL12: 3065 | IM12: 3101.9 | IN12: 2945.4 | IO12: 3045.1 | IP12: 3114 | IQ12: 2940.1 | IR12: 2877.9 | IS12: 3010 | IT12: 3592.6 | IU12: 3216.8 | IV12: 3250.4 | IW12: 3067.9 | IX12: 3271.5 | IY12: 3272.7 | IZ12: 3130.8 | JA12: 3195.7 | JB12: 3284.9 | JC12: 3241.9 | JD12: 3313.2 | JE12: 3237.5 | JF12: 4310.1 | JG12: 3879.7 | JH12: 3833.5 | JI12: 3613.1 | JJ12: 3828 | JK12: 3731.4 | JL12: 3519.5 | JM12: 3661.5 | JN12: 3551.6 | JO12: 3476.8 | JP12: 3686.5 | JQ12: 3725.5 | JR12: 4505 | JS12: 3776.7 | JT12: 3832.5 | JU12: 3738.4 | JV12: 3963.4 | JW12: 3989.7 | JX12: 4020.4 | JY12: 4331.1 | JZ12: 4223.6 | KA12: 4367.2 | KB12: 4078.6 | KC12: 4252.9 | KD12: 4762 | KE12: 4526.6 | KF12: 4621 | KG12: 4837.1 | KH12: 4876.1 | KI12: 5000 | KJ12: 5018.7 | KK12: 4740.4 | KL12: 4752.5 | KM12: 4903.1 | KN12: 4777.8 | KO12: 4844.4 | KP12: 5536.9 | KQ12: 5220.6 | KR12: 5181.8 | KS12: 5260.9 | KT12: 5448 | KU12: 5325.1 | KV12: 5639.2 | KW12: 5376.6 | KX12: 5903.9 | KY12: 5831.6 | KZ12: 5724.8 | LA12: 6035.9 | LB12: 6990.1 | LC12: 6264.1 | LD12: 6325.1 | LE12: 6324 | LF12: 6095.7 | LG12: 6373.6 | LH12: 6370.3 | LI12: 6310.4 | LJ12: 6127 | LK12: 6348.6 | LL12: 6343.8 | LM12: 6927.1 | LN12: 7843.7 | LO12: 7262.2 | LP12: 7213 | LQ12: 7343.9 | LR12: 7289.7 | LS12: 7192.7 | LT12: 7281.4 | LU12: 7142.4 | LV12: 7083.3 | LW12: 7509.5 | LX12: 7543.9 | LY12: 7401.1 | LZ12: 8414.4 | MA12: 7827.6 | MB12: 7914.8 | MC12: 8069.4 | MD12: 8174.2 | ME12: 8177.2 | MF12: 8153.7 | MG12: 8304.3 | MH12: 8294.9 | MI12: 8601.9 | MJ12: 8847.9 | MK12: 9374.9 | ML12: 10779.4 | MM12: 9884.9 | MN12: 10181.5 | MO12: 11252.9 | MP12: 11120.5 | MQ12: 10941.7 | MR12: 10748.3 | MS12: 10606.4 | MT12: 11779.5 | MU12: 12334.7 | MV12: 12207 | MW12: 13157.4 | MX12: 15233.2 | MY12: 13729.9 | MZ12: 14302.5 | NA12: 14638.5 | NB12: 14369.1 | NC12: 14231.3 | ND12: 14129.1 | NE12: 13955.8 | NF12: 14542.7 | NG12: 14834.6 | NH12: 14658.3 | NI12: 15198.1 | NJ12: 17530.7 | NK12: 17027.6 | NL12: 17095.6 | NM12: 16558.7 | NN12: 18452.4 | NO12: 17008.3 | NP12: 17091.5 | NQ12: 16851.6 | NR12: 17709 | NS12: 17818.4 | NT12: 18536.3 | NU12: 19420.4 | NV12: 20300.2 | NW12: 19595.9 | NX12: 19427 | NY12: 18228.3 | NZ12: 18764.3 | OA12: 18772.6 | OB12: 18253.9 | OC12: 18616.9 | OD12: 19581.3 | OE12: 19086.9 | OF12: 19886.5 | OG12: 20790 | OH12: 21949 | OI12: 20608.7 | OJ12: 21493.5 | OK12: 20053.4 | OL12: 20449.2 | OM12: 21050.3 | ON12: 21047.4 | OO12: 21869
A13: Other deposits of households | CT13: 210.2 | CU13: 218 | CV13: 223.9 | CW13: 229 | CX13: 235.6 | CY13: 240.9 | CZ13: 244.9 | DA13: 250.8 | DB13: 259 | DC13: 269.9 | DD13: 287.7 | DE13: 311.6 | DF13: 339.3 | DG13: 360.7 | DH13: 378.2 | DI13: 392.4 | DJ13: 408.4 | DK13: 416.8 | DL13: 428.3 | DM13: 442.5 | DN13: 456.4 | DO13: 470 | DP13: 492.3 | DQ13: 509.7 | DR13: 525.5 | DS13: 547.3 | DT13: 577.6 | DU13: 602.3 | DV13: 627.6 | DW13: 654.4 | DX13: 685 | DY13: 711.3 | DZ13: 734.1 | EA13: 747.9 | EB13: 776.6 | EC13: 813.4 | ED13: 882.3 | EE13: 948.2 | EF13: 991 | EG13: 1024.4 | EH13: 1052.2 | EI13: 1065.6 | EJ13: 1080.6 | EK13: 1073.6 | EL13: 1088.1 | EM13: 1113.2 | EN13: 1142.9 | EO13: 1182.8 | EP13: 1246.3 | EQ13: 1270.1 | ER13: 1309 | ES13: 1355.6 | ET13: 1399.8 | EU13: 1429.6 | EV13: 1463.5 | EW13: 1498.3 | EX13: 1535.3 | EY13: 1576.9 | EZ13: 1610.6 | FA13: 1655.2 | FB13: 1748.8 | FC13: 1775.7 | FD13: 1830.6 | FE13: 1888.6 | FF13: 1943.7 | FG13: 2009.8 | FH13: 2075.3 | FI13: 2139.3 | FJ13: 2210 | FK13: 2274 | FL13: 2347.6 | FM13: 2430.4 | FN13: 2602 | FO13: 2666.3 | FP13: 2752.3 | FQ13: 2835.9 | FR13: 2928.6 | FS13: 3000.3 | FT13: 3079.9 | FU13: 3165.1 | FV13: 3250 | FW13: 3326.6 | FX13: 3388.4 | FY13: 3481.8 | FZ13: 3641.2 | GA13: 3671.7 | GB13: 3726 | GC13: 3797.2 | GD13: 3890.6 | GE13: 3966.1 | GF13: 4048 | GG13: 4117.7 | GH13: 4210.4 | GI13: 4163.8 | GJ13: 3839.4 | GK13: 3672 | GL13: 3504.8 | GM13: 3331.1 | GN13: 3365.2 | GO13: 3440.7 | GP13: 3543.8 | GQ13: 3654.6 | GR13: 3744.9 | GS13: 3803.6 | GT13: 3849.3 | GU13: 3927.4 | GV13: 4065.8 | GW13: 4208.5 | GX13: 4473.6 | GY13: 4604.9 | GZ13: 4794.6 | HA13: 4984.4 | HB13: 5181.6 | HC13: 5326.2 | HD13: 5467.3 | HE13: 5612.9 | HF13: 5740.2 | HG13: 5849.7 | HH13: 5978.6 | HI13: 6143.5 | HJ13: 6410.9 | HK13: 6504.9 | HL13: 6631.4 | HM13: 6735.7 | HN13: 6830.9 | HO13: 6903.2 | HP13: 6985.5 | HQ13: 7086.7 | HR13: 7149.7 | HS13: 7177.7 | HT13: 7216 | HU13: 7347.5 | HV13: 7684.2 | HW13: 7775.9 | HX13: 7891.3 | HY13: 8010.2 | HZ13: 8154.2 | IA13: 8240.7 | IB13: 8332.3 | IC13: 8379.9 | ID13: 8473.9 | IE13: 8529 | IF13: 8656.3 | IG13: 8797.6 | IH13: 9139.3 | II13: 9313.6 | IJ13: 9508.5 | IK13: 9691.9 | IL13: 9905 | IM13: 9993.1 | IN13: 10113.1 | IO13: 10219.1 | IP13: 10325.3 | IQ13: 10366 | IR13: 10507.8 | IS13: 10582.5 | IT13: 10837.7 | IU13: 10759.5 | IV13: 10755.8 | IW13: 10536.2 | IX13: 10634.9 | IY13: 10722.8 | IZ13: 10814.1 | JA13: 10919.5 | JB13: 11014.2 | JC13: 11057.1 | JD13: 10986.9 | JE13: 10908.3 | JF13: 10669.5 | JG13: 10867.2 | JH13: 11132.8 | JI13: 11348.4 | JJ13: 11558.4 | JK13: 11679.3 | JL13: 11808 | JM13: 11938.4 | JN13: 12067.5 | JO13: 12149.5 | JP13: 12273 | JQ13: 12419.1 | JR13: 12773.9 | JS13: 12901.6 | JT13: 13058.9 | JU13: 13177.8 | JV13: 13354.1 | JW13: 13492.2 | JX13: 13568.7 | JY13: 13676.8 | JZ13: 13812.3 | KA13: 13833.9 | KB13: 14004.4 | KC13: 14242.8 | KD13: 14633.4 | KE13: 14801.3 | KF13: 14953.1 | KG13: 15035.4 | KH13: 15086.1 | KI13: 15191.4 | KJ13: 15289.8 | KK13: 15269.7 | KL13: 15360.4 | KM13: 15445 | KN13: 15553 | KO13: 15713.3 | KP13: 16077.3 | KQ13: 16191.2 | KR13: 16279.4 | KS13: 16477.8 | KT13: 16577.5 | KU13: 16528.4 | KV13: 16610.2 | KW13: 16652 | KX13: 16662.1 | KY13: 16603.9 | KZ13: 16706.8 | LA13: 16874.9 | LB13: 17185.6 | LC13: 17258.6 | LD13: 17435.5 | LE13: 17562.5 | LF13: 17735.8 | LG13: 17770.1 | LH13: 17810.3 | LI13: 17836.8 | LJ13: 17993.8 | LK13: 18012.5 | LL13: 18087.8 | LM13: 18145.1 | LN13: 18397.8 | LO13: 18390 | LP13: 18455.2 | LQ13: 18213.1 | LR13: 17947.5 | LS13: 17773.5 | LT13: 17754.5 | LU13: 17736.6 | LV13: 17503.2 | LW13: 17295.6 | LX13: 16957.1 | LY13: 16597 | LZ13: 16685.6 | MA13: 16486.1 | MB13: 16326.7 | MC13: 16161.3 | MD13: 16109.2 | ME13: 15897.5 | MF13: 15780.2 | MG13: 15739.9 | MH13: 15888.1 | MI13: 16054.5 | MJ13: 16204 | MK13: 16377.1 | ML13: 17168.9 | MM13: 17359.4 | MN13: 17060.7 | MO13: 19818.9 | MP13: 20826.4 | MQ13: 21080.5 | MR13: 20198 | MS13: 20286.8 | MT13: 20210.8 | MU13: 19571 | MV13: 19516.2 | MW13: 19580.1 | MX13: 20276.7 | MY13: 20412.6 | MZ13: 20602.3 | NA13: 20801.7 | NB13: 21194.1 | NC13: 21349 | ND13: 21432 | NE13: 21545.6 | NF13: 22478.9 | NG13: 23510.2 | NH13: 24479.7 | NI13: 25855.1 | NJ13: 27385.8 | NK13: 28042.9 | NL13: 28615 | NM13: 29394.6 | NN13: 30335.4 | NO13: 30965 | NP13: 31657.4 | NQ13: 31957.5 | NR13: 33038.2 | NS13: 33936.5 | NT13: 35534.7 | NU13: 37146.1 | NV13: 39384 | NW13: 39987.5 | NX13: 40805.3 | NY13: 41452.6 | NZ13: 42246.2 | OA13: 42502.4 | OB13: 42774 | OC13: 43198.6 | OD13: 43344.5 | OE13: 43328.4 | OF13: 44056.1 | OG13: 44223.8 | OH13: 45751.1 | OI13: 46231.5 | OJ13: 46705.2 | OK13: 46511.9 | OL13: 46512.9 | OM13: 46235.2 | ON13: 46296.9 | OO13: 46169.2
A14: Monetary aggregate М2 | B14: 6.5 | C14: 7.7 | D14: 8.4 | E14: 9.6 | F14: 11.8 | G14: 14.5 | H14: 13.8 | I14: 19.6 | J14: 22.3 | K14: 22.9 | L14: 25.8 | M14: 28 | N14: 33.2 | O14: 35.5 | P14: 37 | Q14: 40.3 | R14: 47.3 | S14: 53.7 | T14: 60.7 | U14: 65.7 | V14: 72.6 | W14: 78.6 | X14: 82.5 | Y14: 86.6 | Z14: 97.8 | AA14: 93.5 | AB14: 101.7 | AC14: 107.2 | AD14: 123.2 | AE14: 138.2 | AF14: 156.6 | AG14: 165 | AH14: 173.8 | AI14: 179.7 | AJ14: 184.1 | AK14: 195.1 | AL14: 220.8 | AM14: 216.7 | AN14: 229.2 | AO14: 241.7 | AP14: 251 | AQ14: 254.2 | AR14: 266.9 | AS14: 271.8 | AT14: 275.3 | AU14: 276.1 | AV14: 278.8 | AW14: 282.4 | AX14: 288.3 | AY14: 289.9 | AZ14: 299.5 | BA14: 305.8 | BB14: 317.8 | BC14: 328.4 | BD14: 352 | BE14: 363 | BF14: 364.6 | BG14: 363 | BH14: 368.8 | BI14: 357.4 | BJ14: 374.1 | BK14: 364.9 | BL14: 366.9 | BM14: 364.7 | BN14: 372.6 | BO14: 375.7 | BP14: 374.5 | BQ14: 365.6 | BR14: 350.5 | BS14: 374.1 | BT14: 386.9 | BU14: 407.4 | BV14: 453.7 | BW14: 450.6 | BX14: 471.3 | BY14: 482.2 | BZ14: 518.8 | CA14: 553.7 | CB14: 581.5 | CC14: 596 | CD14: 605.7 | CE14: 611.9 | CF14: 639.4 | CG14: 663.5 | CH14: 714.6 | CI14: 709.6 | CJ14: 742 | CK14: 768.4 | CL14: 802.5 | CM14: 850.1 | CN14: 905.8 | CO14: 950.5 | CP14: 977.6 | CQ14: 1008.8 | CR14: 1016.4 | CS14: 1054.6 | CT14: 1150.6 | CU14: 1090 | CV14: 1118.5 | CW14: 1159.6 | CX14: 1220.5 | CY14: 1242.6 | CZ14: 1301.3 | DA14: 1337.4 | DB14: 1374.5 | DC14: 1421.5 | DD14: 1449.8 | DE14: 1448.2 | DF14: 1609.4 | DG14: 1511.2 | DH14: 1532.8 | DI14: 1574.1 | DJ14: 1630.7 | DK14: 1700.2 | DL14: 1764.1 | DM14: 1790.2 | DN14: 1824.3 | DO14: 1857.4 | DP14: 1900 | DQ14: 1943.9 | DR14: 2130.6 | DS14: 2033.3 | DT14: 2114.1 | DU14: 2218.4 | DV14: 2326.1 | DW14: 2447.3 | DX14: 2619.3 | DY14: 2638.3 | DZ14: 2695.4 | EA14: 2744.1 | EB14: 2753.6 | EC14: 2835.2 | ED14: 3205.2 | EE14: 3203.3 | EF14: 3323.5 | EG14: 3409.7 | EH14: 3474.2 | EI14: 3514.9 | EJ14: 3670.9 | EK14: 3626.7 | EL14: 3649.8 | EM14: 3717.5 | EN14: 3787.7 | EO14: 3928.5 | EP14: 4353.9 | EQ14: 4179.9 | ER14: 4300.6 | ES14: 4462.7 | ET14: 4577.5 | EU14: 4677.7 | EV14: 4915.4 | EW14: 4974.3 | EX14: 5118.2 | EY14: 5274.9 | EZ14: 5296.5 | FA14: 5417.1 | FB14: 6032.1 | FC14: 5822.1 | FD14: 5899.7 | FE14: 6148.1 | FF14: 6333.4 | FG14: 6663.4 | FH14: 7057.2 | FI14: 7199.6 | FJ14: 7417.4 | FK14: 7727.1 | FL14: 7743.4 | FM14: 7974.4 | FN14: 8970.7 | FO14: 8674.9 | FP14: 8873.4 | FQ14: 9381.7 | FR14: 9964.3 | FS14: 10673 | FT14: 10827.4 | FU14: 10888.4 | FV14: 11128.5 | FW14: 11461.8 | FX14: 11382.2 | FY14: 11756 | FZ14: 12869 | GA14: 12509.7 | GB14: 12662.9 | GC14: 12973.8 | GD14: 12944.4 | GE14: 13312.8 | GF14: 13841.2 | GG14: 13842.6 | GH14: 14196.6 | GI14: 14045.7 | GJ14: 13173.1 | GK14: 12839.2 | GL14: 12975.9 | GM14: 11430.9 | GN14: 11465.2 | GO14: 11581.6 | GP14: 11838.7 | GQ14: 12331.6 | GR14: 12650.5 | GS14: 12618.1 | GT14: 12797.3 | GU14: 13101.9 | GV14: 13376.9 | GW14: 13713.3 | GX14: 15267.6 | GY14: 14904.1 | GZ14: 15236.4 | HA14: 15639.4 | HB14: 16098.6 | HC14: 16470.6 | HD14: 16900.9 | HE14: 17063.3 | HF14: 17437.7 | HG14: 17690.2 | HH14: 17848.3 | HI14: 18264.9 | HJ14: 20011.9 | HK14: 19307.7 | HL14: 19536.7 | HM14: 19788.7 | HN14: 20020.8 | HO14: 20160.9 | HP14: 20721.9 | HQ14: 20828.1 | HR14: 21061.9 | HS14: 21480.4 | HT14: 21366.7 | HU14: 21920 | HV14: 24204.8 | HW14: 23349.1 | HX14: 23542.5 | HY14: 23747.8 | HZ14: 23923.8 | IA14: 24036.3 | IB14: 24461 | IC14: 24306.3 | ID14: 24284.2 | IE14: 24437.8 | IF14: 24444.8 | IG14: 24741 | IH14: 27164.6 | II14: 26348.7 | IJ14: 26768.4 | IK14: 27198.6 | IL14: 27377.1 | IM14: 27593.4 | IN14: 28212.3 | IO14: 28443.9 | IP14: 28499.9 | IQ14: 28352.6 | IR14: 28276.4 | IS14: 28873.3 | IT14: 31155.6 | IU14: 29861.2 | IV14: 30169 | IW14: 29519.3 | IX14: 29879.2 | IY14: 29890.8 | IZ14: 30071.8 | JA14: 30178.3 | JB14: 30338.7 | JC14: 30297.6 | JD14: 29831.2 | JE14: 30141.9 | JF14: 31615.7 | JG14: 31033.5 | JH14: 31224.9 | JI14: 31028.4 | JJ14: 31696.9 | JK14: 31820.4 | JL14: 31936.3 | JM14: 32046 | JN14: 32257.3 | JO14: 32052.5 | JP14: 32161 | JQ14: 32743.4 | JR14: 35179.7 | JS14: 33935 | JT14: 34309.6 | JU14: 34688.8 | JV14: 35103.6 | JW14: 35642.9 | JX14: 35856.9 | JY14: 36031.2 | JZ14: 36145.6 | KA14: 36148.8 | KB14: 36051.1 | KC14: 36433 | KD14: 38417.7 | KE14: 38017.1 | KF14: 38462.6 | KG14: 38555.5 | KH14: 38664.1 | KI14: 39223.2 | KJ14: 39623.1 | KK14: 39276.3 | KL14: 39419.7 | KM14: 39572.4 | KN14: 39667.7 | KO14: 40114.5 | KP14: 42442.2 | KQ14: 41598.1 | KR14: 42046.2 | KS14: 42376.2 | KT14: 43122.6 | KU14: 43258 | KV14: 44126.7 | KW14: 43911.5 | KX14: 44370.3 | KY14: 44254 | KZ14: 44219.6 | LA14: 44892.8 | LB14: 47109.3 | LC14: 45723.2 | LD14: 46214.7 | LE14: 46141.4 | LF14: 46437.5 | LG14: 46736.9 | LH14: 47349.4 | LI14: 47352.5 | LJ14: 47586.7 | LK14: 48267 | LL14: 48084 | LM14: 49196.9 | LN14: 51660.3 | LO14: 50623.2 | LP14: 51314.5 | LQ14: 52327.1 | LR14: 52951.7 | LS14: 53067.4 | LT14: 54392.6 | LU14: 54686.8 | LV14: 55293.7 | LW14: 56024.9 | LX14: 55871.1 | LY14: 56122.6 | LZ14: 58652.1 | MA14: 57597.9 | MB14: 58178.2 | MC14: 58262.6 | MD14: 59205.8 | ME14: 59194.1 | MF14: 59583.9 | MG14: 59379.7 | MH14: 59816.9 | MI14: 60606.2 | MJ14: 60813.7 | MK14: 62312.5 | ML14: 66252.9 | MM14: 65310.3 | MN14: 66659.7 | MO14: 68203.5 | MP14: 68475.3 | MQ14: 68993.4 | MR14: 69623.2 | MS14: 70825.4 | MT14: 73333.3 | MU14: 75096.8 | MV14: 75636.5 | MW14: 76872.2 | MX14: 82388 | MY14: 82221.7 | MZ14: 83955.9 | NA14: 84813.1 | NB14: 84636 | NC14: 86197.3 | ND14: 87276.8 | NE14: 88294 | NF14: 90110.9 | NG14: 90597.3 | NH14: 91134.7 | NI14: 92546.9 | NJ14: 98385.4 | NK14: 97816.7 | NL14: 99422 | NM14: 99595.8 | NN14: 103107.4 | NO14: 102519.1 | NP14: 103557.2 | NQ14: 104351.3 | NR14: 106242.7 | NS14: 107634.8 | NT14: 108947.9 | NU14: 111025.2 | NV14: 117256.4 | NW14: 116577.8 | NX14: 117697.6 | NY14: 116499 | NZ14: 117537.1 | OA14: 118211.4 | OB14: 119088.7 | OC14: 120037.2 | OD14: 121566.9 | OE14: 121260.6 | OF14: 123065.6 | OG14: 124715.8 | OH14: 129628.7 | OI14: 127853.8 | OJ14: 131071.8 | OK14: 130224.2 | OL14: 131989.3 | OM14: 133633.3 | ON14: 134848.2 | OO14: 135683.4
