Workbook

Sheet README
A1: FRED Graph Observations
A2: Federal Reserve Economic Data, Federal Reserve Bank of St. Louis
A3: Link: https://fred.stlouisfed.org
A4: Help: https://fredhelp.stlouisfed.org
A5: This data may be copyrighted. Please refer to the Terms of Use: https://fred.stlouisfed.org/legal#fred-terms-faq
A6: File Created: 2026-08-16 10:15 am CDT
A8: NGDPRNSAXDCRUQ | B8: Real Gross Domestic Product for Russia, Millions of Domestic Currency, Quarterly, Not Seasonally Adjusted | C8: Data Updated: 2026-07-13

Sheet Quarterly
A1: observation_date | B1: NGDPRNSAXDCRUQ
A2: 40544 | B2: 18440084
A3: 40634 | B3: 19714798
A4: 40725 | B4: 20978424
A5: 40817 | B5: 22617264
A6: 40909 | B6: 19492308
A7: 41000 | B7: 20672447
A8: 41091 | B8: 21711575
A9: 41183 | B9: 23163953
A10: 41275 | B10: 19712531
A11: 41365 | B11: 21028104
A12: 41456 | B12: 22039092
A13: 41548 | B13: 23753372
... A62: 46023 | B62: 32837291

Sheet IPI
A1: SDDS Data Category | B1: Unit Description | C1: 01.2015 | D1: 02.2015 | E1: 03.2015 | F1: 04.2015 | G1: 05.2015 | H1: 06.2015 | I1: 07.2015 | J1: 08.2015 | K1: 09.2015 | L1: 10.2015 | M1: 11.2015 | N1: 12.2015 | O1: 01.2016 | P1: 02.2016 | Q1: 03.2016 | R1: 04.2016 | S1: 05.2016 | T1: 06.2016 | U1: 07.2016 | V1: 08.2016 | W1: 09.2016 | X1: 10.2016 | Y1: 11.2016 | Z1: 12.2016 | AA1: 01.2017 | AB1: 02.2017 | AC1: 03.2017 | AD1: 04.2017 | AE1: 05.2017 | AF1: 06.2017 | AG1: 07.2017 | AH1: 08.2017 | AI1: 09.2017 | AJ1: 10.2017 | AK1: 11.2017 | AL1: 12.2017 | AM1: 01.2018 | AN1: 02.2018 | AO1: 03.2018 | AP1: 04.2018 | AQ1: 05.2018 | AR1: 06.2018 | AS1: 07.2018 | AT1: 08.2018 | AU1: 09.2018 | AV1: 10.2018 | AW1: 11.2018 | AX1: 12.2018 | AY1: 01.2019 | AZ1: 02.2019 | BA1: 03.2019 | BB1: 04.2019 | BC1: 05.2019 | BD1: 06.2019 | BE1: 07.2019 | BF1: 08.2019 | BG1: 09.2019 | BH1: 10.2019 | BI1: 11.2019 | BJ1: 12.2019 | BK1: 01.2020 | BL1: 02.2020 | BM1: 03.2020 | BN1: 04.2020 | BO1: 05.2020 | BP1: 06.2020 | BQ1: 07.2020 | BR1: 08.2020 | BS1: 09.2020 | BT1: 10.2020 | BU1: 11.2020 | BV1: 12.2020 | BW1: 01.2021 | BX1: 02.2021 | BY1: 03.2021 | BZ1: 04.2021 | CA1: 05.2021 | CB1: 06.2021 | CC1: 07.2021 | CD1: 08.2021 | CE1: 09.2021 | CF1: 10.2021 | CG1: 11.2021 | CH1: 12.2021 | CI1: 01.2022 | CJ1: 02.2022 | CK1: 03.2022 | CL1: 04.2022 | CM1: 05.2022 | CN1: 06.2022 | CO1: 07.2022 | CP1: 08.2022 | CQ1: 09.2022 | CR1: 10.2022 | CS1: 11.2022 | CT1: 12.2022 | CU1: 01.2023 | CV1: 02.2023 | CW1: 03.2023 | CX1: 04.2023 | CY1: 05.2023 | CZ1: 06.2023 | DA1: 07.2023 | DB1: 08.2023 | DC1: 09.2023 | DD1: 10.2023 | DE1: 11.2023 | DF1: 12.2023 | DG1: 01.2024 | DH1: 02.2024 | DI1: 03.2024 | DJ1: 04.2024 | DK1: 05.2024 | DL1: 06.2024 | DM1: 07.2024 | DN1: 08.2024 | DO1: 09.2024 | DP1: 10.2024 | DQ1: 11.2024 | DR1: 12.2024 | DS1: 01.2025 | DT1: 02.2025 | DU1: 03.2025 | DV1: 04.2025 | DW1: 05.2025 | DX1: 06.2025 | DY1: 07.2025 | DZ1: 08.2025 | EA1: 09.2025 | EB1: 10.2025 | EC1: 11.2025 | ED1: 12.2025 | EE1: 01.2026 | EF1: 02.2026 | EG1: 03.2026 | EH1: 04.2026 | EI1: 05.2026 | EJ1: 06.2026
A2: Industrial Production Index * | B2: 2023=100 | C2: 76.4 | D2: 74.2 | E2: 82.3 | F2: 78.4 | G2: 77.6 | H2: 78.8 | I2: 79.8 | J2: 80.2 | K2: 81 | L2: 85.3 | M2: 84.8 | N2: 91.5 | O2: 75.7 | P2: 75.8 | Q2: 83.1 | R2: 78.4 | S2: 78 | T2: 79.8 | U2: 80.2 | V2: 82 | W2: 83.1 | X2: 87.9 | Y2: 89.3 | Z2: 95.2 | AA2: 80.8 | AB2: 77.1 | AC2: 86.2 | AD2: 81.9 | AE2: 83 | AF2: 84.2 | AG2: 83.9 | AH2: 86.3 | AI2: 86.5 | AJ2: 89.9 | AK2: 90.3 | AL2: 95.5 | AM2: 82.9 | AN2: 79.5 | AO2: 88.5 | AP2: 84.4 | AQ2: 85.8 | AR2: 86 | AS2: 86.8 | AT2: 88.7 | AU2: 88.5 | AV2: 94.7 | AW2: 94.3 | AX2: 101.6 | AY2: 85.2 | AZ2: 82.8 | BA2: 91 | BB2: 88.9 | BC2: 86.8 | BD2: 88.8 | BE2: 90.6 | BF2: 92.2 | BG2: 93 | BH2: 98.9 | BI2: 95.7 | BJ2: 104.3 | BK2: 86.6 | BL2: 87 | BM2: 93.5 | BN2: 84.9 | BO2: 79.9 | BP2: 82.8 | BQ2: 85.4 | BR2: 88.4 | BS2: 89.6 | BT2: 93.5 | BU2: 94.6 | BV2: 108.1 | BW2: 85.1 | BX2: 84.6 | BY2: 96.1 | BZ2: 92.5 | CA2: 90.4 | CB2: 92.3 | CC2: 92.2 | CD2: 93.4 | CE2: 96.7 | CF2: 101.4 | CG2: 102.2 | CH2: 116.3 | CI2: 92.8 | CJ2: 90.2 | CK2: 99.6 | CL2: 90.8 | CM2: 89.1 | CN2: 91.1 | CO2: 92.7 | CP2: 94.2 | CQ2: 94.7 | CR2: 99.9 | CS2: 102 | CT2: 113.8 | CU2: 91 | CV2: 89.1 | CW2: 101.1 | CX2: 95.6 | CY2: 95.6 | CZ2: 96.6 | DA2: 98.2 | DB2: 100.4 | DC2: 101.1 | DD2: 106.1 | DE2: 107.3 | DF2: 118 | DG2: 95.8 | DH2: 97.1 | DI2: 105.5 | DJ2: 100.5 | DK2: 101.6 | DL2: 99.2 | DM2: 102 | DN2: 103.4 | DO2: 104 | DP2: 111.8 | DQ2: 111.3 | DR2: 128.2 | DS2: 96.7 | DT2: 96.1 | DU2: 105.6 | DV2: 101.8 | DW2: 102.7 | DX2: 101.3 | DY2: 103.5 | DZ2: 104.5 | EA2: 105.3 | EB2: 114.6 | EC2: 111.7 | ED2: 132.9 | EE2: 101.4 | EF2: 100.2 | EG2: 112.6 | EH2: 108 | EI2: 106.2 | EJ2: 105.5
A4: * The indicator “Industrial Production Index” are calculated by types of activity: “Mining and quarrying of natural minerals”, “Manufacturing”, “Electricity, gas and steam supply; air conditioning”, “Water supply; water disposal, organizing of collection and utilization of wastes, activities on liquidation of pollution”. Data by month are given in % to the average monthly value for 2023. Excluding statistical information on: Lugansk People’s Republic, Donetsk People’s Republic, Kherson Region and Zaporozhye Region.
A6: 01.2015 | B6: 2015 | C6: =B6&"-"&TEXT(A6,"00") -> 2015-01 | D6: 76.4
A7: 02.2015 | B7: 2015 | C7: =B7&"-"&TEXT(A7,"00") -> 2015-02 | D7: 74.2
A8: 03.2015 | B8: 2015 | C8: =B8&"-"&TEXT(A8,"00") -> 2015-03 | D8: 82.3
A9: 04.2015 | B9: 2015 | C9: =B9&"-"&TEXT(A9,"00") -> 2015-04 | D9: 78.4
A10: 05.2015 | B10: 2015 | C10: =B10&"-"&TEXT(A10,"00") -> 2015-05 | D10: 77.6
A11: 06.2015 | B11: 2015 | C11: =B11&"-"&TEXT(A11,"00") -> 2015-06 | D11: 78.8
A12: 07.2015 | B12: 2015 | C12: =B12&"-"&TEXT(A12,"00") -> 2015-07 | D12: 79.8
A13: 08.2015 | B13: 2015 | C13: =B13&"-"&TEXT(A13,"00") -> 2015-08 | D13: 80.2
A14: 09.2015 | B14: 2015 | C14: =B14&"-"&TEXT(A14,"00") -> 2015-09 | D14: 81
A15: 10.2015 | B15: 2015 | C15: =B15&"-"&TEXT(A15,"00") -> 2015-10 | D15: 85.3
A16: 11.2015 | B16: 2015 | C16: =B16&"-"&TEXT(A16,"00") -> 2015-11 | D16: 84.8
A17: 12.2015 | B17: 2015 | C17: =B17&"-"&TEXT(A17,"00") -> 2015-12 | D17: 91.5
... A143: 06.2026 | B143: 2026 | C143: =B143&"-"&TEXT(A143,"00") -> 2026-06 | D143: 105.5

Sheet Sheet1
A1: Date Full | B1: GDP | C1: IPI Date | D1: IPI Quarter | E1: Index Value | F1: Quarterly sum | G1: Monthly proportion | H1: Monthly GDP
A2: =DATE(2011,1,1) -> 40544 | B2: =VLOOKUP(A2,Quarterly!$A$2:$B$62,2,FALSE) -> 18440084
A3: =EDATE(A2,1) -> 40575 | B3: =B2 -> 18440084
A4: =EDATE(A3,1) -> 40603 | B4: =B3 -> 18440084
A5: =EDATE(A4,1) -> 40634 | B5: =VLOOKUP(A5,Quarterly!$A$2:$B$62,2,FALSE) -> 19714798
A6: =EDATE(A5,1) -> 40664 | B6: =B5 -> 19714798
A7: =EDATE(A6,1) -> 40695 | B7: =B6 -> 19714798
A8: =EDATE(A7,1) -> 40725 | B8: =VLOOKUP(A8,Quarterly!$A$2:$B$62,2,FALSE) -> 20978424
A9: =EDATE(A8,1) -> 40756 | B9: =B8 -> 20978424
A10: =EDATE(A9,1) -> 40787 | B10: =B9 -> 20978424
A11: =EDATE(A10,1) -> 40817 | B11: =VLOOKUP(A11,Quarterly!$A$2:$B$62,2,FALSE) -> 22617264
A12: =EDATE(A11,1) -> 40848 | B12: =B11 -> 22617264
A13: =EDATE(A12,1) -> 40878 | B13: =B12 -> 22617264
A14: =EDATE(A13,1) -> 40909 | B14: =VLOOKUP(A14,Quarterly!$A$2:$B$62,2,FALSE) -> 19492308
A15: =EDATE(A14,1) -> 40940 | B15: =B14 -> 19492308
A16: =EDATE(A15,1) -> 40969 | B16: =B15 -> 19492308
A17: =EDATE(A16,1) -> 41000 | B17: =VLOOKUP(A17,Quarterly!$A$2:$B$62,2,FALSE) -> 20672447
A18: =EDATE(A17,1) -> 41030 | B18: =B17 -> 20672447
A19: =EDATE(A18,1) -> 41061 | B19: =B18 -> 20672447
A20: =EDATE(A19,1) -> 41091 | B20: =VLOOKUP(A20,Quarterly!$A$2:$B$62,2,FALSE) -> 21711575
A21: =EDATE(A20,1) -> 41122 | B21: =B20 -> 21711575
A22: =EDATE(A21,1) -> 41153 | B22: =B21 -> 21711575
A23: =EDATE(A22,1) -> 41183 | B23: =VLOOKUP(A23,Quarterly!$A$2:$B$62,2,FALSE) -> 23163953
A24: =EDATE(A23,1) -> 41214 | B24: =B23 -> 23163953
A25: =EDATE(A24,1) -> 41244 | B25: =B24 -> 23163953
A26: =EDATE(A25,1) -> 41275 | B26: =VLOOKUP(A26,Quarterly!$A$2:$B$62,2,FALSE) -> 19712531
A27: =EDATE(A26,1) -> 41306 | B27: =B26 -> 19712531
A28: =EDATE(A27,1) -> 41334 | B28: =B27 -> 19712531
A29: =EDATE(A28,1) -> 41365 | B29: =VLOOKUP(A29,Quarterly!$A$2:$B$62,2,FALSE) -> 21028104
A30: =EDATE(A29,1) -> 41395 | B30: =B29 -> 21028104
A31: =EDATE(A30,1) -> 41426 | B31: =B30 -> 21028104
A32: =EDATE(A31,1) -> 41456 | B32: =VLOOKUP(A32,Quarterly!$A$2:$B$62,2,FALSE) -> 22039092
A33: =EDATE(A32,1) -> 41487 | B33: =B32 -> 22039092
A34: =EDATE(A33,1) -> 41518 | B34: =B33 -> 22039092
A35: =EDATE(A34,1) -> 41548 | B35: =VLOOKUP(A35,Quarterly!$A$2:$B$62,2,FALSE) -> 23753372
A36: =EDATE(A35,1) -> 41579 | B36: =B35 -> 23753372
A37: =EDATE(A36,1) -> 41609 | B37: =B36 -> 23753372
A38: =EDATE(A37,1) -> 41640 | B38: =VLOOKUP(A38,Quarterly!$A$2:$B$62,2,FALSE) -> 28173675
A39: =EDATE(A38,1) -> 41671 | B39: =B38 -> 28173675
A40: =EDATE(A39,1) -> 41699 | B40: =B39 -> 28173675
...

Sheet Final Cleaned
A1: date | B1: ru_gdp_m
A2: 2015-01-01 | B2: =Sheet1!H50 -> 9100976.1
A3: 2015-02-01 | B3: =Sheet1!H51 -> 8838906.1
A4: 2015-03-01 | B4: =Sheet1!H52 -> 9803800.2
A5: 2015-04-01 | B5: =Sheet1!H53 -> 9858828.1
A6: 2015-05-01 | B6: =Sheet1!H54 -> 9758227.9
A7: 2015-06-01 | B7: =Sheet1!H55 -> 9909128.3
A8: 2015-07-01 | B8: =Sheet1!H56 -> 10361673
A9: 2015-08-01 | B9: =Sheet1!H57 -> 10413611
A10: 2015-09-01 | B10: =Sheet1!H58 -> 10517487
A11: 2015-10-01 | B11: =Sheet1!H59 -> 10889519
A12: 2015-11-01 | B12: =Sheet1!H60 -> 10825688
A13: 2015-12-01 | B13: =Sheet1!H61 -> 11681019
... A136: 2026-03-01 | B136: =Sheet1!H184 -> 11767915
