Workbook

Sheet Worksheet
A1: Monetary Base and Aggregates of Broad Money
A2: mln of tenge/ end of period
A3: Initial date | B3: 08.00 | C3: 09.00 | D3: 10.00 | E3: 11.00 | F3: 12.00 | G3: 01.01 | H3: 02.01 | I3: 03.01 | J3: 04.01 | K3: 05.01 | L3: 06.01 | M3: 07.01 | N3: 08.01 | O3: 09.01 | P3: 10.01 | Q3: 11.01 | R3: 12.01 | S3: 01.02 | T3: 02.02 | U3: 03.02 | V3: 04.02 | W3: 05.02 | X3: 06.02 | Y3: 07.02 | Z3: 08.02 | AA3: 09.02 | AB3: 10.02 | AC3: 11.02 | AD3: 12.02 | AE3: 01.03 | AF3: 02.03 | AG3: 03.03 | AH3: 04.03 | AI3: 05.03 | AJ3: 06.03 | AK3: 07.03 | AL3: 08.03 | AM3: 09.03 | AN3: 10.03 | AO3: 11.03 | AP3: 12.03 | AQ3: 01.04 | AR3: 02.04 | AS3: 03.04 | AT3: 04.04 | AU3: 05.04 | AV3: 06.04 | AW3: 07.04 | AX3: 08.04 | AY3: 09.04 | AZ3: 10.04 | BA3: 11.04 | BB3: 12.04 | BC3: 01.05 | BD3: 02.05 | BE3: 03.05 | BF3: 04.05 | BG3: 05.05 | BH3: 06.05 | BI3: 07.05 | BJ3: 08.05 | BK3: 09.05 | BL3: 10.05 | BM3: 11.05 | BN3: 12.05 | BO3: 01.06 | BP3: 02.06 | BQ3: 03.06 | BR3: 04.06 | BS3: 05.06 | BT3: 06.06 | BU3: 07.06 | BV3: 08.06 | BW3: 09.06 | BX3: 10.06 | BY3: 11.06 | BZ3: 12.06 | CA3: 01.07 | CB3: 02.07 | CC3: 03.07 | CD3: 04.07 | CE3: 05.07 | CF3: 06.07 | CG3: 07.07 | CH3: 08.07 | CI3: 09.07 | CJ3: 10.07 | CK3: 11.07 | CL3: 12.07 | CM3: 01.08 | CN3: 02.08 | CO3: 03.08 | CP3: 04.08 | CQ3: 05.08 | CR3: 06.08 | CS3: 07.08 | CT3: 08.08 | CU3: 09.08 | CV3: 10.08 | CW3: 11.08 | CX3: 12.08 | CY3: 01.09 | CZ3: 02.09 | DA3: 03.09 | DB3: 04.09 | DC3: 05.09 | DD3: 06.09 | DE3: 07.09 | DF3: 08.09 | DG3: 09.09 | DH3: 10.09 | DI3: 11.09 | DJ3: 12.09 | DK3: 01.10 | DL3: 02.10 | DM3: 03.10 | DN3: 04.10 | DO3: 05.10 | DP3: 06.10 | DQ3: 07.10 | DR3: 08.10 | DS3: 09.10 | DT3: 10.10 | DU3: 11.10 | DV3: 12.10 | DW3: 01.11 | DX3: 02.11 | DY3: 03.11 | DZ3: 04.11 | EA3: 05.11 | EB3: 06.11 | EC3: 07.11 | ED3: 08.11 | EE3: 09.11 | EF3: 10.11 | EG3: 11.11 | EH3: 12.11 | EI3: 01.12 | EJ3: 02.12 | EK3: 03.12 | EL3: 04.12 | EM3: 05.12 | EN3: 06.12 | EO3: 07.12 | EP3: 08.12 | EQ3: 09.12 | ER3: 10.12 | ES3: 11.12 | ET3: 12.12 | EU3: 01.13 | EV3: 02.13 | EW3: 03.13 | EX3: 04.13 | EY3: 05.13 | EZ3: 06.13 | FA3: 07.13 | FB3: 08.13 | FC3: 09.13 | FD3: 10.13 | FE3: 11.13 | FF3: 12.13 | FG3: 01.14 | FH3: 02.14 | FI3: 03.14 | FJ3: 04.14 | FK3: 05.14 | FL3: 06.14 | FM3: 07.14 | FN3: 08.14 | FO3: 09.14 | FP3: 10.14 | FQ3: 11.14 | FR3: 12.14 | FS3: 01.15 | FT3: 02.15 | FU3: 03.15 | FV3: 04.15 | FW3: 05.15 | FX3: 06.15 | FY3: 07.15 | FZ3: 08.15 | GA3: 09.15 | GB3: 10.15 | GC3: 11.15 | GD3: 12.15 | GE3: 01.16 | GF3: 02.16 | GG3: 03.16 | GH3: 04.16 | GI3: 05.16 | GJ3: 06.16 | GK3: 07.16 | GL3: 08.16 | GM3: 09.16 | GN3: 10.16 | GO3: 11.16 | GP3: 12.16 | GQ3: 01.17 | GR3: 02.17 | GS3: 03.17 | GT3: 04.17 | GU3: 05.17 | GV3: 06.17 | GW3: 07.17 | GX3: 08.17 | GY3: 09.17 | GZ3: 10.17 | HA3: 11.17 | HB3: 12.17 | HC3: 01.18 | HD3: 02.18 | HE3: 03.18 | HF3: 04.18 | HG3: 05.18 | HH3: 06.18 | HI3: 07.18 | HJ3: 08.18 | HK3: 09.18 | HL3: 10.18 | HM3: 11.18 | HN3: 12.18 | HO3: 01.19 | HP3: 02.19 | HQ3: 03.19 | HR3: 04.19 | HS3: 05.19 | HT3: 06.19 | HU3: 07.19 | HV3: 08.19 | HW3: 09.19 | HX3: 10.19 | HY3: 11.19 | HZ3: 12.19 | IA3: 01.20 | IB3: 02.20 | IC3: 03.20 | ID3: 04.20 | IE3: 05.20 | IF3: 06.20 | IG3: 07.20 | IH3: 08.20 | II3: 09.20 | IJ3: 10.20 | IK3: 11.20 | IL3: 12.20 | IM3: 01.21 | IN3: 02.21 | IO3: 03.21 | IP3: 04.21 | IQ3: 05.21 | IR3: 06.21 | IS3: 07.21 | IT3: 08.21 | IU3: 09.21 | IV3: 10.21 | IW3: 11.21 | IX3: 12.21 | IY3: 01.22 | IZ3: 02.22 | JA3: 03.22 | JB3: 04.22 | JC3: 05.22 | JD3: 06.22 | JE3: 07.22 | JF3: 08.22 | JG3: 09.22 | JH3: 10.22 | JI3: 11.22 | JJ3: 12.22 | JK3: 01.23 | JL3: 02.23 | JM3: 03.23 | JN3: 04.23 | JO3: 05.23 | JP3: 06.23 | JQ3: 07.23 | JR3: 08.23 | JS3: 09.23 | JT3: 10.23 | JU3: 11.23 | JV3: 12.23 | JW3: 01.24 | JX3: 02.24 | JY3: 03.24 | JZ3: 04.24 | KA3: 05.24 | KB3: 06.24 | KC3: 07.24 | KD3: 08.24 | KE3: 09.24 | KF3: 10.24 | KG3: 11.24 | KH3: 12.24 | KI3: 01.25 | KJ3: 02.25 | KK3: 03.25 | KL3: 04.25 | KM3: 05.25 | KN3: 06.25 | KO3: 07.25 | KP3: 08.25 | KQ3: 09.25 | KR3: 10.25 | KS3: 11.25 | KT3: 12.25 | KU3: 01.26 | KV3: 02.26 | KW3: 03.26 | KX3: 04.26 | KY3: 05.26 | KZ3: 06.26
A4: RM (Reserve Money) | B4: 124415 | C4: 135418 | D4: 152358 | E4: 131252 | F4: 134416 | G4: 125033 | H4: 132690 | I4: 130765 | J4: 130960 | K4: 134393 | L4: 142827 | M4: 145887 | N4: 146532 | O4: 157996 | P4: 154221 | Q4: 157182 | R4: 174959 | S4: 159646 | T4: 153877 | U4: 154932 | V4: 154834 | W4: 156787 | X4: 174258 | Y4: 173083 | Z4: 179166 | AA4: 183732 | AB4: 192015 | AC4: 187461 | AD4: 208171 | AE4: 186926 | AF4: 200380 | AG4: 205995 | AH4: 214458 | AI4: 218828 | AJ4: 254077 | AK4: 257220 | AL4: 259970 | AM4: 294449 | AN4: 294114 | AO4: 292333 | AP4: 316962 | AQ4: 298521 | AR4: 307820 | AS4: 325590 | AT4: 316252 | AU4: 360360 | AV4: 388535 | AW4: 380291 | AX4: 386031 | AY4: 404209 | AZ4: 445005 | BA4: 489453 | BB4: 577841 | BC4: 485842 | BD4: 528484 | BE4: 546087 | BF4: 547683 | BG4: 549829 | BH4: 550629 | BI4: 564794 | BJ4: 554900 | BK4: 642333 | BL4: 640720 | BM4: 609723 | BN4: 663005 | BO4: 616639 | BP4: 793880 | BQ4: 1040392 | BR4: 992708 | BS4: 1041610 | BT4: 1058984 | BU4: 1162852 | BV4: 1098956 | BW4: 1196181 | BX4: 1191090 | BY4: 1181591 | BZ4: 1501328 | CA4: 1391002 | CB4: 1587979 | CC4: 1583970 | CD4: 1534440 | CE4: 1602747 | CF4: 1666674 | CG4: 1696397 | CH4: 1751136 | CI4: 1713139 | CJ4: 1502658 | CK4: 1489996 | CL4: 1464136 | CM4: 1509503 | CN4: 1579496 | CO4: 1578890 | CP4: 1534208 | CQ4: 1695073 | CR4: 1752991 | CS4: 1669857 | CT4: 1750952 | CU4: 1754914 | CV4: 1570214 | CW4: 1298552 | CX4: 1525238 | CY4: 2032438 | CZ4: 2252087 | DA4: 2236772 | DB4: 2193334 | DC4: 2261268 | DD4: 2333767 | DE4: 2707836 | DF4: 2577690 | DG4: 2747648 | DH4: 2563712 | DI4: 2502905 | DJ4: 2450836 | DK4: 2584606 | DL4: 2653023 | DM4: 2736282 | DN4: 2650779 | DO4: 2518311 | DP4: 2738397 | DQ4: 2600035 | DR4: 2523403 | DS4: 2529901 | DT4: 2744373 | DU4: 2372578 | DV4: 2572217 | DW4: 2641507 | DX4: 2630137 | DY4: 2810231 | DZ4: 2906459 | EA4: 2842547 | EB4: 2888094 | EC4: 3195563 | ED4: 2885672 | EE4: 2883088 | EF4: 3063973 | EG4: 2964336 | EH4: 2837356 | EI4: 3384140 | EJ4: 3469472 | EK4: 3282665 | EL4: 3490230 | EM4: 3304523 | EN4: 3454684 | EO4: 2951901 | EP4: 2809970 | EQ4: 2953136 | ER4: 2832517 | ES4: 2686108 | ET4: 2890061 | EU4: 2746246 | EV4: 2628804 | EW4: 3044985 | EX4: 2852896 | EY4: 3038715 | EZ4: 3094682 | FA4: 3109197 | FB4: 2906042 | FC4: 2781820 | FD4: 2776294 | FE4: 2609637 | FF4: 2825961 | FG4: 2861003 | FH4: 3240023 | FI4: 3408022 | FJ4: 3633316 | FK4: 3595581 | FL4: 3715258 | FM4: 3859730 | FN4: 3654727 | FO4: 3753134 | FP4: 3723626 | FQ4: 3414322 | FR4: 3413841 | FS4: 3109020 | FT4: 3144815 | FU4: 3287005 | FV4: 3418576 | FW4: 3644795 | FX4: 4191185 | FY4: 3871600 | FZ4: 4307271 | GA4: 4644278 | GB4: 4678045 | GC4: 4816225 | GD4: 4750746 | GE4: 4722030 | GF4: 4566189 | GG4: 4993159 | GH4: 4653021 | GI4: 4495113 | GJ4: 4894149 | GK4: 4452803 | GL4: 4524027 | GM4: 4646906 | GN4: 4347750 | GO4: 4671068 | GP4: 5162573 | GQ4: 4678806 | GR4: 4686894 | GS4: 5198807 | GT4: 5253533 | GU4: 5536229 | GV4: 5173896 | GW4: 5459616 | GX4: 5342897 | GY4: 6067983 | GZ4: 5690787 | HA4: 5782435 | HB4: 5537057 | HC4: 5208414 | HD4: 4893466 | HE4: 4565508 | HF4: 4799905 | HG4: 4787605 | HH4: 5734184 | HI4: 6367717 | HJ4: 6118672 | HK4: 6183748 | HL4: 5799325 | HM4: 5988371 | HN4: 6650873 | HO4: 6983953 | HP4: 6519013 | HQ4: 6248429 | HR4: 5694776 | HS4: 6617443 | HT4: 6346150 | HU4: 7078495 | HV4: 6602428 | HW4: 6528275 | HX4: 7058849 | HY4: 6718657 | HZ4: 6893176 | IA4: 6269522 | IB4: 6395199 | IC4: 8652501 | ID4: 8284220 | IE4: 8253667 | IF4: 8428322 | IG4: 9097118 | IH4: 9139678 | II4: 9023035 | IJ4: 9661803 | IK4: 9667538 | IL4: 9777551 | IM4: 9173822 | IN4: 9565291 | IO4: 9859517 | IP4: 9878434 | IQ4: 10317236 | IR4: 10270127 | IS4: 10300160 | IT4: 10298221 | IU4: 10689698 | IV4: 10402089 | IW4: 10476192 | IX4: 10957714 | IY4: 10683934 | IZ4: 10764863 | JA4: 10791800 | JB4: 9968049 | JC4: 9875008 | JD4: 10688772 | JE4: 11579074 | JF4: 12076477 | JG4: 11871384 | JH4: 12374432 | JI4: 11719902 | JJ4: 11874422 | JK4: 10678782 | JL4: 10047215 | JM4: 10284491 | JN4: 9854371 | JO4: 9654031 | JP4: 10440847 | JQ4: 9586967 | JR4: 9068158 | JS4: 8843495 | JT4: 9620615 | JU4: 10126464 | JV4: 11539973 | JW4: 11819843 | JX4: 11526650 | JY4: 12302588 | JZ4: 12290583 | KA4: 12681766 | KB4: 13275974 | KC4: 13477031 | KD4: 13324363 | KE4: 13741720 | KF4: 13540027 | KG4: 12546103 | KH4: 14606537 | KI4: 14012242 | KJ4: 13662625 | KK4: 13787210 | KL4: 13534795 | KM4: 13973748 | KN4: 14019117 | KO4: 14687046 | KP4: 15067944 | KQ4: 14344179 | KR4: 14842893 | KS4: 13765314 | KT4: 15678721 | KU4: 15273813 | KV4: 14262793 | KW4: 14749112 | KX4: 14919075 | KY4: 14840823 | KZ4: 15579704
A5: % changes to the previous month | B5: 2.4 | C5: 8.8 | D5: 12.5 | E5: -13.9 | F5: 2.4 | G5: -7 | H5: 6.1 | I5: -1.5 | J5: 0.1 | K5: 2.6 | L5: 6.3 | M5: 2.1 | N5: 0.4 | O5: 7.8 | P5: -2.4 | Q5: 1.9 | R5: 11.3 | S5: -8.8 | T5: -3.6 | U5: 0.7 | V5: -0.1 | W5: 1.3 | X5: 11.1 | Y5: -0.7 | Z5: 3.5 | AA5: 2.5 | AB5: 4.5 | AC5: -2.4 | AD5: 11 | AE5: -10.2 | AF5: 7.2 | AG5: 2.8 | AH5: 4.1 | AI5: 2 | AJ5: 16.1 | AK5: 1.2 | AL5: 1.1 | AM5: 13.3 | AN5: -0.1 | AO5: -0.6 | AP5: 8.4 | AQ5: -5.8 | AR5: 3.1 | AS5: 5.8 | AT5: -2.9 | AU5: 13.9 | AV5: 7.8 | AW5: -2.1 | AX5: 1.5 | AY5: 4.7 | AZ5: 10.1 | BA5: 10 | BB5: 18.1 | BC5: -15.9 | BD5: 8.8 | BE5: 3.3 | BF5: 0.3 | BG5: 0.4 | BH5: 0.1 | BI5: 2.6 | BJ5: -1.8 | BK5: 15.8 | BL5: -0.3 | BM5: -4.8 | BN5: 8.7 | BO5: -7 | BP5: 28.7 | BQ5: 31.1 | BR5: -4.6 | BS5: 4.9 | BT5: 1.7 | BU5: 9.8 | BV5: -5.5 | BW5: 8.8 | BX5: -0.4 | BY5: -0.8 | BZ5: 27.1 | CA5: -7.3 | CB5: 14.2 | CC5: -0.3 | CD5: -3.1 | CE5: 4.5 | CF5: 4 | CG5: 1.8 | CH5: 3.2 | CI5: -2.2 | CJ5: -12.3 | CK5: -0.8 | CL5: -1.7 | CM5: 3.1 | CN5: 4.6 | CP5: -2.8 | CQ5: 10.5 | CR5: 3.4 | CS5: -4.7 | CT5: 4.9 | CU5: 0.2 | CV5: -10.5 | CW5: -17.3 | CX5: 17.5 | CY5: 33.3 | CZ5: 10.8 | DA5: -0.7 | DB5: -1.9 | DC5: 3.1 | DD5: 3.2 | DE5: 16 | DF5: -4.8 | DG5: 6.6 | DH5: -6.7 | DI5: -2.4 | DJ5: -2.1 | DK5: 5.5 | DL5: 2.6 | DM5: 3.1 | DN5: -3.1 | DO5: -5 | DP5: 8.7 | DQ5: -5.1 | DR5: -2.9 | DS5: 0.3 | DT5: 8.5 | DU5: -13.5 | DV5: 8.4 | DW5: 2.7 | DX5: -0.4 | DY5: 6.8 | DZ5: 3.4 | EA5: -2.2 | EB5: 1.6 | EC5: 10.6 | ED5: -9.7 | EE5: -0.1 | EF5: 6.3 | EG5: -3.3 | EH5: -4.3 | EI5: 19.3 | EJ5: 2.5 | EK5: -5.4 | EL5: 6.3 | EM5: -5.3 | EN5: 4.5 | EO5: -14.6 | EP5: -4.8 | EQ5: 5.1 | ER5: -4.1 | ES5: -5.2 | ET5: 7.6 | EU5: -5 | EV5: -4.3 | EW5: 15.8 | EX5: -6.3 | EY5: 6.5 | EZ5: 1.8 | FA5: 0.5 | FB5: -6.5 | FC5: -4.3 | FD5: -0.2 | FE5: -6 | FF5: 8.3 | FG5: 1.2 | FH5: 13.2 | FI5: 5.2 | FJ5: 6.6 | FK5: -1 | FL5: 3.3 | FM5: 3.9 | FN5: -5.3 | FO5: 2.7 | FP5: -0.8 | FQ5: -8.3 | FS5: -8.9 | FT5: 1.2 | FU5: 4.5 | FV5: 4 | FW5: 6.6 | FX5: 15 | FY5: -7.6 | FZ5: 11.3 | GA5: 7.8 | GB5: 0.7 | GC5: 3 | GD5: -1.4 | GE5: -0.6 | GF5: -3.3 | GG5: 9.4 | GH5: -6.8 | GI5: -3.4 | GJ5: 8.9 | GK5: -9 | GL5: 1.6 | GM5: 2.7 | GN5: -6.4 | GO5: 7.4 | GP5: 10.5 | GQ5: -9.4 | GR5: 0.2 | GS5: 10.9 | GT5: 1.1 | GU5: 5.4 | GV5: -6.5 | GW5: 5.5 | GX5: -2.1 | GY5: 13.6 | GZ5: -6.2 | HA5: 1.6 | HB5: -4.2 | HC5: -6 | HD5: -6 | HE5: -6.7 | HF5: 5.1 | HG5: -0.3 | HH5: 19.8 | HI5: 11 | HJ5: -3.9 | HK5: 1.1 | HL5: -6.2 | HM5: 3.3 | HN5: 11.1 | HO5: 5 | HP5: -6.7 | HQ5: -4.2 | HR5: -8.9 | HS5: 16.2 | HT5: -4.1 | HU5: 11.5 | HV5: -6.7 | HW5: -1.1 | HX5: 8.1 | HY5: -4.8 | HZ5: 2.6 | IA5: -9 | IB5: 2 | IC5: 35.3 | ID5: -4.3 | IE5: -0.4 | IF5: 2.1 | IG5: 7.9 | IH5: 0.5 | II5: -1.3 | IJ5: 7.1 | IK5: 0.1 | IL5: 1.1 | IM5: -6.2 | IN5: 4.3 | IO5: 3.1 | IP5: 0.2 | IQ5: 4.4 | IR5: -0.5 | IS5: 0.3 | IU5: 3.8 | IV5: -2.7 | IW5: 0.7 | IX5: 4.6 | IY5: -2.5 | IZ5: 0.8 | JA5: 0.3 | JB5: -7.6 | JC5: -0.9 | JD5: 8.2 | JE5: 8.3 | JF5: 4.3 | JG5: -1.7 | JH5: 4.2 | JI5: -5.3 | JJ5: 1.3 | JK5: -10.1 | JL5: -5.9 | JM5: 2.4 | JN5: -4.2 | JO5: -2 | JP5: 8.2 | JQ5: -8.2 | JR5: -5.4 | JS5: -2.5 | JT5: 8.8 | JU5: 5.3 | JV5: 14 | JW5: 2.4 | JX5: -2.5 | JY5: 6.7 | JZ5: -0.1 | KA5: 3.2 | KB5: 4.7 | KC5: 1.5 | KD5: -1.1 | KE5: 3.1 | KF5: -1.5 | KG5: -7.3 | KH5: 16.4 | KI5: -4.1 | KJ5: -2.5 | KK5: 0.9 | KL5: -1.8 | KM5: 3.2 | KN5: 0.3 | KO5: 4.8 | KP5: 2.6 | KQ5: -4.8 | KR5: 3.5 | KS5: -7.3 | KT5: 13.9 | KU5: -2.6 | KV5: -6.6 | KW5: 3.4 | KX5: 1.2 | KY5: -0.5 | KZ5: 5
A6: % changes to December of the previous year | B6: -1.8 | C6: 6.8 | D6: 20.2 | E6: 3.6 | F6: 6 | G6: -7 | H6: -1.3 | I6: -2.7 | J6: -2.6 | L6: 6.3 | M6: 8.5 | N6: 9 | O6: 17.5 | P6: 14.7 | Q6: 16.9 | R6: 30.2 | S6: -8.8 | T6: -12 | U6: -11.4 | V6: -11.5 | W6: -10.4 | X6: -0.4 | Y6: -1.1 | Z6: 2.4 | AA6: 5 | AB6: 9.7 | AC6: 7.1 | AD6: 19 | AE6: -10.2 | AF6: -3.7 | AG6: -1 | AH6: 3 | AI6: 5.1 | AJ6: 22.1 | AK6: 23.6 | AL6: 24.9 | AM6: 41.4 | AN6: 41.3 | AO6: 40.4 | AP6: 52.3 | AQ6: -5.8 | AR6: -2.9 | AS6: 2.7 | AT6: -0.2 | AU6: 13.7 | AV6: 22.6 | AW6: 20 | AX6: 21.8 | AY6: 27.5 | AZ6: 40.4 | BA6: 54.4 | BB6: 82.3 | BC6: -15.9 | BD6: -8.5 | BE6: -5.5 | BF6: -5.2 | BG6: -4.8 | BH6: -4.7 | BI6: -2.3 | BJ6: -4 | BK6: 11.2 | BL6: 10.9 | BM6: 5.5 | BN6: 14.7 | BO6: -7 | BP6: 19.7 | BQ6: 56.9 | BR6: 49.7 | BS6: 57.1 | BT6: 59.7 | BU6: 75.4 | BV6: 65.8 | BW6: 80.4 | BX6: 79.7 | BY6: 78.2 | BZ6: 126.4 | CA6: -7.3 | CB6: 5.8 | CC6: 5.5 | CD6: 2.2 | CE6: 6.8 | CF6: 11 | CG6: 13 | CH6: 16.6 | CI6: 14.1 | CJ6: 0.1 | CK6: -0.8 | CL6: -2.5 | CM6: 3.1 | CN6: 7.9 | CO6: 7.8 | CP6: 4.8 | CQ6: 15.8 | CR6: 19.7 | CS6: 14.1 | CT6: 19.6 | CU6: 19.9 | CV6: 7.2 | CW6: -11.3 | CX6: 4.2 | CY6: 33.3 | CZ6: 47.7 | DA6: 46.7 | DB6: 43.8 | DC6: 48.3 | DD6: 53 | DE6: 77.5 | DF6: 69 | DG6: 80.1 | DH6: 68.1 | DI6: 64.1 | DJ6: 60.7 | DK6: 5.5 | DL6: 8.2 | DM6: 11.6 | DN6: 8.2 | DO6: 2.8 | DP6: 11.7 | DQ6: 6.1 | DR6: 3 | DS6: 3.2 | DT6: 12 | DU6: -3.2 | DV6: 5 | DW6: 2.7 | DX6: 2.3 | DY6: 9.3 | DZ6: 13 | EA6: 10.5 | EB6: 12.3 | EC6: 24.2 | ED6: 12.2 | EE6: 12.1 | EF6: 19.1 | EG6: 15.2 | EH6: 10.3 | EI6: 19.3 | EJ6: 22.3 | EK6: 15.7 | EL6: 23.1 | EM6: 16.5 | EN6: 21.8 | EO6: 4 | EP6: -1 | EQ6: 4.1 | ER6: -0.2 | ES6: -5.3 | ET6: 1.9 | EU6: -5 | EV6: -9 | EW6: 5.4 | EX6: -1.3 | EY6: 5.1 | EZ6: 7.1 | FA6: 7.6 | FB6: 0.6 | FC6: -3.7 | FD6: -3.9 | FE6: -9.7 | FF6: -2.2 | FG6: 1.2 | FH6: 14.7 | FI6: 20.6 | FJ6: 28.6 | FK6: 27.2 | FL6: 31.5 | FM6: 36.6 | FN6: 29.3 | FO6: 32.8 | FP6: 31.8 | FQ6: 20.8 | FR6: 20.8 | FS6: -8.9 | FT6: -7.9 | FU6: -3.7 | FV6: 0.1 | FW6: 6.8 | FX6: 22.8 | FY6: 13.4 | FZ6: 26.2 | GA6: 36 | GB6: 37 | GC6: 41.1 | GD6: 39.2 | GE6: -0.6 | GF6: -3.9 | GG6: 5.1 | GH6: -2.1 | GI6: -5.4 | GJ6: 3 | GK6: -6.3 | GL6: -4.8 | GM6: -2.2 | GN6: -8.5 | GO6: -1.7 | GP6: 8.7 | GQ6: -9.4 | GR6: -9.2 | GS6: 0.7 | GT6: 1.8 | GU6: 7.2 | GV6: 0.2 | GW6: 5.8 | GX6: 3.5 | GY6: 17.5 | GZ6: 10.2 | HA6: 12 | HB6: 7.3 | HC6: -6 | HD6: -11.7 | HE6: -17.5 | HF6: -13.3 | HG6: -13.6 | HH6: 3.5 | HI6: 15 | HJ6: 10.5 | HK6: 11.6 | HL6: 4.7 | HM6: 8.2 | HN6: 20.1 | HO6: 5 | HP6: -2 | HQ6: -6.1 | HR6: -14.4 | HS6: -0.5 | HT6: -4.6 | HU6: 6.4 | HV6: -0.7 | HW6: -1.8 | HX6: 6.1 | HY6: 1 | HZ6: 3.6 | IA6: -9 | IB6: -7.2 | IC6: 25.5 | ID6: 20.2 | IE6: 19.7 | IF6: 22.3 | IG6: 32 | IH6: 32.6 | II6: 30.9 | IJ6: 40.2 | IK6: 40.2 | IL6: 41.8 | IM6: -6.2 | IN6: -2.2 | IO6: 0.8 | IP6: 1 | IQ6: 5.5 | IR6: 5 | IS6: 5.3 | IT6: 5.3 | IU6: 9.3 | IV6: 6.4 | IW6: 7.1 | IX6: 12.1 | IY6: -2.5 | IZ6: -1.8 | JA6: -1.5 | JB6: -9 | JC6: -9.9 | JD6: -2.5 | JE6: 5.7 | JF6: 10.2 | JG6: 8.3 | JH6: 12.9 | JI6: 7 | JJ6: 8.4 | JK6: -10.1 | JL6: -15.4 | JM6: -13.4 | JN6: -17 | JO6: -18.7 | JP6: -12.1 | JQ6: -19.3 | JR6: -23.6 | JS6: -25.5 | JT6: -19 | JU6: -14.7 | JV6: -2.8 | JW6: 2.4 | JX6: -0.1 | JY6: 6.6 | JZ6: 6.5 | KA6: 9.9 | KB6: 15 | KC6: 16.8 | KD6: 15.5 | KE6: 19.1 | KF6: 17.3 | KG6: 8.7 | KH6: 26.6 | KI6: -4.1 | KJ6: -6.5 | KK6: -5.6 | KL6: -7.3 | KM6: -4.3 | KN6: -4 | KO6: 0.6 | KP6: 3.2 | KQ6: -1.8 | KR6: 1.6 | KS6: -5.8 | KT6: 7.3 | KU6: -2.6 | KV6: -9 | KW6: -5.9 | KX6: -4.8 | KY6: -5.3 | KZ6: -0.6
A7: 1.1. Currency out of the NBK | B7: 105990 | C7: 113587 | D7: 113503 | E7: 106403 | F7: 116335 | G7: 104859 | H7: 108603 | I7: 110797 | J7: 114064 | K7: 113500 | L7: 119287 | M7: 124342 | N7: 126571 | O7: 133949 | P7: 133895 | Q7: 126916 | R7: 145477 | S7: 127461 | T7: 131313 | U7: 135943 | V7: 136447 | W7: 139130 | X7: 146897 | Y7: 150729 | Z7: 155044 | AA7: 155394 | AB7: 163828 | AC7: 161509 | AD7: 177899 | AE7: 156107 | AF7: 167172 | AG7: 175794 | AH7: 180744 | AI7: 188235 | AJ7: 206088 | AK7: 218205 | AL7: 224880 | AM7: 238636 | AN7: 255598 | AO7: 246799 | AP7: 262093 | AQ7: 250756 | AR7: 261604 | AS7: 264980 | AT7: 277575 | AU7: 283250 | AV7: 303204 | AW7: 321518 | AX7: 333384 | AY7: 338635 | AZ7: 359047 | BA7: 374640 | BB7: 410898 | BC7: 377357 | BD7: 388607 | BE7: 394110 | BF7: 409766 | BG7: 417143 | BH7: 425475 | BI7: 432873 | BJ7: 442329 | BK7: 452079 | BL7: 463750 | BM7: 442955 | BN7: 458518 | BO7: 426426 | BP7: 451229 | BQ7: 480293 | BR7: 505033 | BS7: 548513 | BT7: 597037 | BU7: 625884 | BV7: 619450 | BW7: 612971 | BX7: 597813 | BY7: 602662 | BZ7: 687257 | CA7: 679704 | CB7: 698594 | CC7: 739447 | CD7: 793795 | CE7: 847279 | CF7: 891254 | CG7: 926614 | CH7: 938128 | CI7: 881985 | CJ7: 842219 | CK7: 807899 | CL7: 859852 | CM7: 784885 | CN7: 789964 | CO7: 809238 | CP7: 828327 | CQ7: 847921 | CR7: 883103 | CS7: 895149 | CT7: 908295 | CU7: 920457 | CV7: 936012 | CW7: 923606 | CX7: 986856 | CY7: 839101 | CZ7: 829446 | DA7: 836807 | DB7: 866495 | DC7: 892756 | DD7: 933014 | DE7: 927522 | DF7: 929486 | DG7: 926969 | DH7: 939778 | DI7: 967795 | DJ7: 1047795 | DK7: 1005845 | DL7: 1012610 | DM7: 1025325 | DN7: 1085661 | DO7: 1126742 | DP7: 1162403 | DQ7: 1208896 | DR7: 1213858 | DS7: 1222987 | DT7: 1242113 | DU7: 1223546 | DV7: 1306208 | DW7: 1252898 | DX7: 1248329 | DY7: 1253260 | DZ7: 1279954 | EA7: 1301055 | EB7: 1350259 | EC7: 1387916 | ED7: 1419509 | EE7: 1427688 | EF7: 1430428 | EG7: 1414237 | EH7: 1548166 | EI7: 1483816 | EJ7: 1468570 | EK7: 1492278 | EL7: 1524936 | EM7: 1531051 | EN7: 1578851 | EO7: 1591455 | EP7: 1612091 | EQ7: 1614788 | ER7: 1607736 | ES7: 1574479 | ET7: 1736646 | EU7: 1623074 | EV7: 1616718 | EW7: 1651519 | EX7: 1655412 | EY7: 1665622 | EZ7: 1736736 | FA7: 1700515 | FB7: 1694860 | FC7: 1669076 | FD7: 1658487 | FE7: 1615766 | FF7: 1762907 | FG7: 1623028 | FH7: 1673638 | FI7: 1553022 | FJ7: 1595662 | FK7: 1622671 | FL7: 1674644 | FM7: 1677389 | FN7: 1614166 | FO7: 1598778 | FP7: 1508608 | FQ7: 1457919 | FR7: 1382183 | FS7: 1254094 | FT7: 1241507 | FU7: 1273493 | FV7: 1266328 | FW7: 1305871 | FX7: 1363086 | FY7: 1356580 | FZ7: 1433202 | GA7: 1421127 | GB7: 1433498 | GC7: 1443620 | GD7: 1494930 | GE7: 1394955 | GF7: 1469812 | GG7: 1537636 | GH7: 1647545 | GI7: 1727427 | GJ7: 1825191 | GK7: 1862000 | GL7: 1828619 | GM7: 1818787 | GN7: 1834827 | GO7: 1841542 | GP7: 2050087 | GQ7: 1912365 | GR7: 1937004 | GS7: 1961113 | GT7: 2029004 | GU7: 2030794 | GV7: 2132666 | GW7: 2179024 | GX7: 2171016 | GY7: 2120089 | GZ7: 2086632 | HA7: 2102739 | HB7: 2257218 | HC7: 2104909 | HD7: 2084574 | HE7: 2101125 | HF7: 2199421 | HG7: 2225974 | HH7: 2377051 | HI7: 2489122 | HJ7: 2423059 | HK7: 2381264 | HL7: 2390923 | HM7: 2428846 | HN7: 2618852 | HO7: 2471410 | HP7: 2458568 | HQ7: 2501173 | HR7: 2536209 | HS7: 2584479 | HT7: 2541174 | HU7: 2563232 | HV7: 2600097 | HW7: 2569470 | HX7: 2559787 | HY7: 2554685 | HZ7: 2688265 | IA7: 2538014 | IB7: 2581017 | IC7: 2703786 | ID7: 2955734 | IE7: 3145959 | IF7: 3184287 | IG7: 3274440 | IH7: 3311008 | II7: 3204061 | IJ7: 3183426 | IK7: 3117539 | IL7: 3250372 | IM7: 3081432 | IN7: 3109238 | IO7: 3189736 | IP7: 3323340 | IQ7: 3367646 | IR7: 3450950 | IS7: 3458788 | IT7: 3424734 | IU7: 3382482 | IV7: 3407310 | IW7: 3343569 | IX7: 3451715 | IY7: 3429933 | IZ7: 3408116 | JA7: 3523866 | JB7: 3574720 | JC7: 3520450 | JD7: 3674234 | JE7: 3779485 | JF7: 3762229 | JG7: 3762939 | JH7: 3765032 | JI7: 3701002 | JJ7: 3823793 | JK7: 3687694 | JL7: 3630271 | JM7: 3656211 | JN7: 3793068 | JO7: 3775641 | JP7: 3914126 | JQ7: 3919342 | JR7: 3950919 | JS7: 3960098 | JT7: 3965167 | JU7: 3902340 | JV7: 4109817 | JW7: 4039710 | JX7: 4028124 | JY7: 4060834 | JZ7: 4068003 | KA7: 4134431 | KB7: 4323683 | KC7: 4408645 | KD7: 4503882 | KE7: 4415747 | KF7: 4488750 | KG7: 4525368 | KH7: 4862203 | KI7: 4735682 | KJ7: 4681680 | KK7: 4725146 | KL7: 4874328 | KM7: 4934084 | KN7: 5158676 | KO7: 5259184 | KP7: 5286624 | KQ7: 5173407 | KR7: 5179134 | KS7: 5036725 | KT7: 5271109 | KU7: 5041049 | KV7: 4959162 | KW7: 4962080 | KX7: 5091844 | KY7: 5214053 | KZ7: 5339901
A8: 1.2. Transferable deposits of Banks and other organizations in NBK | B8: 18425 | C8: 21831 | D8: 38855 | E8: 24848 | F8: 18081 | G8: 20174 | H8: 24087 | I8: 19968 | J8: 16896 | K8: 20893 | L8: 23540 | M8: 21545 | N8: 19960 | O8: 24047 | P8: 20327 | Q8: 30266 | R8: 29482 | S8: 32185 | T8: 22564 | U8: 18989 | V8: 18387 | W8: 17657 | X8: 27361 | Y8: 22354 | Z8: 24122 | AA8: 28338 | AB8: 28188 | AC8: 25952 | AD8: 30272 | AE8: 30819 | AF8: 33208 | AG8: 30202 | AH8: 33714 | AI8: 30593 | AJ8: 47989 | AK8: 39015 | AL8: 35090 | AM8: 55813 | AN8: 38517 | AO8: 45534 | AP8: 54869 | AQ8: 47765 | AR8: 46217 | AS8: 60610 | AT8: 38677 | AU8: 77110 | AV8: 85331 | AW8: 58774 | AX8: 52647 | AY8: 65574 | AZ8: 85958 | BA8: 114813 | BB8: 166943 | BC8: 108485 | BD8: 139877 | BE8: 151977 | BF8: 137917 | BG8: 132686 | BH8: 125154 | BI8: 131921 | BJ8: 112571 | BK8: 190254 | BL8: 176969 | BM8: 166768 | BN8: 204488 | BO8: 190213 | BP8: 342651 | BQ8: 560099 | BR8: 487675 | BS8: 493098 | BT8: 461947 | BU8: 536968 | BV8: 479506 | BW8: 583210 | BX8: 593277 | BY8: 578929 | BZ8: 814072 | CA8: 711298 | CB8: 889386 | CC8: 844523 | CD8: 740645 | CE8: 755468 | CF8: 775420 | CG8: 769783 | CH8: 813008 | CI8: 831154 | CJ8: 660438 | CK8: 682097 | CL8: 604283 | CM8: 724617 | CN8: 789532 | CO8: 769652 | CP8: 705881 | CQ8: 847152 | CR8: 869888 | CS8: 774708 | CT8: 842658 | CU8: 834457 | CV8: 634202 | CW8: 374946 | CX8: 538382 | CY8: 1193337 | CZ8: 1422642 | DA8: 1399965 | DB8: 1326840 | DC8: 1368511 | DD8: 1400753 | DE8: 1780314 | DF8: 1648204 | DG8: 1820679 | DH8: 1623934 | DI8: 1535110 | DJ8: 1403041 | DK8: 1578760 | DL8: 1640413 | DM8: 1710957 | DN8: 1565117 | DO8: 1391568 | DP8: 1575993 | DQ8: 1391140 | DR8: 1309545 | DS8: 1306914 | DT8: 1502260 | DU8: 1149033 | DV8: 1266009 | DW8: 1388608 | DX8: 1381808 | DY8: 1556971 | DZ8: 1626505 | EA8: 1541493 | EB8: 1537835 | EC8: 1807647 | ED8: 1466162 | EE8: 1455400 | EF8: 1633545 | EG8: 1550100 | EH8: 1289190 | EI8: 1900324 | EJ8: 2000902 | EK8: 1790387 | EL8: 1965294 | EM8: 1773472 | EN8: 1875833 | EO8: 1360446 | EP8: 1197879 | EQ8: 1338348 | ER8: 1224780 | ES8: 1111629 | ET8: 1153415 | EU8: 1123172 | EV8: 1012087 | EW8: 1393467 | EX8: 1197484 | EY8: 1373093 | EZ8: 1357945 | FA8: 1408682 | FB8: 1211181 | FC8: 1112744 | FD8: 1117807 | FE8: 993871 | FF8: 1063054 | FG8: 1237975 | FH8: 1566385 | FI8: 1855000 | FJ8: 2037654 | FK8: 1972910 | FL8: 2040614 | FM8: 2182341 | FN8: 2040561 | FO8: 2154357 | FP8: 2215018 | FQ8: 1956403 | FR8: 2031658 | FS8: 1854925 | FT8: 1903308 | FU8: 2013512 | FV8: 2152249 | FW8: 2338924 | FX8: 2828099 | FY8: 2515020 | FZ8: 2874068 | GA8: 3223151 | GB8: 3244547 | GC8: 3372604 | GD8: 3255816 | GE8: 3327075 | GF8: 3096377 | GG8: 3455522 | GH8: 3005476 | GI8: 2767686 | GJ8: 3068957 | GK8: 2590803 | GL8: 2695408 | GM8: 2828119 | GN8: 2512924 | GO8: 2829526 | GP8: 3112486 | GQ8: 2766440 | GR8: 2749890 | GS8: 3237694 | GT8: 3224530 | GU8: 3505436 | GV8: 3041231 | GW8: 3280593 | GX8: 3171881 | GY8: 3947894 | GZ8: 3604156 | HA8: 3679696 | HB8: 3279840 | HC8: 3103505 | HD8: 2808892 | HE8: 2464383 | HF8: 2600484 | HG8: 2561631 | HH8: 3357133 | HI8: 3878595 | HJ8: 3695613 | HK8: 3802485 | HL8: 3408402 | HM8: 3559526 | HN8: 4032021 | HO8: 4512543 | HP8: 4060445 | HQ8: 3747256 | HR8: 3158567 | HS8: 4032965 | HT8: 3804976 | HU8: 4515263 | HV8: 4002330 | HW8: 3958805 | HX8: 4499062 | HY8: 4163972 | HZ8: 4204912 | IA8: 3731508 | IB8: 3814182 | IC8: 5948715 | ID8: 5328486 | IE8: 5107708 | IF8: 5244034 | IG8: 5822678 | IH8: 5828670 | II8: 5818974 | IJ8: 6478377 | IK8: 6549999 | IL8: 6527179 | IM8: 6092390 | IN8: 6456053 | IO8: 6669782 | IP8: 6555093 | IQ8: 6949589 | IR8: 6819177 | IS8: 6841371 | IT8: 6873487 | IU8: 7307216 | IV8: 6994779 | IW8: 7132622 | IX8: 7505999 | IY8: 7254001 | IZ8: 7356747 | JA8: 7267934 | JB8: 6393329 | JC8: 6354557 | JD8: 7014538 | JE8: 7799589 | JF8: 8314247 | JG8: 8108445 | JH8: 8609400 | JI8: 8018900 | JJ8: 8050629 | JK8: 6991088 | JL8: 6416944 | JM8: 6628280 | JN8: 6061303 | JO8: 5878390 | JP8: 6526720 | JQ8: 5667625 | JR8: 5117238 | JS8: 4883397 | JT8: 5655448 | JU8: 6224124 | JV8: 7430156 | JW8: 7780133 | JX8: 7498526 | JY8: 8241754 | JZ8: 8222580 | KA8: 8547335 | KB8: 8952292 | KC8: 9068387 | KD8: 8820481 | KE8: 9325973 | KF8: 9051277 | KG8: 8020734 | KH8: 9744334 | KI8: 9276560 | KJ8: 8980946 | KK8: 9062064 | KL8: 8660467 | KM8: 9039664 | KN8: 8860441 | KO8: 9427863 | KP8: 9781320 | KQ8: 9170772 | KR8: 9663759 | KS8: 8728589 | KT8: 10407612 | KU8: 10232764 | KV8: 9303631 | KW8: 9787032 | KX8: 9827231 | KY8: 9626770 | KZ8: 10239802
A10: Narrow Reserve Money | BB10: 499087 | BC10: 456538 | BD10: 450069 | BE10: 471135 | BF10: 467848 | BG10: 477683 | BH10: 508180 | BI10: 517454 | BJ10: 521040 | BK10: 561381 | BL10: 577092 | BM10: 538086 | BN10: 576158 | BO10: 550390 | BP10: 644698 | BQ10: 667104 | BR10: 698783 | BS10: 764206 | BT10: 840162 | BU10: 1059969 | BV10: 1024531 | BW10: 1147889 | BX10: 1100663 | BY10: 1097734 | BZ10: 1369741 | CA10: 1234895 | CB10: 1414344 | CC10: 1274602 | CD10: 1481382 | CE10: 1481397 | CF10: 1598143 | CG10: 1678215 | CH10: 1746534 | CI10: 1708536 | CJ10: 1498706 | CK10: 1485224 | CL10: 1454198 | CM10: 1496026 | CN10: 1531857 | CO10: 1494327 | CP10: 1515879 | CQ10: 1550936 | CR10: 1532511 | CS10: 1499353 | CT10: 1479502 | CU10: 1546595 | CV10: 1461811 | CW10: 1255864 | CX10: 1492201 | CY10: 2005052 | CZ10: 2227678 | DA10: 2062628 | DB10: 2017871 | DC10: 2001691 | DD10: 1899960 | DE10: 2152736 | DF10: 2092547 | DG10: 2201643 | DH10: 2041655 | DI10: 1875175 | DJ10: 1961737 | DK10: 2045882 | DL10: 2041393 | DM10: 2027147 | DN10: 2047701 | DO10: 2057071 | DP10: 2218416 | DQ10: 2064170 | DR10: 2165466 | DS10: 2162184 | DT10: 2315949 | DU10: 2023387 | DV10: 2142999 | DW10: 2196323 | DX10: 2143030 | DY10: 2351402 | DZ10: 2350156 | EA10: 2307583 | EB10: 2358248 | EC10: 2496442 | ED10: 2620699 | EE10: 2621530 | EF10: 2874889 | EG10: 2836733 | EH10: 2740573 | EI10: 3167658 | EJ10: 3286759 | EK10: 2927870 | EL10: 3170720 | EM10: 3097798 | EN10: 3310638 | EO10: 2798001 | EP10: 2701777 | EQ10: 2856592 | ER10: 2767535 | ES10: 2645849 | ET10: 2831153 | EU10: 2669532 | EV10: 2559878 | EW10: 2835760 | EX10: 2773279 | EY10: 2975854 | EZ10: 3048522 | FA10: 3057183 | FB10: 2875535 | FC10: 2752314 | FD10: 2745289 | FE10: 2580632 | FF10: 2786556 | FG10: 2832999 | FH10: 3219520 | FI10: 3380012 | FJ10: 3461007 | FK10: 3393285 | FL10: 3524465 | FM10: 3633733 | FN10: 3529912 | FO10: 3574884 | FP10: 3654424 | FQ10: 3382108 | FR10: 3313211 | FS10: 3015908 | FT10: 3059874 | FU10: 3111316 | FV10: 3242518 | FW10: 3490223 | FX10: 3877907 | FY10: 3488674 | FZ10: 4173220 | GA10: 4535881 | GB10: 4569045 | GC10: 4704629 | GD10: 4670994 | GE10: 4637608 | GF10: 4286590 | GG10: 4127715 | GH10: 4237844 | GI10: 4108100 | GJ10: 4285886 | GK10: 4158349 | GL10: 4257599 | GM10: 4451053 | GN10: 4207541 | GO10: 4513819 | GP10: 4793020 | GQ10: 4214277 | GR10: 4136385 | GS10: 4706421 | GT10: 4778771 | GU10: 4978607 | GV10: 4862278 | GW10: 5209013 | GX10: 5049559 | GY10: 5669225 | GZ10: 5300765 | HA10: 5456802 | HB10: 5160654 | HC10: 4709222 | HD10: 4584149 | HE10: 4239021 | HF10: 4589974 | HG10: 4509878 | HH10: 5015211 | HI10: 5629231 | HJ10: 5961930 | HK10: 5844674 | HL10: 5313447 | HM10: 5749985 | HN10: 5995748 | HO10: 6452606 | HP10: 5874774 | HQ10: 5087549 | HR10: 5086454 | HS10: 5522555 | HT10: 5241736 | HU10: 6132164 | HV10: 5888989 | HW10: 5244379 | HX10: 5501981 | HY10: 5532865 | HZ10: 5430745 | IA10: 4978029 | IB10: 5347729 | IC10: 6475461 | ID10: 5196014 | IE10: 5209118 | IF10: 5036920 | IG10: 4864547 | IH10: 5230683 | II10: 4920428 | IJ10: 5317494 | IK10: 5633831 | IL10: 5087846 | IM10: 4919790 | IN10: 4874140 | IO10: 5336948 | IP10: 5743987 | IQ10: 6034911 | IR10: 6297037 | IS10: 6117688 | IT10: 6300172 | IU10: 5815599 | IV10: 5878235 | IW10: 6150888 | IX10: 6945442 | IY10: 7008007 | IZ10: 7909224 | JA10: 7211683 | JB10: 7242428 | JC10: 7037712 | JD10: 7096525 | JE10: 7574108 | JF10: 7941086 | JG10: 7210051 | JH10: 7570781 | JI10: 6897649 | JJ10: 7374898 | JK10: 6582257 | JL10: 6544293 | JM10: 6606830 | JN10: 6383209 | JO10: 6208576 | JP10: 6860013 | JQ10: 6491522 | JR10: 6551424 | JS10: 6493873 | JT10: 6529219 | JU10: 6577664 | JV10: 7142913 | JW10: 6831249 | JX10: 6713521 | JY10: 6278732 | JZ10: 6781258 | KA10: 6907991 | KB10: 6886619 | KC10: 6738224 | KD10: 6846525 | KE10: 6681236 | KF10: 6817764 | KG10: 6878649 | KH10: 7532310 | KI10: 7132184 | KJ10: 7222418 | KK10: 6912772 | KL10: 6927221 | KM10: 7058908 | KN10: 7110612 | KO10: 7539173 | KP10: 7661704 | KQ10: 8927040 | KR10: 9300659 | KS10: 9043566 | KT10: 10270708 | KU10: 9522696 | KV10: 9353794 | KW10: 9082143 | KX10: 10913338 | KY10: 10763937 | KZ10: 10898765
A11: % changes to the previous month | BB11: 14.9 | BC11: -8.5 | BD11: -1.4 | BE11: 4.7 | BF11: -0.7 | BG11: 2.1 | BH11: 6.4 | BI11: 1.8 | BJ11: 0.7 | BK11: 7.7 | BL11: 2.8 | BM11: -6.8 | BN11: 7.1 | BO11: -4.5 | BP11: 17.1 | BQ11: 3.5 | BR11: 4.7 | BS11: 9.4 | BT11: 9.9 | BU11: 26.2 | BV11: -3.3 | BW11: 12 | BX11: -4.1 | BY11: -0.3 | BZ11: 24.8 | CA11: -9.8 | CB11: 14.5 | CC11: -9.9 | CD11: 16.2 | CF11: 7.9 | CG11: 5 | CH11: 4.1 | CI11: -2.2 | CJ11: -12.3 | CK11: -0.9 | CL11: -2.1 | CM11: 2.9 | CN11: 2.4 | CO11: -2.4 | CP11: 1.4 | CQ11: 2.3 | CR11: -1.2 | CS11: -2.2 | CT11: -1.3 | CU11: 4.5 | CV11: -5.5 | CW11: -14.1 | CX11: 18.8 | CY11: 34.4 | CZ11: 11.1 | DA11: -7.4 | DB11: -2.2 | DC11: -0.8 | DD11: -5.1 | DE11: 13.3 | DF11: -2.8 | DG11: 5.2 | DH11: -7.3 | DI11: -8.2 | DJ11: 4.6 | DK11: 4.3 | DL11: -0.2 | DM11: -0.7 | DN11: 1 | DO11: 0.5 | DP11: 7.8 | DQ11: -7 | DR11: 4.9 | DS11: -0.2 | DT11: 7.1 | DU11: -12.6 | DV11: 5.9 | DW11: 2.5 | DX11: -2.4 | DY11: 9.7 | DZ11: -0.1 | EA11: -1.8 | EB11: 2.2 | EC11: 5.9 | ED11: 5 | EF11: 9.7 | EG11: -1.3 | EH11: -3.4 | EI11: 15.6 | EJ11: 3.8 | EK11: -10.9 | EL11: 8.3 | EM11: -2.3 | EN11: 6.9 | EO11: -15.5 | EP11: -3.4 | EQ11: 5.7 | ER11: -3.1 | ES11: -4.4 | ET11: 7 | EU11: -5.7 | EV11: -4.1 | EW11: 10.8 | EX11: -2.2 | EY11: 7.3 | EZ11: 2.4 | FA11: 0.3 | FB11: -5.9 | FC11: -4.3 | FD11: -0.3 | FE11: -6 | FF11: 8 | FG11: 1.7 | FH11: 13.6 | FI11: 5 | FJ11: 2.4 | FK11: -2 | FL11: 3.9 | FM11: 3.1 | FN11: -2.9 | FO11: 1.3 | FP11: 2.2 | FQ11: -7.5 | FS11: -9 | FT11: 1.5 | FU11: 1.7 | FV11: 4.2 | FW11: 7.6 | FX11: 11.1 | FY11: -10 | FZ11: 19.6 | GA11: 8.7 | GB11: 0.7 | GC11: 3 | GD11: -0.7 | GE11: -0.7 | GF11: -7.6 | GG11: -3.7 | GH11: 2.7 | GI11: -3.1 | GJ11: 4.3 | GK11: -3 | GL11: 2.4 | GM11: 4.5 | GN11: -5.5 | GO11: 7.3 | GP11: 6.2 | GQ11: -12.1 | GR11: -1.8 | GS11: 13.8 | GT11: 1.5 | GU11: 4.2 | GV11: -2.3 | GW11: 7.1 | GX11: -3.1 | GY11: 12.3 | GZ11: -6.5 | HA11: 2.9 | HB11: -5.4 | HC11: -8.8 | HD11: -2.7 | HE11: -7.5 | HF11: 8.3 | HG11: -1.7 | HH11: 11.2 | HI11: 12.2 | HJ11: 5.9 | HK11: -2 | HL11: -9.1 | HM11: 8.2 | HN11: 4.3 | HO11: 7.6 | HP11: -9 | HQ11: -13.4 | HS11: 8.6 | HT11: -5.1 | HU11: 17 | HV11: -4 | HW11: -10.9 | HX11: 4.9 | HY11: 0.6 | HZ11: -1.8 | IA11: -8.3 | IB11: 7.4 | IC11: 21.1 | ID11: -19.8 | IE11: 0.3 | IF11: -3.3 | IG11: -3.4 | IH11: 7.5 | II11: -5.9 | IJ11: 8.1 | IK11: 5.9 | IL11: -9.7 | IM11: -3.3 | IN11: -0.9 | IO11: 9.5 | IP11: 7.6 | IQ11: 5.1 | IR11: 4.3 | IS11: -2.8 | IT11: 3 | IU11: -7.7 | IV11: 1.1 | IW11: 4.6 | IX11: 12.9 | IY11: 0.9 | IZ11: 12.9 | JA11: -8.8 | JB11: 0.4 | JC11: -2.8 | JD11: 0.8 | JE11: 6.7 | JF11: 4.8 | JG11: -9.2 | JH11: 5 | JI11: -8.9 | JJ11: 6.9 | JK11: -10.7 | JL11: -0.6 | JM11: 1 | JN11: -3.4 | JO11: -2.7 | JP11: 10.5 | JQ11: -5.4 | JR11: 0.9 | JS11: -0.9 | JT11: 0.5 | JU11: 0.7 | JV11: 8.6 | JW11: -4.4 | JX11: -1.7 | JY11: -6.5 | JZ11: 8 | KA11: 1.9 | KB11: -0.3 | KC11: -2.2 | KD11: 1.6 | KE11: -2.4 | KF11: 2 | KG11: 0.9 | KH11: 9.5 | KI11: -5.3 | KJ11: 1.3 | KK11: -4.3 | KL11: 0.2 | KM11: 1.9 | KN11: 0.7 | KO11: 6 | KP11: 1.6 | KQ11: 16.5 | KR11: 4.2 | KS11: -2.8 | KT11: 13.6 | KU11: -7.3 | KV11: -1.8 | KW11: -2.9 | KX11: 20.2 | KY11: -1.4 | KZ11: 1.3
A12: % changes to December of the previous year | BB12: 67.9 | BC12: -8.5 | BD12: -9.8 | BE12: -5.6 | BF12: -6.3 | BG12: -4.3 | BH12: 1.8 | BI12: 3.7 | BJ12: 4.4 | BK12: 12.5 | BL12: 15.6 | BM12: 7.8 | BN12: 15.4 | BO12: -4.5 | BP12: 11.9 | BQ12: 15.8 | BR12: 21.3 | BS12: 32.6 | BT12: 45.8 | BU12: 84 | BV12: 77.8 | BW12: 99.2 | BX12: 91 | BY12: 90.5 | BZ12: 137.7 | CA12: -9.8 | CB12: 3.3 | CC12: -6.9 | CD12: 8.2 | CE12: 8.2 | CF12: 16.7 | CG12: 22.5 | CH12: 27.5 | CI12: 24.7 | CJ12: 9.4 | CK12: 8.4 | CL12: 6.2 | CM12: 2.9 | CN12: 5.3 | CO12: 2.8 | CP12: 4.2 | CQ12: 6.7 | CR12: 5.4 | CS12: 3.1 | CT12: 1.7 | CU12: 6.4 | CV12: 0.5 | CW12: -13.6 | CX12: 2.6 | CY12: 34.4 | CZ12: 49.3 | DA12: 38.2 | DB12: 35.2 | DC12: 34.1 | DD12: 27.3 | DE12: 44.3 | DF12: 40.2 | DG12: 47.5 | DH12: 36.8 | DI12: 25.7 | DJ12: 31.5 | DK12: 4.3 | DL12: 4.1 | DM12: 3.3 | DN12: 4.4 | DO12: 4.9 | DP12: 13.1 | DQ12: 5.2 | DR12: 10.4 | DS12: 10.2 | DT12: 18.1 | DU12: 3.1 | DV12: 9.2 | DW12: 2.5 | DY12: 9.7 | DZ12: 9.7 | EA12: 7.7 | EB12: 10 | EC12: 16.5 | ED12: 22.3 | EE12: 22.3 | EF12: 34.2 | EG12: 32.4 | EH12: 27.9 | EI12: 15.6 | EJ12: 20 | EK12: 6.9 | EL12: 15.7 | EM12: 13.1 | EN12: 20.9 | EO12: 2.1 | EP12: -1.4 | EQ12: 4.2 | ER12: 1 | ES12: -3.5 | ET12: 3.3 | EU12: -5.7 | EV12: -9.6 | EW12: 0.2 | EX12: -2 | EY12: 5.1 | EZ12: 7.7 | FA12: 8 | FB12: 1.6 | FC12: -2.8 | FD12: -3 | FE12: -8.8 | FF12: -1.6 | FG12: 1.7 | FH12: 15.5 | FI12: 21.3 | FJ12: 24.2 | FK12: 21.8 | FL12: 26.5 | FM12: 30.4 | FN12: 26.7 | FO12: 28.3 | FP12: 31.1 | FQ12: 21.4 | FR12: 18.9 | FS12: -9 | FT12: -7.6 | FU12: -6.1 | FV12: -2.1 | FW12: 5.3 | FX12: 17 | FY12: 5.3 | FZ12: 26 | GA12: 36.9 | GB12: 37.9 | GC12: 42 | GD12: 41 | GE12: -0.7 | GF12: -8.2 | GG12: -11.6 | GH12: -9.3 | GI12: -12 | GJ12: -8.2 | GK12: -11 | GL12: -8.9 | GM12: -4.7 | GN12: -9.9 | GO12: -3.4 | GP12: 2.6 | GQ12: -12.1 | GR12: -13.7 | GS12: -1.8 | GT12: -0.3 | GU12: 3.9 | GV12: 1.4 | GW12: 8.7 | GX12: 5.4 | GY12: 18.3 | GZ12: 10.6 | HA12: 13.8 | HB12: 7.7 | HC12: -8.8 | HD12: -11.2 | HE12: -17.9 | HF12: -11.1 | HG12: -12.6 | HH12: -2.9 | HI12: 9 | HJ12: 15.5 | HK12: 13.2 | HL12: 2.9 | HM12: 11.4 | HN12: 16.2 | HO12: 7.6 | HP12: -2 | HQ12: -15.1 | HR12: -15.2 | HS12: -7.9 | HT12: -12.6 | HU12: 2.3 | HV12: -1.8 | HW12: -12.5 | HX12: -8.2 | HY12: -7.7 | HZ12: -9.4 | IA12: -8.3 | IB12: -1.5 | IC12: 19.2 | ID12: -4.3 | IE12: -4.1 | IF12: -7.3 | IG12: -10.4 | IH12: -3.7 | II12: -9.4 | IJ12: -2.1 | IK12: 3.7 | IL12: -6.3 | IM12: -3.3 | IN12: -4.2 | IO12: 4.9 | IP12: 12.9 | IQ12: 18.6 | IR12: 23.8 | IS12: 20.2 | IT12: 23.8 | IU12: 14.3 | IV12: 15.5 | IW12: 20.9 | IX12: 36.5 | IY12: 0.9 | IZ12: 13.9 | JA12: 3.8 | JB12: 4.3 | JC12: 1.3 | JD12: 2.2 | JE12: 9.1 | JF12: 14.3 | JG12: 3.8 | JH12: 9 | JI12: -0.7 | JJ12: 6.2 | JK12: -10.7 | JL12: -11.3 | JM12: -10.4 | JN12: -13.4 | JO12: -15.8 | JP12: -7 | JQ12: -12 | JR12: -11.2 | JS12: -11.9 | JT12: -11.5 | JU12: -10.8 | JV12: -3.1 | JW12: -4.4 | JX12: -6 | JY12: -12.1 | JZ12: -5.1 | KA12: -3.3 | KB12: -3.6 | KC12: -5.7 | KD12: -4.1 | KE12: -6.5 | KF12: -4.6 | KG12: -3.7 | KH12: 5.5 | KI12: -5.3 | KJ12: -4.1 | KK12: -8.2 | KL12: -8 | KM12: -6.3 | KN12: -5.6 | KO12: 0.1 | KP12: 1.7 | KQ12: 18.5 | KR12: 23.5 | KS12: 20.1 | KT12: 36.4 | KU12: -7.3 | KV12: -8.9 | KW12: -11.6 | KX12: 6.3 | KY12: 4.8 | KZ12: 6.1
A13: Reserve deposits of Commercial Banks in NBK | BO13: 104246 | BP13: 167523 | BQ13: 168465 | BR13: 167478 | BS13: 198173 | BT13: 222582 | BU13: 400636 | BV13: 389420 | BW13: 499137 | BX13: 485688 | BY13: 475809 | BZ13: 665353 | CA13: 521119 | CB13: 690755 | CC13: 506133 | CD13: 650324 | CE13: 604213 | CF13: 679691 | CG13: 721718 | CH13: 784748 | CI13: 793870 | CJ13: 636931 | CK13: 633609 | CL13: 557755 | CM13: 654018 | CN13: 683779 | CO13: 630400 | CP13: 633113 | CQ13: 638629 | CR13: 591504 | CS13: 551683 | CT13: 497812 | CU13: 546268 | CV13: 457414 | CW13: 235496 | CX13: 295179 | CY13: 608632 | CZ13: 721496 | DA13: 592390 | DB13: 561115 | DC13: 550356 | DD13: 395346 | DE13: 469558 | DF13: 604502 | DG13: 695344 | DH13: 625205 | DI13: 437740 | DJ13: 460395 | DK13: 498421 | DL13: 478391 | DM13: 493153 | DN13: 452073 | DO13: 533216 | DP13: 570279 | DQ13: 400941 | DR13: 474798 | DS13: 355611 | DT13: 486109 | DU13: 372897 | DV13: 292371 | DW13: 387193 | DX13: 342311 | DY13: 499793 | DZ13: 454557 | EA13: 308051 | EB13: 329837 | EC13: 446864 | ED13: 536519 | EE13: 565031 | EF13: 849172 | EG13: 827655 | EH13: 631460 | EI13: 1091545 | EJ13: 1215195 | EK13: 806384 | EL13: 1183188 | EM13: 1096117 | EN13: 1245427 | EO13: 732578 | EP13: 656104 | EQ13: 717188 | ER13: 721985 | ES13: 672777 | ET13: 665236 | EU13: 620510 | EV13: 650272 | EW13: 904246 | EX13: 831399 | EY13: 1034969 | EZ13: 1035896 | FA13: 1079383 | FB13: 951687 | FC13: 834749 | FD13: 852001 | FE13: 747732 | FF13: 804426 | FG13: 968116 | FH13: 1257364 | FI13: 1313016 | FJ13: 1198748 | FK13: 1162201 | FL13: 1118926 | FM13: 1307312 | FN13: 1209355 | FO13: 1419282 | FP13: 1635563 | FQ13: 1517936 | FR13: 1399485 | FS13: 1309106 | FT13: 1325699 | FU13: 1360175 | FV13: 1433386 | FW13: 1446441 | FX13: 1837992 | FY13: 1555689 | FZ13: 2152225 | GA13: 2584821 | GB13: 2709436 | GC13: 2820049 | GD13: 2755913 | GE13: 2890292 | GF13: 2281180 | GG13: 2056893 | GH13: 2087059 | GI13: 1910325 | GJ13: 2041405 | GK13: 1692299 | GL13: 1954400 | GM13: 2109097 | GN13: 1985254 | GO13: 2140100 | GP13: 2310652 | GQ13: 1993542 | GR13: 1875978 | GS13: 1936390 | GT13: 1852155 | GU13: 2159960 | GV13: 1987952 | GW13: 2472084 | GX13: 2467920 | GY13: 2402189 | GZ13: 2409850 | HA13: 2652431 | HB13: 2314690 | HC13: 2088318 | HD13: 1879142 | HE13: 1600439 | HF13: 1747678 | HG13: 1644369 | HH13: 1733309 | HI13: 2543200 | HJ13: 2983842 | HK13: 2949889 | HL13: 2415811 | HM13: 2863210 | HN13: 2608448 | HO13: 2474568 | HP13: 2785612 | HQ13: 2105029 | HR13: 2035592 | HS13: 2048866 | HT13: 2078894 | HU13: 2459208 | HV13: 2523565 | HW13: 1873685 | HX13: 2140366 | HY13: 2148058 | HZ13: 1700882 | IA13: 1574798 | IB13: 1855039 | IC13: 2400428 | ID13: 1466597 | IE13: 1370114 | IF13: 1221236 | IG13: 1018849 | IH13: 1299999 | II13: 915136 | IJ13: 969462 | IK13: 1348357 | IL13: 1299270 | IM13: 1086564 | IN13: 1192837 | IO13: 1250191 | IP13: 1502393 | IQ13: 1756918 | IR13: 2018366 | IS13: 1687445 | IT13: 2038207 | IU13: 1584889 | IV13: 1691071 | IW13: 2131012 | IX13: 2074806 | IY13: 2355116 | IZ13: 3241122 | JA13: 2535485 | JB13: 2572547 | JC13: 2355292 | JD13: 2201695 | JE13: 2630146 | JF13: 2982461 | JG13: 2304152 | JH13: 2592492 | JI13: 1913640 | JJ13: 2202901 | JK13: 1643442 | JL13: 1659809 | JM13: 1654622 | JN13: 1292230 | JO13: 1139901 | JP13: 1309348 | JQ13: 1342609 | JR13: 1449843 | JS13: 1271845 | JT13: 1347906 | JU13: 1283778 | JV13: 1483719 | JW13: 1556051 | JX13: 1395575 | JY13: 1035162 | JZ13: 1209203 | KA13: 1190485 | KB13: 1073890 | KC13: 1004243 | KD13: 1084200 | KE13: 991225 | KF13: 1132641 | KG13: 1186766 | KH13: 1372456 | KI13: 1156468 | KJ13: 1255203 | KK13: 1220802 | KL13: 1130854 | KM13: 1199383 | KN13: 993761 | KO13: 1343839 | KP13: 1388616 | KQ13: 2745602 | KR13: 3093313 | KS13: 2779930 | KT13: 3742168 | KU13: 3157003 | KV13: 3078962 | KW13: 2799858 | KX13: 4494563 | KY13: 4195065 | KZ13: 4250443
A15: M0 | B15: 98705 | C15: 106105 | D15: 104356 | E15: 97267 | F15: 106428 | G15: 96126 | H15: 100186 | I15: 101993 | J15: 106168 | K15: 104479 | L15: 110538 | M15: 113806 | N15: 116879 | O15: 124234 | P15: 123057 | Q15: 117054 | R15: 131175 | S15: 116261 | T15: 119925 | U15: 123915 | V15: 124695 | W15: 127581 | X15: 134966 | Y15: 138081 | Z15: 141823 | AA15: 141360 | AB15: 149144 | AC15: 148365 | AD15: 161701 | AE15: 143087 | AF15: 153620 | AG15: 159233 | AH15: 166954 | AI15: 174283 | AJ15: 190039 | AK15: 202822 | AL15: 207974 | AM15: 217967 | AN15: 231886 | AO15: 224752 | AP15: 238545 | AQ15: 231074 | AR15: 241154 | AS15: 244817 | AT15: 256876 | AU15: 260438 | AV15: 281457 | AW15: 299014 | AX15: 305738 | AY15: 312083 | AZ15: 332032 | BA15: 345937 | BB15: 379273 | BC15: 345726 | BD15: 356828 | BE15: 364830 | BF15: 379870 | BG15: 386205 | BH15: 389452 | BI15: 399519 | BJ15: 401956 | BK15: 414713 | BL15: 416768 | BM15: 395511 | BN15: 411813 | BO15: 385714 | BP15: 404446 | BQ15: 436668 | BR15: 462704 | BS15: 503411 | BT15: 550041 | BU15: 572149 | BV15: 554974 | BW15: 550931 | BX15: 529391 | BY15: 524663 | BZ15: 600832 | CA15: 599308 | CB15: 613245 | CC15: 652146 | CD15: 699939 | CE15: 750390 | CF15: 793088 | CG15: 815401 | CH15: 806070 | CI15: 770694 | CJ15: 724686 | CK15: 686061 | CL15: 739687 | CM15: 677389 | CN15: 683895 | CO15: 696403 | CP15: 719223 | CQ15: 741460 | CR15: 769601 | CS15: 786977 | CT15: 796755 | CU15: 806775 | CV15: 815935 | CW15: 806667 | CX15: 857842 | CY15: 714096 | CZ15: 701571 | DA15: 717865 | DB15: 747225 | DC15: 779827 | DD15: 818735 | DE15: 807319 | DF15: 807062 | DG15: 809662 | DH15: 820629 | DI15: 836670 | DJ15: 913443 | DK15: 874577 | DL15: 882451 | DM15: 898241 | DN15: 957620 | DO15: 990568 | DP15: 1033962 | DQ15: 1072300 | DR15: 1069834 | DS15: 1086459 | DT15: 1096039 | DU15: 1074837 | DV15: 1148489 | DW15: 1094781 | DX15: 1091552 | DY15: 1097141 | DZ15: 1124804 | EA15: 1142660 | EB15: 1191674 | EC15: 1234223 | ED15: 1254132 | EE15: 1260656 | EF15: 1260243 | EG15: 1234734 | EH15: 1365698 | EI15: 1301396 | EJ15: 1291276 | EK15: 1307762 | EL15: 1341433 | EM15: 1350136 | EN15: 1389424 | EO15: 1398763 | EP15: 1405179 | EQ15: 1421824 | ER15: 1407553 | ES15: 1379943 | ET15: 1528077 | EU15: 1422379 | EV15: 1409475 | EW15: 1428375 | EX15: 1438927 | EY15: 1460239 | EZ15: 1523517 | FA15: 1475865 | FB15: 1467659 | FC15: 1453566 | FD15: 1437651 | FE15: 1404152 | FF15: 1512261 | FG15: 1397708 | FH15: 1399675 | FI15: 1319887 | FJ15: 1359033 | FK15: 1397801 | FL15: 1452216 | FM15: 1439601 | FN15: 1382569 | FO15: 1369299 | FP15: 1274397 | FQ15: 1221633 | FR15: 1122319 | FS15: 1035712 | FT15: 1020848 | FU15: 1037126 | FV15: 1018439 | FW15: 1086948 | FX15: 1143598 | FY15: 1135293 | FZ15: 1186211 | GA15: 1199959 | GB15: 1201559 | GC15: 1190243 | GD15: 1236973 | GE15: 1174178 | GF15: 1237519 | GG15: 1302768 | GH15: 1395984 | GI15: 1485329 | GJ15: 1582258 | GK15: 1593378 | GL15: 1548974 | GM15: 1560761 | GN15: 1572842 | GO15: 1567794 | GP15: 1748810 | GQ15: 1619063 | GR15: 1640297 | GS15: 1645407 | GT15: 1724115 | GU15: 1741857 | GV15: 1830669 | GW15: 1869034 | GX15: 1820613 | GY15: 1816089 | GZ15: 1778145 | HA15: 1766492 | HB15: 1946338 | HC15: 1817235 | HD15: 1794473 | HE15: 1810244 | HF15: 1886063 | HG15: 1940652 | HH15: 2059000 | HI15: 2103425 | HJ15: 2100151 | HK15: 2067026 | HL15: 2102866 | HM15: 2082467 | HN15: 2260157 | HO15: 2170013 | HP15: 2134988 | HQ15: 2193233 | HR15: 2207421 | HS15: 2245869 | HT15: 2231486 | HU15: 2236207 | HV15: 2247723 | HW15: 2232862 | HX15: 2231036 | HY15: 2200878 | HZ15: 2300505 | IA15: 2189815 | IB15: 2215110 | IC15: 2301265 | ID15: 2572940 | IE15: 2766404 | IF15: 2784088 | IG15: 2885316 | IH15: 2922621 | II15: 2808870 | IJ15: 2804394 | IK15: 2707107 | IL15: 2828046 | IM15: 2716272 | IN15: 2746749 | IO15: 2793576 | IP15: 2884383 | IQ15: 2964596 | IR15: 3027160 | IS15: 3034440 | IT15: 3014468 | IU15: 2984325 | IV15: 3013564 | IW15: 2905399 | IX15: 2997723 | IY15: 2990997 | IZ15: 2992529 | JA15: 3058620 | JB15: 3106580 | JC15: 3076771 | JD15: 3260227 | JE15: 3344648 | JF15: 3296689 | JG15: 3316247 | JH15: 3309675 | JI15: 3251187 | JJ15: 3360653 | JK15: 3251127 | JL15: 3196089 | JM15: 3219144 | JN15: 3363522 | JO15: 3351386 | JP15: 3495339 | JQ15: 3506866 | JR15: 3514416 | JS15: 3553371 | JT15: 3531833 | JU15: 3471926 | JV15: 3639662 | JW15: 3614419 | JX15: 3620669 | JY15: 3639093 | JZ15: 3638486 | KA15: 3702853 | KB15: 3917267 | KC15: 3967485 | KD15: 4047903 | KE15: 3991214 | KF15: 4038230 | KG15: 4062417 | KH15: 4374546 | KI15: 4281381 | KJ15: 4224931 | KK15: 4281997 | KL15: 4419978 | KM15: 4501805 | KN15: 4723999 | KO15: 4796892 | KP15: 4822508 | KQ15: 4692018 | KR15: 4652724 | KS15: 4570342 | KT15: 4749199 | KU15: 4571140 | KV15: 4485043 | KW15: 4479899 | KX15: 4590886 | KY15: 4764859 | KZ15: 4864774
A16: % changes to the previous month | B16: 1.3 | C16: 7.5 | D16: -1.6 | E16: -6.8 | F16: 9.4 | G16: -9.7 | H16: 4.2 | I16: 1.8 | J16: 4.1 | K16: -1.6 | L16: 5.8 | M16: 3 | N16: 2.7 | O16: 6.3 | P16: -0.9 | Q16: -4.9 | R16: 12.1 | S16: -11.4 | T16: 3.2 | U16: 3.3 | V16: 0.6 | W16: 2.3 | X16: 5.8 | Y16: 2.3 | Z16: 2.7 | AA16: -0.3 | AB16: 5.5 | AC16: -0.5 | AD16: 9 | AE16: -11.5 | AF16: 7.4 | AG16: 3.7 | AH16: 4.8 | AI16: 4.4 | AJ16: 9 | AK16: 6.7 | AL16: 2.5 | AM16: 4.8 | AN16: 6.4 | AO16: -3.1 | AP16: 6.1 | AQ16: -3.1 | AR16: 4.4 | AS16: 1.5 | AT16: 4.9 | AU16: 1.4 | AV16: 8.1 | AW16: 6.2 | AX16: 2.2 | AY16: 2.1 | AZ16: 6.4 | BA16: 4.2 | BB16: 9.6 | BC16: -8.8 | BD16: 3.2 | BE16: 2.2 | BF16: 4.1 | BG16: 1.7 | BH16: 0.8 | BI16: 2.6 | BJ16: 0.6 | BK16: 3.2 | BL16: 0.5 | BM16: -5.1 | BN16: 4.1 | BO16: -6.3 | BP16: 4.9 | BQ16: 8 | BR16: 6 | BS16: 8.8 | BT16: 9.3 | BU16: 4 | BV16: -3 | BW16: -0.7 | BX16: -3.9 | BY16: -0.9 | BZ16: 14.5 | CA16: -0.3 | CB16: 2.3 | CC16: 6.3 | CD16: 7.3 | CE16: 7.2 | CF16: 5.7 | CG16: 2.8 | CH16: -1.1 | CI16: -4.4 | CJ16: -6 | CK16: -5.3 | CL16: 7.8 | CM16: -8.4 | CN16: 1 | CO16: 1.8 | CP16: 3.3 | CQ16: 3.1 | CR16: 3.8 | CS16: 2.3 | CT16: 1.2 | CU16: 1.3 | CV16: 1.1 | CW16: -1.1 | CX16: 6.3 | CY16: -16.8 | CZ16: -1.8 | DA16: 2.3 | DB16: 4.1 | DC16: 4.4 | DD16: 5 | DE16: -1.4 | DG16: 0.3 | DH16: 1.4 | DI16: 2 | DJ16: 9.2 | DK16: -4.3 | DL16: 0.9 | DM16: 1.8 | DN16: 6.6 | DO16: 3.4 | DP16: 4.4 | DQ16: 3.7 | DR16: -0.2 | DS16: 1.6 | DT16: 0.9 | DU16: -1.9 | DV16: 6.9 | DW16: -4.7 | DX16: -0.3 | DY16: 0.5 | DZ16: 2.5 | EA16: 1.6 | EB16: 4.3 | EC16: 3.6 | ED16: 1.6 | EE16: 0.5 | EG16: -2 | EH16: 10.6 | EI16: -4.7 | EJ16: -0.8 | EK16: 1.3 | EL16: 2.6 | EM16: 0.6 | EN16: 2.9 | EO16: 0.7 | EP16: 0.5 | EQ16: 1.2 | ER16: -1 | ES16: -2 | ET16: 10.7 | EU16: -6.9 | EV16: -0.9 | EW16: 1.3 | EX16: 0.7 | EY16: 1.5 | EZ16: 4.3 | FA16: -3.1 | FB16: -0.6 | FC16: -1 | FD16: -1.1 | FE16: -2.3 | FF16: 7.7 | FG16: -7.6 | FH16: 0.1 | FI16: -5.7 | FJ16: 3 | FK16: 2.9 | FL16: 3.9 | FM16: -0.9 | FN16: -4 | FO16: -1 | FP16: -6.9 | FQ16: -4.1 | FS16: -7.7 | FT16: -1.4 | FU16: 1.6 | FV16: -1.8 | FW16: 6.7 | FX16: 5.2 | FY16: -0.7 | FZ16: 4.5 | GA16: 1.2 | GB16: 0.1 | GC16: -0.9 | GD16: 3.9 | GE16: -5.1 | GF16: 5.4 | GG16: 5.3 | GH16: 7.2 | GI16: 6.4 | GJ16: 6.5 | GK16: 0.7 | GL16: -2.8 | GM16: 0.8 | GN16: 0.8 | GO16: -0.3 | GP16: 11.5 | GQ16: -7.4 | GR16: 1.3 | GS16: 0.3 | GT16: 4.8 | GU16: 1 | GV16: 5.1 | GW16: 2.1 | GX16: -2.6 | GY16: -0.2 | GZ16: -2.1 | HA16: -0.7 | HB16: 10.2 | HC16: -6.6 | HD16: -1.3 | HE16: 0.9 | HF16: 4.2 | HG16: 2.9 | HH16: 6.1 | HI16: 2.2 | HJ16: -0.2 | HK16: -1.6 | HL16: 1.7 | HM16: -1 | HN16: 8.5 | HO16: -4 | HP16: -1.6 | HQ16: 2.7 | HR16: 0.6 | HS16: 1.7 | HT16: -0.6 | HU16: 0.2 | HV16: 0.5 | HW16: -0.7 | HX16: -0.1 | HY16: -1.4 | HZ16: 4.5 | IA16: -4.8 | IB16: 1.2 | IC16: 3.9 | ID16: 11.8 | IE16: 7.5 | IF16: 0.6 | IG16: 3.6 | IH16: 1.3 | II16: -3.9 | IJ16: -0.2 | IK16: -3.5 | IL16: 4.5 | IM16: -4 | IN16: 1.1 | IO16: 1.7 | IP16: 3.3 | IQ16: 2.8 | IR16: 2.1 | IS16: 0.2 | IT16: -0.7 | IU16: -1 | IV16: 1 | IW16: -3.6 | IX16: 3.2 | IY16: -0.2 | IZ16: 0.1 | JA16: 2.2 | JB16: 1.6 | JC16: -1 | JD16: 6 | JE16: 2.6 | JF16: -1.4 | JG16: 0.6 | JH16: -0.2 | JI16: -1.8 | JJ16: 3.4 | JK16: -3.3 | JL16: -1.7 | JM16: 0.7 | JN16: 4.5 | JO16: -0.4 | JP16: 4.3 | JQ16: 0.3 | JR16: 0.2 | JS16: 1.1 | JT16: -0.6 | JU16: -1.7 | JV16: 4.8 | JW16: -0.7 | JX16: 0.2 | JY16: 0.5 | KA16: 1.8 | KB16: 5.8 | KC16: 1.3 | KD16: 2 | KE16: -1.4 | KF16: 1.2 | KG16: 0.6 | KH16: 7.7 | KI16: -2.1 | KJ16: -1.3 | KK16: 1.4 | KL16: 3.2 | KM16: 1.9 | KN16: 4.9 | KO16: 1.5 | KP16: 0.5 | KQ16: -2.7 | KR16: -0.8 | KS16: -1.8 | KT16: 3.9 | KU16: -3.7 | KV16: -1.9 | KW16: -0.1 | KX16: 2.5 | KY16: 3.8 | KZ16: 2.1
A17: % changes to December of the previous year | B17: -4.6 | C17: 2.5 | D17: 0.8 | E17: -6 | F17: 2.8 | G17: -9.7 | H17: -5.9 | I17: -4.2 | J17: -0.2 | K17: -1.8 | L17: 3.9 | M17: 6.9 | N17: 9.8 | O17: 16.7 | P17: 15.6 | Q17: 10 | R17: 23.3 | S17: -11.4 | T17: -8.6 | U17: -5.5 | V17: -4.9 | W17: -2.7 | X17: 2.9 | Y17: 5.3 | Z17: 8.1 | AA17: 7.8 | AB17: 13.7 | AC17: 13.1 | AD17: 23.3 | AE17: -11.5 | AF17: -5 | AG17: -1.5 | AH17: 3.2 | AI17: 7.8 | AJ17: 17.5 | AK17: 25.4 | AL17: 28.6 | AM17: 34.8 | AN17: 43.4 | AO17: 39 | AP17: 47.5 | AQ17: -3.1 | AR17: 1.1 | AS17: 2.6 | AT17: 7.7 | AU17: 9.2 | AV17: 18 | AW17: 25.3 | AX17: 28.2 | AY17: 30.8 | AZ17: 39.2 | BA17: 45 | BB17: 59 | BC17: -8.8 | BD17: -5.9 | BE17: -3.8 | BF17: 0.2 | BG17: 1.8 | BH17: 2.7 | BI17: 5.3 | BJ17: 6 | BK17: 9.3 | BL17: 9.9 | BM17: 4.3 | BN17: 8.6 | BO17: -6.3 | BP17: -1.8 | BQ17: 6 | BR17: 12.4 | BS17: 22.2 | BT17: 33.6 | BU17: 38.9 | BV17: 34.8 | BW17: 33.8 | BX17: 28.6 | BY17: 27.4 | BZ17: 45.9 | CA17: -0.3 | CB17: 2.1 | CC17: 8.5 | CD17: 16.5 | CE17: 24.9 | CF17: 32 | CG17: 35.7 | CH17: 34.2 | CI17: 28.3 | CJ17: 20.6 | CK17: 14.2 | CL17: 23.1 | CM17: -8.4 | CN17: -7.5 | CO17: -5.9 | CP17: -2.8 | CQ17: 0.2 | CR17: 4 | CS17: 6.4 | CT17: 7.7 | CU17: 9.1 | CV17: 10.3 | CW17: 9.1 | CX17: 16 | CY17: -16.8 | CZ17: -18.2 | DA17: -16.3 | DB17: -12.9 | DC17: -9.1 | DD17: -4.6 | DE17: -5.9 | DF17: -5.9 | DG17: -5.6 | DH17: -4.3 | DI17: -2.5 | DJ17: 6.5 | DK17: -4.3 | DL17: -3.4 | DM17: -1.7 | DN17: 4.8 | DO17: 8.4 | DP17: 13.2 | DQ17: 17.4 | DR17: 17.1 | DS17: 18.9 | DT17: 20 | DU17: 17.7 | DV17: 25.7 | DW17: -4.7 | DX17: -5 | DY17: -4.5 | DZ17: -2.1 | EA17: -0.5 | EB17: 3.8 | EC17: 7.5 | ED17: 9.2 | EE17: 9.8 | EF17: 9.7 | EG17: 7.5 | EH17: 18.9 | EI17: -4.7 | EJ17: -5.4 | EK17: -4.2 | EL17: -1.8 | EM17: -1.1 | EN17: 1.7 | EO17: 2.4 | EP17: 2.9 | EQ17: 4.1 | ER17: 3.1 | ES17: 1 | ET17: 11.9 | EU17: -6.9 | EV17: -7.8 | EW17: -6.5 | EX17: -5.8 | EY17: -4.4 | EZ17: -0.3 | FA17: -3.4 | FB17: -3.9 | FC17: -4.9 | FD17: -5.9 | FE17: -8.1 | FF17: -1 | FG17: -7.6 | FH17: -7.4 | FI17: -12.7 | FJ17: -10.1 | FK17: -7.6 | FL17: -4 | FM17: -4.8 | FN17: -8.6 | FO17: -9.5 | FP17: -15.7 | FQ17: -19.2 | FR17: -25.8 | FS17: -7.7 | FT17: -9 | FU17: -7.6 | FV17: -9.3 | FW17: -3.2 | FX17: 1.9 | FY17: 1.2 | FZ17: 5.7 | GA17: 6.9 | GB17: 7.1 | GC17: 6.1 | GD17: 10.2 | GE17: -5.1 | GG17: 5.3 | GH17: 12.9 | GI17: 20.1 | GJ17: 27.9 | GK17: 28.8 | GL17: 25.2 | GM17: 26.2 | GN17: 27.2 | GO17: 26.7 | GP17: 41.4 | GQ17: -7.4 | GR17: -6.2 | GS17: -5.9 | GT17: -1.4 | GU17: -0.4 | GV17: 4.7 | GW17: 6.9 | GX17: 4.1 | GY17: 3.8 | GZ17: 1.7 | HA17: 1 | HB17: 11.3 | HC17: -6.6 | HD17: -7.8 | HE17: -7 | HF17: -3.1 | HG17: -0.3 | HH17: 5.8 | HI17: 8.1 | HJ17: 7.9 | HK17: 6.2 | HL17: 8 | HM17: 7 | HN17: 16.1 | HO17: -4 | HP17: -5.5 | HQ17: -3 | HR17: -2.3 | HS17: -0.6 | HT17: -1.3 | HU17: -1.1 | HV17: -0.6 | HW17: -1.2 | HX17: -1.3 | HY17: -2.6 | HZ17: 1.8 | IA17: -4.8 | IB17: -3.7 | ID17: 11.8 | IE17: 20.3 | IF17: 21 | IG17: 25.4 | IH17: 27 | II17: 22.1 | IJ17: 21.9 | IK17: 17.7 | IL17: 22.9 | IM17: -4 | IN17: -2.9 | IO17: -1.2 | IP17: 2 | IQ17: 4.8 | IR17: 7 | IS17: 7.3 | IT17: 6.6 | IU17: 5.5 | IV17: 6.6 | IW17: 2.7 | IX17: 6 | IY17: -0.2 | IZ17: -0.2 | JA17: 2 | JB17: 3.6 | JC17: 2.6 | JD17: 8.8 | JE17: 11.6 | JF17: 10 | JG17: 10.6 | JH17: 10.4 | JI17: 8.5 | JJ17: 12.1 | JK17: -3.3 | JL17: -4.9 | JM17: -4.2 | JN17: 0.1 | JO17: -0.3 | JP17: 4 | JQ17: 4.4 | JR17: 4.6 | JS17: 5.7 | JT17: 5.1 | JU17: 3.3 | JV17: 8.3 | JW17: -0.7 | JX17: -0.5 | KA17: 1.7 | KB17: 7.6 | KC17: 9 | KD17: 11.2 | KE17: 9.7 | KF17: 11 | KG17: 11.6 | KH17: 20.2 | KI17: -2.1 | KJ17: -3.4 | KK17: -2.1 | KL17: 1 | KM17: 2.9 | KN17: 8 | KO17: 9.7 | KP17: 10.2 | KQ17: 7.3 | KR17: 6.4 | KS17: 4.5 | KT17: 8.6 | KU17: -3.7 | KV17: -5.6 | KW17: -5.7 | KX17: -3.3 | KY17: 0.3 | KZ17: 2.4
A19: M1 | B19: 174309 | C19: 186625 | D19: 191640 | E19: 179668 | F19: 195442 | G19: 174647 | H19: 186169 | I19: 194454 | J19: 182772 | K19: 188735 | L19: 206902 | M19: 206182 | N19: 209814 | O19: 227332 | P19: 218044 | Q19: 213537 | R19: 224234 | S19: 193220 | T19: 193349 | U19: 207635 | V19: 208469 | W19: 212694 | X19: 221339 | Y19: 226896 | Z19: 239041 | AA19: 243626 | AB19: 252715 | AC19: 253642 | AD19: 287293 | AE19: 255430 | AF19: 276729 | AG19: 294907 | AH19: 307294 | AI19: 325559 | AJ19: 362465 | AK19: 370584 | AL19: 375752 | AM19: 407353 | AN19: 422702 | AO19: 420972 | AP19: 412139 | AQ19: 403279 | AR19: 427520 | AS19: 443087 | AT19: 453475 | AU19: 483869 | AV19: 515381 | AW19: 534930 | AX19: 557706 | AY19: 566350 | AZ19: 597639 | BA19: 633280 | BB19: 680632 | BC19: 616318 | BD19: 657619 | BE19: 687233 | BF19: 719537 | BG19: 719891 | BH19: 750368 | BI19: 750283 | BJ19: 757748 | BK19: 786047 | BL19: 775566 | BM19: 771401 | BN19: 799440 | BO19: 749574 | BP19: 867494 | BQ19: 913456 | BR19: 933727 | BS19: 1013748 | BT19: 1077420 | BU19: 1155872 | BV19: 1146848 | BW19: 1186755 | BX19: 1132520 | BY19: 1170277 | BZ19: 1281549 | CA19: 1250609 | CB19: 1344095 | CC19: 1393072 | CD19: 1501086 | CE19: 1586502 | CF19: 1719489 | CG19: 1666933 | CH19: 1622284 | CI19: 1649525 | CJ19: 1502444 | CK19: 1471317 | CL19: 1532688 | CM19: 1441389 | CN19: 1497436 | CO19: 1576730 | CP19: 1578419 | CQ19: 1710068 | CR19: 1778665 | CS19: 1812997 | CT19: 1808743 | CU19: 1929268 | CV19: 1786427 | CW19: 1805923 | CX19: 1947570 | CY19: 2006257 | CZ19: 2260440 | DA19: 2278690 | DB19: 2222349 | DC19: 2279615 | DD19: 2444213 | DE19: 2597617 | DF19: 2438362 | DG19: 2384658 | DH19: 2318943 | DI19: 2402657 | DJ19: 2457677 | DK19: 2536665 | DL19: 2595183 | DM19: 2707056 | DN19: 2788684 | DO19: 2641760 | DP19: 2863832 | DQ19: 2830371 | DR19: 2960520 | DS19: 3082180 | DT19: 3161605 | DU19: 2970451 | DV19: 3116049 | DW19: 3112623 | DX19: 3137096 | DY19: 3440728 | DZ19: 3489824 | EA19: 3519077 | EB19: 3684065 | EC19: 3866985 | ED19: 3673637 | EE19: 3704025 | EF19: 3627006 | EG19: 3537250 | EH19: 3844996 | EI19: 3614004 | EJ19: 3762159 | EK19: 3886272 | EL19: 3725310 | EM19: 3812954 | EN19: 3993464 | EO19: 3888499 | EP19: 3732979 | EQ19: 3811804 | ER19: 3759904 | ES19: 3579746 | ET19: 3880611 | EU19: 3719628 | EV19: 3759364 | EW19: 3844133 | EX19: 3884077 | EY19: 3811101 | EZ19: 3973997 | FA19: 3748696 | FB19: 3505672 | FC19: 3640006 | FD19: 3489379 | FE19: 3312367 | FF19: 3518418 | FG19: 3489766 | FH19: 3345979 | FI19: 3461744 | FJ19: 3559615 | FK19: 3583133 | FL19: 3958367 | FM19: 3863590 | FN19: 3773208 | FO19: 3639562 | FP19: 3406501 | FQ19: 3196190 | FR19: 2980974 | FS19: 2800476 | FT19: 2908663 | FU19: 3060341 | FV19: 3036984 | FW19: 3434338 | FX19: 3602481 | FY19: 3457335 | FZ19: 3340687 | GA19: 3284925 | GB19: 3139300 | GC19: 3012824 | GD19: 3032711 | GE19: 2971351 | GF19: 3140515 | GG19: 3587429 | GH19: 3866346 | GI19: 3955149 | GJ19: 4220880 | GK19: 4226445 | GL19: 4026363 | GM19: 4038754 | GN19: 4283330 | GO19: 4354953 | GP19: 4589768 | GQ19: 4310015 | GR19: 4454442 | GS19: 4927779 | GT19: 5046178 | GU19: 5127913 | GV19: 5010955 | GW19: 5143578 | GX19: 4738682 | GY19: 5476568 | GZ19: 4991002 | HA19: 4917595 | HB19: 4967992 | HC19: 4995811 | HD19: 4807891 | HE19: 4807409 | HF19: 4893766 | HG19: 5044409 | HH19: 5577251 | HI19: 5520420 | HJ19: 5252714 | HK19: 5122707 | HL19: 5305813 | HM19: 5051957 | HN19: 5605006 | HO19: 6412273 | HP19: 5507657 | HQ19: 5402116 | HR19: 5411541 | HS19: 5760725 | HT19: 5507695 | HU19: 5599015 | HV19: 5576525 | HW19: 5568288 | HX19: 5703278 | HY19: 5616375 | HZ19: 5928085 | IA19: 5616433 | IB19: 5687711 | IC19: 6164531 | ID19: 6251342 | IE19: 6414901 | IF19: 6640829 | IG19: 6758204 | IH19: 6760726 | II19: 6700333 | IJ19: 6864955 | IK19: 7199420 | IL19: 7186951 | IM19: 6927993 | IN19: 7292252 | IO19: 7531108 | IP19: 7514189 | IQ19: 7749131 | IR19: 7986212 | IS19: 7991971 | IT19: 7963959 | IU19: 7992290 | IV19: 7880492 | IW19: 7654661 | IX19: 8788006 | IY19: 8768737 | IZ19: 8944223 | JA19: 8926147 | JB19: 8498602 | JC19: 8378061 | JD19: 8891388 | JE19: 8884711 | JF19: 8801537 | JG19: 8707879 | JH19: 8846006 | JI19: 9042731 | JJ19: 9382455 | JK19: 8890492 | JL19: 8606227 | JM19: 8592426 | JN19: 8652229 | JO19: 8948466 | JP19: 9752118 | JQ19: 9446279 | JR19: 9358085 | JS19: 9416814 | JT19: 9421155 | JU19: 9431066 | JV19: 10380883 | JW19: 9553002 | JX19: 9658325 | JY19: 9402329 | JZ19: 9960431 | KA19: 10119371 | KB19: 10656953 | KC19: 11025171 | KD19: 10805253 | KE19: 10837433 | KF19: 10667791 | KG19: 10390724 | KH19: 11364043 | KI19: 10559684 | KJ19: 10530798 | KK19: 10231744 | KL19: 10578489 | KM19: 10607383 | KN19: 11332249 | KO19: 11072599 | KP19: 11199909 | KQ19: 11365179 | KR19: 11164141 | KS19: 11333866 | KT19: 11935072 | KU19: 11169443 | KV19: 11294457 | KW19: 11371521 | KX19: 11361233 | KY19: 11665814 | KZ19: 12114107
