Workbook

Sheet Worksheet
A1: International Reserves and foreign currency assets of the National Fund of Republic of Kazakhstan
B3: Gross international reserves | E3: Assets in CFC in International Reserves | H3: Monetary gold in International Reserves | K3: Net international reserves | N3: Foreign currency assets of the National Fund of Republic of Kazakhstan
B4: volume, million dollars | C4: change to the previous month,% | D4: change by the beginning of the year,% | E4: volume, million dollars | F4: change to the previous month,% | G4: change by the beginning of the year,% | H4: volume, million dollars | I4: change to the previous month,% | J4: change by the beginning of the year,% | K4: volume, million dollars | L4: change to the previous month,% | M4: change by the beginning of the year,% | N4: volume, million dollars | O4: change to the previous month,% | P4: change by the beginning of the year,%
A5: 08.94 | B5: 1099 | C5: 18.54 | D5: 54.6 | E5: 813 | F5: 25.69 | G5: 78.48 | H5: 286 | I5: 2.05 | J5: 12.01 | K5: 790 | L5: 1.38 | M5: 14.77 | Q5: =IF(ISNUMBER(SEARCH(".",A5)),DATE(IF(VALUE(RIGHT(A5,2))>=94,1900+VALUE(RIGHT(A5,2)),2000+VALUE(RIGHT(A5,2))),VALUE(LEFT(A5,2)),1),DATE(2000+VALUE(A5),10,1)) -> 34547 | R5: =TEXT(Q5,"yyyy-mm-01") -> 1994-08-01
A6: 09.94 | B6: 1118 | C6: 1.67 | D6: 57.17 | E6: 800 | F6: -1.67 | G6: 75.5 | H6: 318 | I6: 11.13 | J6: 24.48 | K6: 796 | L6: 0.73 | M6: 15.6 | Q6: =IF(ISNUMBER(SEARCH(".",A6)),DATE(IF(VALUE(RIGHT(A6,2))>=94,1900+VALUE(RIGHT(A6,2)),2000+VALUE(RIGHT(A6,2))),VALUE(LEFT(A6,2)),1),DATE(2000+VALUE(A6),10,1)) -> 34578 | R6: =TEXT(Q6,"yyyy-mm-01") -> 1994-09-01
A7: 10.94 | B7: 968 | C7: -13.38 | D7: 36.14 | E7: 623 | F7: -22.08 | G7: 36.76 | H7: 345 | I7: 8.49 | J7: 35.05 | K7: 761 | L7: -4.36 | M7: 10.57 | Q7: =IF(ISNUMBER(SEARCH(".",A7)),DATE(IF(VALUE(RIGHT(A7,2))>=94,1900+VALUE(RIGHT(A7,2)),2000+VALUE(RIGHT(A7,2))),VALUE(LEFT(A7,2)),1),DATE(2000+VALUE(A7),10,1)) -> 34608 | R7: =TEXT(Q7,"yyyy-mm-01") -> 1994-10-01
A8: 11.94 | B8: 952 | C8: -1.65 | D8: 33.89 | E8: 610 | F8: -2.08 | G8: 33.91 | H8: 342 | I8: -0.87 | J8: 33.87 | K8: 751 | L8: -1.38 | M8: 9.04 | Q8: =IF(ISNUMBER(SEARCH(".",A8)),DATE(IF(VALUE(RIGHT(A8,2))>=94,1900+VALUE(RIGHT(A8,2)),2000+VALUE(RIGHT(A8,2))),VALUE(LEFT(A8,2)),1),DATE(2000+VALUE(A8),10,1)) -> 34639 | R8: =TEXT(Q8,"yyyy-mm-01") -> 1994-11-01
A9: 12.94 | B9: 1215 | C9: 27.64 | D9: 70.91 | E9: 838 | F9: 37.26 | G9: 83.8 | H9: 378 | I9: 10.5 | J9: 47.92 | K9: 913 | L9: 21.63 | M9: 32.63 | Q9: =IF(ISNUMBER(SEARCH(".",A9)),DATE(IF(VALUE(RIGHT(A9,2))>=94,1900+VALUE(RIGHT(A9,2)),2000+VALUE(RIGHT(A9,2))),VALUE(LEFT(A9,2)),1),DATE(2000+VALUE(A9),10,1)) -> 34669 | R9: =TEXT(Q9,"yyyy-mm-01") -> 1994-12-01
A10: 01.95 | B10: 1142 | C10: -6.05 | D10: -6.05 | E10: 762 | F10: -9.03 | G10: -9.03 | H10: 380 | I10: 0.55 | J10: 0.55 | K10: 851 | L10: -6.79 | M10: -6.79 | Q10: =IF(ISNUMBER(SEARCH(".",A10)),DATE(IF(VALUE(RIGHT(A10,2))>=94,1900+VALUE(RIGHT(A10,2)),2000+VALUE(RIGHT(A10,2))),VALUE(LEFT(A10,2)),1),DATE(2000+VALUE(A10),10,1)) -> 34700 | R10: =TEXT(Q10,"yyyy-mm-01") -> 1995-01-01
A11: 02.95 | B11: 1159 | C11: 1.53 | D11: -4.62 | E11: 767 | F11: 0.63 | G11: -8.46 | H11: 393 | I11: 3.33 | J11: 3.9 | K11: 869 | L11: 2.13 | M11: -4.81 | Q11: =IF(ISNUMBER(SEARCH(".",A11)),DATE(IF(VALUE(RIGHT(A11,2))>=94,1900+VALUE(RIGHT(A11,2)),2000+VALUE(RIGHT(A11,2))),VALUE(LEFT(A11,2)),1),DATE(2000+VALUE(A11),10,1)) -> 34731 | R11: =TEXT(Q11,"yyyy-mm-01") -> 1995-02-01
A12: 03.95 | B12: 1387 | C12: 19.59 | D12: 14.07 | E12: 967 | F12: 26.2 | G12: 15.52 | H12: 419 | I12: 6.7 | J12: 10.86 | K12: 1089 | L12: 25.26 | M12: 19.24 | Q12: =IF(ISNUMBER(SEARCH(".",A12)),DATE(IF(VALUE(RIGHT(A12,2))>=94,1900+VALUE(RIGHT(A12,2)),2000+VALUE(RIGHT(A12,2))),VALUE(LEFT(A12,2)),1),DATE(2000+VALUE(A12),10,1)) -> 34759 | R12: =TEXT(Q12,"yyyy-mm-01") -> 1995-03-01
A13: 04.95 | B13: 1429 | C13: 3.06 | D13: 17.56 | E13: 995 | F13: 2.8 | G13: 18.75 | H13: 434 | I13: 3.68 | J13: 14.94 | K13: 1126 | L13: 3.35 | M13: 23.24 | Q13: =IF(ISNUMBER(SEARCH(".",A13)),DATE(IF(VALUE(RIGHT(A13,2))>=94,1900+VALUE(RIGHT(A13,2)),2000+VALUE(RIGHT(A13,2))),VALUE(LEFT(A13,2)),1),DATE(2000+VALUE(A13),10,1)) -> 34790 | R13: =TEXT(Q13,"yyyy-mm-01") -> 1995-04-01
A14: 05.95 | B14: 1396 | C14: -2.29 | D14: 14.87 | E14: 957 | F14: -3.81 | G14: 14.22 | H14: 440 | I14: 1.2 | J14: 16.31 | K14: 1096 | L14: -2.63 | M14: 20 | Q14: =IF(ISNUMBER(SEARCH(".",A14)),DATE(IF(VALUE(RIGHT(A14,2))>=94,1900+VALUE(RIGHT(A14,2)),2000+VALUE(RIGHT(A14,2))),VALUE(LEFT(A14,2)),1),DATE(2000+VALUE(A14),10,1)) -> 34820 | R14: =TEXT(Q14,"yyyy-mm-01") -> 1995-05-01
A15: 06.95 | B15: 1589 | C15: 13.83 | D15: 30.76 | E15: 1135 | F15: 18.62 | G15: 35.46 | H15: 455 | I15: 3.4 | J15: 20.27 | K15: 1202 | L15: 9.72 | M15: 31.66 | Q15: =IF(ISNUMBER(SEARCH(".",A15)),DATE(IF(VALUE(RIGHT(A15,2))>=94,1900+VALUE(RIGHT(A15,2)),2000+VALUE(RIGHT(A15,2))),VALUE(LEFT(A15,2)),1),DATE(2000+VALUE(A15),10,1)) -> 34851 | R15: =TEXT(Q15,"yyyy-mm-01") -> 1995-06-01
A16: 07.95 | B16: 1732 | C16: 9 | D16: 42.53 | E16: 1273 | F16: 12.2 | G16: 52.02 | H16: 459 | I16: 1.03 | J16: 21.5 | K16: 1356 | L16: 12.78 | M16: 48.49 | Q16: =IF(ISNUMBER(SEARCH(".",A16)),DATE(IF(VALUE(RIGHT(A16,2))>=94,1900+VALUE(RIGHT(A16,2)),2000+VALUE(RIGHT(A16,2))),VALUE(LEFT(A16,2)),1),DATE(2000+VALUE(A16),10,1)) -> 34881 | R16: =TEXT(Q16,"yyyy-mm-01") -> 1995-07-01
A17: 08.95 | B17: 1721 | C17: -0.64 | D17: 41.62 | E17: 1221 | F17: -4.13 | G17: 45.74 | H17: 501 | I17: 9.04 | J17: 32.49 | K17: 1359 | L17: 0.18 | M17: 48.76 | Q17: =IF(ISNUMBER(SEARCH(".",A17)),DATE(IF(VALUE(RIGHT(A17,2))>=94,1900+VALUE(RIGHT(A17,2)),2000+VALUE(RIGHT(A17,2))),VALUE(LEFT(A17,2)),1),DATE(2000+VALUE(A17),10,1)) -> 34912 | R17: =TEXT(Q17,"yyyy-mm-01") -> 1995-08-01
A18: 09.95 | B18: 1704 | C18: -1.03 | D18: 40.15 | E18: 1262 | F18: 3.39 | G18: 50.68 | H18: 442 | I18: -11.81 | J18: 16.84 | K18: 1260 | L18: -7.23 | M18: 38 | Q18: =IF(ISNUMBER(SEARCH(".",A18)),DATE(IF(VALUE(RIGHT(A18,2))>=94,1900+VALUE(RIGHT(A18,2)),2000+VALUE(RIGHT(A18,2))),VALUE(LEFT(A18,2)),1),DATE(2000+VALUE(A18),10,1)) -> 34943 | R18: =TEXT(Q18,"yyyy-mm-01") -> 1995-09-01
A19: 10.95 | B19: 1679 | C19: -1.41 | D19: 38.17 | E19: 1235 | F19: -2.13 | G19: 47.47 | H19: 444 | I19: 0.64 | J19: 17.59 | K19: 1226 | L19: -2.74 | M19: 34.22 | Q19: =IF(ISNUMBER(SEARCH(".",A19)),DATE(IF(VALUE(RIGHT(A19,2))>=94,1900+VALUE(RIGHT(A19,2)),2000+VALUE(RIGHT(A19,2))),VALUE(LEFT(A19,2)),1),DATE(2000+VALUE(A19),10,1)) -> 34973 | R19: =TEXT(Q19,"yyyy-mm-01") -> 1995-10-01
A20: 11.95 | B20: 1625 | C20: -3.26 | D20: 33.67 | E20: 1172 | F20: -5.11 | G20: 39.93 | H20: 453 | I20: 1.88 | J20: 19.8 | K20: 1095 | L20: -10.64 | M20: 19.94 | Q20: =IF(ISNUMBER(SEARCH(".",A20)),DATE(IF(VALUE(RIGHT(A20,2))>=94,1900+VALUE(RIGHT(A20,2)),2000+VALUE(RIGHT(A20,2))),VALUE(LEFT(A20,2)),1),DATE(2000+VALUE(A20),10,1)) -> 35004 | R20: =TEXT(Q20,"yyyy-mm-01") -> 1995-11-01
A21: 12.95 | B21: 1653 | C21: 1.74 | D21: 36 | E21: 1129 | F21: -3.69 | G21: 34.77 | H21: 524 | I21: 15.79 | J21: 38.71 | K21: 1170 | L21: 6.79 | M21: 28.09 | Q21: =IF(ISNUMBER(SEARCH(".",A21)),DATE(IF(VALUE(RIGHT(A21,2))>=94,1900+VALUE(RIGHT(A21,2)),2000+VALUE(RIGHT(A21,2))),VALUE(LEFT(A21,2)),1),DATE(2000+VALUE(A21),10,1)) -> 35034 | R21: =TEXT(Q21,"yyyy-mm-01") -> 1995-12-01
A22: 01.96 | B22: 1804 | C22: 9.16 | D22: 9.16 | E22: 1257 | F22: 11.36 | G22: 11.36 | H22: 548 | I22: 4.43 | J22: 4.43 | K22: 1208 | L22: 3.24 | M22: 3.24 | Q22: =IF(ISNUMBER(SEARCH(".",A22)),DATE(IF(VALUE(RIGHT(A22,2))>=94,1900+VALUE(RIGHT(A22,2)),2000+VALUE(RIGHT(A22,2))),VALUE(LEFT(A22,2)),1),DATE(2000+VALUE(A22),10,1)) -> 35065 | R22: =TEXT(Q22,"yyyy-mm-01") -> 1996-01-01
A23: 02.96 | B23: 1853 | C23: 2.72 | D23: 12.13 | E23: 1298 | F23: 3.27 | G23: 15 | H23: 555 | I23: 1.45 | J23: 5.95 | K23: 1214 | L23: 0.55 | M23: 3.81 | Q23: =IF(ISNUMBER(SEARCH(".",A23)),DATE(IF(VALUE(RIGHT(A23,2))>=94,1900+VALUE(RIGHT(A23,2)),2000+VALUE(RIGHT(A23,2))),VALUE(LEFT(A23,2)),1),DATE(2000+VALUE(A23),10,1)) -> 35096 | R23: =TEXT(Q23,"yyyy-mm-01") -> 1996-02-01
A24: 03.96 | B24: 1800 | C24: -2.88 | D24: 8.9 | E24: 1229 | F24: -5.29 | G24: 8.92 | H24: 571 | I24: 2.75 | J24: 8.86 | K24: 1275 | L24: 4.98 | M24: 8.98 | Q24: =IF(ISNUMBER(SEARCH(".",A24)),DATE(IF(VALUE(RIGHT(A24,2))>=94,1900+VALUE(RIGHT(A24,2)),2000+VALUE(RIGHT(A24,2))),VALUE(LEFT(A24,2)),1),DATE(2000+VALUE(A24),10,1)) -> 35125 | R24: =TEXT(Q24,"yyyy-mm-01") -> 1996-03-01
A25: 04.96 | B25: 1811 | C25: 0.63 | D25: 9.59 | E25: 1238 | F25: 0.72 | G25: 9.7 | H25: 573 | I25: 0.43 | J25: 9.34 | K25: 1273 | L25: -0.13 | M25: 8.84 | Q25: =IF(ISNUMBER(SEARCH(".",A25)),DATE(IF(VALUE(RIGHT(A25,2))>=94,1900+VALUE(RIGHT(A25,2)),2000+VALUE(RIGHT(A25,2))),VALUE(LEFT(A25,2)),1),DATE(2000+VALUE(A25),10,1)) -> 35156 | R25: =TEXT(Q25,"yyyy-mm-01") -> 1996-04-01
A26: 05.96 | B26: 1911 | C26: 5.47 | D26: 15.58 | E26: 1326 | F26: 7.09 | G26: 17.48 | H26: 585 | I26: 1.96 | J26: 11.48 | K26: 1324 | L26: 3.96 | M26: 13.15 | Q26: =IF(ISNUMBER(SEARCH(".",A26)),DATE(IF(VALUE(RIGHT(A26,2))>=94,1900+VALUE(RIGHT(A26,2)),2000+VALUE(RIGHT(A26,2))),VALUE(LEFT(A26,2)),1),DATE(2000+VALUE(A26),10,1)) -> 35186 | R26: =TEXT(Q26,"yyyy-mm-01") -> 1996-05-01
A27: 06.96 | B27: 1833 | C27: -4.05 | D27: 10.89 | E27: 1248 | F27: -5.85 | G27: 10.61 | H27: 585 | I27: 0.02 | J27: 11.5 | K27: 1245 | L27: -5.98 | M27: 6.39 | Q27: =IF(ISNUMBER(SEARCH(".",A27)),DATE(IF(VALUE(RIGHT(A27,2))>=94,1900+VALUE(RIGHT(A27,2)),2000+VALUE(RIGHT(A27,2))),VALUE(LEFT(A27,2)),1),DATE(2000+VALUE(A27),10,1)) -> 35217 | R27: =TEXT(Q27,"yyyy-mm-01") -> 1996-06-01
A28: 07.96 | B28: 1794 | C28: -2.12 | D28: 8.55 | E28: 1194 | F28: -4.33 | G28: 5.82 | H28: 600 | I28: 2.61 | J28: 14.41 | K28: 1200 | L28: -3.59 | M28: 2.58 | Q28: =IF(ISNUMBER(SEARCH(".",A28)),DATE(IF(VALUE(RIGHT(A28,2))>=94,1900+VALUE(RIGHT(A28,2)),2000+VALUE(RIGHT(A28,2))),VALUE(LEFT(A28,2)),1),DATE(2000+VALUE(A28),10,1)) -> 35247 | R28: =TEXT(Q28,"yyyy-mm-01") -> 1996-07-01
A29: 08.96 | B29: 1788 | C29: -0.37 | D29: 8.14 | E29: 1174 | F29: -1.67 | G29: 4.05 | H29: 613 | I29: 2.23 | J29: 16.96 | K29: 1194 | L29: -0.48 | M29: 2.09 | Q29: =IF(ISNUMBER(SEARCH(".",A29)),DATE(IF(VALUE(RIGHT(A29,2))>=94,1900+VALUE(RIGHT(A29,2)),2000+VALUE(RIGHT(A29,2))),VALUE(LEFT(A29,2)),1),DATE(2000+VALUE(A29),10,1)) -> 35278 | R29: =TEXT(Q29,"yyyy-mm-01") -> 1996-08-01
A30: 09.96 | B30: 1774 | C30: -0.76 | D30: 7.32 | E30: 1166 | F30: -0.75 | G30: 3.27 | H30: 608 | I30: -0.78 | J30: 16.05 | K30: 1161 | L30: -2.76 | M30: -0.73 | Q30: =IF(ISNUMBER(SEARCH(".",A30)),DATE(IF(VALUE(RIGHT(A30,2))>=94,1900+VALUE(RIGHT(A30,2)),2000+VALUE(RIGHT(A30,2))),VALUE(LEFT(A30,2)),1),DATE(2000+VALUE(A30),10,1)) -> 35309 | R30: =TEXT(Q30,"yyyy-mm-01") -> 1996-09-01
A31: 10.96 | B31: 1685 | C31: -5.04 | D31: 1.92 | E31: 1068 | F31: -8.35 | G31: -5.35 | H31: 616 | I31: 1.31 | J31: 17.56 | K31: 1077 | L31: -7.29 | M31: -7.97 | Q31: =IF(ISNUMBER(SEARCH(".",A31)),DATE(IF(VALUE(RIGHT(A31,2))>=94,1900+VALUE(RIGHT(A31,2)),2000+VALUE(RIGHT(A31,2))),VALUE(LEFT(A31,2)),1),DATE(2000+VALUE(A31),10,1)) -> 35339 | R31: =TEXT(Q31,"yyyy-mm-01") -> 1996-10-01
A32: 11.96 | B32: 1699 | C32: 0.88 | D32: 2.81 | E32: 1085 | F32: 1.57 | G32: -3.86 | H32: 614 | I32: -0.33 | J32: 17.18 | K32: 1089 | L32: 1.15 | M32: -6.92 | Q32: =IF(ISNUMBER(SEARCH(".",A32)),DATE(IF(VALUE(RIGHT(A32,2))>=94,1900+VALUE(RIGHT(A32,2)),2000+VALUE(RIGHT(A32,2))),VALUE(LEFT(A32,2)),1),DATE(2000+VALUE(A32),10,1)) -> 35370 | R32: =TEXT(Q32,"yyyy-mm-01") -> 1996-11-01
A33: 12.96 | B33: 1961 | C33: 15.37 | D33: 18.61 | E33: 1294 | F33: 19.26 | G33: 14.65 | H33: 667 | I33: 8.49 | J33: 27.13 | K33: 1334 | L33: 22.55 | M33: 14.07 | Q33: =IF(ISNUMBER(SEARCH(".",A33)),DATE(IF(VALUE(RIGHT(A33,2))>=94,1900+VALUE(RIGHT(A33,2)),2000+VALUE(RIGHT(A33,2))),VALUE(LEFT(A33,2)),1),DATE(2000+VALUE(A33),10,1)) -> 35400 | R33: =TEXT(Q33,"yyyy-mm-01") -> 1996-12-01
A34: 01.97 | B34: 1767 | C34: -9.86 | D34: -9.86 | E34: 1145 | F34: -11.53 | G34: -11.53 | H34: 622 | I34: -6.61 | J34: -6.61 | K34: 1162 | L34: -12.94 | M34: -12.94 | Q34: =IF(ISNUMBER(SEARCH(".",A34)),DATE(IF(VALUE(RIGHT(A34,2))>=94,1900+VALUE(RIGHT(A34,2)),2000+VALUE(RIGHT(A34,2))),VALUE(LEFT(A34,2)),1),DATE(2000+VALUE(A34),10,1)) -> 35431 | R34: =TEXT(Q34,"yyyy-mm-01") -> 1997-01-01
A35: 02.97 | B35: 1814 | C35: 2.63 | D35: -7.49 | E35: 1163 | F35: 1.58 | G35: -10.13 | H35: 651 | I35: 4.56 | J35: -2.35 | K35: 1228 | L35: 5.66 | M35: -8.01 | Q35: =IF(ISNUMBER(SEARCH(".",A35)),DATE(IF(VALUE(RIGHT(A35,2))>=94,1900+VALUE(RIGHT(A35,2)),2000+VALUE(RIGHT(A35,2))),VALUE(LEFT(A35,2)),1),DATE(2000+VALUE(A35),10,1)) -> 35462 | R35: =TEXT(Q35,"yyyy-mm-01") -> 1997-02-01
A36: 03.97 | B36: 1842 | C36: 1.56 | D36: -6.04 | E36: 1211 | F36: 4.13 | G36: -6.41 | H36: 631 | I36: -3.05 | J36: -5.33 | K36: 1254 | L36: 2.12 | M36: -6.06 | Q36: =IF(ISNUMBER(SEARCH(".",A36)),DATE(IF(VALUE(RIGHT(A36,2))>=94,1900+VALUE(RIGHT(A36,2)),2000+VALUE(RIGHT(A36,2))),VALUE(LEFT(A36,2)),1),DATE(2000+VALUE(A36),10,1)) -> 35490 | R36: =TEXT(Q36,"yyyy-mm-01") -> 1997-03-01
A37: 04.97 | B37: 1768 | C37: -4 | D37: -9.81 | E37: 1154 | F37: -4.75 | G37: -10.86 | H37: 615 | I37: -2.57 | J37: -7.76 | K37: 1192 | L37: -4.94 | M37: -10.7 | Q37: =IF(ISNUMBER(SEARCH(".",A37)),DATE(IF(VALUE(RIGHT(A37,2))>=94,1900+VALUE(RIGHT(A37,2)),2000+VALUE(RIGHT(A37,2))),VALUE(LEFT(A37,2)),1),DATE(2000+VALUE(A37),10,1)) -> 35521 | R37: =TEXT(Q37,"yyyy-mm-01") -> 1997-04-01
A38: 05.97 | B38: 1865 | C38: 5.48 | D38: -4.86 | E38: 1241 | F38: 7.56 | G38: -4.12 | H38: 625 | I38: 1.58 | J38: -6.3 | K38: 1209 | L38: 1.44 | M38: -9.42 | Q38: =IF(ISNUMBER(SEARCH(".",A38)),DATE(IF(VALUE(RIGHT(A38,2))>=94,1900+VALUE(RIGHT(A38,2)),2000+VALUE(RIGHT(A38,2))),VALUE(LEFT(A38,2)),1),DATE(2000+VALUE(A38),10,1)) -> 35551 | R38: =TEXT(Q38,"yyyy-mm-01") -> 1997-05-01
A39: 06.97 | B39: 2000 | C39: 7.22 | D39: 2.01 | E39: 1397 | F39: 12.55 | G39: 7.92 | H39: 603 | I39: -3.37 | J39: -9.46 | K39: 1391 | L39: 15.08 | M39: 4.24 | Q39: =IF(ISNUMBER(SEARCH(".",A39)),DATE(IF(VALUE(RIGHT(A39,2))>=94,1900+VALUE(RIGHT(A39,2)),2000+VALUE(RIGHT(A39,2))),VALUE(LEFT(A39,2)),1),DATE(2000+VALUE(A39),10,1)) -> 35582 | R39: =TEXT(Q39,"yyyy-mm-01") -> 1997-06-01
A40: 07.97 | B40: 2038 | C40: 1.88 | D40: 3.92 | E40: 1448 | F40: 3.71 | G40: 11.92 | H40: 589 | I40: -2.37 | J40: -11.61 | K40: 1407 | L40: 1.14 | M40: 5.43 | Q40: =IF(ISNUMBER(SEARCH(".",A40)),DATE(IF(VALUE(RIGHT(A40,2))>=94,1900+VALUE(RIGHT(A40,2)),2000+VALUE(RIGHT(A40,2))),VALUE(LEFT(A40,2)),1),DATE(2000+VALUE(A40),10,1)) -> 35612 | R40: =TEXT(Q40,"yyyy-mm-01") -> 1997-07-01
A41: 08.97 | B41: 2094 | C41: 2.77 | D41: 6.81 | E41: 1506 | F41: 3.97 | G41: 16.37 | H41: 588 | I41: -0.17 | J41: -11.76 | K41: 1532 | L41: 8.88 | M41: 14.79 | Q41: =IF(ISNUMBER(SEARCH(".",A41)),DATE(IF(VALUE(RIGHT(A41,2))>=94,1900+VALUE(RIGHT(A41,2)),2000+VALUE(RIGHT(A41,2))),VALUE(LEFT(A41,2)),1),DATE(2000+VALUE(A41),10,1)) -> 35643 | R41: =TEXT(Q41,"yyyy-mm-01") -> 1997-08-01
...

Sheet Final Cleaned
A1: date | B1: kz_reserves_m
A2: =Worksheet!R5 -> 1994-08-01 | B2: =Worksheet!B5 -> 1099
A3: =Worksheet!R6 -> 1994-09-01 | B3: =Worksheet!B6 -> 1118
A4: =Worksheet!R7 -> 1994-10-01 | B4: =Worksheet!B7 -> 968
A5: =Worksheet!R8 -> 1994-11-01 | B5: =Worksheet!B8 -> 952
A6: =Worksheet!R9 -> 1994-12-01 | B6: =Worksheet!B9 -> 1215
A7: =Worksheet!R10 -> 1995-01-01 | B7: =Worksheet!B10 -> 1142
A8: =Worksheet!R11 -> 1995-02-01 | B8: =Worksheet!B11 -> 1159
A9: =Worksheet!R12 -> 1995-03-01 | B9: =Worksheet!B12 -> 1387
A10: =Worksheet!R13 -> 1995-04-01 | B10: =Worksheet!B13 -> 1429
A11: =Worksheet!R14 -> 1995-05-01 | B11: =Worksheet!B14 -> 1396
A12: =Worksheet!R15 -> 1995-06-01 | B12: =Worksheet!B15 -> 1589
A13: =Worksheet!R16 -> 1995-07-01 | B13: =Worksheet!B16 -> 1732
... A385: =Worksheet!R388 -> 2026-07-01 | B385: =Worksheet!B388 -> 63715
