Workbook

Sheet W3C Example Table
D1: Даты | E1: Январь 2011 г. | F1: Февраль 2011 г. | G1: Март 2011 г. | H1: Апрель 2011 г. | I1: Май 2011 г. | J1: Июнь 2011 г. | K1: Июль 2011 г. | L1: Август 2011 г. | M1: Сентябрь 2011 г. | N1: Октябрь 2011 г. | O1: Ноябрь 2011 г. | P1: Декабрь 2011 г. | Q1: Январь 2012 г. | R1: Февраль 2012 г. | S1: Март 2012 г. | T1: Апрель 2012 г. | U1: Май 2012 г. | V1: Июнь 2012 г. | W1: Июль 2012 г. | X1: Август 2012 г. | Y1: Сентябрь 2012 г. | Z1: Октябрь 2012 г. | AA1: Ноябрь 2012 г. | AB1: Декабрь 2012 г. | AC1: Январь 2013 г. | AD1: Февраль 2013 г. | AE1: Март 2013 г. | AF1: Апрель 2013 г. | AG1: Май 2013 г. | AH1: Июнь 2013 г. | AI1: Июль 2013 г. | AJ1: Август 2013 г. | AK1: Сентябрь 2013 г. | AL1: Октябрь 2013 г. | AM1: Ноябрь 2013 г. | AN1: Декабрь 2013 г. | AO1: Январь 2014 г. | AP1: Февраль 2014 г. | AQ1: Март 2014 г. | AR1: Апрель 2014 г. | AS1: Май 2014 г. | AT1: Июнь 2014 г. | AU1: Июль 2014 г. | AV1: Август 2014 г. | AW1: Сентябрь 2014 г. | AX1: Октябрь 2014 г. | AY1: Ноябрь 2014 г. | AZ1: Декабрь 2014 г. | BA1: Январь 2015 г. | BB1: Февраль 2015 г. | BC1: Март 2015 г. | BD1: Апрель 2015 г. | BE1: Май 2015 г. | BF1: Июнь 2015 г. | BG1: Июль 2015 г. | BH1: Август 2015 г. | BI1: Сентябрь 2015 г. | BJ1: Октябрь 2015 г. | BK1: Ноябрь 2015 г. | BL1: Декабрь 2015 г. | BM1: Январь 2016 г. | BN1: Февраль 2016 г. | BO1: Март 2016 г. | BP1: Апрель 2016 г. | BQ1: Май 2016 г. | BR1: Июнь 2016 г. | BS1: Июль 2016 г. | BT1: Август 2016 г. | BU1: Сентябрь 2016 г. | BV1: Октябрь 2016 г. | BW1: Ноябрь 2016 г. | BX1: Декабрь 2016 г. | BY1: Январь 2017 г. | BZ1: Февраль 2017 г. | CA1: Март 2017 г. | CB1: Апрель 2017 г. | CC1: Май 2017 г. | CD1: Июнь 2017 г. | CE1: Июль 2017 г. | CF1: Август 2017 г. | CG1: Сентябрь 2017 г. | CH1: Октябрь 2017 г. | CI1: Ноябрь 2017 г. | CJ1: Декабрь 2017 г. | CK1: Январь 2018 г. | CL1: Февраль 2018 г. | CM1: Март 2018 г. | CN1: Апрель 2018 г. | CO1: Май 2018 г. | CP1: Июнь 2018 г. | CQ1: Июль 2018 г. | CR1: Август 2018 г. | CS1: Сентябрь 2018 г. | CT1: Октябрь 2018 г. | CU1: Ноябрь 2018 г. | CV1: Декабрь 2018 г. | CW1: Январь 2019 г. | CX1: Февраль 2019 г. | CY1: Март 2019 г. | CZ1: Апрель 2019 г. | DA1: Май 2019 г. | DB1: Июнь 2019 г. | DC1: Июль 2019 г. | DD1: Август 2019 г. | DE1: Сентябрь 2019 г. | DF1: Октябрь 2019 г. | DG1: Ноябрь 2019 г. | DH1: Декабрь 2019 г. | DI1: Январь 2020 г. | DJ1: Февраль 2020 г. | DK1: Март 2020 г. | DL1: Апрель 2020 г. | DM1: Май 2020 г. | DN1: Июнь 2020 г. | DO1: Июль 2020 г. | DP1: Август 2020 г. | DQ1: Сентябрь 2020 г. | DR1: Октябрь 2020 г. | DS1: Ноябрь 2020 г. | DT1: Декабрь 2020 г. | DU1: Январь 2021 г. | DV1: Февраль 2021 г. | DW1: Март 2021 г. | DX1: Апрель 2021 г. | DY1: Май 2021 г. | DZ1: Июнь 2021 г. | EA1: Июль 2021 г. | EB1: Август 2021 г. | EC1: Сентябрь 2021 г. | ED1: Октябрь 2021 г. | EE1: Ноябрь 2021 г. | EF1: Декабрь 2021 г. | EG1: Январь 2022 г. | EH1: Февраль 2022 г. | EI1: Март 2022 г. | EJ1: Апрель 2022 г. | EK1: Май 2022 г. | EL1: Июнь 2022 г. | EM1: Июль 2022 г. | EN1: Август 2022 г. | EO1: Сентябрь 2022 г. | EP1: Октябрь 2022 г. | EQ1: Ноябрь 2022 г. | ER1: Декабрь 2022 г. | ES1: Январь 2023 г. | ET1: Февраль 2023 г. | EU1: Март 2023 г. | EV1: Апрель 2023 г. | EW1: Май 2023 г. | EX1: Июнь 2023 г. | EY1: Июль 2023 г. | EZ1: Август 2023 г. | FA1: Сентябрь 2023 г. | FB1: Октябрь 2023 г. | FC1: Ноябрь 2023 г. | FD1: Декабрь 2023 г. | FE1: Январь 2024 г. | FF1: Февраль 2024 г. | FG1: Март 2024 г. | FH1: Апрель 2024 г. | FI1: Май 2024 г. | FJ1: Июнь 2024 г. | FK1: Июль 2024 г. | FL1: Август 2024 г. | FM1: Сентябрь 2024 г. | FN1: Октябрь 2024 г. | FO1: Ноябрь 2024 г. | FP1: Декабрь 2024 г. | FQ1: Январь 2025 г. | FR1: Февраль 2025 г. | FS1: Март 2025 г. | FT1: Апрель 2025 г. | FU1: Май 2025 г. | FV1: Июнь 2025 г. | FW1: Июль 2025 г. | FX1: Август 2025 г. | FY1: Сентябрь 2025 г. | FZ1: Октябрь 2025 г. | GA1: Ноябрь 2025 г. | GB1: Декабрь 2025 г. | GC1: Январь 2026 г. | GD1: Февраль 2026 г. | GE1: Март 2026 г. | GF1: Апрель 2026 г. | GG1: Май 2026 г. | GH1: Июнь 2026 г. | GI1: Июль 2026 г.
D2: Показатели | E2: Consumer price index() | F2: Consumer price index() | G2: Consumer price index() | H2: Consumer price index() | I2: Consumer price index() | J2: Consumer price index() | K2: Consumer price index() | L2: Consumer price index() | M2: Consumer price index() | N2: Consumer price index() | O2: Consumer price index() | P2: Consumer price index() | Q2: Consumer price index() | R2: Consumer price index() | S2: Consumer price index() | T2: Consumer price index() | U2: Consumer price index() | V2: Consumer price index() | W2: Consumer price index() | X2: Consumer price index() | Y2: Consumer price index() | Z2: Consumer price index() | AA2: Consumer price index() | AB2: Consumer price index() | AC2: Consumer price index() | AD2: Consumer price index() | AE2: Consumer price index() | AF2: Consumer price index() | AG2: Consumer price index() | AH2: Consumer price index() | AI2: Consumer price index() | AJ2: Consumer price index() | AK2: Consumer price index() | AL2: Consumer price index() | AM2: Consumer price index() | AN2: Consumer price index() | AO2: Consumer price index() | AP2: Consumer price index() | AQ2: Consumer price index() | AR2: Consumer price index() | AS2: Consumer price index() | AT2: Consumer price index() | AU2: Consumer price index() | AV2: Consumer price index() | AW2: Consumer price index() | AX2: Consumer price index() | AY2: Consumer price index() | AZ2: Consumer price index() | BA2: Consumer price index() | BB2: Consumer price index() | BC2: Consumer price index() | BD2: Consumer price index() | BE2: Consumer price index() | BF2: Consumer price index() | BG2: Consumer price index() | BH2: Consumer price index() | BI2: Consumer price index() | BJ2: Consumer price index() | BK2: Consumer price index() | BL2: Consumer price index() | BM2: Consumer price index() | BN2: Consumer price index() | BO2: Consumer price index() | BP2: Consumer price index() | BQ2: Consumer price index() | BR2: Consumer price index() | BS2: Consumer price index() | BT2: Consumer price index() | BU2: Consumer price index() | BV2: Consumer price index() | BW2: Consumer price index() | BX2: Consumer price index() | BY2: Consumer price index() | BZ2: Consumer price index() | CA2: Consumer price index() | CB2: Consumer price index() | CC2: Consumer price index() | CD2: Consumer price index() | CE2: Consumer price index() | CF2: Consumer price index() | CG2: Consumer price index() | CH2: Consumer price index() | CI2: Consumer price index() | CJ2: Consumer price index() | CK2: Consumer price index() | CL2: Consumer price index() | CM2: Consumer price index() | CN2: Consumer price index() | CO2: Consumer price index() | CP2: Consumer price index() | CQ2: Consumer price index() | CR2: Consumer price index() | CS2: Consumer price index() | CT2: Consumer price index() | CU2: Consumer price index() | CV2: Consumer price index() | CW2: Consumer price index() | CX2: Consumer price index() | CY2: Consumer price index() | CZ2: Consumer price index() | DA2: Consumer price index() | DB2: Consumer price index() | DC2: Consumer price index() | DD2: Consumer price index() | DE2: Consumer price index() | DF2: Consumer price index() | DG2: Consumer price index() | DH2: Consumer price index() | DI2: Consumer price index() | DJ2: Consumer price index() | DK2: Consumer price index() | DL2: Consumer price index() | DM2: Consumer price index() | DN2: Consumer price index() | DO2: Consumer price index() | DP2: Consumer price index() | DQ2: Consumer price index() | DR2: Consumer price index() | DS2: Consumer price index() | DT2: Consumer price index() | DU2: Consumer price index() | DV2: Consumer price index() | DW2: Consumer price index() | DX2: Consumer price index() | DY2: Consumer price index() | DZ2: Consumer price index() | EA2: Consumer price index() | EB2: Consumer price index() | EC2: Consumer price index() | ED2: Consumer price index() | EE2: Consumer price index() | EF2: Consumer price index() | EG2: Consumer price index() | EH2: Consumer price index() | EI2: Consumer price index() | EJ2: Consumer price index() | EK2: Consumer price index() | EL2: Consumer price index() | EM2: Consumer price index() | EN2: Consumer price index() | EO2: Consumer price index() | EP2: Consumer price index() | EQ2: Consumer price index() | ER2: Consumer price index() | ES2: Consumer price index() | ET2: Consumer price index() | EU2: Consumer price index() | EV2: Consumer price index() | EW2: Consumer price index() | EX2: Consumer price index() | EY2: Consumer price index() | EZ2: Consumer price index() | FA2: Consumer price index() | FB2: Consumer price index() | FC2: Consumer price index() | FD2: Consumer price index() | FE2: Consumer price index() | FF2: Consumer price index() | FG2: Consumer price index() | FH2: Consumer price index() | FI2: Consumer price index() | FJ2: Consumer price index() | FK2: Consumer price index() | FL2: Consumer price index() | FM2: Consumer price index() | FN2: Consumer price index() | FO2: Consumer price index() | FP2: Consumer price index() | FQ2: Consumer price index() | FR2: Consumer price index() | FS2: Consumer price index() | FT2: Consumer price index() | FU2: Consumer price index() | FV2: Consumer price index() | FW2: Consumer price index() | FX2: Consumer price index() | FY2: Consumer price index() | FZ2: Consumer price index() | GA2: Consumer price index() | GB2: Consumer price index() | GC2: Consumer price index() | GD2: Consumer price index() | GE2: Consumer price index() | GF2: Consumer price index() | GG2: Consumer price index() | GH2: Consumer price index() | GI2: Consumer price index()
A3: ӘАОЖ(каталог бойынша) | B3: КАА | C3: ТМТЖТН01
A4: AKTOBE REGION | B4: reporting period to the previous period | C4: Goods and services | E4: 101.6 | F4: 101.3 | G4: 100.2 | H4: 100.5 | I4: 100.6 | J4: 100.3 | K4: 100.9 | L4: 100.1 | M4: 100.3 | N4: 100.2 | O4: 100.4 | P4: 100.3 | Q4: 100.2 | R4: 100.3 | S4: 100.3 | T4: 100.7 | U4: 100.6 | V4: 100.2 | W4: 100.2 | X4: 100.8 | Y4: 100.2 | Z4: 100.6 | AA4: 100.8 | AB4: 100.6 | AC4: 103.4 | AD4: 99.8 | AE4: 99.4 | AF4: 100.2 | AG4: 100.1 | AH4: 100.1 | AI4: 100.1 | AJ4: 100.3 | AK4: 100.2 | AL4: 100.3 | AM4: 100.2 | AN4: 100.4 | AO4: 100.3 | AP4: 101.4 | AQ4: 100.8 | AR4: 100.5 | AS4: 100.7 | AT4: 100.4 | AU4: 100.3 | AV4: 100.4 | AW4: 100.4 | AX4: 100.4 | AY4: 100.5 | AZ4: 100.5 | BA4: 100.4 | BB4: 100.4 | BC4: 100 | BD4: 99.9 | BE4: 100.3 | BF4: 100.1 | BG4: 100 | BH4: 100.4 | BI4: 100.8 | BJ4: 104.8 | BK4: 103.8 | BL4: 100.9 | BM4: 100.9 | BN4: 102.8 | BO4: 100.6 | BP4: 100.7 | BQ4: 100.3 | BR4: 100.3 | BS4: 100.4 | BT4: 100.2 | BU4: 99.7 | BV4: 100.3 | BW4: 101 | BX4: 100.9 | BY4: 100.9 | BZ4: 101.5 | CA4: 100.3 | CB4: 100.3 | CC4: 100.4 | CD4: 100.3 | CE4: 100.2 | CF4: 99.5 | CG4: 100.3 | CH4: 100.9 | CI4: 100.6 | CJ4: 101 | CK4: 100.4 | CL4: 101 | CM4: 100.3 | CN4: 100.4 | CO4: 100.2 | CP4: 100.2 | CQ4: 100 | CR4: 100.3 | CS4: 100.1 | CT4: 100.5 | CU4: 101.6 | CV4: 100.1 | CW4: 100.7 | CX4: 100 | CY4: 100.6 | CZ4: 100.5 | DA4: 100.3 | DB4: 100 | DC4: 100.3 | DD4: 100.1 | DE4: 100.2 | DF4: 100.8 | DG4: 101 | DH4: 100.4 | DI4: 100.9 | DJ4: 100.5 | DK4: 100.7 | DL4: 99.9 | DM4: 100.6 | DN4: 100.6 | DO4: 100.6 | DP4: 100.3 | DQ4: 100.4 | DR4: 100.7 | DS4: 101.2 | DT4: 100.9 | DU4: 100.5 | DV4: 100.8 | DW4: 100.5 | DX4: 100.8 | DY4: 100.7 | DZ4: 101.1 | EA4: 100.8 | EB4: 100.6 | EC4: 100.5 | ED4: 100.6 | EE4: 100.9 | EF4: 100.8 | EG4: 100.9 | EH4: 100.6 | EI4: 104.1 | EJ4: 101.3 | EK4: 101.1 | EL4: 101.6 | EM4: 101.5 | EN4: 101.2 | EO4: 101.5 | EP4: 101.6 | EQ4: 101.6 | ER4: 101.2 | ES4: 101.7 | ET4: 101.3 | EU4: 100.8 | EV4: 100.7 | EW4: 100.4 | EX4: 100.1 | EY4: 100.4 | EZ4: 100.5 | FA4: 100.7 | FB4: 100.6 | FC4: 101.5 | FD4: 100.3 | FE4: 101 | FF4: 101.2 | FG4: 101.1 | FH4: 100.5 | FI4: 100 | FJ4: 100.1 | FK4: 100.8 | FL4: 100.5 | FM4: 100.8 | FN4: 100.5 | FO4: 101.2 | FP4: 100.7 | FQ4: 101.5 | FR4: 101.9 | FS4: 100.6 | FT4: 101.1 | FU4: 100.8 | FV4: 100.8 | FW4: 100.7 | FX4: 101.3 | FY4: 101.7 | FZ4: 100.5 | GA4: 100.6 | GB4: 100.5 | GC4: 101 | GD4: 100.8 | GE4: 100.9 | GF4: 100.4 | GG4: 100.4 | GH4: 101.4 | GI4: 100.3
A5: AKMOLA REGION | B5: reporting period to the previous period | C5: Goods and services | E5: 101.4 | F5: 101.6 | G5: 100.4 | H5: 100 | I5: 100.7 | J5: 100.5 | K5: 100.9 | L5: 100.4 | M5: 100 | N5: 100.3 | O5: 100.3 | P5: 100.5 | Q5: 100.2 | R5: 100.6 | S5: 100.3 | T5: 100.6 | U5: 100.5 | V5: 100.5 | W5: 100 | X5: 100.3 | Y5: 100.5 | Z5: 100.3 | AA5: 100.6 | AB5: 101.5 | AC5: 100.9 | AD5: 100.5 | AE5: 100.3 | AF5: 100.1 | AG5: 100.3 | AH5: 100.4 | AI5: 100.1 | AJ5: 100 | AK5: 100.2 | AL5: 100.2 | AM5: 100.5 | AN5: 101.1 | AO5: 100.4 | AP5: 101.6 | AQ5: 101.4 | AR5: 100.7 | AS5: 100.3 | AT5: 100.3 | AU5: 100.2 | AV5: 100.9 | AW5: 100.3 | AX5: 100.2 | AY5: 100.5 | AZ5: 100.5 | BA5: 100.3 | BB5: 100.4 | BC5: 100.4 | BD5: 100.1 | BE5: 100.3 | BF5: 99.9 | BG5: 100 | BH5: 100.1 | BI5: 100.7 | BJ5: 106.6 | BK5: 102.1 | BL5: 101.5 | BM5: 100.9 | BN5: 101.1 | BO5: 100.7 | BP5: 100.3 | BQ5: 100.3 | BR5: 100.3 | BS5: 100.2 | BT5: 100.4 | BU5: 100.3 | BV5: 100.7 | BW5: 101.4 | BX5: 101.3 | BY5: 100.3 | BZ5: 100.8 | CA5: 100.5 | CB5: 100.4 | CC5: 100.3 | CD5: 100.7 | CE5: 100.3 | CF5: 100.7 | CG5: 100.1 | CH5: 101 | CI5: 101.1 | CJ5: 100.7 | CK5: 100.3 | CL5: 100.5 | CM5: 100.6 | CN5: 100.5 | CO5: 100.4 | CP5: 100.3 | CQ5: 100 | CR5: 100 | CS5: 100.1 | CT5: 100.4 | CU5: 100.9 | CV5: 100.7 | CW5: 100 | CX5: 100.6 | CY5: 100.4 | CZ5: 100.5 | DA5: 100.5 | DB5: 100.3 | DC5: 100.2 | DD5: 100.2 | DE5: 100.1 | DF5: 100.6 | DG5: 100.7 | DH5: 101 | DI5: 100.4 | DJ5: 100.7 | DK5: 100.7 | DL5: 101 | DM5: 100.3 | DN5: 100.6 | DO5: 100.3 | DP5: 100.2 | DQ5: 100.3 | DR5: 100.6 | DS5: 101.1 | DT5: 101 | DU5: 100.4 | DV5: 100.7 | DW5: 100.7 | DX5: 100.8 | DY5: 100.7 | DZ5: 101 | EA5: 100.9 | EB5: 100.2 | EC5: 100.4 | ED5: 100.7 | EE5: 101.1 | EF5: 100.9 | EG5: 100.8 | EH5: 100.7 | EI5: 103.8 | EJ5: 102 | EK5: 100.8 | EL5: 102.2 | EM5: 101.5 | EN5: 101.8 | EO5: 101.5 | EP5: 101.3 | EQ5: 102 | ER5: 101 | ES5: 101.4 | ET5: 101.2 | EU5: 100.7 | EV5: 100.9 | EW5: 100.9 | EX5: 100.6 | EY5: 100.5 | EZ5: 101.2 | FA5: 100.7 | FB5: 100.9 | FC5: 100.6 | FD5: 100.5 | FE5: 100.6 | FF5: 100.8 | FG5: 100.4 | FH5: 100.9 | FI5: 100.6 | FJ5: 101 | FK5: 100.6 | FL5: 100.3 | FM5: 100.9 | FN5: 100.9 | FO5: 101 | FP5: 100.9 | FQ5: 100.9 | FR5: 101.9 | FS5: 101.6 | FT5: 100.7 | FU5: 100.6 | FV5: 101.3 | FW5: 100.8 | FX5: 100.8 | FY5: 101.2 | FZ5: 100.8 | GA5: 101.5 | GB5: 100.8 | GC5: 100.8 | GD5: 101.6 | GE5: 100.8 | GF5: 101.1 | GG5: 100.5 | GH5: 100.8 | GI5: 100.9
A6: REPUBLIC OF KAZAKHSTAN | B6: reporting period to the previous period | C6: Goods and services | E6: 101.7 | F6: 101.5 | G6: 100.5 | H6: 100.5 | I6: 100.5 | J6: 100.3 | K6: 100.5 | L6: 100.3 | M6: 100.3 | N6: 100.2 | O6: 100.6 | P6: 100.3 | Q6: 100.3 | R6: 100.4 | S6: 100.3 | T6: 100.7 | U6: 100.7 | V6: 100.3 | W6: 100.3 | X6: 100.3 | Y6: 100.6 | Z6: 100.7 | AA6: 100.7 | AB6: 100.6 | AC6: 100.9 | AD6: 100.8 | AE6: 100.2 | AF6: 100.3 | AG6: 100.2 | AH6: 100.3 | AI6: 100.2 | AJ6: 100.2 | AK6: 100.2 | AL6: 100.3 | AM6: 100.5 | AN6: 100.7 | AO6: 100.6 | AP6: 101.7 | AQ6: 101 | AR6: 100.6 | AS6: 100.6 | AT6: 100.3 | AU6: 100.1 | AV6: 100.4 | AW6: 100.5 | AX6: 100.4 | AY6: 100.6 | AZ6: 100.5 | BA6: 100.6 | BB6: 100.4 | BC6: 100.1 | BD6: 100.1 | BE6: 100.3 | BF6: 99.9 | BG6: 100.1 | BH6: 100.3 | BI6: 101 | BJ6: 105.2 | BK6: 103.7 | BL6: 101.2 | BM6: 101.3 | BN6: 101.1 | BO6: 100.5 | BP6: 100.6 | BQ6: 100.5 | BR6: 100.4 | BS6: 100.5 | BT6: 100.2 | BU6: 100.2 | BV6: 100.6 | BW6: 101.2 | BX6: 100.9 | BY6: 100.8 | BZ6: 101 | CA6: 100.5 | CB6: 100.5 | CC6: 100.5 | CD6: 100.4 | CE6: 100.1 | CF6: 100.1 | CG6: 100.3 | CH6: 101.2 | CI6: 100.9 | CJ6: 100.7 | CK6: 100.6 | CL6: 100.7 | CM6: 100.5 | CN6: 100.4 | CO6: 100.2 | CP6: 100.2 | CQ6: 100.1 | CR6: 100.2 | CS6: 100.4 | CT6: 100.4 | CU6: 100.9 | CV6: 100.7 | CW6: 100.5 | CX6: 100.3 | CY6: 100.5 | CZ6: 100.5 | DA6: 100.6 | DB6: 100.2 | DC6: 100.2 | DD6: 100.2 | DE6: 100.3 | DF6: 100.6 | DG6: 100.7 | DH6: 100.7 | DI6: 100.7 | DJ6: 100.6 | DK6: 100.9 | DL6: 100.9 | DM6: 100.5 | DN6: 100.4 | DO6: 100.3 | DP6: 100.1 | DQ6: 100.3 | DR6: 100.6 | DS6: 100.9 | DT6: 100.9 | DU6: 100.6 | DV6: 100.7 | DW6: 100.6 | DX6: 100.9 | DY6: 100.7 | DZ6: 101.1 | EA6: 100.7 | EB6: 100.5 | EC6: 100.4 | ED6: 100.7 | EE6: 100.7 | EF6: 100.6 | EG6: 100.7 | EH6: 100.8 | EI6: 103.7 | EJ6: 102 | EK6: 101.4 | EL6: 101.6 | EM6: 101.1 | EN6: 101.4 | EO6: 101.8 | EP6: 101.6 | EQ6: 101.4 | ER6: 101.2 | ES6: 101.1 | ET6: 101.3 | EU6: 100.9 | EV6: 100.9 | EW6: 100.6 | EX6: 100.5 | EY6: 100.6 | EZ6: 100.7 | FA6: 100.6 | FB6: 100.7 | FC6: 101 | FD6: 100.8 | FE6: 100.8 | FF6: 101.1 | FG6: 100.7 | FH6: 100.6 | FI6: 100.4 | FJ6: 100.4 | FK6: 100.7 | FL6: 100.6 | FM6: 100.4 | FN6: 100.9 | FO6: 100.9 | FP6: 100.9 | FQ6: 101.1 | FR6: 101.5 | FS6: 101.3 | FT6: 101.2 | FU6: 100.9 | FV6: 100.8 | FW6: 100.7 | FX6: 101 | FY6: 101.1 | FZ6: 100.5 | GA6: 100.8 | GB6: 100.9 | GC6: 101 | GD6: 101.1 | GE6: 100.6 | GF6: 100.8 | GG6: 100.7 | GH6: 100.8 | GI6: 100.6
A7: SOLTUSTIK KAZAKHSTAN REGION | B7: reporting period to the previous period | C7: Goods and services | E7: 101.7 | F7: 101.4 | G7: 100.7 | H7: 100.3 | I7: 100.5 | J7: 100.6 | K7: 101.7 | L7: 100.3 | M7: 100.2 | N7: 100.1 | O7: 100.4 | P7: 100 | Q7: 99.7 | R7: 100.3 | S7: 100.3 | T7: 101 | U7: 100.7 | V7: 100.4 | W7: 100 | X7: 100.3 | Y7: 100.5 | Z7: 101.1 | AA7: 100.4 | AB7: 101.1 | AC7: 100.7 | AD7: 100.7 | AE7: 100 | AF7: 100.3 | AG7: 100.3 | AH7: 100.1 | AI7: 100.1 | AJ7: 100.1 | AK7: 100.3 | AL7: 100.1 | AM7: 100.9 | AN7: 101.6 | AO7: 100.7 | AP7: 101.6 | AQ7: 101 | AR7: 100.4 | AS7: 100.7 | AT7: 100.2 | AU7: 100.3 | AV7: 100.1 | AW7: 100.1 | AX7: 100.5 | AY7: 100.5 | AZ7: 100.9 | BA7: 100.4 | BB7: 100.2 | BC7: 100.2 | BD7: 100.1 | BE7: 100.6 | BF7: 99.9 | BG7: 100.1 | BH7: 100 | BI7: 100.7 | BJ7: 105.5 | BK7: 103.2 | BL7: 100.8 | BM7: 100.9 | BN7: 101.3 | BO7: 100.4 | BP7: 100.4 | BQ7: 100.4 | BR7: 100.6 | BS7: 100.7 | BT7: 100.2 | BU7: 100.1 | BV7: 100.6 | BW7: 101.2 | BX7: 101.3 | BY7: 100.6 | BZ7: 101.8 | CA7: 100.4 | CB7: 100.8 | CC7: 100.6 | CD7: 100.5 | CE7: 100.3 | CF7: 99.9 | CG7: 100 | CH7: 100.8 | CI7: 100.8 | CJ7: 100.5 | CK7: 100.4 | CL7: 101.7 | CM7: 100.4 | CN7: 100.2 | CO7: 100.1 | CP7: 100.3 | CQ7: 100 | CR7: 100.1 | CS7: 100 | CT7: 100.5 | CU7: 100.8 | CV7: 101 | CW7: 100.4 | CX7: 100.5 | CY7: 100.6 | CZ7: 100.4 | DA7: 100.5 | DB7: 100.2 | DC7: 100.4 | DD7: 100.3 | DE7: 100.2 | DF7: 100.5 | DG7: 100.7 | DH7: 100.8 | DI7: 100.5 | DJ7: 100.6 | DK7: 100.8 | DL7: 100.9 | DM7: 100.6 | DN7: 100.6 | DO7: 100.4 | DP7: 100.2 | DQ7: 100.1 | DR7: 100.6 | DS7: 100.8 | DT7: 100.9 | DU7: 100.6 | DV7: 100.5 | DW7: 100.8 | DX7: 100.7 | DY7: 100.6 | DZ7: 101.4 | EA7: 100.5 | EB7: 100.3 | EC7: 100.3 | ED7: 100.9 | EE7: 100.9 | EF7: 100.6 | EG7: 100.6 | EH7: 100.7 | EI7: 103.7 | EJ7: 101.6 | EK7: 101.2 | EL7: 102.2 | EM7: 101 | EN7: 101.6 | EO7: 101.7 | EP7: 101.4 | EQ7: 101.8 | ER7: 101.4 | ES7: 101.5 | ET7: 101 | EU7: 101 | EV7: 100.8 | EW7: 100.8 | EX7: 100.9 | EY7: 100.6 | EZ7: 100.3 | FA7: 100.6 | FB7: 100.9 | FC7: 100.8 | FD7: 100.9 | FE7: 100.6 | FF7: 101 | FG7: 101.2 | FH7: 100.6 | FI7: 100.5 | FJ7: 100.7 | FK7: 100.6 | FL7: 100.5 | FM7: 100.3 | FN7: 101.1 | FO7: 101.1 | FP7: 100.8 | FQ7: 100.8 | FR7: 101.6 | FS7: 101 | FT7: 101.1 | FU7: 100.9 | FV7: 101.2 | FW7: 100.9 | FX7: 101.1 | FY7: 101.1 | FZ7: 100.9 | GA7: 101.2 | GB7: 101.5 | GC7: 101 | GD7: 101.3 | GE7: 100.6 | GF7: 101.1 | GG7: 100.8 | GH7: 101.1 | GI7: 100.5
A8: ZHAMBYL REGION | B8: reporting period to the previous period | C8: Goods and services | E8: 101.8 | F8: 101.2 | G8: 100.9 | H8: 100.1 | I8: 100.4 | J8: 100.4 | K8: 100.4 | L8: 101.2 | M8: 101.4 | N8: 100.1 | O8: 100.3 | P8: 100.2 | Q8: 100.5 | R8: 100.2 | S8: 100.5 | T8: 100.7 | U8: 100.5 | V8: 100.4 | W8: 100 | X8: 100.2 | Y8: 100.8 | Z8: 100.3 | AA8: 100.5 | AB8: 101.3 | AC8: 101.5 | AD8: 100.6 | AE8: 100.1 | AF8: 100.3 | AG8: 100.2 | AH8: 100.2 | AI8: 100.1 | AJ8: 100.2 | AK8: 100.2 | AL8: 100.1 | AM8: 100.4 | AN8: 100.6 | AO8: 100.7 | AP8: 103.4 | AQ8: 100.2 | AR8: 100.2 | AS8: 100.5 | AT8: 100.3 | AU8: 100.6 | AV8: 100.2 | AW8: 100.1 | AX8: 100.2 | AY8: 100.4 | AZ8: 100.5 | BA8: 101 | BB8: 100.8 | BC8: 100 | BD8: 99.7 | BE8: 100.4 | BF8: 100.1 | BG8: 99.9 | BH8: 100.4 | BI8: 100.7 | BJ8: 106.1 | BK8: 103 | BL8: 100.2 | BM8: 100.8 | BN8: 101.4 | BO8: 100.7 | BP8: 100.9 | BQ8: 100.7 | BR8: 100.1 | BS8: 100.3 | BT8: 100.3 | BU8: 100.4 | BV8: 100.5 | BW8: 101.1 | BX8: 101 | BY8: 101.2 | BZ8: 100.5 | CA8: 100.4 | CB8: 100.4 | CC8: 100.7 | CD8: 100.4 | CE8: 100.5 | CF8: 99.8 | CG8: 100.2 | CH8: 101.1 | CI8: 100.8 | CJ8: 100.9 | CK8: 100.5 | CL8: 100.5 | CM8: 100.6 | CN8: 100.4 | CO8: 100.2 | CP8: 100.1 | CQ8: 100 | CR8: 100.2 | CS8: 100.5 | CT8: 100.5 | CU8: 100.7 | CV8: 100.9 | CW8: 100.8 | CX8: 100 | CY8: 100.6 | CZ8: 100.4 | DA8: 100.4 | DB8: 100 | DC8: 100.3 | DD8: 100.4 | DE8: 100.3 | DF8: 100.4 | DG8: 100.8 | DH8: 100.7 | DI8: 100.8 | DJ8: 100.5 | DK8: 100.7 | DL8: 100.9 | DM8: 100.6 | DN8: 100.5 | DO8: 100.1 | DP8: 100.2 | DQ8: 100.3 | DR8: 100.4 | DS8: 100.8 | DT8: 101 | DU8: 100.7 | DV8: 100.5 | DW8: 100.7 | DX8: 100.8 | DY8: 101 | DZ8: 100.8 | EA8: 100.8 | EB8: 100.5 | EC8: 100.6 | ED8: 100.4 | EE8: 100.7 | EF8: 100.4 | EG8: 100.6 | EH8: 100.6 | EI8: 104.2 | EJ8: 102 | EK8: 101 | EL8: 101.3 | EM8: 101 | EN8: 101.3 | EO8: 101.4 | EP8: 101.3 | EQ8: 101.7 | ER8: 101.9 | ES8: 100.9 | ET8: 101.2 | EU8: 101 | EV8: 100.7 | EW8: 100.9 | EX8: 100.3 | EY8: 100.3 | EZ8: 100.9 | FA8: 100.6 | FB8: 100.4 | FC8: 101.1 | FD8: 100.6 | FE8: 100.8 | FF8: 101 | FG8: 100.6 | FH8: 100.4 | FI8: 100 | FJ8: 100.4 | FK8: 100.9 | FL8: 100.4 | FM8: 100 | FN8: 100.6 | FO8: 100.5 | FP8: 101.3 | FQ8: 101.3 | FR8: 101 | FS8: 101.2 | FT8: 100.9 | FU8: 100.9 | FV8: 100.9 | FW8: 100.7 | FX8: 100.6 | FY8: 101.1 | FZ8: 100.6 | GA8: 100.7 | GB8: 101.3 | GC8: 101 | GD8: 101.2 | GE8: 100.6 | GF8: 100.8 | GG8: 100.5 | GH8: 100.6 | GI8: 100.2
A9: PAVLODAR REGION | B9: reporting period to the previous period | C9: Goods and services | E9: 102 | F9: 101.1 | G9: 100.6 | H9: 100.5 | I9: 100.4 | J9: 100.4 | K9: 100.5 | L9: 100.2 | M9: 100.3 | N9: 100.6 | O9: 100.1 | P9: 100.6 | Q9: 100.7 | R9: 100.4 | S9: 100.4 | T9: 101.1 | U9: 100.6 | V9: 100.1 | W9: 100.2 | X9: 100.4 | Y9: 100.3 | Z9: 100.6 | AA9: 100.6 | AB9: 100.6 | AC9: 101 | AD9: 101 | AE9: 100.1 | AF9: 100.5 | AG9: 100.2 | AH9: 100.2 | AI9: 100.1 | AJ9: 100.2 | AK9: 100.1 | AL9: 100.1 | AM9: 100.4 | AN9: 101 | AO9: 100.5 | AP9: 102.5 | AQ9: 100.4 | AR9: 100.7 | AS9: 101.1 | AT9: 100.3 | AU9: 100.4 | AV9: 100.2 | AW9: 100 | AX9: 100.1 | AY9: 100.4 | AZ9: 100.6 | BA9: 100.6 | BB9: 100.1 | BC9: 100.2 | BD9: 99.9 | BE9: 100.3 | BF9: 100.2 | BG9: 99.8 | BH9: 100.9 | BI9: 100.5 | BJ9: 105 | BK9: 103.5 | BL9: 100.8 | BM9: 101.3 | BN9: 101.4 | BO9: 100.5 | BP9: 100.5 | BQ9: 100.5 | BR9: 100.4 | BS9: 100.8 | BT9: 100.9 | BU9: 99.2 | BV9: 100.5 | BW9: 101.1 | BX9: 101.1 | BY9: 100.8 | BZ9: 101.8 | CA9: 100.5 | CB9: 100.4 | CC9: 101.5 | CD9: 99.8 | CE9: 100.2 | CF9: 99.7 | CG9: 100 | CH9: 101.3 | CI9: 101 | CJ9: 100.4 | CK9: 100.8 | CL9: 101 | CM9: 100.5 | CN9: 100.3 | CO9: 100.4 | CP9: 99.8 | CQ9: 100.2 | CR9: 100.1 | CS9: 100.3 | CT9: 100.3 | CU9: 101.5 | CV9: 100.2 | CW9: 100.6 | CX9: 100.4 | CY9: 100.5 | CZ9: 100.4 | DA9: 100.3 | DB9: 100 | DC9: 100.6 | DD9: 100 | DE9: 100.3 | DF9: 100.7 | DG9: 100.8 | DH9: 100.8 | DI9: 100.6 | DJ9: 100.8 | DK9: 101.5 | DL9: 100.6 | DM9: 100.3 | DN9: 100.2 | DO9: 100.1 | DP9: 100.2 | DQ9: 100.4 | DR9: 101.1 | DS9: 100.9 | DT9: 101 | DU9: 100.4 | DV9: 100.6 | DW9: 100.6 | DX9: 100.9 | DY9: 100.6 | DZ9: 101.2 | EA9: 100.9 | EB9: 100.2 | EC9: 100.1 | ED9: 100.9 | EE9: 101 | EF9: 100.4 | EG9: 100.6 | EH9: 100.6 | EI9: 103.3 | EJ9: 101.9 | EK9: 101.5 | EL9: 101.4 | EM9: 101.7 | EN9: 101.2 | EO9: 101.3 | EP9: 101.7 | EQ9: 101.8 | ER9: 101.3 | ES9: 101.1 | ET9: 101.5 | EU9: 100.8 | EV9: 101.2 | EW9: 100.1 | EX9: 100.4 | EY9: 100.3 | EZ9: 100.2 | FA9: 100.5 | FB9: 101 | FC9: 101.6 | FD9: 100.3 | FE9: 100.7 | FF9: 101.1 | FG9: 102.1 | FH9: 100.3 | FI9: 100.2 | FJ9: 100.5 | FK9: 100.7 | FL9: 100.2 | FM9: 100.1 | FN9: 100.4 | FO9: 101 | FP9: 100.3 | FQ9: 101 | FR9: 100.9 | FS9: 101.2 | FT9: 101 | FU9: 102 | FV9: 100.8 | FW9: 100.7 | FX9: 101.2 | FY9: 101.4 | FZ9: 100.3 | GA9: 101.4 | GB9: 100.8 | GC9: 101.1 | GD9: 100.6 | GE9: 100.2 | GF9: 100.9 | GG9: 100.7 | GH9: 100.7 | GI9: 100.4
A10: BATYS-KAZAKHSTAN REGION | B10: reporting period to the previous period | C10: Goods and services | E10: 101.4 | F10: 101.3 | G10: 100.4 | H10: 100.3 | I10: 100.4 | J10: 100.8 | K10: 100.5 | L10: 100.4 | M10: 100.4 | N10: 100.1 | O10: 100.4 | P10: 100.4 | Q10: 100.3 | R10: 100.3 | S10: 100.3 | T10: 100.3 | U10: 100.6 | V10: 100.1 | W10: 100.1 | X10: 100.2 | Y10: 100.4 | Z10: 100.5 | AA10: 100.4 | AB10: 100.6 | AC10: 101.9 | AD10: 100.8 | AE10: 101.3 | AF10: 100.5 | AG10: 100.1 | AH10: 100.4 | AI10: 100.2 | AJ10: 100.4 | AK10: 99.9 | AL10: 100.3 | AM10: 100.2 | AN10: 100.3 | AO10: 100.4 | AP10: 101.2 | AQ10: 100.7 | AR10: 100.6 | AS10: 100.5 | AT10: 100.4 | AU10: 100.4 | AV10: 100.4 | AW10: 100.2 | AX10: 100.3 | AY10: 100.8 | AZ10: 100.6 | BA10: 100.4 | BB10: 100.6 | BC10: 100.1 | BD10: 100.3 | BE10: 100.2 | BF10: 99.8 | BG10: 100.2 | BH10: 100.2 | BI10: 100.7 | BJ10: 105.3 | BK10: 104.1 | BL10: 100.2 | BM10: 101.3 | BN10: 102.4 | BO10: 100 | BP10: 100.8 | BQ10: 100.1 | BR10: 100.2 | BS10: 100.7 | BT10: 100 | BU10: 100 | BV10: 100.5 | BW10: 101 | BX10: 101.2 | BY10: 100.6 | BZ10: 100.6 | CA10: 100.4 | CB10: 100.3 | CC10: 100.4 | CD10: 100.6 | CE10: 100.3 | CF10: 100.2 | CG10: 100.4 | CH10: 100.7 | CI10: 101 | CJ10: 100.9 | CK10: 100.3 | CL10: 100.7 | CM10: 100.4 | CN10: 100.5 | CO10: 100.2 | CP10: 100.3 | CQ10: 100 | CR10: 100.2 | CS10: 100.5 | CT10: 100.4 | CU10: 101 | CV10: 100.5 | CW10: 100.9 | CX10: 100 | CY10: 100.3 | CZ10: 100.4 | DA10: 100.5 | DB10: 100.3 | DC10: 100.4 | DD10: 100.1 | DE10: 100.2 | DF10: 100.6 | DG10: 100.6 | DH10: 100.8 | DI10: 100.6 | DJ10: 100.5 | DK10: 101 | DL10: 100.7 | DM10: 100.5 | DN10: 100.5 | DO10: 100.4 | DP10: 100.2 | DQ10: 100.3 | DR10: 100.5 | DS10: 100.8 | DT10: 100.9 | DU10: 100.6 | DV10: 100.5 | DW10: 100.9 | DX10: 100.6 | DY10: 100.7 | DZ10: 101 | EA10: 100.8 | EB10: 100.2 | EC10: 100.7 | ED10: 100.5 | EE10: 100.9 | EF10: 100.6 | EG10: 100.7 | EH10: 100.6 | EI10: 102.8 | EJ10: 101.9 | EK10: 101.9 | EL10: 101.8 | EM10: 101.4 | EN10: 101.1 | EO10: 101.6 | EP10: 101.7 | EQ10: 101.3 | ER10: 101.8 | ES10: 101 | ET10: 100.8 | EU10: 100.7 | EV10: 101.2 | EW10: 100.7 | EX10: 100.4 | EY10: 100.6 | EZ10: 100.2 | FA10: 100.5 | FB10: 100.8 | FC10: 101 | FD10: 101 | FE10: 100.8 | FF10: 100.7 | FG10: 100.5 | FH10: 100.7 | FI10: 100.5 | FJ10: 100.7 | FK10: 100.8 | FL10: 100.6 | FM10: 100.4 | FN10: 101.3 | FO10: 100.5 | FP10: 100.8 | FQ10: 101.7 | FR10: 101.5 | FS10: 100.8 | FT10: 101 | FU10: 101.4 | FV10: 100.8 | FW10: 100.3 | FX10: 101.4 | FY10: 101.3 | FZ10: 100.5 | GA10: 100.1 | GB10: 100.5 | GC10: 101.4 | GD10: 101.1 | GE10: 100.5 | GF10: 101.1 | GG10: 100.4 | GH10: 101.1 | GI10: 100.5
A11: South-Kazakhstan region | B11: reporting period to the previous period | C11: Goods and services | E11: 101.5 | F11: 101.3 | G11: 101 | H11: 100.2 | I11: 100.4 | J11: 100.4 | K11: 100.3 | L11: 100.5 | M11: 100.4 | N11: 100.1 | O11: 100.5 | P11: 100.1 | Q11: 100.5 | R11: 100.3 | S11: 100.3 | T11: 100.4 | U11: 100.4 | V11: 100.3 | W11: 100.4 | X11: 100.2 | Y11: 100.5 | Z11: 101.1 | AA11: 100.5 | AB11: 100.6 | AC11: 100.8 | AD11: 100.8 | AE11: 99.9 | AF11: 100.1 | AG11: 100.2 | AH11: 100.3 | AI11: 100.2 | AJ11: 100.5 | AK11: 100.3 | AL11: 100.2 | AM11: 100.5 | AN11: 100.4 | AO11: 100.4 | AP11: 101.3 | AQ11: 101.3 | AR11: 100.5 | AS11: 100.5 | AT11: 100.4 | AU11: 99.8 | AV11: 100.8 | AW11: 100.9 | AX11: 100.5 | AY11: 100.3 | AZ11: 100.4 | BA11: 100.3 | BB11: 100.3 | BC11: 100.4 | BD11: 100.2 | BE11: 100 | BF11: 100 | BG11: 99.9 | BH11: 100.7 | BI11: 101.3 | BJ11: 104.9 | BK11: 102.6 | BL11: 101.9 | BM11: 101.2 | BN11: 101 | BO11: 100.9 | BP11: 100.5 | BQ11: 101.1 | BR11: 100.3 | BS11: 100.4 | BT11: 100.5 | BU11: 100.4 | BV11: 100.4 | BW11: 100.9 | BX11: 100.8 | BY11: 101.2 | BZ11: 100.6 | CA11: 101.1 | CB11: 100.3 | CC11: 100.4 | CD11: 100.3 | CE11: 99.8 | CF11: 100.9 | CG11: 100.1 | CH11: 101.2 | CI11: 101.7 | CJ11: 99.4 | CK11: 100.5 | CL11: 100.6 | CM11: 100.8 | CN11: 100.3 | CO11: 100.3
A12: ATYRAU REGION | B12: reporting period to the previous period | C12: Goods and services | E12: 101.6 | F12: 101.4 | G12: 100.5 | H12: 100.4 | I12: 101.2 | J12: 100.3 | K12: 100.9 | L12: 100 | M12: 100.1 | N12: 100.2 | O12: 100.1 | P12: 100.2 | Q12: 100.2 | R12: 100.3 | S12: 100.5 | T12: 100.6 | U12: 102.2 | V12: 100.1 | W12: 100 | X12: 100.5 | Y12: 100.5 | Z12: 100.7 | AA12: 100.2 | AB12: 100.4 | AC12: 100.9 | AD12: 100.4 | AE12: 100.1 | AF12: 100.7 | AG12: 100.3 | AH12: 100.1 | AI12: 100.2 | AJ12: 100.1 | AK12: 100.3 | AL12: 100.2 | AM12: 100.4 | AN12: 101.1 | AO12: 100.3 | AP12: 100.9 | AQ12: 100.9 | AR12: 100.9 | AS12: 100.8 | AT12: 100.6 | AU12: 100.5 | AV12: 100.2 | AW12: 100.2 | AX12: 100.1 | AY12: 100.5 | AZ12: 100.8 | BA12: 100.6 | BB12: 100.1 | BC12: 100.5 | BD12: 100.4 | BE12: 100.1 | BF12: 99.8 | BG12: 100 | BH12: 100.7 | BI12: 101.8 | BJ12: 104.3 | BK12: 103.8 | BL12: 100.5 | BM12: 101.9 | BN12: 101.4 | BO12: 100.3 | BP12: 100.3 | BQ12: 100.2 | BR12: 100.3 | BS12: 101.2 | BT12: 100.3 | BU12: 99.8 | BV12: 100.2 | BW12: 101 | BX12: 102.1 | BY12: 101 | BZ12: 101.6 | CA12: 100.4 | CB12: 100.6 | CC12: 100.2 | CD12: 100.3 | CE12: 100.6 | CF12: 100.8 | CG12: 100.3 | CH12: 100.3 | CI12: 100.3 | CJ12: 100.6 | CK12: 100.4 | CL12: 100.7 | CM12: 100.4 | CN12: 100.6 | CO12: 100.7 | CP12: 100.3 | CQ12: 100.5 | CR12: 100.2 | CS12: 100.1 | CT12: 100.1 | CU12: 100.7 | CV12: 101 | CW12: 100.9 | CX12: 100.4 | CY12: 100.2 | CZ12: 100.7 | DA12: 100.5 | DB12: 100.2 | DC12: 100.2 | DD12: 100.2 | DE12: 100 | DF12: 100.7 | DG12: 100.7 | DH12: 100.6 | DI12: 100.8 | DJ12: 101 | DK12: 100.5 | DL12: 100.7 | DM12: 100.5 | DN12: 100.5 | DO12: 100.5 | DP12: 100.2 | DQ12: 100.2 | DR12: 100.7 | DS12: 101 | DT12: 101 | DU12: 100.4 | DV12: 100.9 | DW12: 100.6 | DX12: 100.9 | DY12: 100.7 | DZ12: 101.5 | EA12: 100.5 | EB12: 100.5 | EC12: 100.4 | ED12: 100.5 | EE12: 100.3 | EF12: 100.9 | EG12: 100.7 | EH12: 100.7 | EI12: 102.6 | EJ12: 102.1 | EK12: 101.7 | EL12: 102.4 | EM12: 102.1 | EN12: 100.9 | EO12: 100.9 | EP12: 101 | EQ12: 101.5 | ER12: 101.5 | ES12: 100.8 | ET12: 101.1 | EU12: 100.9 | EV12: 100.9 | EW12: 100.8 | EX12: 100.5 | EY12: 100.4 | EZ12: 100.2 | FA12: 100.8 | FB12: 100.8 | FC12: 100.7 | FD12: 101.4 | FE12: 101.2 | FF12: 100.9 | FG12: 100.3 | FH12: 100.6 | FI12: 100.5 | FJ12: 100.5 | FK12: 100.6 | FL12: 100.8 | FM12: 100.3 | FN12: 100.7 | FO12: 100.7 | FP12: 100.8 | FQ12: 102.2 | FR12: 100.8 | FS12: 101 | FT12: 101 | FU12: 101.1 | FV12: 101.2 | FW12: 100.7 | FX12: 101.8 | FY12: 100.9 | FZ12: 101 | GA12: 100.4 | GB12: 100.8 | GC12: 100.9 | GD12: 101.2 | GE12: 100.8 | GF12: 100.7 | GG12: 101 | GH12: 101 | GI12: 100.6
A13: MANGYSTAU REGION | B13: reporting period to the previous period | C13: Goods and services | E13: 102.4 | F13: 100.9 | G13: 100.6 | H13: 100.4 | I13: 100.4 | J13: 100.2 | K13: 100.6 | L13: 100.4 | M13: 100.5 | N13: 100 | O13: 100.1 | P13: 100.3 | Q13: 100.1 | R13: 100.3 | S13: 100.5 | T13: 100.5 | U13: 100.4 | V13: 100.9 | W13: 100.1 | X13: 100.4 | Y13: 100.6 | Z13: 100.3 | AA13: 101.2 | AB13: 100.5 | AC13: 100.5 | AD13: 100.6 | AE13: 100.1 | AF13: 100.3 | AG13: 100.3 | AH13: 100.2 | AI13: 100.3 | AJ13: 100.3 | AK13: 100.1 | AL13: 100.2 | AM13: 100.2 | AN13: 100.2 | AO13: 100.4 | AP13: 101.3 | AQ13: 100.9 | AR13: 101.1 | AS13: 100.8 | AT13: 100.5 | AU13: 100.3 | AV13: 100.2 | AW13: 100.4 | AX13: 100.5 | AY13: 100.4 | AZ13: 100.1 | BA13: 100.5 | BB13: 101.2 | BC13: 100.1 | BD13: 100.2 | BE13: 100.3 | BF13: 99.9 | BG13: 100.1 | BH13: 100.9 | BI13: 101.2 | BJ13: 104.4 | BK13: 106.7 | BL13: 100.7 | BM13: 101 | BN13: 101.8 | BO13: 100.6 | BP13: 101 | BQ13: 100.7 | BR13: 100.2 | BS13: 100.2 | BT13: 100.3 | BU13: 101.2 | BV13: 100.2 | BW13: 100.6 | BX13: 100.8 | BY13: 100.6 | BZ13: 100.5 | CA13: 100.2 | CB13: 100.5 | CC13: 100.4 | CD13: 100.7 | CE13: 100.6 | CF13: 100.3 | CG13: 100 | CH13: 101.6 | CI13: 100.6 | CJ13: 100.8 | CK13: 100.9 | CL13: 100.3 | CM13: 100.4 | CN13: 100.2 | CO13: 100.4 | CP13: 100.8 | CQ13: 100.4 | CR13: 100.3 | CS13: 100.3 | CT13: 99.9 | CU13: 100.8 | CV13: 100.6 | CW13: 100.7 | CX13: 100.3 | CY13: 100.4 | CZ13: 100.7 | DA13: 100.4 | DB13: 100.4 | DC13: 100.3 | DD13: 100.3 | DE13: 100.5 | DF13: 100.4 | DG13: 100.8 | DH13: 100.4 | DI13: 100.4 | DJ13: 100.6 | DK13: 101.6 | DL13: 100.9 | DM13: 100.6 | DN13: 100.5 | DO13: 100.4 | DP13: 100.1 | DQ13: 100.4 | DR13: 100.5 | DS13: 100.9 | DT13: 100.7 | DU13: 101.2 | DV13: 100.6 | DW13: 100.6 | DX13: 101.1 | DY13: 101 | DZ13: 101 | EA13: 100.6 | EB13: 100.6 | EC13: 100.5 | ED13: 100.6 | EE13: 100.4 | EF13: 100.5 | EG13: 100.8 | EH13: 100.6 | EI13: 103.5 | EJ13: 102.9 | EK13: 102.2 | EL13: 102.6 | EM13: 101.4 | EN13: 101.8 | EO13: 102.4 | EP13: 101.5 | EQ13: 101.3 | ER13: 100.7 | ES13: 100.9 | ET13: 101.4 | EU13: 100.7 | EV13: 100.7 | EW13: 100.9 | EX13: 100.9 | EY13: 100.5 | EZ13: 100.6 | FA13: 100.4 | FB13: 100.9 | FC13: 101.4 | FD13: 101 | FE13: 100.8 | FF13: 100.8 | FG13: 100.8 | FH13: 101 | FI13: 100.6 | FJ13: 100.9 | FK13: 100.6 | FL13: 100.3 | FM13: 100.1 | FN13: 100.8 | FO13: 101.1 | FP13: 100.8 | FQ13: 100.8 | FR13: 101.7 | FS13: 100.4 | FT13: 101.4 | FU13: 100.6 | FV13: 100.6 | FW13: 101 | FX13: 101.2 | FY13: 101.1 | FZ13: 100.9 | GA13: 100.6 | GB13: 101 | GC13: 101 | GD13: 101.4 | GE13: 100.7 | GF13: 100.9 | GG13: 100.6 | GH13: 100.4 | GI13: 100.7
A14: ALMATY REGION | B14: reporting period to the previous period | C14: Goods and services | E14: 101.4 | F14: 102.3 | G14: 100 | H14: 100.4 | I14: 100.4 | J14: 100.3 | K14: 100.6 | L14: 100.3 | M14: 100.1 | N14: 100.2 | O14: 101.2 | P14: 99.6 | Q14: 100.2 | R14: 100.3 | S14: 100.3 | T14: 100.6 | U14: 100.5 | V14: 100.3 | W14: 100.1 | X14: 100.2 | Y14: 100.5 | Z14: 101.3 | AA14: 101.2 | AB14: 100.1 | AC14: 100.5 | AD14: 100.6 | AE14: 100.7 | AF14: 100.3 | AG14: 100.3 | AH14: 100.1 | AI14: 100.1 | AJ14: 100.1 | AK14: 100.8 | AL14: 100.2 | AM14: 100.6 | AN14: 100.4 | AO14: 100.6 | AP14: 101.3 | AQ14: 100.6 | AR14: 100.9 | AS14: 100.4 | AT14: 100.2 | AU14: 100.3 | AV14: 100.7 | AW14: 100.6 | AX14: 100.2 | AY14: 100.4 | AZ14: 100.5 | BA14: 101.1 | BB14: 100.3 | BC14: 99.5 | BD14: 99.8 | BE14: 100.4 | BF14: 99.9 | BG14: 100 | BH14: 100.2 | BI14: 101.2 | BJ14: 104.8 | BK14: 102.7 | BL14: 102.6 | BM14: 101.9 | BN14: 100.4 | BO14: 100.1 | BP14: 100.8 | BQ14: 100.5 | BR14: 100.7 | BS14: 100.1 | BT14: 100.1 | BU14: 100.1 | BV14: 100.5 | BW14: 101.4 | BX14: 101.2 | BY14: 100.5 | BZ14: 100.6 | CA14: 100.4 | CB14: 100.3 | CC14: 100.9 | CD14: 100.4 | CE14: 99.8 | CF14: 100 | CG14: 100.7 | CH14: 101.4 | CI14: 100.3 | CJ14: 101.1 | CK14: 101.3 | CL14: 100 | CM14: 100.3 | CN14: 100.4 | CO14: 100 | CP14: 100.4 | CQ14: 100.1 | CR14: 100.2 | CS14: 100.3 | CT14: 100.6 | CU14: 100.6 | CV14: 100.8 | CW14: 100.3 | CX14: 100.1 | CY14: 100.6 | CZ14: 100.5 | DA14: 100.8 | DB14: 100.2 | DC14: 100.1 | DD14: 100.1 | DE14: 100.3 | DF14: 100.7 | DG14: 100.7 | DH14: 100.9 | DI14: 100.6 | DJ14: 100.5 | DK14: 100.8 | DL14: 100.9 | DM14: 100.5 | DN14: 100.5 | DO14: 100.4 | DP14: 100 | DQ14: 100.2 | DR14: 100.6 | DS14: 100.8 | DT14: 101 | DU14: 100.5 | DV14: 100.6 | DW14: 100.6 | DX14: 100.9 | DY14: 100.7 | DZ14: 101 | EA14: 101 | EB14: 100.4 | EC14: 100 | ED14: 100.6 | EE14: 100.8 | EF14: 100.9 | EG14: 100.5 | EH14: 100.7 | EI14: 103.7 | EJ14: 101.5 | EK14: 101.6 | EL14: 101.8 | EM14: 100.6 | EN14: 100.9 | EO14: 101.8 | EP14: 101.5 | EQ14: 101.5 | ER14: 101 | ES14: 100.7 | ET14: 101.8 | EU14: 101.5 | EV14: 100.8 | EW14: 100.5 | EX14: 100.2 | EY14: 100.1 | EZ14: 100.6 | FA14: 100 | FB14: 100.4 | FC14: 100.7 | FD14: 100.8 | FE14: 100.9 | FF14: 100.5 | FG14: 101 | FH14: 100.6 | FI14: 100 | FJ14: 100.1 | FK14: 100.3 | FL14: 100.1 | FM14: 100.3 | FN14: 100.7 | FO14: 101.3 | FP14: 100.9 | FQ14: 100.8 | FR14: 101.2 | FS14: 101.4 | FT14: 101.2 | FU14: 100.6 | FV14: 100.7 | FW14: 101 | FX14: 101.2 | FY14: 101.2 | FZ14: 101.1 | GA14: 100.7 | GB14: 100.2 | GC14: 101.3 | GD14: 101.1 | GE14: 100.4 | GF14: 100.8 | GG14: 100.5 | GH14: 101.1 | GI14: 101
A15: ALMATY CITY | B15: reporting period to the previous period | C15: Goods and services | E15: 101.6 | F15: 101.6 | G15: 100.2 | H15: 100.6 | I15: 100.7 | J15: 100.3 | K15: 100.4 | L15: 100 | M15: 100.2 | N15: 100.2 | O15: 100.5 | P15: 100.4 | Q15: 100.4 | R15: 100.4 | S15: 100.3 | T15: 100.5 | U15: 100.6 | V15: 100.1 | W15: 101 | X15: 100 | Y15: 101.2 | Z15: 100.7 | AA15: 100.3 | AB15: 100.5 | AC15: 100.4 | AD15: 101.9 | AE15: 100.2 | AF15: 100.1 | AG15: 100.2 | AH15: 100.1 | AI15: 100.2 | AJ15: 99.9 | AK15: 99.9 | AL15: 100.3 | AM15: 100.4 | AN15: 100.8 | AO15: 101 | AP15: 101.4 | AQ15: 101 | AR15: 100.8 | AS15: 100.3 | AT15: 100.1 | AU15: 99.9 | AV15: 100.3 | AW15: 100.4 | AX15: 100.5 | AY15: 100.6 | AZ15: 100.6 | BA15: 101.2 | BB15: 100 | BC15: 100 | BD15: 100.3 | BE15: 100.1 | BF15: 99.9 | BG15: 99.9 | BH15: 100.3 | BI15: 101 | BJ15: 104.8 | BK15: 104.7 | BL15: 102.1 | BM15: 101.5 | BN15: 100.8 | BO15: 100.6 | BP15: 100.9 | BQ15: 100.1 | BR15: 100.1 | BS15: 100.2 | BT15: 100.4 | BU15: 100.7 | BV15: 100.3 | BW15: 100.9 | BX15: 101.2 | BY15: 100.8 | BZ15: 101 | CA15: 100.2 | CB15: 100.8 | CC15: 100.3 | CD15: 100.4 | CE15: 100 | CF15: 100 | CG15: 100.4 | CH15: 101.2 | CI15: 100.7 | CJ15: 101.1 | CK15: 100.7 | CL15: 100.7 | CM15: 100.6 | CN15: 100.3 | CO15: 100 | CP15: 100.1 | CQ15: 100 | CR15: 100.2 | CS15: 100.8 | CT15: 100.4 | CU15: 100.7 | CV15: 100.7 | CW15: 100.7 | CX15: 100.1 | CY15: 100.4 | CZ15: 100.3 | DA15: 100.5 | DB15: 100.3 | DC15: 100.1 | DD15: 100.4 | DE15: 100.5 | DF15: 100.5 | DG15: 100.6 | DH15: 100.7 | DI15: 100.6 | DJ15: 100.6 | DK15: 101.1 | DL15: 101 | DM15: 100.5 | DN15: 100.5 | DO15: 100 | DP15: 100.3 | DQ15: 100.1 | DR15: 100.5 | DS15: 100.9 | DT15: 100.9 | DU15: 100.5 | DV15: 100.8 | DW15: 100.4 | DX15: 100.9 | DY15: 100.7 | DZ15: 101.1 | EA15: 100.3 | EB15: 100.8 | EC15: 100.5 | ED15: 100.6 | EE15: 100.7 | EF15: 100.5 | EG15: 101 | EH15: 100.6 | EI15: 103.9 | EJ15: 101.7 | EK15: 101.4 | EL15: 101.4 | EM15: 100.9 | EN15: 101.6 | EO15: 101.8 | EP15: 101.9 | EQ15: 101.3 | ER15: 101 | ES15: 101 | ET15: 101.1 | EU15: 100.8 | EV15: 101 | EW15: 100.4 | EX15: 100.6 | EY15: 100.8 | EZ15: 101.1 | FA15: 100.6 | FB15: 100.7 | FC15: 100.8 | FD15: 100.8 | FE15: 100.6 | FF15: 101.1 | FG15: 100.7 | FH15: 100.4 | FI15: 100.4 | FJ15: 100 | FK15: 100.9 | FL15: 101.2 | FM15: 100.4 | FN15: 101.7 | FO15: 100.4 | FP15: 101 | FQ15: 100.7 | FR15: 101.3 | FS15: 101.5 | FT15: 101.5 | FU15: 101.7 | FV15: 100.7 | FW15: 100.4 | FX15: 100.7 | FY15: 100.8 | FZ15: 99.9 | GA15: 100.6 | GB15: 101.2 | GC15: 100.8 | GD15: 101 | GE15: 100.7 | GF15: 100.9 | GG15: 100.8 | GH15: 100.7 | GI15: 100.4
A16: KYZYLORDA REGION | B16: reporting period to the previous period | C16: Goods and services | E16: 101.9 | F16: 101.7 | G16: 100.5 | H16: 100.3 | I16: 100.5 | J16: 100.5 | K16: 100.1 | L16: 100.2 | M16: 100.3 | N16: 100.1 | O16: 100.4 | P16: 100.6 | Q16: 100.3 | R16: 100.6 | S16: 100.2 | T16: 100.7 | U16: 101.1 | V16: 100.1 | W16: 100 | X16: 100.2 | Y16: 100.7 | Z16: 100.6 | AA16: 100.8 | AB16: 100.9 | AC16: 100.6 | AD16: 100.9 | AE16: 99.9 | AF16: 100.1 | AG16: 100.2 | AH16: 100.4 | AI16: 100.1 | AJ16: 100.1 | AK16: 100.1 | AL16: 100.2 | AM16: 100.3 | AN16: 100.7 | AO16: 100.6 | AP16: 101.7 | AQ16: 101.2 | AR16: 100.8 | AS16: 100.3 | AT16: 100.3 | AU16: 100.7 | AV16: 100.3 | AW16: 100.2 | AX16: 100.3 | AY16: 100.7 | AZ16: 100.5 | BA16: 100.9 | BB16: 100.3 | BC16: 99.9 | BD16: 100.1 | BE16: 100.2 | BF16: 99.8 | BG16: 100.1 | BH16: 100.1 | BI16: 101.8 | BJ16: 105.1 | BK16: 105 | BL16: 100.6 | BM16: 100.7 | BN16: 100.4 | BO16: 100.9 | BP16: 100.2 | BQ16: 100.5 | BR16: 100.4 | BS16: 101.3 | BT16: 100.1 | BU16: 100.3 | BV16: 100.6 | BW16: 101.2 | BX16: 101.5 | BY16: 100.5 | BZ16: 100.8 | CA16: 100.4 | CB16: 100.6 | CC16: 100.2 | CD16: 100.4 | CE16: 100 | CF16: 100.8 | CG16: 100 | CH16: 101 | CI16: 100.7 | CJ16: 101 | CK16: 100.3 | CL16: 101.3 | CM16: 100.7 | CN16: 100.2 | CO16: 100.1 | CP16: 100.4 | CQ16: 100 | CR16: 100.1 | CS16: 100 | CT16: 100.5 | CU16: 100.9 | CV16: 101 | CW16: 100.4 | CX16: 100.2 | CY16: 100.5 | CZ16: 100.7 | DA16: 100.2 | DB16: 100.5 | DC16: 100.1 | DD16: 100.3 | DE16: 100.3 | DF16: 100.5 | DG16: 100.7 | DH16: 100.9 | DI16: 100.5 | DJ16: 100.5 | DK16: 100.8 | DL16: 101 | DM16: 100.2 | DN16: 100.7 | DO16: 100.3 | DP16: 100.4 | DQ16: 100.1 | DR16: 100.6 | DS16: 101 | DT16: 100.8 | DU16: 100.6 | DV16: 100.5 | DW16: 100.5 | DX16: 100.9 | DY16: 100.7 | DZ16: 101.1 | EA16: 100.7 | EB16: 100.3 | EC16: 100.6 | ED16: 100.7 | EE16: 100.8 | EF16: 100.5 | EG16: 100.4 | EH16: 100.8 | EI16: 103.1 | EJ16: 102 | EK16: 101.4 | EL16: 102 | EM16: 101.2 | EN16: 101.1 | EO16: 101.5 | EP16: 102.2 | EQ16: 101.4 | ER16: 101.2 | ES16: 101.2 | ET16: 100.7 | EU16: 101 | EV16: 100.7 | EW16: 100.8 | EX16: 100.6 | EY16: 100.8 | EZ16: 100.5 | FA16: 100.6 | FB16: 100.4 | FC16: 100.8 | FD16: 100.5 | FE16: 100.5 | FF16: 101 | FG16: 100.6 | FH16: 100.6 | FI16: 100.2 | FJ16: 100.4 | FK16: 101.2 | FL16: 100.7 | FM16: 101 | FN16: 100.6 | FO16: 100.5 | FP16: 100.6 | FQ16: 101.3 | FR16: 100.7 | FS16: 101 | FT16: 101.2 | FU16: 100.9 | FV16: 101 | FW16: 100.6 | FX16: 101.2 | FY16: 100.8 | FZ16: 101 | GA16: 100.9 | GB16: 100.8 | GC16: 100.9 | GD16: 100.9 | GE16: 100.7 | GF16: 101 | GG16: 100.7 | GH16: 100.4 | GI16: 100.5
A17: ASTANA CITY | B17: reporting period to the previous period | C17: Goods and services | E17: 102.2 | F17: 101.2 | G17: 100.3 | H17: 100.6 | I17: 101 | J17: 100 | K17: 100.6 | L17: 100.3 | M17: 100.5 | N17: 100.2 | O17: 101.3 | P17: 100.4 | Q17: 100.4 | R17: 100.5 | S17: 100.3 | T17: 100.9 | U17: 100.6 | V17: 100.1 | W17: 100.1 | X17: 100.2 | Y17: 100.7 | Z17: 100.3 | AA17: 101.4 | AB17: 100.4 | AC17: 100.8 | AD17: 100.4 | AE17: 100.3 | AF17: 100.3 | AG17: 100.2 | AH17: 99.7 | AI17: 99.9 | AJ17: 99.9 | AK17: 99.9 | AL17: 100.6 | AM17: 101 | AN17: 100.8 | AO17: 100.8 | AP17: 102.3 | AQ17: 100.9 | AR17: 100.8 | AS17: 101 | AT17: 100.5 | AU17: 99.3 | AV17: 100.1 | AW17: 100.8 | AX17: 100.8 | AY17: 100.8 | AZ17: 100.5 | BA17: 100.6 | BB17: 100.5 | BC17: 100.3 | BD17: 100.1 | BE17: 100 | BF17: 99.7 | BG17: 100.2 | BH17: 100 | BI17: 101 | BJ17: 107.9 | BK17: 106.9 | BL17: 100.6 | BM17: 101.3 | BN17: 100.9 | BO17: 100.6 | BP17: 100.8 | BQ17: 100.8 | BR17: 100.2 | BS17: 101 | BT17: 100.4 | BU17: 100.4 | BV17: 101.1 | BW17: 102.1 | BX17: 100.1 | BY17: 100.6 | BZ17: 100.8 | CA17: 100.6 | CB17: 100.5 | CC17: 100.6 | CD17: 100.5 | CE17: 100.4 | CF17: 99.8 | CG17: 100.9 | CH17: 101.3 | CI17: 101.1 | CJ17: 100.4 | CK17: 100.8 | CL17: 100.5 | CM17: 100.4 | CN17: 100.5 | CO17: 100.3 | CP17: 100.3 | CQ17: 100.4 | CR17: 100 | CS17: 100.5 | CT17: 100.4 | CU17: 101.1 | CV17: 100.5 | CW17: 100.9 | CX17: 100 | CY17: 100.4 | CZ17: 100.7 | DA17: 101 | DB17: 100 | DC17: 99.9 | DD17: 100 | DE17: 100.3 | DF17: 100.6 | DG17: 101.2 | DH17: 100.6 | DI17: 100.7 | DJ17: 101.3 | DK17: 101.3 | DL17: 101 | DM17: 100.5 | DN17: 100.3 | DO17: 100 | DP17: 99.6 | DQ17: 100.4 | DR17: 100.6 | DS17: 101 | DT17: 100.7 | DU17: 100.8 | DV17: 100.7 | DW17: 100.6 | DX17: 100.7 | DY17: 100.8 | DZ17: 101.2 | EA17: 100.5 | EB17: 100.2 | EC17: 100.5 | ED17: 100.6 | EE17: 100.9 | EF17: 100.9 | EG17: 100.4 | EH17: 101.2 | EI17: 103.4 | EJ17: 102.5 | EK17: 101.2 | EL17: 101.4 | EM17: 101.1 | EN17: 101.9 | EO17: 102.8 | EP17: 102.1 | EQ17: 101.6 | ER17: 101.3 | ES17: 101 | ET17: 101 | EU17: 100.4 | EV17: 100.5 | EW17: 100.3 | EX17: 100.7 | EY17: 100.8 | EZ17: 100.6 | FA17: 100.7 | FB17: 100.6 | FC17: 100.9 | FD17: 101.2 | FE17: 100.8 | FF17: 101.6 | FG17: 100.3 | FH17: 100.6 | FI17: 101.2 | FJ17: 100.5 | FK17: 101.3 | FL17: 100.4 | FM17: 100.5 | FN17: 100.4 | FO17: 101 | FP17: 101.6 | FQ17: 101.3 | FR17: 102.9 | FS17: 100.9 | FT17: 101 | FU17: 100.3 | FV17: 100.7 | FW17: 100.7 | FX17: 100.8 | FY17: 101.1 | FZ17: 100.1 | GA17: 100.9 | GB17: 100.9 | GC17: 101.1 | GD17: 100.9 | GE17: 100.5 | GF17: 100.6 | GG17: 100.9 | GH17: 101.1 | GI17: 100.6
A18: KOSTANAY REGION | B18: reporting period to the previous period | C18: Goods and services | E18: 101.7 | F18: 101.7 | G18: 100.2 | H18: 100.3 | I18: 100.3 | J18: 100.3 | K18: 100.4 | L18: 100.2 | M18: 100.3 | N18: 100.3 | O18: 100.5 | P18: 100.5 | Q18: 100.2 | R18: 100.3 | S18: 100.3 | T18: 100.8 | U18: 100.4 | V18: 100.2 | W18: 100.2 | X18: 100.2 | Y18: 100.4 | Z18: 100.5 | AA18: 100.6 | AB18: 100.8 | AC18: 101.6 | AD18: 100.5 | AE18: 100 | AF18: 100.7 | AG18: 100.1 | AH18: 100 | AI18: 100.5 | AJ18: 100.2 | AK18: 100.2 | AL18: 100.3 | AM18: 100.2 | AN18: 100.3 | AO18: 100.4 | AP18: 101.8 | AQ18: 100.6 | AR18: 100.4 | AS18: 100.5 | AT18: 100.3 | AU18: 100.2 | AV18: 100.4 | AW18: 100.3 | AX18: 100.5 | AY18: 100.8 | AZ18: 100.5 | BA18: 100.8 | BB18: 100 | BC18: 100 | BD18: 100.3 | BE18: 100.3 | BF18: 99.9 | BG18: 100.1 | BH18: 100.1 | BI18: 100.8 | BJ18: 105.6 | BK18: 102.8 | BL18: 100.6 | BM18: 102.1 | BN18: 100.7 | BO18: 100.3 | BP18: 100.1 | BQ18: 100.3 | BR18: 100.6 | BS18: 100.5 | BT18: 100.5 | BU18: 100.1 | BV18: 100.8 | BW18: 101.1 | BX18: 101.3 | BY18: 100.6 | BZ18: 100.8 | CA18: 101 | CB18: 100.5 | CC18: 100.4 | CD18: 100.7 | CE18: 100 | CF18: 99.6 | CG18: 100.2 | CH18: 100.9 | CI18: 100.9 | CJ18: 101.1 | CK18: 100.4 | CL18: 100.5 | CM18: 100.7 | CN18: 100.7 | CO18: 100.3 | CP18: 100 | CQ18: 100 | CR18: 100 | CS18: 100.4 | CT18: 100.4 | CU18: 100.9 | CV18: 100.7 | CW18: 100.5 | CX18: 100.2 | CY18: 100.4 | CZ18: 100.5 | DA18: 100.5 | DB18: 100.3 | DC18: 100.1 | DD18: 100.3 | DE18: 100.1 | DF18: 100.6 | DG18: 100.8 | DH18: 100.7 | DI18: 100.6 | DJ18: 100.5 | DK18: 100.9 | DL18: 100.9 | DM18: 100.6 | DN18: 100.2 | DO18: 100.5 | DP18: 100.1 | DQ18: 100.2 | DR18: 100.8 | DS18: 100.9 | DT18: 100.8 | DU18: 100.5 | DV18: 100.6 | DW18: 100.6 | DX18: 100.9 | DY18: 100.7 | DZ18: 101.2 | EA18: 100.6 | EB18: 100.4 | EC18: 100.3 | ED18: 100.7 | EE18: 100.8 | EF18: 100.7 | EG18: 100.5 | EH18: 100.7 | EI18: 103.8 | EJ18: 101.5 | EK18: 101.5 | EL18: 101.8 | EM18: 101.3 | EN18: 101.3 | EO18: 102.5 | EP18: 100.8 | EQ18: 101 | ER18: 101.9 | ES18: 101 | ET18: 101.5 | EU18: 100.6 | EV18: 100.7 | EW18: 100.8 | EX18: 100.5 | EY18: 100.5 | EZ18: 100.4 | FA18: 100.7 | FB18: 100.7 | FC18: 100.7 | FD18: 100.9 | FE18: 100.6 | FF18: 101 | FG18: 100.6 | FH18: 100.7 | FI18: 100.8 | FJ18: 100.2 | FK18: 100.2 | FL18: 100.5 | FM18: 100.3 | FN18: 100.6 | FO18: 101 | FP18: 101 | FQ18: 101 | FR18: 101.4 | FS18: 101 | FT18: 101.1 | FU18: 101.2 | FV18: 100.7 | FW18: 100.5 | FX18: 100.8 | FY18: 101.1 | FZ18: 100.7 | GA18: 100.9 | GB18: 100.7 | GC18: 100.8 | GD18: 101.2 | GE18: 100.7 | GF18: 100.8 | GG18: 100.8 | GH18: 100.7 | GI18: 100.5
A19: SHYGYS KAZAKHSTAN REGION | B19: reporting period to the previous period | C19: Goods and services | E19: 101.5 | F19: 101.3 | G19: 100.7 | H19: 101.1 | I19: 100.3 | J19: 100.5 | K19: 99.9 | L19: 100 | M19: 100.2 | N19: 100.4 | O19: 100.4 | P19: 100.6 | Q19: 100.4 | R19: 100.4 | S19: 100.3 | T19: 100.5 | U19: 100.9 | V19: 100.4 | W19: 100.3 | X19: 100 | Y19: 100.5 | Z19: 100.5 | AA19: 100.9 | AB19: 100.8 | AC19: 100.5 | AD19: 100.6 | AE19: 100 | AF19: 100.4 | AG19: 100.2 | AH19: 100.3 | AI19: 100.4 | AJ19: 100.1 | AK19: 100.1 | AL19: 100.3 | AM19: 100.6 | AN19: 100.8 | AO19: 100.4 | AP19: 101.5 | AQ19: 101.3 | AR19: 100.3 | AS19: 100.7 | AT19: 100.2 | AU19: 100.2 | AV19: 100.5 | AW19: 100.4 | AX19: 100.4 | AY19: 100.6 | AZ19: 100.5 | BA19: 100.5 | BB19: 100.3 | BC19: 100.1 | BD19: 100.2 | BE19: 100.2 | BF19: 99.9 | BG19: 101.3 | BH19: 100.1 | BI19: 101.5 | BJ19: 103.7 | BK19: 103.7 | BL19: 101 | BM19: 101.1 | BN19: 101.1 | BO19: 100.6 | BP19: 100.6 | BQ19: 100.6 | BR19: 101 | BS19: 100.4 | BT19: 100 | BU19: 99.9 | BV19: 100.6 | BW19: 101.2 | BX19: 100.9 | BY19: 100.8 | BZ19: 101.6 | CA19: 100.5 | CB19: 100.4 | CC19: 100.2 | CD19: 100.4 | CE19: 100.2 | CF19: 99.7 | CG19: 100.2 | CH19: 101.4 | CI19: 100.8 | CJ19: 100.7 | CK19: 100.4 | CL19: 100.8 | CM19: 100.8 | CN19: 100.1 | CO19: 100 | CP19: 100.1 | CQ19: 100.2 | CR19: 100.1 | CS19: 100.2 | CT19: 100.7 | CU19: 100.9 | CV19: 100.7 | CW19: 100.5 | CX19: 100.3 | CY19: 100.6 | CZ19: 100.4 | DA19: 100.6 | DB19: 100.3 | DC19: 100.2 | DD19: 100 | DE19: 100.3 | DF19: 100.8 | DG19: 100.7 | DH19: 100.7 | DI19: 100.4 | DJ19: 100.7 | DK19: 100.7 | DL19: 100.8 | DM19: 100.8 | DN19: 100.5 | DO19: 100.3 | DP19: 100.2 | DQ19: 100.2 | DR19: 100.8 | DS19: 100.8 | DT19: 100.8 | DU19: 100 | DV19: 100 | DW19: 100.7 | DX19: 101 | DY19: 100.5 | DZ19: 101.5 | EA19: 100.5 | EB19: 100.4 | EC19: 100.2 | ED19: 100.9 | EE19: 101.2 | EF19: 100.6 | EL19: 101.3 | EM19: 101.6 | EN19: 101.6 | EO19: 101.9 | EP19: 101.2 | EQ19: 101.2 | ER19: 101.2 | ES19: 101 | ET19: 101.1 | EU19: 101.4 | EV19: 100.9 | EW19: 100.6 | EX19: 100.7 | EY19: 100.6 | EZ19: 100.5 | FA19: 100.5 | FB19: 100.8 | FC19: 100.9 | FD19: 100.7 | FE19: 101.1 | FF19: 101.1 | FG19: 101 | FH19: 100.7 | FI19: 100.3 | FJ19: 100.3 | FK19: 100.7 | FL19: 100.8 | FM19: 100.5 | FN19: 100.7 | FO19: 100.7 | FP19: 100.7 | FQ19: 101.4 | FR19: 101.3 | FS19: 101.7 | FT19: 101 | FU19: 100.7 | FV19: 101.2 | FW19: 100.6 | FX19: 100.6 | FY19: 101 | FZ19: 100.9 | GA19: 100.6 | GB19: 100.6 | GC19: 101.1 | GD19: 101.2 | GE19: 100.7 | GF19: 100.8 | GG19: 100.7 | GH19: 100.8 | GI19: 100.5
A20: KARAGANDY REGION | B20: reporting period to the previous period | C20: Goods and services | E20: 102 | F20: 102 | G20: 100.3 | H20: 100.7 | I20: 100.4 | J20: 100.3 | K20: 100.4 | L20: 100.2 | M20: 100 | N20: 100.5 | O20: 100.7 | P20: 100.4 | Q20: 100.3 | R20: 100.3 | S20: 100.4 | T20: 101.2 | U20: 101 | V20: 100.5 | W20: 100 | X20: 101.1 | Y20: 100.5 | Z20: 100.6 | AA20: 100.8 | AB20: 100.3 | AC20: 100.8 | AD20: 100.9 | AE20: 100.1 | AF20: 100.4 | AG20: 100.2 | AH20: 101.5 | AI20: 100.2 | AJ20: 101.2 | AK20: 100.4 | AL20: 100.3 | AM20: 100.8 | AN20: 100.4 | AO20: 100.9 | AP20: 101.5 | AQ20: 101.4 | AR20: 100.5 | AS20: 100.4 | AT20: 100.2 | AU20: 100.2 | AV20: 100.5 | AW20: 100.7 | AX20: 100.5 | AY20: 100.8 | AZ20: 100.1 | BA20: 100.3 | BB20: 100.8 | BC20: 100 | BD20: 100.4 | BE20: 100.6 | BF20: 99.7 | BG20: 100 | BH20: 100.1 | BI20: 101 | BJ20: 105 | BK20: 102.5 | BL20: 100.7 | BM20: 101.2 | BN20: 101.5 | BO20: 100.3 | BP20: 100.6 | BQ20: 100.7 | BR20: 101 | BS20: 100.9 | BT20: 99.2 | BU20: 99.9 | BV20: 101.1 | BW20: 101.5 | BX20: 100.1 | BY20: 100.9 | BZ20: 101.1 | CA20: 100.3 | CB20: 100.4 | CC20: 100.7 | CD20: 100.8 | CE20: 99.7 | CF20: 99.9 | CG20: 100 | CH20: 101.3 | CI20: 100.9 | CJ20: 100.8 | CK20: 100.2 | CL20: 101 | CM20: 100.3 | CN20: 100.7 | CO20: 100.2 | CP20: 100 | CQ20: 100.2 | CR20: 100.1 | CS20: 100.1 | CT20: 100.3 | CU20: 101.1 | CV20: 100.8 | CW20: 100.5 | CX20: 100.5 | CY20: 100.4 | CZ20: 100.8 | DA20: 100.6 | DB20: 100.2 | DC20: 100.3 | DD20: 100 | DE20: 100.2 | DF20: 100.7 | DG20: 100.8 | DH20: 100.5 | DI20: 100.7 | DJ20: 100.7 | DK20: 100.8 | DL20: 101.2 | DM20: 100 | DN20: 100.5 | DO20: 100.7 | DP20: 100 | DQ20: 100.2 | DR20: 100.8 | DS20: 101.2 | DT20: 100.8 | DU20: 100.7 | DV20: 100.7 | DW20: 100.8 | DX20: 100.7 | DY20: 100.5 | DZ20: 100.9 | EA20: 101.1 | EB20: 100.2 | EC20: 100.7 | ED20: 100.9 | EE20: 100.6 | EF20: 100.4 | EG20: 100.9 | EH20: 101.1 | EI20: 103.4 | EJ20: 102.1 | EK20: 101.7 | EL20: 101.5 | EM20: 101 | EN20: 101.5 | EO20: 102.2 | EP20: 101.6 | EQ20: 101.3 | ER20: 100.8 | ES20: 100.8 | ET20: 101.7 | EU20: 101 | EV20: 100.7 | EW20: 100.4 | EX20: 100.3 | EY20: 100.8 | EZ20: 101.3 | FA20: 101.1 | FB20: 100.9 | FC20: 101.3 | FD20: 100.4 | FE20: 101 | FF20: 101.9 | FG20: 100.3 | FH20: 100.6 | FI20: 100.3 | FJ20: 100.5 | FK20: 100.6 | FL20: 100.2 | FM20: 100.5 | FN20: 100.8 | FO20: 101.5 | FP20: 101 | FQ20: 101.2 | FR20: 101.9 | FS20: 102.4 | FT20: 101.2 | FU20: 100.2 | FV20: 101.2 | FW20: 100.8 | FX20: 100.8 | FY20: 100.9 | FZ20: 100.2 | GA20: 100.6 | GB20: 101 | GC20: 100.9 | GD20: 101 | GE20: 100.4 | GF20: 100.7 | GG20: 100.6 | GH20: 101 | GI20: 100.4
A21: SHYMKENT CITY | B21: reporting period to the previous period | C21: Goods and services | CP21: 100.1 | CQ21: 100 | CR21: 100.3 | CS21: 100.6 | CT21: 100.3 | CU21: 100.7 | CV21: 100.8 | CW21: 100 | CX21: 101.1 | CY21: 100.8 | CZ21: 100.7 | DA21: 100.5 | DB21: 100.2 | DC21: 99.8 | DD21: 100.4 | DE21: 100.2 | DF21: 100.6 | DG21: 100.6 | DH21: 100.6 | DI21: 101 | DJ21: 100.4 | DK21: 101 | DL21: 100.8 | DM21: 100.7 | DN21: 100.1 | DO21: 100.1 | DP21: 100.1 | DQ21: 100.5 | DR21: 100.8 | DS21: 100.8 | DT21: 100.6 | DU21: 100.6 | DV21: 100.8 | DW21: 100.6 | DX21: 101.1 | DY21: 100.5 | DZ21: 101.1 | EA21: 100.6 | EB21: 100.4 | EC21: 100.7 | ED21: 100.6 | EE21: 100.4 | EF21: 100.5 | EG21: 100.9 | EH21: 100.7 | EI21: 104.3 | EJ21: 101.2 | EK21: 101.4 | EL21: 101.3 | EM21: 101.1 | EN21: 101.4 | EO21: 101.5 | EP21: 102.3 | EQ21: 101.3 | ER21: 100.7 | ES21: 101.5 | ET21: 101 | EU21: 100.7 | EV21: 100.7 | EW21: 101 | EX21: 100 | EY21: 100.7 | EZ21: 100.2 | FA21: 100.3 | FB21: 101.1 | FC21: 100.9 | FD21: 101 | FE21: 101 | FF21: 100.9 | FG21: 100.8 | FH21: 100.4 | FI21: 100 | FJ21: 100.2 | FK21: 100.3 | FL21: 100.3 | FM21: 100.4 | FN21: 100.7 | FO21: 101.4 | FP21: 100.6 | FQ21: 101.1 | FR21: 101.5 | FS21: 101.1 | FT21: 101.5 | FU21: 100.9 | FV21: 100.3 | FW21: 101 | FX21: 100.9 | FY21: 101.5 | FZ21: 100.7 | GA21: 100.1 | GB21: 100.9 | GC21: 101 | GD21: 101.2 | GE21: 100.4 | GF21: 101.2 | GG21: 100.3 | GH21: 100.8 | GI21: 100.4
A22: TURKISTAN REGION | B22: reporting period to the previous period | C22: Goods and services | CP22: 100 | CQ22: 99.8 | CR22: 100.3 | CS22: 100.6 | CT22: 100.3 | CU22: 100.3 | CV22: 100.9 | CW22: 100.2 | CX22: 100.6 | CY22: 100.8 | CZ22: 100.4 | DA22: 100.6 | DB22: 100.4 | DC22: 100 | DD22: 100.6 | DE22: 100 | DF22: 100.2 | DG22: 100.6 | DH22: 100.8 | DI22: 101.4 | DJ22: 100.4 | DK22: 100.7 | DL22: 100.9 | DM22: 100.8 | DN22: 100.2 | DO22: 100 | DP22: 100.3 | DQ22: 100.6 | DR22: 100.6 | DS22: 100.9 | DT22: 101 | DU22: 100.6 | DV22: 100.6 | DW22: 100.7 | DX22: 100.7 | DY22: 101 | DZ22: 100.9 | EA22: 100.7 | EB22: 101 | EC22: 100.3 | ED22: 101 | EE22: 100.3 | EF22: 100.3 | EG22: 100.7 | EH22: 101.3 | EI22: 104.1 | EJ22: 103 | EK22: 100.9 | EL22: 101.1 | EM22: 100.7 | EN22: 101.3 | EO22: 101.6 | EP22: 101.1 | EQ22: 101.4 | ER22: 101.6 | ES22: 101.2 | ET22: 101.6 | EU22: 101 | EV22: 101.2 | EW22: 100.6 | EX22: 100.3 | EY22: 100.3 | EZ22: 100.6 | FA22: 100.4 | FB22: 100.6 | FC22: 101.3 | FD22: 100.8 | FE22: 100.7 | FF22: 100.8 | FG22: 100.2 | FH22: 100.3 | FI22: 100 | FJ22: 100.4 | FK22: 100.7 | FL22: 100.9 | FM22: 100.6 | FN22: 100.6 | FO22: 101.2 | FP22: 100.7 | FQ22: 100.7 | FR22: 101.3 | FS22: 101.3 | FT22: 101.5 | FU22: 100.6 | FV22: 100.8 | FW22: 100.3 | FX22: 101.4 | FY22: 101.1 | FZ22: 100.7 | GA22: 101.2 | GB22: 100.8 | GC22: 101.1 | GD22: 101.4 | GE22: 100.6 | GF22: 100.8 | GG22: 100.7 | GH22: 100.2 | GI22: 100.9
A23: ABAY REGION | B23: reporting period to the previous period | C23: Goods and services | EL23: 101.3 | EM23: 101.5 | EN23: 101.7 | EO23: 101.8 | EP23: 101.4 | EQ23: 101.1 | ER23: 101.1 | ES23: 101.2 | ET23: 100.8 | EU23: 101 | EV23: 101.4 | EW23: 100.5 | EX23: 100.4 | EY23: 100.4 | EZ23: 100.7 | FA23: 100.3 | FB23: 100.5 | FC23: 101 | FD23: 101.2 | FE23: 101.1 | FF23: 100.5 | FG23: 100.9 | FH23: 100.3 | FI23: 100.4 | FJ23: 100.2 | FK23: 100.6 | FL23: 100.7 | FM23: 100.9 | FN23: 100.9 | FO23: 101.1 | FP23: 100.9 | FQ23: 101.2 | FR23: 100.7 | FS23: 101.3 | FT23: 101 | FU23: 100.9 | FV23: 101.3 | FW23: 100.8 | FX23: 100.3 | FY23: 100.9 | FZ23: 100.8 | GA23: 101 | GB23: 100.8 | GC23: 101 | GD23: 101 | GE23: 100.7 | GF23: 100.7 | GG23: 100.4 | GH23: 100.8 | GI23: 100.3
A24: ZHETISU REGION | B24: reporting period to the previous period | C24: Goods and services | EL24: 102.4 | EM24: 100.9 | EN24: 101.6 | EO24: 101.1 | EP24: 101.4 | EQ24: 101.5 | ER24: 101.4 | ES24: 101 | ET24: 101.2 | EU24: 101.2 | EV24: 101.1 | EW24: 100.8 | EX24: 100.6 | EY24: 100.6 | EZ24: 100.7 | FA24: 100.6 | FB24: 100.5 | FC24: 100.6 | FD24: 100.8 | FE24: 100.9 | FF24: 101 | FG24: 100.8 | FH24: 101.1 | FI24: 100.3 | FJ24: 100.5 | FK24: 100.6 | FL24: 100.3 | FM24: 100.5 | FN24: 100.5 | FO24: 100.8 | FP24: 100.9 | FQ24: 100.9 | FR24: 101.2 | FS24: 100.8 | FT24: 101.1 | FU24: 101.3 | FV24: 101 | FW24: 100.8 | FX24: 101.1 | FY24: 101.3 | FZ24: 101 | GA24: 100.6 | GB24: 100.4 | GC24: 101 | GD24: 100.9 | GE24: 100.8 | GF24: 100.8 | GG24: 100.5 | GH24: 102.1 | GI24: 101.2
A25: ULYTAU REGION | B25: reporting period to the previous period | C25: Goods and services | EL25: 101.3 | EM25: 101.4 | EN25: 102.7 | EO25: 101.5 | EP25: 100.8 | EQ25: 101.2 | ER25: 100.8 | ES25: 101 | ET25: 101.6 | EU25: 100.6 | EV25: 101.4 | EW25: 100.8 | EX25: 100.8 | EY25: 101 | EZ25: 100.3 | FA25: 100.6 | FB25: 100.5 | FC25: 101 | FD25: 100.3 | FE25: 100.5 | FF25: 100.7 | FG25: 100.5 | FH25: 100.7 | FI25: 100.1 | FJ25: 100.3 | FK25: 100.8 | FL25: 100.2 | FM25: 100.4 | FN25: 101.1 | FO25: 101 | FP25: 101 | FQ25: 101.3 | FR25: 101.4 | FS25: 101.6 | FT25: 101 | FU25: 100.6 | FV25: 100.6 | FW25: 101.1 | FX25: 101.8 | FY25: 101.1 | FZ25: 100.9 | GA25: 100.9 | GB25: 100.5 | GC25: 101.4 | GD25: 101.4 | GE25: 101 | GF25: 101 | GG25: 101 | GH25: 100.6 | GI25: 100.6

Sheet KZ Whole
B1: ='W3C Example Table'!D1 -> Даты | C1: ='W3C Example Table'!E1 -> Январь 2011 г. | D1: ='W3C Example Table'!F1 -> Февраль 2011 г. | E1: ='W3C Example Table'!G1 -> Март 2011 г. | F1: ='W3C Example Table'!H1 -> Апрель 2011 г. | G1: ='W3C Example Table'!I1 -> Май 2011 г. | H1: ='W3C Example Table'!J1 -> Июнь 2011 г. | I1: ='W3C Example Table'!K1 -> Июль 2011 г. | ... GG1: ='W3C Example Table'!GI1 -> Июль 2026 г.
A2: ='W3C Example Table'!A6 -> REPUBLIC OF KAZAKHSTAN | B2: ='W3C Example Table'!B6 -> reporting period to the previous period | C2: ='W3C Example Table'!E6 -> 101.7 | D2: ='W3C Example Table'!F6 -> 101.5 | E2: ='W3C Example Table'!G6 -> 100.5 | F2: ='W3C Example Table'!H6 -> 100.5 | G2: ='W3C Example Table'!I6 -> 100.5 | H2: ='W3C Example Table'!J6 -> 100.3 | I2: ='W3C Example Table'!K6 -> 100.5 | J2: ='W3C Example Table'!L6 -> 100.3 | ... GG2: ='W3C Example Table'!GI6 -> 100.6
A4: Даты | B4: =A2 -> REPUBLIC OF KAZAKHSTAN | C4: DATES | D4: DATE | E4: YoY Inflation
A5: Январь 2011 г. | B5: {=TRANSPOSE(C2:GG2)} -> 101.7 | C5: =DATE(VALUE(MID(A5,FIND(" ",A5)+1,4)),MATCH(LEFT(A5,FIND(" ",A5)-1),{"Январь","Февраль","Март","Апрель","Май","Июнь","Июль","Август","Сентябрь","Октябрь","Ноябрь","Декабрь"},0),1) -> 40544 | D5: =TEXT(C5,"yyyy-mm-01") -> 2011-01-01
A6: Февраль 2011 г. | B6: 101.5 | C6: =DATE(VALUE(MID(A6,FIND(" ",A6)+1,4)),MATCH(LEFT(A6,FIND(" ",A6)-1),{"Январь","Февраль","Март","Апрель","Май","Июнь","Июль","Август","Сентябрь","Октябрь","Ноябрь","Декабрь"},0),1) -> 40575 | D6: =TEXT(C6,"yyyy-mm-01") -> 2011-02-01
A7: Март 2011 г. | B7: 100.5 | C7: =DATE(VALUE(MID(A7,FIND(" ",A7)+1,4)),MATCH(LEFT(A7,FIND(" ",A7)-1),{"Январь","Февраль","Март","Апрель","Май","Июнь","Июль","Август","Сентябрь","Октябрь","Ноябрь","Декабрь"},0),1) -> 40603 | D7: =TEXT(C7,"yyyy-mm-01") -> 2011-03-01
A8: Апрель 2011 г. | B8: 100.5 | C8: =DATE(VALUE(MID(A8,FIND(" ",A8)+1,4)),MATCH(LEFT(A8,FIND(" ",A8)-1),{"Январь","Февраль","Март","Апрель","Май","Июнь","Июль","Август","Сентябрь","Октябрь","Ноябрь","Декабрь"},0),1) -> 40634 | D8: =TEXT(C8,"yyyy-mm-01") -> 2011-04-01
A9: Май 2011 г. | B9: 100.5 | C9: =DATE(VALUE(MID(A9,FIND(" ",A9)+1,4)),MATCH(LEFT(A9,FIND(" ",A9)-1),{"Январь","Февраль","Март","Апрель","Май","Июнь","Июль","Август","Сентябрь","Октябрь","Ноябрь","Декабрь"},0),1) -> 40664 | D9: =TEXT(C9,"yyyy-mm-01") -> 2011-05-01
