Workbook

Sheet W3C Example Table
B1: ӘАОЖ(каталог бойынша) | C1: REPUBLIC OF KAZAKHSTAN
B2: Даты | C2: Апрель 2013 г. | D2: Май 2013 г. | E2: Июнь 2013 г. | F2: Июль 2013 г. | G2: Январь 2014 г. | H2: Февраль 2014 г. | I2: Июнь 2014 г. | J2: Август 2014 г. | K2: Сентябрь 2014 г. | L2: Октябрь 2014 г. | M2: Ноябрь 2014 г. | N2: Январь 2015 г. | O2: Февраль 2015 г. | P2: Март 2015 г. | Q2: Апрель 2015 г. | R2: Май 2015 г. | S2: Июнь 2015 г. | T2: Июль 2015 г. | U2: Август 2015 г. | V2: Сентябрь 2015 г. | W2: Октябрь 2015 г. | X2: Ноябрь 2015 г. | Y2: Декабрь 2015 г. | Z2: Январь 2016 г. | AA2: Февраль 2016 г. | AB2: Март 2016 г. | AC2: Апрель 2016 г. | AD2: Май 2016 г. | AE2: Июль 2016 г. | AF2: Август 2016 г. | AG2: Сентябрь 2016 г. | AH2: Октябрь 2016 г. | AI2: Ноябрь 2016 г. | AJ2: Декабрь 2016 г. | AK2: Январь 2017 г. | AL2: Февраль 2017 г. | AM2: Март 2017 г. | AN2: Апрель 2017 г. | AO2: Май 2017 г. | AP2: Июнь 2017 г. | AQ2: Август 2017 г. | AR2: Сентябрь 2017 г. | AS2: Октябрь 2017 г. | AT2: Ноябрь 2017 г. | AU2: Декабрь 2017 г. | AV2: Январь 2018 г. | AW2: Февраль 2018 г. | AX2: Март 2018 г. | AY2: Апрель 2018 г. | AZ2: Май 2018 г. | BA2: Июнь 2018 г. | BB2: Июль 2018 г. | BC2: Август 2018 г. | BD2: Сентябрь 2018 г. | BE2: Октябрь 2018 г. | BF2: Ноябрь 2018 г. | BG2: Декабрь 2018 г. | BH2: Январь 2019 г. | BI2: Февраль 2019 г. | BJ2: Март 2019 г. | BK2: Апрель 2019 г. | BL2: Май 2019 г. | BM2: Июнь 2019 г. | BN2: Июль 2019 г. | BO2: Август 2019 г. | BP2: Сентябрь 2019 г. | BQ2: Октябрь 2019 г. | BR2: Ноябрь 2019 г. | BS2: Декабрь 2019 г. | BT2: Январь 2020 г. | BU2: Февраль 2020 г. | BV2: Март 2020 г. | BW2: Июль 2021 г. | BX2: Август 2021 г. | BY2: Сентябрь 2021 г. | BZ2: Октябрь 2021 г. | CA2: Ноябрь 2021 г. | CB2: Февраль 2022 г. | CC2: Октябрь 2022 г. | CD2: Ноябрь 2022 г. | CE2: Декабрь 2022 г. | CF2: Январь 2023 г. | CG2: Февраль 2023 г. | CH2: Март 2023 г. | CI2: Апрель 2023 г. | CJ2: Май 2023 г. | CK2: Июнь 2023 г. | CL2: Июль 2023 г. | CM2: Август 2023 г. | CN2: Сентябрь 2023 г. | CO2: Октябрь 2023 г. | CP2: Ноябрь 2023 г. | CQ2: Декабрь 2023 г. | CR2: Январь 2024 г. | CS2: Февраль 2024 г. | CT2: Март 2024 г. | CU2: Апрель 2024 г. | CV2: Май 2024 г. | CW2: Июнь 2024 г. | CX2: Июль 2024 г. | CY2: Август 2024 г. | CZ2: Сентябрь 2024 г. | DA2: Октябрь 2024 г. | DB2: Ноябрь 2024 г. | DC2: Декабрь 2024 г. | DD2: Январь 2025 г. | DE2: Февраль 2025 г. | DF2: Март 2025 г. | DG2: Апрель 2025 г. | DH2: Май 2025 г. | DI2: Июнь 2025 г. | DJ2: Июль 2025 г. | DK2: Август 2025 г. | DL2: Сентябрь 2025 г. | DM2: Октябрь 2025 г. | DN2: Ноябрь 2025 г. | DO2: Январь 2026 г. | DP2: Февраль 2026 г. | DQ2: Март 2026 г. | DR2: Апрель 2026 г.
A3: Показатели
A4: unemployment rate() | C4: 5.3 | D4: 5.3 | E4: 5.2 | F4: 5.2 | G4: 5.2 | H4: 5.2 | I4: 5 | J4: 5.1 | K4: 5 | L4: 5 | M4: 5.1 | N4: 5 | O4: 5 | P4: 5 | Q4: 5 | R4: 5 | S4: 4.9 | T4: 4.9 | U4: 4.9 | V4: 4.9 | W4: 4.9 | X4: 5 | Y4: 5 | Z4: 5.1 | AA4: 5.1 | AB4: 5.1 | AC4: 4.9 | AD4: 4.9 | AE4: 5.1 | AF4: 5 | AG4: 5 | AH4: 4.9 | AI4: 5 | AJ4: 5 | AK4: 4.9 | AL4: 4.9 | AM4: 4.9 | AN4: 4.9 | AO4: 4.8 | AP4: 4.9 | AQ4: 4.9 | AR4: 4.9 | AS4: 4.9 | AT4: 5 | AU4: 5 | AV4: 4.9 | AW4: 4.9 | AX4: 4.9 | AY4: 4.9 | AZ4: 4.9 | BA4: 4.9 | BB4: 4.8 | BC4: 4.8 | BD4: 4.8 | BE4: 4.8 | BF4: 4.8 | BG4: 4.8 | BH4: 4.8 | BI4: 4.8 | BJ4: 4.8 | BK4: 4.8 | BL4: 4.8 | BM4: 4.8 | BN4: 4.8 | BO4: 4.8 | BP4: 4.8 | BQ4: 4.8 | BR4: 4.8 | BS4: 4.8 | BT4: 4.8 | BU4: 4.8 | BV4: 4.8 | BW4: 4.9 | BX4: 4.9 | BY4: 4.9 | BZ4: 4.9 | CA4: 4.9 | CB4: 4.9 | CC4: 4.9 | CD4: 4.9 | CE4: 4.9 | CF4: 4.8 | CG4: 4.8 | CH4: 4.8 | CI4: 4.7 | CJ4: 4.7 | CK4: 4.7 | CL4: 4.7 | CM4: 4.7 | CN4: 4.7 | CO4: 4.7 | CP4: 4.7 | CQ4: 4.7 | CR4: 4.7 | CS4: 4.7 | CT4: 4.7 | CU4: 4.7 | CV4: 4.7 | CW4: 4.7 | CX4: 4.6 | CY4: 4.6 | CZ4: 4.6 | DA4: 4.6 | DB4: 4.6 | DC4: 4.6 | DD4: 4.6 | DE4: 4.6 | DF4: 4.6 | DG4: 4.6 | DH4: 4.6 | DI4: 4.6 | DJ4: 4.6 | DK4: 4.6 | DL4: 4.6 | DM4: 4.6 | DN4: 4.6 | DO4: 4.5 | DP4: 4.5 | DQ4: 4.5 | DR4: 4.5

Sheet Final Clean
A1: DATE | B1: Numerical Date | C1: DATE | D1: unemployment rate()
A2: Апрель 2013 г. | B2: =DATE(VALUE(MID(A2,FIND(" ",A2)+1,4)),MATCH(LEFT(A2,FIND(" ",A2)-1),{"Январь","Февраль","Март","Апрель","Май","Июнь","Июль","Август","Сентябрь","Октябрь","Ноябрь","Декабрь"},0),1) -> 41365 | C2: =TEXT(B2,"yyyy-mm-01") -> 2013-04-01 | D2: 5.3
A3: Май 2013 г. | B3: =DATE(VALUE(MID(A3,FIND(" ",A3)+1,4)),MATCH(LEFT(A3,FIND(" ",A3)-1),{"Январь","Февраль","Март","Апрель","Май","Июнь","Июль","Август","Сентябрь","Октябрь","Ноябрь","Декабрь"},0),1) -> 41395 | C3: =TEXT(B3,"yyyy-mm-01") -> 2013-05-01 | D3: 5.3
A4: Июнь 2013 г. | B4: =DATE(VALUE(MID(A4,FIND(" ",A4)+1,4)),MATCH(LEFT(A4,FIND(" ",A4)-1),{"Январь","Февраль","Март","Апрель","Май","Июнь","Июль","Август","Сентябрь","Октябрь","Ноябрь","Декабрь"},0),1) -> 41426 | C4: =TEXT(B4,"yyyy-mm-01") -> 2013-06-01 | D4: 5.2
A5: Июль 2013 г. | B5: =DATE(VALUE(MID(A5,FIND(" ",A5)+1,4)),MATCH(LEFT(A5,FIND(" ",A5)-1),{"Январь","Февраль","Март","Апрель","Май","Июнь","Июль","Август","Сентябрь","Октябрь","Ноябрь","Декабрь"},0),1) -> 41456 | C5: =TEXT(B5,"yyyy-mm-01") -> 2013-07-01 | D5: 5.2
A6: Август 2013 г. | B6: =DATE(VALUE(MID(A6,FIND(" ",A6)+1,4)),MATCH(LEFT(A6,FIND(" ",A6)-1),{"Январь","Февраль","Март","Апрель","Май","Июнь","Июль","Август","Сентябрь","Октябрь","Ноябрь","Декабрь"},0),1) -> 41487 | C6: =TEXT(B6,"yyyy-mm-01") -> 2013-08-01 | D6: =D5 -> 5.2
A7: Сентябрь 2013 г. | B7: =DATE(VALUE(MID(A7,FIND(" ",A7)+1,4)),MATCH(LEFT(A7,FIND(" ",A7)-1),{"Январь","Февраль","Март","Апрель","Май","Июнь","Июль","Август","Сентябрь","Октябрь","Ноябрь","Декабрь"},0),1) -> 41518 | C7: =TEXT(B7,"yyyy-mm-01") -> 2013-09-01 | D7: =D6 -> 5.2
A8: Октябрь 2013 г. | B8: =DATE(VALUE(MID(A8,FIND(" ",A8)+1,4)),MATCH(LEFT(A8,FIND(" ",A8)-1),{"Январь","Февраль","Март","Апрель","Май","Июнь","Июль","Август","Сентябрь","Октябрь","Ноябрь","Декабрь"},0),1) -> 41548 | C8: =TEXT(B8,"yyyy-mm-01") -> 2013-10-01 | D8: =D7 -> 5.2
A9: Ноябрь 2013 г. | B9: =DATE(VALUE(MID(A9,FIND(" ",A9)+1,4)),MATCH(LEFT(A9,FIND(" ",A9)-1),{"Январь","Февраль","Март","Апрель","Май","Июнь","Июль","Август","Сентябрь","Октябрь","Ноябрь","Декабрь"},0),1) -> 41579 | C9: =TEXT(B9,"yyyy-mm-01") -> 2013-11-01 | D9: =D8 -> 5.2
A10: Декабрь 2013 г. | B10: =DATE(VALUE(MID(A10,FIND(" ",A10)+1,4)),MATCH(LEFT(A10,FIND(" ",A10)-1),{"Январь","Февраль","Март","Апрель","Май","Июнь","Июль","Август","Сентябрь","Октябрь","Ноябрь","Декабрь"},0),1) -> 41609 | C10: =TEXT(B10,"yyyy-mm-01") -> 2013-12-01 | D10: =D9 -> 5.2
A11: Январь 2014 г. | B11: =DATE(VALUE(MID(A11,FIND(" ",A11)+1,4)),MATCH(LEFT(A11,FIND(" ",A11)-1),{"Январь","Февраль","Март","Апрель","Май","Июнь","Июль","Август","Сентябрь","Октябрь","Ноябрь","Декабрь"},0),1) -> 41640 | C11: =TEXT(B11,"yyyy-mm-01") -> 2014-01-01 | D11: 5.2
A12: Февраль 2014 г. | B12: =DATE(VALUE(MID(A12,FIND(" ",A12)+1,4)),MATCH(LEFT(A12,FIND(" ",A12)-1),{"Январь","Февраль","Март","Апрель","Май","Июнь","Июль","Август","Сентябрь","Октябрь","Ноябрь","Декабрь"},0),1) -> 41671 | C12: =TEXT(B12,"yyyy-mm-01") -> 2014-02-01 | D12: 5.2
A13: Март 2014 г. | B13: =DATE(VALUE(MID(A13,FIND(" ",A13)+1,4)),MATCH(LEFT(A13,FIND(" ",A13)-1),{"Январь","Февраль","Март","Апрель","Май","Июнь","Июль","Август","Сентябрь","Октябрь","Ноябрь","Декабрь"},0),1) -> 41699 | C13: =TEXT(B13,"yyyy-mm-01") -> 2014-03-01 | D13: =D12 -> 5.2
A14: Апрель 2014 г. | B14: =DATE(VALUE(MID(A14,FIND(" ",A14)+1,4)),MATCH(LEFT(A14,FIND(" ",A14)-1),{"Январь","Февраль","Март","Апрель","Май","Июнь","Июль","Август","Сентябрь","Октябрь","Ноябрь","Декабрь"},0),1) -> 41730 | C14: =TEXT(B14,"yyyy-mm-01") -> 2014-04-01 | D14: =D13 -> 5.2
A15: Май 2014 г. | B15: =DATE(VALUE(MID(A15,FIND(" ",A15)+1,4)),MATCH(LEFT(A15,FIND(" ",A15)-1),{"Январь","Февраль","Март","Апрель","Май","Июнь","Июль","Август","Сентябрь","Октябрь","Ноябрь","Декабрь"},0),1) -> 41760 | C15: =TEXT(B15,"yyyy-mm-01") -> 2014-05-01 | D15: =D14 -> 5.2
A16: Июнь 2014 г. | B16: =DATE(VALUE(MID(A16,FIND(" ",A16)+1,4)),MATCH(LEFT(A16,FIND(" ",A16)-1),{"Январь","Февраль","Март","Апрель","Май","Июнь","Июль","Август","Сентябрь","Октябрь","Ноябрь","Декабрь"},0),1) -> 41791 | C16: =TEXT(B16,"yyyy-mm-01") -> 2014-06-01 | D16: 5
A17: Июль 2014 г. | B17: =DATE(VALUE(MID(A17,FIND(" ",A17)+1,4)),MATCH(LEFT(A17,FIND(" ",A17)-1),{"Январь","Февраль","Март","Апрель","Май","Июнь","Июль","Август","Сентябрь","Октябрь","Ноябрь","Декабрь"},0),1) -> 41821 | C17: =TEXT(B17,"yyyy-mm-01") -> 2014-07-01 | D17: =D16 -> 5
A18: Август 2014 г. | B18: =DATE(VALUE(MID(A18,FIND(" ",A18)+1,4)),MATCH(LEFT(A18,FIND(" ",A18)-1),{"Январь","Февраль","Март","Апрель","Май","Июнь","Июль","Август","Сентябрь","Октябрь","Ноябрь","Декабрь"},0),1) -> 41852 | C18: =TEXT(B18,"yyyy-mm-01") -> 2014-08-01 | D18: 5.1
A19: Сентябрь 2014 г. | B19: =DATE(VALUE(MID(A19,FIND(" ",A19)+1,4)),MATCH(LEFT(A19,FIND(" ",A19)-1),{"Январь","Февраль","Март","Апрель","Май","Июнь","Июль","Август","Сентябрь","Октябрь","Ноябрь","Декабрь"},0),1) -> 41883 | C19: =TEXT(B19,"yyyy-mm-01") -> 2014-09-01 | D19: 5
A20: Октябрь 2014 г. | B20: =DATE(VALUE(MID(A20,FIND(" ",A20)+1,4)),MATCH(LEFT(A20,FIND(" ",A20)-1),{"Январь","Февраль","Март","Апрель","Май","Июнь","Июль","Август","Сентябрь","Октябрь","Ноябрь","Декабрь"},0),1) -> 41913 | C20: =TEXT(B20,"yyyy-mm-01") -> 2014-10-01 | D20: 5
A21: Ноябрь 2014 г. | B21: =DATE(VALUE(MID(A21,FIND(" ",A21)+1,4)),MATCH(LEFT(A21,FIND(" ",A21)-1),{"Январь","Февраль","Март","Апрель","Май","Июнь","Июль","Август","Сентябрь","Октябрь","Ноябрь","Декабрь"},0),1) -> 41944 | C21: =TEXT(B21,"yyyy-mm-01") -> 2014-11-01 | D21: 5.1
A22: Декабрь 2014 г. | B22: =DATE(VALUE(MID(A22,FIND(" ",A22)+1,4)),MATCH(LEFT(A22,FIND(" ",A22)-1),{"Январь","Февраль","Март","Апрель","Май","Июнь","Июль","Август","Сентябрь","Октябрь","Ноябрь","Декабрь"},0),1) -> 41974 | C22: =TEXT(B22,"yyyy-mm-01") -> 2014-12-01 | D22: =D21 -> 5.1
A23: Январь 2015 г. | B23: =DATE(VALUE(MID(A23,FIND(" ",A23)+1,4)),MATCH(LEFT(A23,FIND(" ",A23)-1),{"Январь","Февраль","Март","Апрель","Май","Июнь","Июль","Август","Сентябрь","Октябрь","Ноябрь","Декабрь"},0),1) -> 42005 | C23: =TEXT(B23,"yyyy-mm-01") -> 2015-01-01 | D23: 5
A24: Февраль 2015 г. | B24: =DATE(VALUE(MID(A24,FIND(" ",A24)+1,4)),MATCH(LEFT(A24,FIND(" ",A24)-1),{"Январь","Февраль","Март","Апрель","Май","Июнь","Июль","Август","Сентябрь","Октябрь","Ноябрь","Декабрь"},0),1) -> 42036 | C24: =TEXT(B24,"yyyy-mm-01") -> 2015-02-01 | D24: 5
A25: Март 2015 г. | B25: =DATE(VALUE(MID(A25,FIND(" ",A25)+1,4)),MATCH(LEFT(A25,FIND(" ",A25)-1),{"Январь","Февраль","Март","Апрель","Май","Июнь","Июль","Август","Сентябрь","Октябрь","Ноябрь","Декабрь"},0),1) -> 42064 | C25: =TEXT(B25,"yyyy-mm-01") -> 2015-03-01 | D25: 5
A26: Апрель 2015 г. | B26: =DATE(VALUE(MID(A26,FIND(" ",A26)+1,4)),MATCH(LEFT(A26,FIND(" ",A26)-1),{"Январь","Февраль","Март","Апрель","Май","Июнь","Июль","Август","Сентябрь","Октябрь","Ноябрь","Декабрь"},0),1) -> 42095 | C26: =TEXT(B26,"yyyy-mm-01") -> 2015-04-01 | D26: 5
A27: Май 2015 г. | B27: =DATE(VALUE(MID(A27,FIND(" ",A27)+1,4)),MATCH(LEFT(A27,FIND(" ",A27)-1),{"Январь","Февраль","Март","Апрель","Май","Июнь","Июль","Август","Сентябрь","Октябрь","Ноябрь","Декабрь"},0),1) -> 42125 | C27: =TEXT(B27,"yyyy-mm-01") -> 2015-05-01 | D27: 5
A28: Июнь 2015 г. | B28: =DATE(VALUE(MID(A28,FIND(" ",A28)+1,4)),MATCH(LEFT(A28,FIND(" ",A28)-1),{"Январь","Февраль","Март","Апрель","Май","Июнь","Июль","Август","Сентябрь","Октябрь","Ноябрь","Декабрь"},0),1) -> 42156 | C28: =TEXT(B28,"yyyy-mm-01") -> 2015-06-01 | D28: 4.9
A29: Июль 2015 г. | B29: =DATE(VALUE(MID(A29,FIND(" ",A29)+1,4)),MATCH(LEFT(A29,FIND(" ",A29)-1),{"Январь","Февраль","Март","Апрель","Май","Июнь","Июль","Август","Сентябрь","Октябрь","Ноябрь","Декабрь"},0),1) -> 42186 | C29: =TEXT(B29,"yyyy-mm-01") -> 2015-07-01 | D29: 4.9
A30: Август 2015 г. | B30: =DATE(VALUE(MID(A30,FIND(" ",A30)+1,4)),MATCH(LEFT(A30,FIND(" ",A30)-1),{"Январь","Февраль","Март","Апрель","Май","Июнь","Июль","Август","Сентябрь","Октябрь","Ноябрь","Декабрь"},0),1) -> 42217 | C30: =TEXT(B30,"yyyy-mm-01") -> 2015-08-01 | D30: 4.9
A31: Сентябрь 2015 г. | B31: =DATE(VALUE(MID(A31,FIND(" ",A31)+1,4)),MATCH(LEFT(A31,FIND(" ",A31)-1),{"Январь","Февраль","Март","Апрель","Май","Июнь","Июль","Август","Сентябрь","Октябрь","Ноябрь","Декабрь"},0),1) -> 42248 | C31: =TEXT(B31,"yyyy-mm-01") -> 2015-09-01 | D31: 4.9
A32: Октябрь 2015 г. | B32: =DATE(VALUE(MID(A32,FIND(" ",A32)+1,4)),MATCH(LEFT(A32,FIND(" ",A32)-1),{"Январь","Февраль","Март","Апрель","Май","Июнь","Июль","Август","Сентябрь","Октябрь","Ноябрь","Декабрь"},0),1) -> 42278 | C32: =TEXT(B32,"yyyy-mm-01") -> 2015-10-01 | D32: 4.9
A33: Ноябрь 2015 г. | B33: =DATE(VALUE(MID(A33,FIND(" ",A33)+1,4)),MATCH(LEFT(A33,FIND(" ",A33)-1),{"Январь","Февраль","Март","Апрель","Май","Июнь","Июль","Август","Сентябрь","Октябрь","Ноябрь","Декабрь"},0),1) -> 42309 | C33: =TEXT(B33,"yyyy-mm-01") -> 2015-11-01 | D33: 5
A34: Декабрь 2015 г. | B34: =DATE(VALUE(MID(A34,FIND(" ",A34)+1,4)),MATCH(LEFT(A34,FIND(" ",A34)-1),{"Январь","Февраль","Март","Апрель","Май","Июнь","Июль","Август","Сентябрь","Октябрь","Ноябрь","Декабрь"},0),1) -> 42339 | C34: =TEXT(B34,"yyyy-mm-01") -> 2015-12-01 | D34: 5
... A39: Май 2016 г. | B39: =DATE(VALUE(MID(A39,FIND(" ",A39)+1,4)),MATCH(LEFT(A39,FIND(" ",A39)-1),{"Январь","Февраль","Март","Апрель","Май","Июнь","Июль","Август","Сентябрь","Октябрь","Ноябрь","Декабрь"},0),1) -> 42491 | C39: =TEXT(B39,"yyyy-mm-01") -> 2016-05-01 | D39: 4.9
A40: Июнь 2016 г. | B40: =DATE(VALUE(MID(A40,FIND(" ",A40)+1,4)),MATCH(LEFT(A40,FIND(" ",A40)-1),{"Январь","Февраль","Март","Апрель","Май","Июнь","Июль","Август","Сентябрь","Октябрь","Ноябрь","Декабрь"},0),1) -> 42522 | C40: =TEXT(B40,"yyyy-mm-01") -> 2016-06-01 | D40: =D39 -> 4.9
A41: Июль 2016 г. | B41: =DATE(VALUE(MID(A41,FIND(" ",A41)+1,4)),MATCH(LEFT(A41,FIND(" ",A41)-1),{"Январь","Февраль","Март","Апрель","Май","Июнь","Июль","Август","Сентябрь","Октябрь","Ноябрь","Декабрь"},0),1) -> 42552 | C41: =TEXT(B41,"yyyy-mm-01") -> 2016-07-01 | D41: 5.1
A42: Август 2016 г. | B42: =DATE(VALUE(MID(A42,FIND(" ",A42)+1,4)),MATCH(LEFT(A42,FIND(" ",A42)-1),{"Январь","Февраль","Март","Апрель","Май","Июнь","Июль","Август","Сентябрь","Октябрь","Ноябрь","Декабрь"},0),1) -> 42583 | C42: =TEXT(B42,"yyyy-mm-01") -> 2016-08-01 | D42: 5
A43: Сентябрь 2016 г. | B43: =DATE(VALUE(MID(A43,FIND(" ",A43)+1,4)),MATCH(LEFT(A43,FIND(" ",A43)-1),{"Январь","Февраль","Март","Апрель","Май","Июнь","Июль","Август","Сентябрь","Октябрь","Ноябрь","Декабрь"},0),1) -> 42614 | C43: =TEXT(B43,"yyyy-mm-01") -> 2016-09-01 | D43: 5
A44: Октябрь 2016 г. | B44: =DATE(VALUE(MID(A44,FIND(" ",A44)+1,4)),MATCH(LEFT(A44,FIND(" ",A44)-1),{"Январь","Февраль","Март","Апрель","Май","Июнь","Июль","Август","Сентябрь","Октябрь","Ноябрь","Декабрь"},0),1) -> 42644 | C44: =TEXT(B44,"yyyy-mm-01") -> 2016-10-01 | D44: 4.9
...

Sheet Final Cleaned
A1: date | B1: kz_unemp_m
A2: ='Final Clean'!C2 -> 2013-04-01 | B2: ='Final Clean'!D2 -> 5.3
A3: ='Final Clean'!C3 -> 2013-05-01 | B3: ='Final Clean'!D3 -> 5.3
A4: ='Final Clean'!C4 -> 2013-06-01 | B4: ='Final Clean'!D4 -> 5.2
A5: ='Final Clean'!C5 -> 2013-07-01 | B5: ='Final Clean'!D5 -> 5.2
A6: ='Final Clean'!C6 -> 2013-08-01 | B6: ='Final Clean'!D6 -> 5.2
A7: ='Final Clean'!C7 -> 2013-09-01 | B7: ='Final Clean'!D7 -> 5.2
A8: ='Final Clean'!C8 -> 2013-10-01 | B8: ='Final Clean'!D8 -> 5.2
A9: ='Final Clean'!C9 -> 2013-11-01 | B9: ='Final Clean'!D9 -> 5.2
A10: ='Final Clean'!C10 -> 2013-12-01 | B10: ='Final Clean'!D10 -> 5.2
A11: ='Final Clean'!C11 -> 2014-01-01 | B11: ='Final Clean'!D11 -> 5.2
A12: ='Final Clean'!C12 -> 2014-02-01 | B12: ='Final Clean'!D12 -> 5.2
A13: ='Final Clean'!C13 -> 2014-03-01 | B13: ='Final Clean'!D13 -> 5.2
... A158: ='Final Clean'!C158 -> 2026-04-01 | B158: ='Final Clean'!D158 -> 4.5
