Workbook
Name ____QR001: [1]Control!$H$2
Name ____QR002: [1]Control!$H$3
Name ____QR003: [1]Control!$H$4
Name ____QR004: [1]Control!$H$5
Name ____QR011: [1]Control!$I$2
Name ____QR012: [1]Control!$I$3
Name ____QR013: [1]Control!$I$4
Name ____QR014: [1]Control!$I$5
Name ____QR021: [1]Control!$J$2
Name ____QR022: [1]Control!$J$3
Name ____QR023: [1]Control!$J$4
Name ____QR024: [1]Control!$J$5
Name ____QR031: [1]Control!$K$2
Name ____QR032: [1]Control!$K$3
Name ____QR033: [1]Control!$K$4
Name ____QR034: [1]Control!$K$5
Name ____QR041: [1]Control!$L$2
Name ____QR042: [1]Control!$L$3
Name ____QR043: [1]Control!$L$4
Name ____QR044: [1]Control!$L$5
Name ____QR971: [1]Control!$E$2
Name ____QR972: [1]Control!$E$3
Name ____QR981: [1]Control!$F$2
Name ____QR982: [1]Control!$F$3
Name ____QR983: [1]Control!$F$4
Name ____QR984: [1]Control!$F$5
Name ____QR991: [1]Control!$G$2
Name ____QR992: [1]Control!$G$3
Name ____QR993: [1]Control!$G$4
Name ____qr994: [1]Control!$G$5
Name ___QR001: [1]Control!$H$2
Name ___QR002: [1]Control!$H$3
Name ___QR003: [1]Control!$H$4
Name ___QR004: [1]Control!$H$5
Name ___QR011: [1]Control!$I$2
Name ___QR012: [1]Control!$I$3
Name ___QR013: [1]Control!$I$4
Name ___QR014: [1]Control!$I$5
Name ___QR021: [1]Control!$J$2
Name ___QR022: [1]Control!$J$3
Name ___QR023: [1]Control!$J$4
Name ___QR024: [1]Control!$J$5
Name ___QR031: [1]Control!$K$2
Name ___QR032: [1]Control!$K$3
Name ___QR033: [1]Control!$K$4
Name ___QR034: [1]Control!$K$5
Name ___QR041: [1]Control!$L$2
Name ___QR042: [1]Control!$L$3
Name ___QR043: [1]Control!$L$4
Name ___QR044: [1]Control!$L$5
Name ___QR971: [1]Control!$E$2
Name ___QR972: [1]Control!$E$3
Name ___QR981: [1]Control!$F$2
Name ___QR982: [1]Control!$F$3
Name ___QR983: [1]Control!$F$4
Name ___QR984: [1]Control!$F$5
Name ___QR991: [1]Control!$G$2
Name ___QR992: [1]Control!$G$3
Name ___QR993: [1]Control!$G$4
Name ___qr994: [1]Control!$G$5

Sheet 2003-2026
A1: Внешний долг Российской Федерации
CQ3: млн долларов США
B4: 37622 | C4: 37712 | D4: 37803 | E4: 37895 | F4: 37987 | G4: 38078 | H4: 38169 | I4: 38261 | J4: 38353 | K4: 38443 | L4: 38534 | M4: 38626 | N4: 38718 | O4: 38808 | P4: 38899 | Q4: 38991 | R4: 39083 | S4: 39173 | T4: 39264 | U4: 39356 | V4: 39448 | W4: 39539 | X4: 39630 | Y4: 39722 | Z4: 39814 | AA4: 39904 | AB4: 39995 | AC4: 40087 | AD4: 40179 | AE4: 40269 | AF4: 40360 | AG4: 40452 | AH4: 40544 | AI4: 40634 | AJ4: 40725 | AK4: 40817 | AL4: 40909 | AM4: 41000 | AN4: 41091 | AO4: 41183 | AP4: 41275 | AQ4: 41365 | AR4: 41456 | AS4: 41548 | AT4: 41640 | AU4: 41730 | AV4: 41821 | AW4: 41913 | AX4: 42005 | AY4: 42095 | AZ4: 42186 | BA4: 42278 | BB4: 42370 | BC4: 42461 | BD4: 42552 | BE4: 42644 | BF4: 42736 | BG4: 42826 | BH4: 42917 | BI4: 43009 | BJ4: 43101 | BK4: 43191 | BL4: 43282 | BM4: 43374 | BN4: 43466 | BO4: 43556 | BP4: 43647 | BQ4: 43739 | BR4: 43831 | BS4: 43922 | BT4: 44013 | BU4: 44105 | BV4: 44197 | BW4: 44287 | BX4: 44378 | BY4: 44470 | BZ4: 44562 | CA4: 44652 | CB4: 44743 | CC4: 44835 | CD4: 44927 | CE4: 45017 | CF4: 45108 | CG4: 45200 | CH4: 45292 | CI4: 45383 | CJ4: 45474 | CK4: 45566 | CL4: 45658 | CM4: 45748 | CN4: 45839 | CO4: 45931 | CP4: 46023 | CQ4: 46113
A5: Всего | B5: 151302 | C5: 153215 | D5: 158166 | E5: 165834 | F5: 184955 | G5: 189539 | H5: 192349 | I5: 193199 | J5: 213335 | K5: 219353 | L5: 227829 | M5: 226708 | N5: 257204 | O5: 273280 | P5: 289110 | Q5: 269512 | R5: 313214 | S5: 355587 | T5: 399548 | U5: 438836 | V5: 464384 | W5: 482501 | X5: 533423 | Y5: 540232 | Z5: 479823 | AA5: 445526 | AB5: 465886 | AC5: 473398 | AD5: 466294 | AE5: 462840 | AF5: 456956 | AG5: 476186 | AH5: 488537 | AI5: 508361 | AJ5: 538120 | AK5: 525578 | AL5: 538884 | AM5: 557521 | AN5: 570652 | AO5: 598927 | AP5: 636421 | AQ5: 691672 | AR5: 707764 | AS5: 716260 | AT5: 728864 | AU5: 715892 | AV5: 732779 | AW5: 680857 | AX5: 599901 | AY5: 557295 | AZ5: 556340 | BA5: 536890 | BB5: 518489 | BC5: 520121 | BD5: 523015 | BE5: 518330 | BF5: 511752 | BG5: 521595 | BH5: 527027 | BI5: 529585 | BJ5: 518445 | BK5: 520585 | BL5: 491045 | BM5: 470717 | BN5: 455073 | BO5: 469348 | BP5: 483704 | BQ5: 474930 | BR5: 491452 | BS5: 458745 | BT5: 483430 | BU5: 462760 | BV5: 467604.61 | BW5: 460603.75 | BX5: 474129.11 | BY5: 497049.01 | BZ5: 488414.78 | CA5: 462130.22 | CB5: 486717.12 | CC5: 441257.99 | CD5: 385080.64 | CE5: 358360.94 | CF5: 340879.71 | CG5: 324045.62 | CH5: 318288.68 | CI5: 308744.9 | CJ5: 317449.81 | CK5: 309319.98 | CL5: 289885.82 | CM5: 313045.26 | CN5: 324050.21 | CO5: 310182.2 | CP5: 306766.97 | CQ5: 299063.74
A6: Органы государственного управления | B6: 103299 | C6: 101373 | D6: 99901 | E6: 98841 | F6: 103244 | G6: 100422 | H6: 98133 | I6: 96833 | J6: 100721 | K6: 92710 | L6: 90971 | M6: 71888 | N6: 71104 | O6: 69511.3 | P6: 66412 | Q6: 45343 | R6: 44720 | S6: 43376 | T6: 40787 | U6: 39667 | V6: 37380 | W6: 36863 | X6: 34664 | Y6: 32571 | Z6: 29486 | AA6: 27384 | AB6: 30049 | AC6: 31196 | AD6: 31323 | AE6: 31347 | AF6: 35478 | AG6: 34850 | AH6: 34550 | AI6: 35391 | AJ6: 36836 | AK6: 34849 | AL6: 34732 | AM6: 36386 | AN6: 41529 | AO6: 46574 | AP6: 54411 | AQ6: 57479 | AR6: 55933 | AS6: 62679 | AT6: 61743 | AU6: 53639 | AV6: 57128 | AW6: 49382 | AX6: 41606 | AY6: 33522 | AZ6: 36381 | BA6: 32325 | BB6: 30517 | BC6: 32058 | BD6: 35948 | BE6: 40357 | BF6: 39143 | BG6: 45829 | BH6: 46485 | BI6: 54112 | BJ6: 55628 | BK6: 59741 | BL6: 49764 | BM6: 46281 | BN6: 43955 | BO6: 53329 | BP6: 64553 | BQ6: 64869 | BR6: 70056 | BS6: 59558 | BT6: 65253 | BU6: 59452 | BV6: 65256.28 | BW6: 61310.79 | BX6: 62806.21 | BY6: 68005.36 | BZ6: 63352.51 | CA6: 53266.07 | CB6: 74568.46 | CC6: 66899.4 | CD6: 46103.97 | CE6: 40435.31 | CF6: 36850.73 | CG6: 31797.95 | CH6: 32709.54 | CI6: 31775.87 | CJ6: 32264.19 | CK6: 30443.85 | CL6: 19323.96 | CM6: 21982.54 | CN6: 23431.65 | CO6: 23458.86 | CP6: 23459.5 | CQ6: 23042.4
A7: Федеральные органы управления | B7: 102214 | C7: 100312 | D7: 98846 | E7: 97746 | F7: 101980 | G7: 99046 | H7: 96716 | I7: 95465 | J7: 99088 | K7: 91184 | L7: 89498 | M7: 70562 | N7: 69919 | O7: 68309 | P7: 65621 | Q7: 44439 | R7: 43234 | S7: 41858 | T7: 39324 | U7: 38111 | V7: 35846 | W7: 35193 | X7: 33118 | Y7: 31120 | Z7: 28174 | AA7: 26178 | AB7: 28533 | AC7: 29509 | AD7: 29489 | AE7: 28908 | AF7: 32992 | AG7: 32366 | AH7: 32192 | AI7: 32882 | AJ7: 34356 | AK7: 32638 | AL7: 33591 | AM7: 35208 | AN7: 40730 | AO7: 45814 | AP7: 53471 | AQ7: 56535 | AR7: 55066 | AS7: 61872 | AT7: 60962 | AU7: 52867 | AV7: 56446 | AW7: 48748 | AX7: 41027 | AY7: 33008 | AZ7: 35809 | BA7: 31730 | BB7: 29953 | BC7: 31475 | BD7: 35358 | BE7: 39694 | BF7: 38931 | BG7: 45594 | BH7: 46279 | BI7: 53894 | BJ7: 55410 | BK7: 59523 | BL7: 49571 | BM7: 46102 | BN7: 43801 | BO7: 53164 | BP7: 64389 | BQ7: 64718 | BR7: 69909 | BS7: 59441 | BT7: 65124 | BU7: 59354 | BV7: 65162.91 | BW7: 61221.62 | BX7: 62707.02 | BY7: 67911.63 | BZ7: 63268.36 | CA7: 53191.86 | CB7: 74532.89 | CC7: 66868.49 | CD7: 46086.75 | CE7: 40419.6 | CF7: 36842.07 | CG7: 31790.31 | CH7: 32702.71 | CI7: 31769.25 | CJ7: 32261.06 | CK7: 30440.96 | CL7: 19322.24 | CM7: 21982.44 | CN7: 23431.38 | CO7: 23458.65 | CP7: 23457.19 | CQ7: 23036.89
A8: Новый российский долг | B8: 46288 | C8: 44870 | D8: 42649 | E8: 42079 | F8: 43688 | G8: 44930 | H8: 43025 | I8: 42703 | J8: 43152 | K8: 38104 | L8: 38699 | M8: 35907 | N8: 35652 | O8: 34510 | P8: 32179 | Q8: 32945 | R8: 33844 | S8: 33000 | T8: 30798 | U8: 29956 | V8: 28745 | W8: 28189 | X8: 28435 | Y8: 26553 | Z8: 23624 | AA8: 21744 | AB8: 24100 | AC8: 25058 | AD8: 26300 | AE8: 25758 | AF8: 29920 | AG8: 29384 | AH8: 29292 | AI8: 30096 | AJ8: 31658 | AK8: 30061 | AL8: 31081 | AM8: 32798 | AN8: 38411 | AO8: 43635 | AP8: 51342 | AQ8: 54427 | AR8: 53023 | AS8: 59809 | AT8: 58949 | AU8: 50863 | AV8: 54557 | AW8: 46926 | AX8: 39257 | AY8: 31235 | AZ8: 34071 | BA8: 30024 | BB8: 28713 | BC8: 30238 | BD8: 34276 | BE8: 38613 | BF8: 37886 | BG8: 44548 | BH8: 45267 | BI8: 53258 | BJ8: 54809 | BK8: 58943 | BL8: 49026 | BM8: 45557 | BN8: 43292 | BO8: 52655 | BP8: 63914 | BQ8: 64244 | BR8: 69469 | BS8: 59001 | BT8: 64718 | BU8: 58947 | BV8: 64790.77 | BW8: 60850.86 | BX8: 62370.76 | BY8: 67575.55 | BZ8: 62967 | CA8: 52890.68 | CB8: 74232.38 | CC8: 66568.57 | CD8: 45855.46 | CE8: 40188.14 | CF8: 36610.1 | CG8: 31558.69 | CH8: 32469.28 | CI8: 31537.55 | CJ8: 32029.2 | CK8: 30208.94 | CL8: 19090.39 | CM8: 21750.15 | CN8: 23196.7 | CO8: 23223.9 | CP8: 23222.21 | CQ8: 22802.26
A9: кредиты | B9: 18987 | C9: 18167 | D9: 17546 | E9: 16951 | F9: 16576 | G9: 15800 | H9: 14790 | I9: 14016 | J9: 13953 | K9: 9890 | L9: 9310 | M9: 9027 | N9: 8605 | O9: 8352 | P9: 8201 | Q9: 8043 | R9: 8038 | S9: 7725 | T9: 7437 | U9: 7269 | V9: 6754 | W9: 6648 | X9: 6311 | Y9: 6005 | Z9: 5884 | AA9: 5474 | AB9: 5252 | AC9: 5050 | AD9: 4802 | AE9: 4502 | AF9: 4297 | AG9: 4111 | AH9: 3939 | AI9: 3665 | AJ9: 3462 | AK9: 3271 | AL9: 3092 | AM9: 2838 | AN9: 2662 | AO9: 2487 | AP9: 2356 | AQ9: 2137 | AR9: 2000 | AS9: 1818 | AT9: 1727 | AU9: 1542.53 | AV9: 1469 | AW9: 1316 | AX9: 1241 | AY9: 1122 | AZ9: 1059 | BA9: 1043 | BB9: 999 | BC9: 979 | BD9: 923 | BE9: 907 | BF9: 858 | BG9: 836 | BH9: 771 | BI9: 761 | BJ9: 713 | BK9: 689 | BL9: 624 | BM9: 606 | BN9: 539 | BO9: 526 | BP9: 531 | BQ9: 535 | BR9: 522 | BS9: 491 | BT9: 479 | BU9: 485 | BV9: 485.08 | BW9: 519.91 | BX9: 500.98 | BY9: 527.15 | BZ9: 1501.21 | CA9: 1384.01 | CB9: 2094.22 | CC9: 1886.48 | CD9: 1412.42 | CE9: 1237.68 | CF9: 1099.12 | CG9: 1124.29 | CH9: 1114.56 | CI9: 1083.25 | CJ9: 1174.77 | CK9: 1079.42 | CL9: 987.17 | CM9: 1192.37 | CN9: 1269.45 | CO9: 1203.86 | CP9: 1273.32 | CQ9: 1226.52
A10: ценные бумаги в иностранной валюте | B10: 26653 | C10: 26013 | D10: 24519 | E10: 24623 | F10: 26791 | G10: 28723 | H10: 27972 | I10: 28427 | J10: 28929 | K10: 27942 | L10: 29108 | M10: 26592 | N10: 26743 | O10: 25828 | P10: 23556 | Q10: 24101 | R10: 24966 | S10: 24238 | T10: 22267 | U10: 21935 | V10: 21329 | W10: 21078 | X10: 21620 | Y10: 20040 | Z10: 17253 | AA10: 15857 | AB10: 18410 | AC10: 19438 | AD10: 20348 | AE10: 19876 | AF10: 24332 | AG10: 23736 | AH10: 23111 | AI10: 22495 | AJ10: 22234 | AK10: 21654 | AL10: 21693 | AM10: 20921 | AN10: 26745 | AO10: 25786 | AP10: 24661 | AQ10: 23894 | AR10: 23607 | AS10: 28876 | AT10: 27820.68 | AU10: 24735.89 | AV10: 23367.43 | AW10: 21534.25 | AX10: 21484 | AY10: 14897 | AZ10: 14895 | BA10: 13653 | BB10: 12646 | BC10: 11909 | BD10: 11999 | BE10: 14456 | BF10: 11662 | BG10: 11302 | BH10: 12525 | BI10: 14561 | BJ10: 15030 | BK10: 16912 | BL10: 16525 | BM10: 16401 | BN10: 16686 | BO10: 20220 | BP10: 22522 | BQ10: 22793 | BR10: 22297 | BS10: 21251 | BT10: 20329 | BU10: 20533 | BV10: 21071.12 | BW10: 20415.26 | BX10: 20586.5 | BY10: 20531.44 | BZ10: 19959.21 | CA10: 18550.1 | CB10: 18035.09 | CC10: 16942.59 | CD10: 16307.11 | CE10: 16143.72 | CF10: 16083.45 | CG10: 14979.59 | CH10: 14807.78 | CI10: 14724.46 | CJ10: 14602.08 | CK10: 14399.04 | CL10: 9098.59 | CM10: 9101.96 | CN10: 9247.78 | CO10: 9351.07 | CP10: 9158.5 | CQ10: 9245.01
A11: еврооблигации, ОВГВЗ | B11: 10304 | C11: 10066 | D11: 8719.63 | E11: 8627 | F11: 10024 | G11: 10482 | H11: 9944 | I11: 10016 | J11: 10309 | K11: 9486 | L11: 10091 | M11: 7630 | N11: 7765 | O11: 7490 | P11: 5921 | Q11: 5973 | R11: 5698 | S11: 5637 | T11: 3760 | U11: 3718 | V11: 3734 | W11: 3697 | X11: 3701 | Y11: 2955 | Z11: 2144 | AA11: 1817 | AB11: 2124 | AC11: 2178 | AD11: 2213 | AE11: 2116 | AF11: 6590 | AG11: 6738 | AH11: 6522 | AI11: 6521 | AJ11: 6175 | AK11: 6229 | AL11: 6200 | AM11: 6049 | AN11: 11861 | AO11: 11786 | AP11: 11146 | AQ11: 10953 | AR11: 10354 | AS11: 16054 | AT11: 15403.94 | AU11: 14225.34 | AV11: 13679 | AW11: 13248 | AX11: 13089 | AY11: 12203 | AZ11: 11262 | BA11: 10716 | BB11: 9679 | BC11: 9447 | BD11: 9625 | BE11: 11518 | BF11: 11034 | BG11: 10654 | BH11: 11850 | BI11: 14560 | BJ11: 15011 | BK11: 16912 | BL11: 16525 | BM11: 16401 | BN11: 16682 | BO11: 20211 | BP11: 22491 | BQ11: 22724 | BR11: 22216 | BS11: 21232 | BT11: 20289 | BU11: 20485 | BV11: 20918.98 | BW11: 20138.44 | BX11: 20276.26 | BY11: 20266.88 | BZ11: 19685.65 | CA11: 18323.74 | CB11: 17810.23 | CC11: 16848.65 | CD11: 16222.49 | CE11: 16084.2 | CF11: 16029.45 | CG11: 14938.53 | CH11: 14766.74 | CI11: 14692.28 | CJ11: 14569.91 | CK11: 14375.44 | CL11: 9083.33 | CM11: 9088.75 | CN11: 9234.57 | CO11: 9339.17 | CP11: 9042.09 | CQ11: 9161.75
A12: еврооблигации (выпущенные при второй реструктуризации задолженности перед Лондонским клубом кредиторов) | B12: 16349 | C12: 15947 | D12: 15799 | E12: 15996 | F12: 16767 | G12: 18241 | H12: 18028 | I12: 18411 | J12: 18620 | K12: 18455 | L12: 19017 | M12: 18962 | N12: 18979 | O12: 18339 | P12: 17634 | Q12: 18128 | R12: 19268 | S12: 18601 | T12: 18506 | U12: 18217 | V12: 17595 | W12: 17381 | X12: 17919 | Y12: 17085 | Z12: 15109 | AA12: 14040 | AB12: 16286 | AC12: 17261 | AD12: 18135 | AE12: 17760 | AF12: 17741 | AG12: 16997 | AH12: 16590 | AI12: 15974 | AJ12: 16059 | AK12: 15425 | AL12: 15492 | AM12: 14872 | AN12: 14884 | AO12: 14000 | AP12: 13514 | AQ12: 12941 | AR12: 13254 | AS12: 12822 | AT12: 12416.74 | AU12: 10510.55 | AV12: 9688 | AW12: 8286.14 | AX12: 8395 | AY12: 2694 | AZ12: 3632 | BA12: 2937 | BB12: 2967 | BC12: 2461 | BD12: 2374 | BE12: 2938 | BF12: 628 | BG12: 648 | BH12: 675 | BI12: 1 | BJ12: 19 | BK12: 0 | BL12: 0 | BM12: 0 | BN12: 4 | BO12: 9 | BP12: 31 | BQ12: 69 | BR12: 81 | BS12: 19 | BT12: 40 | BU12: 48 | BV12: 152.14 | BW12: 276.82 | BX12: 310.24 | BY12: 264.56 | BZ12: 273.56 | CA12: 226.36 | CB12: 224.86 | CC12: 93.94 | CD12: 84.61 | CE12: 59.52 | CF12: 53.99 | CG12: 41.06 | CH12: 41.03 | CI12: 32.18 | CJ12: 32.18 | CK12: 23.6 | CL12: 15.27 | CM12: 13.21 | CN12: 13.21 | CO12: 11.89 | CP12: 11.89 | CQ12: 10.57
A13: ОФЗ | BU13: — | BV13: — | BW13: — | BX13: — | BY13: — | BZ13: — | CA13: — | CB13: — | CC13: — | CD13: — | CE13: — | CF13: — | CG13: — | CH13: 0 | CI13: 0 | CJ13: 0 | CK13: 0 | CL13: 0 | CM13: 0 | CN13: 0 | CO13: 0 | CP13: 104.52 | CQ13: 72.69
A14: ценные бумаги в российских рублях | B14: 479 | C14: 513 | D14: 401 | E14: 315 | F14: 125 | G14: 204 | H14: 52 | I14: 43 | J14: 47 | K14: 41 | L14: 44 | M14: 44 | N14: 37 | O14: 39 | P14: 125 | Q14: 500 | R14: 537 | S14: 674 | T14: 728 | U14: 381 | V14: 347 | W14: 138 | X14: 190 | Y14: 193 | Z14: 146 | AA14: 77 | AB14: 115 | AC14: 245 | AD14: 811 | AE14: 1050 | AF14: 976 | AG14: 1218 | AH14: 1914 | AI14: 3607 | AJ14: 5639 | AK14: 4814 | AL14: 5939 | AM14: 8673 | AN14: 8674 | AO14: 15024 | AP14: 24018 | AQ14: 28028 | AR14: 27074 | AS14: 28764 | AT14: 29023.29 | AU14: 24213.86 | AV14: 29355 | AW14: 23717.84 | AX14: 16139 | AY14: 14871 | AZ14: 17790 | BA14: 15020 | BB14: 14735 | BC14: 17011 | BD14: 21022 | BE14: 22924 | BF14: 25032 | BG14: 32069 | BH14: 31634 | BI14: 37592 | BJ14: 38781 | BK14: 41050 | BL14: 31584 | BM14: 28252 | BN14: 25772 | BO14: 31609 | BP14: 40566 | BQ14: 40631 | BR14: 46359 | BS14: 37200 | BT14: 43857 | BU14: 37886 | BV14: 43190.27 | BW14: 39877.18 | BX14: 41249.64 | BY14: 46488.39 | BZ14: 41482.81 | CA14: 32937.67 | CB14: 54084.91 | CC14: 47722 | CD14: 28119.15 | CE14: 22796.77 | CF14: 19417.68 | CG14: 15445.08 | CH14: 16537.01 | CI14: 15720.04 | CJ14: 16242.62 | CK14: 14720.43 | CL14: 8994.96 | CM14: 11445.98 | CN14: 12669.3 | CO14: 12658.87 | CP14: 12780.24 | CQ14: 12320.68
A15: ОФЗ | B15: 479 | C15: 513 | D15: 401 | E15: 315 | F15: 125 | G15: 204 | H15: 52 | I15: 43 | J15: 47 | K15: 41 | L15: 44 | M15: 44 | N15: 37 | O15: 39 | P15: 125 | Q15: 500 | R15: 537 | S15: 674 | T15: 728 | U15: 381 | V15: 347 | W15: 138 | X15: 190 | Y15: 193 | Z15: 146 | AA15: 77 | AB15: 115 | AC15: 245 | AD15: 811 | AE15: 1050 | AF15: 976 | AG15: 1218 | AH15: 1914 | AI15: 2342 | AJ15: 2739 | AK15: 2267 | AL15: 3325 | AM15: 5821 | AN15: 6185 | AO15: 12516 | AP15: 21582 | AQ15: 25691 | AR15: 25023 | AS15: 26860 | AT15: 27324.5 | AU15: 22846.84 | AV15: 28092.76 | AW15: 22793.54 | AX15: 15594 | AY15: 14530 | AZ15: 17667 | BA15: 14961 | BB15: 14691 | BC15: 16937 | BD15: 21010 | BE15: 22916 | BF15: 25017 | BG15: 32013 | BH15: 31626 | BI15: 37591 | BJ15: 38712 | BK15: 41050 | BL15: 31584 | BM15: 28252 | BN15: 25772 | BO15: 31609 | BP15: 40566 | BQ15: 40631 | BR15: 46359 | BS15: 37200 | BT15: 43857 | BU15: 37886 | BV15: 43190.27 | BW15: 39877.18 | BX15: 41249.64 | BY15: 46488.39 | BZ15: 41482.81 | CA15: 32937.67 | CB15: 54084.91 | CC15: 47722 | CD15: 28119.15 | CE15: 22796.77 | CF15: 19417.68 | CG15: 15445.08 | CH15: 16537.01 | CI15: 15720.04 | CJ15: 16242.62 | CK15: 14720.43 | CL15: 8994.96 | CM15: 11445.98 | CN15: 12669.3 | CO15: 12658.87 | CP15: 12780.24 | CQ15: 12320.68
A16: еврооблигации | B16: 0 | C16: 0 | D16: 0 | E16: 0 | F16: 0 | G16: 0 | H16: 0 | I16: 0 | J16: 0 | K16: 0 | L16: 0 | M16: 0 | N16: 0 | O16: 0 | P16: 0 | Q16: 0 | R16: 0 | S16: 0 | T16: 0 | U16: 0 | V16: 0 | W16: 0 | X16: 0 | Y16: 0 | Z16: 0 | AA16: 0 | AB16: 0 | AC16: 0 | AD16: 0 | AE16: 0 | AF16: 0 | AG16: 0 | AH16: 0 | AI16: 1265 | AJ16: 2900 | AK16: 2547 | AL16: 2613 | AM16: 2853 | AN16: 2489 | AO16: 2508 | AP16: 2436 | AQ16: 2337 | AR16: 2051 | AS16: 1904 | AT16: 1698.79 | AU16: 1367.02 | AV16: 1262.3 | AW16: 924.3 | AX16: 545 | AY16: 340 | AZ16: 123 | BA16: 59 | BB16: 44 | BC16: 74 | BD16: 12 | BE16: 8 | BF16: 14 | BG16: 56 | BH16: 8 | BI16: 1 | BJ16: 69 | BK16: 0 | BL16: 0 | BM16: 0 | BN16: 0 | BO16: 0 | BP16: 0 | BQ16: 0 | BR16: 0 | BS16: 0 | BT16: 0 | BU16: 0 | BV16: 0 | BW16: 0 | BX16: 0 | BY16: 0 | BZ16: 0 | CA16: 0 | CB16: 0 | CC16: 0 | CD16: 0 | CE16: 0 | CF16: 0 | CG16: 0 | CH16: 0 | CI16: 0 | CJ16: 0 | CK16: 0 | CL16: 0 | CM16: 0 | CN16: 0 | CO16: 0 | CP16: 0 | CQ16: 0
A17: прочая задолженность | B17: 169 | C17: 176 | D17: 183 | E17: 190 | F17: 197 | G17: 203 | H17: 210 | I17: 217 | J17: 224 | K17: 231 | L17: 238 | M17: 245 | N17: 266 | O17: 291 | P17: 297 | Q17: 300 | R17: 302 | S17: 363 | T17: 366 | U17: 370 | V17: 316 | W17: 325 | X17: 315 | Y17: 315 | Z17: 341 | AA17: 336 | AB17: 324 | AC17: 326 | AD17: 340 | AE17: 330 | AF17: 315 | AG17: 319 | AH17: 328 | AI17: 329 | AJ17: 324 | AK17: 322 | AL17: 358 | AM17: 365 | AN17: 330 | AO17: 338 | AP17: 307 | AQ17: 369 | AR17: 342 | AS17: 350 | AT17: 377.48 | AU17: 371.61 | AV17: 366 | AW17: 357.5 | AX17: 393 | AY17: 345 | AZ17: 328 | BA17: 308 | BB17: 332 | BC17: 340 | BD17: 333 | BE17: 326 | BF17: 334 | BG17: 341 | BH17: 337 | BI17: 344 | BJ17: 285 | BK17: 292 | BL17: 293 | BM17: 298 | BN17: 294 | BO17: 299 | BP17: 296 | BQ17: 285 | BR17: 291 | BS17: 59 | BT17: 52 | BU17: 43 | BV17: 44.3 | BW17: 38.51 | BX17: 33.64 | BY17: 28.58 | BZ17: 23.76 | CA17: 18.91 | CB17: 18.16 | CC17: 17.51 | CD17: 16.79 | CE17: 9.97 | CF17: 9.86 | CG17: 9.74 | CH17: 9.94 | CI17: 9.8 | CJ17: 9.74 | CK17: 10.04 | CL17: 9.66 | CM17: 9.84 | CN17: 10.17 | CO17: 10.11 | CP17: 10.15 | CQ17: 10.06
A18: Долг бывшего СССР | B18: 55926 | C18: 55443 | D18: 56197 | E18: 55668 | F18: 58292 | G18: 54116 | H18: 53692 | I18: 52763 | J18: 55936 | K18: 53081 | L18: 50799 | M18: 34654 | N18: 34268 | O18: 33799 | P18: 33442 | Q18: 11494 | R18: 9390 | S18: 8857 | T18: 8527 | U18: 8155 | V18: 7100 | W18: 7004 | X18: 4682 | Y18: 4567 | Z18: 4550 | AA18: 4434 | AB18: 4432 | AC18: 4451 | AD18: 3189 | AE18: 3149 | AF18: 3072 | AG18: 2983 | AH18: 2900 | AI18: 2786 | AJ18: 2697 | AK18: 2577 | AL18: 2510 | AM18: 2410 | AN18: 2319 | AO18: 2179 | AP18: 2129 | AQ18: 2107 | AR18: 2042 | AS18: 2063 | AT18: 2012 | AU18: 2004 | AV18: 1888 | AW18: 1821 | AX18: 1770 | AY18: 1773 | AZ18: 1738 | BA18: 1706 | BB18: 1240 | BC18: 1237 | BD18: 1081 | BE18: 1081 | BF18: 1045 | BG18: 1046 | BH18: 1012 | BI18: 636 | BJ18: 601 | BK18: 580 | BL18: 544 | BM18: 545 | BN18: 510 | BO18: 509 | BP18: 475 | BQ18: 475 | BR18: 440 | BS18: 440 | BT18: 406 | BU18: 406 | BV18: 372.13 | BW18: 370.76 | BX18: 336.27 | BY18: 336.08 | BZ18: 301.36 | CA18: 301.18 | CB18: 300.51 | CC18: 299.92 | CD18: 231.29 | CE18: 231.45 | CF18: 231.97 | CG18: 231.61 | CH18: 233.43 | CI18: 231.7 | CJ18: 231.86 | CK18: 232.02 | CL18: 231.85 | CM18: 232.29 | CN18: 234.68 | CO18: 234.75 | CP18: 234.99 | CQ18: 234.62
A19: Субъекты Российской Федерации | B19: 1085 | C19: 1060 | D19: 1055 | E19: 1094 | F19: 1264 | G19: 1376 | H19: 1417 | I19: 1368 | J19: 1633 | K19: 1526 | L19: 1472 | M19: 1326 | N19: 1185 | O19: 1202 | P19: 791 | Q19: 905 | R19: 1486 | S19: 1518 | T19: 1462 | U19: 1556 | V19: 1534 | W19: 1670 | X19: 1546 | Y19: 1451 | Z19: 1312 | AA19: 1206 | AB19: 1516 | AC19: 1688 | AD19: 1834 | AE19: 2439 | AF19: 2486 | AG19: 2483 | AH19: 2359 | AI19: 2509 | AJ19: 2480 | AK19: 2211 | AL19: 1141 | AM19: 1177 | AN19: 800 | AO19: 761 | AP19: 941 | AQ19: 945 | AR19: 867 | AS19: 808 | AT19: 781 | AU19: 771 | AV19: 682 | AW19: 635 | AX19: 580 | AY19: 513 | AZ19: 573 | BA19: 594 | BB19: 564 | BC19: 583 | BD19: 591 | BE19: 662 | BF19: 212 | BG19: 235 | BH19: 207 | BI19: 218 | BJ19: 219 | BK19: 218 | BL19: 194 | BM19: 179 | BN19: 154 | BO19: 164 | BP19: 164 | BQ19: 151 | BR19: 147 | BS19: 117 | BT19: 130 | BU19: 99 | BV19: 93.37 | BW19: 89.17 | BX19: 99.19 | BY19: 93.73 | BZ19: 84.14 | CA19: 74.21 | CB19: 35.57 | CC19: 30.9 | CD19: 17.22 | CE19: 15.71 | CF19: 8.66 | CG19: 7.64 | CH19: 6.82 | CI19: 6.63 | CJ19: 3.13 | CK19: 2.9 | CL19: 1.73 | CM19: 0.1 | CN19: 0.27 | CO19: 0.2 | CP19: 2.31 | CQ19: 5.52
A20: кредиты | B20: 961 | C20: 947 | D20: 955.75 | E20: 949 | F20: 998 | G20: 969 | H20: 958 | I20: 963 | J20: 1088 | K20: 1031 | L20: 954 | M20: 939 | N20: 924 | O20: 936 | P20: 472 | Q20: 475 | R20: 1029 | S20: 1041 | T20: 1050 | U20: 1106 | V20: 1143 | W20: 1231 | X20: 1229 | Y20: 1125 | Z20: 1102 | AA20: 1032 | AB20: 1094 | AC20: 1142 | AD20: 1120 | AE20: 1056 | AF20: 956 | AG20: 1062 | AH20: 1034 | AI20: 1099 | AJ20: 1123 | AK20: 1063 | AL20: 552 | AM20: 569 | AN20: 537 | AO20: 551 | AP20: 564 | AQ20: 546 | AR20: 557 | AS20: 574 | AT20: 559 | AU20: 559 | AV20: 555 | AW20: 516 | AX20: 494 | AY20: 441 | AZ20: 451 | BA20: 458 | BB20: 445 | BC20: 461 | BD20: 451 | BE20: 457 | BF20: 0 | BG20: 0 | BH20: 0 | BI20: 0 | BJ20: 0 | BK20: 0 | BL20: 0 | BM20: 0 | BN20: 0 | BO20: 0 | BP20: 0 | BQ20: 0 | BR20: 0 | BS20: 0 | BT20: 0 | BU20: 0 | BV20: 0 | BW20: 0 | BX20: 0 | BY20: 0 | BZ20: 0 | CA20: 0 | CB20: 0 | CC20: 0 | CD20: 0 | CE20: 0 | CF20: 0 | CG20: 0 | CH20: 0 | CI20: 0 | CJ20: 0 | CK20: 0 | CL20: 0 | CM20: 0 | CN20: 0 | CO20: 0 | CP20: 0 | CQ20: 0
A21: ценные бумаги в иностранной валюте | B21: 100 | C21: 100 | D21: 79.52 | E21: 80 | F21: 60 | G21: 60 | H21: 40 | I21: 40 | J21: 20 | K21: 20 | L21: 0 | M21: 0 | N21: 0 | O21: 0 | P21: 0 | Q21: 0 | R21: 0 | S21: 0 | T21: 0 | U21: 0 | V21: 0 | W21: 0 | X21: 0 | Y21: 0 | Z21: 0 | AA21: 0 | AB21: 0 | AC21: 0 | AD21: 0 | AE21: 0 | AF21: 0 | AG21: 0 | AH21: 0 | AI21: 0 | AJ21: 0 | AK21: 0 | AL21: 0 | AM21: 0 | AN21: 0 | AO21: 0 | AP21: 0 | AQ21: 0 | AR21: 0 | AS21: 0 | AT21: 0 | AU21: 0 | AV21: 0 | AW21: 0 | AX21: 0 | AY21: 0 | AZ21: 0 | BA21: 0 | BB21: 0 | BC21: 0 | BD21: 0 | BE21: 0 | BF21: 0 | BG21: 0 | BH21: 0 | BI21: 0 | BJ21: 0 | BK21: 0 | BL21: 0 | BM21: 0 | BN21: 0 | BO21: 0 | BP21: 0 | BQ21: 0 | BR21: 0 | BS21: 0 | BT21: 0 | BU21: 0 | BV21: 0 | BW21: 0 | BX21: 0 | BY21: 0 | BZ21: 0 | CA21: 0 | CB21: 0 | CC21: 0 | CD21: 0 | CE21: 0 | CF21: 0 | CG21: 0 | CH21: 0 | CI21: 0 | CJ21: 0 | CK21: 0 | CL21: 0 | CM21: 0 | CN21: 0 | CO21: 0 | CP21: 0 | CQ21: 0
A22: ценные бумаги в российских рублях | B22: 24 | C22: 14 | D22: 19.7 | E22: 65 | F22: 206 | G22: 347 | H22: 419 | I22: 365 | J22: 525 | K22: 475 | L22: 518 | M22: 387 | N22: 260 | O22: 266 | P22: 319 | Q22: 430 | R22: 456 | S22: 477 | T22: 412 | U22: 449 | V22: 391 | W22: 439 | X22: 318 | Y22: 326 | Z22: 211 | AA22: 174 | AB22: 423 | AC22: 546 | AD22: 714 | AE22: 1383 | AF22: 1530 | AG22: 1421 | AH22: 1325 | AI22: 1409 | AJ22: 1356 | AK22: 1148 | AL22: 589 | AM22: 609 | AN22: 262 | AO22: 209 | AP22: 377 | AQ22: 398 | AR22: 311 | AS22: 233 | AT22: 222.1 | AU22: 211.99 | AV22: 127.74 | AW22: 118.45 | AX22: 85 | AY22: 72 | AZ22: 122 | BA22: 136 | BB22: 119 | BC22: 123 | BD22: 140 | BE22: 205 | BF22: 212 | BG22: 235 | BH22: 207 | BI22: 218 | BJ22: 219 | BK22: 218 | BL22: 194 | BM22: 179 | BN22: 154 | BO22: 164 | BP22: 164 | BQ22: 151 | BR22: 147 | BS22: 117 | BT22: 130 | BU22: 99 | BV22: 93.37 | BW22: 89.17 | BX22: 99.19 | BY22: 93.73 | BZ22: 84.14 | CA22: 74.21 | CB22: 35.57 | CC22: 30.9 | CD22: 17.22 | CE22: 15.71 | CF22: 8.66 | CG22: 7.64 | CH22: 6.82 | CI22: 6.63 | CJ22: 3.13 | CK22: 2.9 | CL22: 1.73 | CM22: 0.1 | CN22: 0.27 | CO22: 0.2 | CP22: 2.31 | CQ22: 5.52
A23: Центральный банк и банки | B23: 15208 | C23: 15675 | D23: 18583 | E23: 21562 | F23: 27572 | G23: 28894 | H23: 28755 | I23: 28887 | J23: 37018 | K23: 42333 | L23: 46665 | M23: 52621 | N23: 61073 | O23: 73733 | P23: 79137 | Q23: 87475 | R23: 105022 | S23: 119596 | T23: 139431 | U23: 160790 | V23: 165890 | W23: 174188 | X23: 196254 | Y23: 201261 | Z23: 168984 | AA23: 148838 | AB23: 145521 | AC23: 148021 | AD23: 141787 | AE23: 141203 | AF23: 133975 | AG23: 152198 | AH23: 156181 | AI23: 161438 | AJ23: 171592 | AK23: 168982 | AL23: 174311 | AM23: 181310 | AN23: 187398 | AO23: 203409 | AP23: 217206 | AQ23: 225409 | AR23: 230891 | AS23: 224646 | AT23: 230357 | AU23: 229519 | AV23: 225084 | AW23: 208065 | AX23: 182049 | AY23: 165376 | AZ23: 159178 | BA23: 150286 | BB23: 143449 | BC23: 140596 | BD23: 138359 | BE23: 134396 | BF23: 131472 | BG23: 134182 | BH23: 130182 | BI23: 129279 | BJ23: 117865 | BK23: 122071 | BL23: 108634 | BM23: 103609 | BN23: 96761 | BO23: 98908 | BP23: 92468 | BQ23: 86448 | BR23: 90777 | BS23: 84744 | BT23: 82133 | BU23: 86172 | BV23: 84930.29 | BW23: 89236.23 | BX23: 90103.67 | BY23: 110086.29 | BZ23: 114682.9 | CA23: 118617.2 | CB23: 113258.77 | CC23: 105139.79 | CD23: 94180.7 | CE23: 92201.47 | CF23: 92964.69 | CG23: 93681.82 | CH23: 94755.6 | CI23: 90922.47 | CJ23: 97792.76 | CK23: 100793.59 | CL23: 95872.41 | CM23: 101663.65 | CN23: 105703.77 | CO23: 108932.52 | CP23: 111551.98 | CQ23: 106723.21
A24: долговые обязательства перед прямыми инвесторами и предприятиями прямого инвестирования | B24: 17 | C24: 20 | D24: 19 | E24: 19 | F24: 14 | G24: 19 | H24: 25 | I24: 27 | J24: 30 | K24: 30 | L24: 30 | M24: 25 | N24: 33 | O24: 35 | P24: 110 | Q24: 125 | R24: 60 | S24: 64 | T24: 182 | U24: 111 | V24: 126 | W24: 181 | X24: 286 | Y24: 300 | Z24: 432 | AA24: 248 | AB24: 252 | AC24: 517 | AD24: 452 | AE24: 460 | AF24: 211 | AG24: 227 | AH24: 199 | AI24: 169 | AJ24: 135 | AK24: 405 | AL24: 620 | AM24: 913 | AN24: 1271 | AO24: 1502 | AP24: 2003 | AQ24: 3232 | AR24: 4920 | AS24: 4591 | AT24: 4510 | AU24: 5031 | AV24: 4078 | AW24: 2794 | AX24: 1897 | AY24: 5037 | AZ24: 4909 | BA24: 4477 | BB24: 5499 | BC24: 4863 | BD24: 4721 | BE24: 4362 | BF24: 5179 | BG24: 5353 | BH24: 5294 | BI24: 4389 | BJ24: 4541 | BK24: 5017 | BL24: 4813 | BM24: 5050 | BN24: 4416 | BO24: 4454 | BP24: 4515 | BQ24: 3798 | BR24: 4560 | BS24: 4630 | BT24: 4370 | BU24: 4274 | BV24: 4584.13 | BW24: 5625.96 | BX24: 4091.25 | BY24: 4620.68 | BZ24: 4763.6 | CA24: 6555.78 | CB24: 4176 | CC24: 4079.18 | CD24: 3907.78 | CE24: 4007.87 | CF24: 3936.4 | CG24: 3837.93 | CH24: 3450.9 | CI24: 3196.87 | CJ24: 3045.31 | CK24: 2012.42 | CL24: 2000.85 | CM24: 1929.37 | CN24: 685.34 | CO24: 687.87 | CP24: 637.16 | CQ24: 632
A25: долговые ценные бумаги | B25: 1768 | C25: 1310 | D25: 1629 | E25: 1037 | F25: 1218 | G25: 1247 | H25: 1448 | I25: 1377 | J25: 1823 | K25: 1692 | L25: 1692 | M25: 1953 | N25: 1826 | O25: 2121 | P25: 2568 | Q25: 2971 | R25: 3301 | S25: 4178 | T25: 5316 | U25: 5860 | V25: 6167 | W25: 5764 | X25: 5546 | Y25: 4532 | Z25: 3652 | AA25: 3016 | AB25: 3210 | AC25: 3352 | AD25: 4116 | AE25: 4211 | AF25: 3516 | AG25: 3848 | AH25: 4321 | AI25: 4406 | AJ25: 4959 | AK25: 4208 | AL25: 4493 | AM25: 8819 | AN25: 8286 | AO25: 10507 | AP25: 9102 | AQ25: 8842 | AR25: 8426 | AS25: 7908 | AT25: 7729 | AU25: 7550 | AV25: 7556 | AW25: 6672 | AX25: 5197 | AY25: 5376 | AZ25: 5236 | BA25: 5371 | BB25: 5721 | BC25: 5299 | BD25: 5463 | BE25: 5444 | BF25: 6148 | BG25: 5681 | BH25: 5564 | BI25: 5815 | BJ25: 5376 | BK25: 5493 | BL25: 4798 | BM25: 4758 | BN25: 4478 | BO25: 4525 | BP25: 4572 | BQ25: 4450 | BR25: 4431 | BS25: 3404 | BT25: 3731 | BU25: 3331 | BV25: 3599.05 | BW25: 3554.51 | BX25: 3761.44 | BY25: 3832.62 | BZ25: 3551.55 | CA25: 3562.41 | CB25: 5103.71 | CC25: 4407.26 | CD25: 1788.11 | CE25: 1288.84 | CF25: 1233.1 | CG25: 1196.38 | CH25: 1344.58 | CI25: 1483.1 | CJ25: 1758.63 | CK25: 1376.29 | CL25: 1316.27 | CM25: 1714.18 | CN25: 1851.92 | CO25: 1634.1 | CP25: 1756.14 | CQ25: 1718.35
... A32: прочая задолженность | B32: 0 | C32: 0 | D32: 0 | E32: 0 | F32: 0 | G32: 0 | H32: 0 | I32: 0 | J32: 0 | K32: 0 | L32: 0 | M32: 0 | N32: 17 | O32: 19 | P32: 22 | Q32: 24 | R32: 48 | S32: 99 | T32: 3122 | U32: 2091 | V32: 1302 | W32: 926 | X32: 5016 | Y32: 3945 | Z32: 2300 | AA32: 1956 | AB32: 4508 | AC32: 4193 | AD32: 2915 | AE32: 3247 | AF32: 6630 | AG32: 5226 | AH32: 3069 | AI32: 3888 | AJ32: 8066 | AK32: 4481 | AL32: 3596 | AM32: 4106 | AN32: 9519 | AO32: 4284 | AP32: 4225 | AQ32: 4322 | AR32: 8409 | AS32: 6292 | AT32: 5815.23 | AU32: 6002.65 | AV32: 10173.86 | AW32: 6538.41 | AX32: 6558 | AY32: 4513 | AZ32: 7984 | BA32: 4888 | BB32: 5143 | BC32: 4532 | BD32: 7477 | BE32: 5260 | BF32: 6198 | BG32: 5075 | BH32: 8657 | BI32: 6775 | BJ32: 6792 | BK32: 5846 | BL32: 10332 | BM32: 8433 | BN32: 8002 | BO32: 6285 | BP32: 13949 | BQ32: 11047 | BR32: 15694 | BS32: 13649 | BT32: 24522 | BU32: 15670 | BV32: 17395.83 | BW32: 18410.41 | BX32: 26604.57 | BY32: 27286.58 | BZ32: 29973.06 | CA32: 32803.64 | CB32: 27387.23 | CC32: 23974.65 | CD32: 20808.12 | CE32: 20679.97 | CF32: 22735.45 | CG32: 25958.73 | CH32: 27733.82 | CI32: 34937.59 | CJ32: 40104.86 | CK32: 42168.38 | CL32: 53560.16 | CM32: 61080.81 | CN32: 61671.8 | CO32: 51289.5 | CP32: 49814.67 | CQ32: 51051.81
A34: Примечания.
A35: Сведения о состоянии внешнего долга разработаны в соответствии с методологией, изложенной в шестом издании "Руководства по платежному балансу и международной инвестиционной позиции (2009 г.)", МВФ, и "Руководстве для составителей и пользователей. Статистика внешнего долга" (2013 г.).
A36: Включается внешняя задолженность в национальной и иностранной валютах.
A37: Государственные ценные бумаги отражаются в части задолженности перед нерезидентами и оцениваются по номинальной стоимости.
A38: Долговые ценные бумаги прочих секторов отражаются, начиная с данных на 01.01.2018, по номинальной стоимости.
A39: Данные по центральному банку и банкам включают данные государственной корпорации развития "ВЭБ.РФ".
A40: В данные по внешнему долгу могут вноситься изменения (преимущественно в течение года после первой публикации).
A41: В отдельных случаях возможны расхождения между итогом и суммой слагаемых, что связано с округлением данных.
A43: Условные обозначения:
A44: «—» явление отсутствует
A46: Дата последнего обновления: 30 июня 2026 года.
A48: {=TRANSPOSE(B4:CQ4)} -> 37622 | B48: {=TRANSPOSE(B5:CQ5)} -> 151302
A49: 37712 | B49: 153215
A50: 37803 | B50: 158166
A51: 37895 | B51: 165834
...

Sheet Sheet1
A1: Dates | B1: DATE | C1: External debt
A2: 37622 | B2: =TEXT(A2,"yyyy-mm-01") -> 2003-01-01 | C2: =VLOOKUP(A2,'2003-2026'!$A$48:$B$141,2,FALSE) -> 151302
A3: =EDATE(A2,1) -> 37653 | B3: =TEXT(A3,"yyyy-mm-01") -> 2003-02-01 | C3: {=INDEX($C:$C,MATCH(ROW()-MOD(ROW()-ROW($C$2),3),ROW($C:$C),0))+(B3-INDEX($B:$B,MATCH(ROW()-MOD(ROW()-ROW($C$2),3),ROW($C:$C),0)))/(INDEX($B:$B,MATCH(ROW()-MOD(ROW()-ROW($C$2),3),ROW($C:$C),0)+3)-INDEX($B:$B,MATCH(ROW()-MOD(ROW()-ROW($C$2),3),ROW($C:$C),0)))*(INDEX($C:$C,MATCH(ROW()-MOD(ROW()-ROW($C$2),3),ROW($C:$C),0)+3)-INDEX($C:$C,MATCH(ROW()-MOD(ROW()-ROW($C$2),3),ROW($C:$C),0)))} -> 151960.92
A4: =EDATE(A3,1) -> 37681 | B4: =TEXT(A4,"yyyy-mm-01") -> 2003-03-01 | C4: {=INDEX($C:$C,MATCH(ROW()-MOD(ROW()-ROW($C$2),3),ROW($C:$C),0))+(B4-INDEX($B:$B,MATCH(ROW()-MOD(ROW()-ROW($C$2),3),ROW($C:$C),0)))/(INDEX($B:$B,MATCH(ROW()-MOD(ROW()-ROW($C$2),3),ROW($C:$C),0)+3)-INDEX($B:$B,MATCH(ROW()-MOD(ROW()-ROW($C$2),3),ROW($C:$C),0)))*(INDEX($C:$C,MATCH(ROW()-MOD(ROW()-ROW($C$2),3),ROW($C:$C),0)+3)-INDEX($C:$C,MATCH(ROW()-MOD(ROW()-ROW($C$2),3),ROW($C:$C),0)))} -> 152556.08
A5: =EDATE(A4,1) -> 37712 | B5: =TEXT(A5,"yyyy-mm-01") -> 2003-04-01 | C5: =VLOOKUP(A5,'2003-2026'!$A$48:$B$141,2,FALSE) -> 153215
A6: =EDATE(A5,1) -> 37742 | B6: =TEXT(A6,"yyyy-mm-01") -> 2003-05-01 | C6: {=INDEX($C:$C,MATCH(ROW()-MOD(ROW()-ROW($C$2),3),ROW($C:$C),0))+(B6-INDEX($B:$B,MATCH(ROW()-MOD(ROW()-ROW($C$2),3),ROW($C:$C),0)))/(INDEX($B:$B,MATCH(ROW()-MOD(ROW()-ROW($C$2),3),ROW($C:$C),0)+3)-INDEX($B:$B,MATCH(ROW()-MOD(ROW()-ROW($C$2),3),ROW($C:$C),0)))*(INDEX($C:$C,MATCH(ROW()-MOD(ROW()-ROW($C$2),3),ROW($C:$C),0)+3)-INDEX($C:$C,MATCH(ROW()-MOD(ROW()-ROW($C$2),3),ROW($C:$C),0)))} -> 154847.2
A7: =EDATE(A6,1) -> 37773 | B7: =TEXT(A7,"yyyy-mm-01") -> 2003-06-01 | C7: {=INDEX($C:$C,MATCH(ROW()-MOD(ROW()-ROW($C$2),3),ROW($C:$C),0))+(B7-INDEX($B:$B,MATCH(ROW()-MOD(ROW()-ROW($C$2),3),ROW($C:$C),0)))/(INDEX($B:$B,MATCH(ROW()-MOD(ROW()-ROW($C$2),3),ROW($C:$C),0)+3)-INDEX($B:$B,MATCH(ROW()-MOD(ROW()-ROW($C$2),3),ROW($C:$C),0)))*(INDEX($C:$C,MATCH(ROW()-MOD(ROW()-ROW($C$2),3),ROW($C:$C),0)+3)-INDEX($C:$C,MATCH(ROW()-MOD(ROW()-ROW($C$2),3),ROW($C:$C),0)))} -> 156533.8
A8: =EDATE(A7,1) -> 37803 | B8: =TEXT(A8,"yyyy-mm-01") -> 2003-07-01 | C8: =VLOOKUP(A8,'2003-2026'!$A$48:$B$141,2,FALSE) -> 158166
A9: =EDATE(A8,1) -> 37834 | B9: =TEXT(A9,"yyyy-mm-01") -> 2003-08-01 | C9: {=INDEX($C:$C,MATCH(ROW()-MOD(ROW()-ROW($C$2),3),ROW($C:$C),0))+(B9-INDEX($B:$B,MATCH(ROW()-MOD(ROW()-ROW($C$2),3),ROW($C:$C),0)))/(INDEX($B:$B,MATCH(ROW()-MOD(ROW()-ROW($C$2),3),ROW($C:$C),0)+3)-INDEX($B:$B,MATCH(ROW()-MOD(ROW()-ROW($C$2),3),ROW($C:$C),0)))*(INDEX($C:$C,MATCH(ROW()-MOD(ROW()-ROW($C$2),3),ROW($C:$C),0)+3)-INDEX($C:$C,MATCH(ROW()-MOD(ROW()-ROW($C$2),3),ROW($C:$C),0)))} -> 160749.78
A10: =EDATE(A9,1) -> 37865 | B10: =TEXT(A10,"yyyy-mm-01") -> 2003-09-01 | C10: {=INDEX($C:$C,MATCH(ROW()-MOD(ROW()-ROW($C$2),3),ROW($C:$C),0))+(B10-INDEX($B:$B,MATCH(ROW()-MOD(ROW()-ROW($C$2),3),ROW($C:$C),0)))/(INDEX($B:$B,MATCH(ROW()-MOD(ROW()-ROW($C$2),3),ROW($C:$C),0)+3)-INDEX($B:$B,MATCH(ROW()-MOD(ROW()-ROW($C$2),3),ROW($C:$C),0)))*(INDEX($C:$C,MATCH(ROW()-MOD(ROW()-ROW($C$2),3),ROW($C:$C),0)+3)-INDEX($C:$C,MATCH(ROW()-MOD(ROW()-ROW($C$2),3),ROW($C:$C),0)))} -> 163333.57
A11: =EDATE(A10,1) -> 37895 | B11: =TEXT(A11,"yyyy-mm-01") -> 2003-10-01 | C11: =VLOOKUP(A11,'2003-2026'!$A$48:$B$141,2,FALSE) -> 165834
A12: =EDATE(A11,1) -> 37926 | B12: =TEXT(A12,"yyyy-mm-01") -> 2003-11-01 | C12: {=INDEX($C:$C,MATCH(ROW()-MOD(ROW()-ROW($C$2),3),ROW($C:$C),0))+(B12-INDEX($B:$B,MATCH(ROW()-MOD(ROW()-ROW($C$2),3),ROW($C:$C),0)))/(INDEX($B:$B,MATCH(ROW()-MOD(ROW()-ROW($C$2),3),ROW($C:$C),0)+3)-INDEX($B:$B,MATCH(ROW()-MOD(ROW()-ROW($C$2),3),ROW($C:$C),0)))*(INDEX($C:$C,MATCH(ROW()-MOD(ROW()-ROW($C$2),3),ROW($C:$C),0)+3)-INDEX($C:$C,MATCH(ROW()-MOD(ROW()-ROW($C$2),3),ROW($C:$C),0)))} -> 172276.95
A13: =EDATE(A12,1) -> 37956 | B13: =TEXT(A13,"yyyy-mm-01") -> 2003-12-01 | C13: {=INDEX($C:$C,MATCH(ROW()-MOD(ROW()-ROW($C$2),3),ROW($C:$C),0))+(B13-INDEX($B:$B,MATCH(ROW()-MOD(ROW()-ROW($C$2),3),ROW($C:$C),0)))/(INDEX($B:$B,MATCH(ROW()-MOD(ROW()-ROW($C$2),3),ROW($C:$C),0)+3)-INDEX($B:$B,MATCH(ROW()-MOD(ROW()-ROW($C$2),3),ROW($C:$C),0)))*(INDEX($C:$C,MATCH(ROW()-MOD(ROW()-ROW($C$2),3),ROW($C:$C),0)+3)-INDEX($C:$C,MATCH(ROW()-MOD(ROW()-ROW($C$2),3),ROW($C:$C),0)))} -> 178512.05
A14: =EDATE(A13,1) -> 37987 | B14: =TEXT(A14,"yyyy-mm-01") -> 2004-01-01 | C14: =VLOOKUP(A14,'2003-2026'!$A$48:$B$141,2,FALSE) -> 184955
A15: =EDATE(A14,1) -> 38018 | B15: =TEXT(A15,"yyyy-mm-01") -> 2004-02-01 | C15: {=INDEX($C:$C,MATCH(ROW()-MOD(ROW()-ROW($C$2),3),ROW($C:$C),0))+(B15-INDEX($B:$B,MATCH(ROW()-MOD(ROW()-ROW($C$2),3),ROW($C:$C),0)))/(INDEX($B:$B,MATCH(ROW()-MOD(ROW()-ROW($C$2),3),ROW($C:$C),0)+3)-INDEX($B:$B,MATCH(ROW()-MOD(ROW()-ROW($C$2),3),ROW($C:$C),0)))*(INDEX($C:$C,MATCH(ROW()-MOD(ROW()-ROW($C$2),3),ROW($C:$C),0)+3)-INDEX($C:$C,MATCH(ROW()-MOD(ROW()-ROW($C$2),3),ROW($C:$C),0)))} -> 186516.58
A16: =EDATE(A15,1) -> 38047 | B16: =TEXT(A16,"yyyy-mm-01") -> 2004-03-01 | C16: {=INDEX($C:$C,MATCH(ROW()-MOD(ROW()-ROW($C$2),3),ROW($C:$C),0))+(B16-INDEX($B:$B,MATCH(ROW()-MOD(ROW()-ROW($C$2),3),ROW($C:$C),0)))/(INDEX($B:$B,MATCH(ROW()-MOD(ROW()-ROW($C$2),3),ROW($C:$C),0)+3)-INDEX($B:$B,MATCH(ROW()-MOD(ROW()-ROW($C$2),3),ROW($C:$C),0)))*(INDEX($C:$C,MATCH(ROW()-MOD(ROW()-ROW($C$2),3),ROW($C:$C),0)+3)-INDEX($C:$C,MATCH(ROW()-MOD(ROW()-ROW($C$2),3),ROW($C:$C),0)))} -> 187977.42
A17: =EDATE(A16,1) -> 38078 | B17: =TEXT(A17,"yyyy-mm-01") -> 2004-04-01 | C17: =VLOOKUP(A17,'2003-2026'!$A$48:$B$141,2,FALSE) -> 189539
A18: =EDATE(A17,1) -> 38108 | B18: =TEXT(A18,"yyyy-mm-01") -> 2004-05-01 | C18: {=INDEX($C:$C,MATCH(ROW()-MOD(ROW()-ROW($C$2),3),ROW($C:$C),0))+(B18-INDEX($B:$B,MATCH(ROW()-MOD(ROW()-ROW($C$2),3),ROW($C:$C),0)))/(INDEX($B:$B,MATCH(ROW()-MOD(ROW()-ROW($C$2),3),ROW($C:$C),0)+3)-INDEX($B:$B,MATCH(ROW()-MOD(ROW()-ROW($C$2),3),ROW($C:$C),0)))*(INDEX($C:$C,MATCH(ROW()-MOD(ROW()-ROW($C$2),3),ROW($C:$C),0)+3)-INDEX($C:$C,MATCH(ROW()-MOD(ROW()-ROW($C$2),3),ROW($C:$C),0)))} -> 190465.37
A19: =EDATE(A18,1) -> 38139 | B19: =TEXT(A19,"yyyy-mm-01") -> 2004-06-01 | C19: {=INDEX($C:$C,MATCH(ROW()-MOD(ROW()-ROW($C$2),3),ROW($C:$C),0))+(B19-INDEX($B:$B,MATCH(ROW()-MOD(ROW()-ROW($C$2),3),ROW($C:$C),0)))/(INDEX($B:$B,MATCH(ROW()-MOD(ROW()-ROW($C$2),3),ROW($C:$C),0)+3)-INDEX($B:$B,MATCH(ROW()-MOD(ROW()-ROW($C$2),3),ROW($C:$C),0)))*(INDEX($C:$C,MATCH(ROW()-MOD(ROW()-ROW($C$2),3),ROW($C:$C),0)+3)-INDEX($C:$C,MATCH(ROW()-MOD(ROW()-ROW($C$2),3),ROW($C:$C),0)))} -> 191422.63
A20: =EDATE(A19,1) -> 38169 | B20: =TEXT(A20,"yyyy-mm-01") -> 2004-07-01 | C20: =VLOOKUP(A20,'2003-2026'!$A$48:$B$141,2,FALSE) -> 192349
A21: =EDATE(A20,1) -> 38200 | B21: =TEXT(A21,"yyyy-mm-01") -> 2004-08-01 | C21: {=INDEX($C:$C,MATCH(ROW()-MOD(ROW()-ROW($C$2),3),ROW($C:$C),0))+(B21-INDEX($B:$B,MATCH(ROW()-MOD(ROW()-ROW($C$2),3),ROW($C:$C),0)))/(INDEX($B:$B,MATCH(ROW()-MOD(ROW()-ROW($C$2),3),ROW($C:$C),0)+3)-INDEX($B:$B,MATCH(ROW()-MOD(ROW()-ROW($C$2),3),ROW($C:$C),0)))*(INDEX($C:$C,MATCH(ROW()-MOD(ROW()-ROW($C$2),3),ROW($C:$C),0)+3)-INDEX($C:$C,MATCH(ROW()-MOD(ROW()-ROW($C$2),3),ROW($C:$C),0)))} -> 192635.41
A22: =EDATE(A21,1) -> 38231 | B22: =TEXT(A22,"yyyy-mm-01") -> 2004-09-01 | C22: {=INDEX($C:$C,MATCH(ROW()-MOD(ROW()-ROW($C$2),3),ROW($C:$C),0))+(B22-INDEX($B:$B,MATCH(ROW()-MOD(ROW()-ROW($C$2),3),ROW($C:$C),0)))/(INDEX($B:$B,MATCH(ROW()-MOD(ROW()-ROW($C$2),3),ROW($C:$C),0)+3)-INDEX($B:$B,MATCH(ROW()-MOD(ROW()-ROW($C$2),3),ROW($C:$C),0)))*(INDEX($C:$C,MATCH(ROW()-MOD(ROW()-ROW($C$2),3),ROW($C:$C),0)+3)-INDEX($C:$C,MATCH(ROW()-MOD(ROW()-ROW($C$2),3),ROW($C:$C),0)))} -> 192921.83
A23: =EDATE(A22,1) -> 38261 | B23: =TEXT(A23,"yyyy-mm-01") -> 2004-10-01 | C23: =VLOOKUP(A23,'2003-2026'!$A$48:$B$141,2,FALSE) -> 193199
A24: =EDATE(A23,1) -> 38292 | B24: =TEXT(A24,"yyyy-mm-01") -> 2004-11-01 | C24: {=INDEX($C:$C,MATCH(ROW()-MOD(ROW()-ROW($C$2),3),ROW($C:$C),0))+(B24-INDEX($B:$B,MATCH(ROW()-MOD(ROW()-ROW($C$2),3),ROW($C:$C),0)))/(INDEX($B:$B,MATCH(ROW()-MOD(ROW()-ROW($C$2),3),ROW($C:$C),0)+3)-INDEX($B:$B,MATCH(ROW()-MOD(ROW()-ROW($C$2),3),ROW($C:$C),0)))*(INDEX($C:$C,MATCH(ROW()-MOD(ROW()-ROW($C$2),3),ROW($C:$C),0)+3)-INDEX($C:$C,MATCH(ROW()-MOD(ROW()-ROW($C$2),3),ROW($C:$C),0)))} -> 199983.96
A25: =EDATE(A24,1) -> 38322 | B25: =TEXT(A25,"yyyy-mm-01") -> 2004-12-01 | C25: {=INDEX($C:$C,MATCH(ROW()-MOD(ROW()-ROW($C$2),3),ROW($C:$C),0))+(B25-INDEX($B:$B,MATCH(ROW()-MOD(ROW()-ROW($C$2),3),ROW($C:$C),0)))/(INDEX($B:$B,MATCH(ROW()-MOD(ROW()-ROW($C$2),3),ROW($C:$C),0)+3)-INDEX($B:$B,MATCH(ROW()-MOD(ROW()-ROW($C$2),3),ROW($C:$C),0)))*(INDEX($C:$C,MATCH(ROW()-MOD(ROW()-ROW($C$2),3),ROW($C:$C),0)+3)-INDEX($C:$C,MATCH(ROW()-MOD(ROW()-ROW($C$2),3),ROW($C:$C),0)))} -> 206550.04
A26: =EDATE(A25,1) -> 38353 | B26: =TEXT(A26,"yyyy-mm-01") -> 2005-01-01 | C26: =VLOOKUP(A26,'2003-2026'!$A$48:$B$141,2,FALSE) -> 213335
A27: =EDATE(A26,1) -> 38384 | B27: =TEXT(A27,"yyyy-mm-01") -> 2005-02-01 | C27: {=INDEX($C:$C,MATCH(ROW()-MOD(ROW()-ROW($C$2),3),ROW($C:$C),0))+(B27-INDEX($B:$B,MATCH(ROW()-MOD(ROW()-ROW($C$2),3),ROW($C:$C),0)))/(INDEX($B:$B,MATCH(ROW()-MOD(ROW()-ROW($C$2),3),ROW($C:$C),0)+3)-INDEX($B:$B,MATCH(ROW()-MOD(ROW()-ROW($C$2),3),ROW($C:$C),0)))*(INDEX($C:$C,MATCH(ROW()-MOD(ROW()-ROW($C$2),3),ROW($C:$C),0)+3)-INDEX($C:$C,MATCH(ROW()-MOD(ROW()-ROW($C$2),3),ROW($C:$C),0)))} -> 215407.87
A28: =EDATE(A27,1) -> 38412 | B28: =TEXT(A28,"yyyy-mm-01") -> 2005-03-01 | C28: {=INDEX($C:$C,MATCH(ROW()-MOD(ROW()-ROW($C$2),3),ROW($C:$C),0))+(B28-INDEX($B:$B,MATCH(ROW()-MOD(ROW()-ROW($C$2),3),ROW($C:$C),0)))/(INDEX($B:$B,MATCH(ROW()-MOD(ROW()-ROW($C$2),3),ROW($C:$C),0)+3)-INDEX($B:$B,MATCH(ROW()-MOD(ROW()-ROW($C$2),3),ROW($C:$C),0)))*(INDEX($C:$C,MATCH(ROW()-MOD(ROW()-ROW($C$2),3),ROW($C:$C),0)+3)-INDEX($C:$C,MATCH(ROW()-MOD(ROW()-ROW($C$2),3),ROW($C:$C),0)))} -> 217280.13
A29: =EDATE(A28,1) -> 38443 | B29: =TEXT(A29,"yyyy-mm-01") -> 2005-04-01 | C29: =VLOOKUP(A29,'2003-2026'!$A$48:$B$141,2,FALSE) -> 219353
A30: =EDATE(A29,1) -> 38473 | B30: =TEXT(A30,"yyyy-mm-01") -> 2005-05-01 | C30: {=INDEX($C:$C,MATCH(ROW()-MOD(ROW()-ROW($C$2),3),ROW($C:$C),0))+(B30-INDEX($B:$B,MATCH(ROW()-MOD(ROW()-ROW($C$2),3),ROW($C:$C),0)))/(INDEX($B:$B,MATCH(ROW()-MOD(ROW()-ROW($C$2),3),ROW($C:$C),0)+3)-INDEX($B:$B,MATCH(ROW()-MOD(ROW()-ROW($C$2),3),ROW($C:$C),0)))*(INDEX($C:$C,MATCH(ROW()-MOD(ROW()-ROW($C$2),3),ROW($C:$C),0)+3)-INDEX($C:$C,MATCH(ROW()-MOD(ROW()-ROW($C$2),3),ROW($C:$C),0)))} -> 222147.29
A31: =EDATE(A30,1) -> 38504 | B31: =TEXT(A31,"yyyy-mm-01") -> 2005-06-01 | C31: {=INDEX($C:$C,MATCH(ROW()-MOD(ROW()-ROW($C$2),3),ROW($C:$C),0))+(B31-INDEX($B:$B,MATCH(ROW()-MOD(ROW()-ROW($C$2),3),ROW($C:$C),0)))/(INDEX($B:$B,MATCH(ROW()-MOD(ROW()-ROW($C$2),3),ROW($C:$C),0)+3)-INDEX($B:$B,MATCH(ROW()-MOD(ROW()-ROW($C$2),3),ROW($C:$C),0)))*(INDEX($C:$C,MATCH(ROW()-MOD(ROW()-ROW($C$2),3),ROW($C:$C),0)+3)-INDEX($C:$C,MATCH(ROW()-MOD(ROW()-ROW($C$2),3),ROW($C:$C),0)))} -> 225034.71
A32: =EDATE(A31,1) -> 38534 | B32: =TEXT(A32,"yyyy-mm-01") -> 2005-07-01 | C32: =VLOOKUP(A32,'2003-2026'!$A$48:$B$141,2,FALSE) -> 227829
A33: =EDATE(A32,1) -> 38565 | B33: =TEXT(A33,"yyyy-mm-01") -> 2005-08-01 | C33: {=INDEX($C:$C,MATCH(ROW()-MOD(ROW()-ROW($C$2),3),ROW($C:$C),0))+(B33-INDEX($B:$B,MATCH(ROW()-MOD(ROW()-ROW($C$2),3),ROW($C:$C),0)))/(INDEX($B:$B,MATCH(ROW()-MOD(ROW()-ROW($C$2),3),ROW($C:$C),0)+3)-INDEX($B:$B,MATCH(ROW()-MOD(ROW()-ROW($C$2),3),ROW($C:$C),0)))*(INDEX($C:$C,MATCH(ROW()-MOD(ROW()-ROW($C$2),3),ROW($C:$C),0)+3)-INDEX($C:$C,MATCH(ROW()-MOD(ROW()-ROW($C$2),3),ROW($C:$C),0)))} -> 227451.27
A34: =EDATE(A33,1) -> 38596 | B34: =TEXT(A34,"yyyy-mm-01") -> 2005-09-01 | C34: {=INDEX($C:$C,MATCH(ROW()-MOD(ROW()-ROW($C$2),3),ROW($C:$C),0))+(B34-INDEX($B:$B,MATCH(ROW()-MOD(ROW()-ROW($C$2),3),ROW($C:$C),0)))/(INDEX($B:$B,MATCH(ROW()-MOD(ROW()-ROW($C$2),3),ROW($C:$C),0)+3)-INDEX($B:$B,MATCH(ROW()-MOD(ROW()-ROW($C$2),3),ROW($C:$C),0)))*(INDEX($C:$C,MATCH(ROW()-MOD(ROW()-ROW($C$2),3),ROW($C:$C),0)+3)-INDEX($C:$C,MATCH(ROW()-MOD(ROW()-ROW($C$2),3),ROW($C:$C),0)))} -> 227073.54
A35: =EDATE(A34,1) -> 38626 | B35: =TEXT(A35,"yyyy-mm-01") -> 2005-10-01 | C35: =VLOOKUP(A35,'2003-2026'!$A$48:$B$141,2,FALSE) -> 226708
A36: =EDATE(A35,1) -> 38657 | B36: =TEXT(A36,"yyyy-mm-01") -> 2005-11-01 | C36: {=INDEX($C:$C,MATCH(ROW()-MOD(ROW()-ROW($C$2),3),ROW($C:$C),0))+(B36-INDEX($B:$B,MATCH(ROW()-MOD(ROW()-ROW($C$2),3),ROW($C:$C),0)))/(INDEX($B:$B,MATCH(ROW()-MOD(ROW()-ROW($C$2),3),ROW($C:$C),0)+3)-INDEX($B:$B,MATCH(ROW()-MOD(ROW()-ROW($C$2),3),ROW($C:$C),0)))*(INDEX($C:$C,MATCH(ROW()-MOD(ROW()-ROW($C$2),3),ROW($C:$C),0)+3)-INDEX($C:$C,MATCH(ROW()-MOD(ROW()-ROW($C$2),3),ROW($C:$C),0)))} -> 236983.83
A37: =EDATE(A36,1) -> 38687 | B37: =TEXT(A37,"yyyy-mm-01") -> 2005-12-01 | C37: {=INDEX($C:$C,MATCH(ROW()-MOD(ROW()-ROW($C$2),3),ROW($C:$C),0))+(B37-INDEX($B:$B,MATCH(ROW()-MOD(ROW()-ROW($C$2),3),ROW($C:$C),0)))/(INDEX($B:$B,MATCH(ROW()-MOD(ROW()-ROW($C$2),3),ROW($C:$C),0)+3)-INDEX($B:$B,MATCH(ROW()-MOD(ROW()-ROW($C$2),3),ROW($C:$C),0)))*(INDEX($C:$C,MATCH(ROW()-MOD(ROW()-ROW($C$2),3),ROW($C:$C),0)+3)-INDEX($C:$C,MATCH(ROW()-MOD(ROW()-ROW($C$2),3),ROW($C:$C),0)))} -> 246928.17
A38: =EDATE(A37,1) -> 38718 | B38: =TEXT(A38,"yyyy-mm-01") -> 2006-01-01 | C38: =VLOOKUP(A38,'2003-2026'!$A$48:$B$141,2,FALSE) -> 257204
A39: =EDATE(A38,1) -> 38749 | B39: =TEXT(A39,"yyyy-mm-01") -> 2006-02-01 | C39: {=INDEX($C:$C,MATCH(ROW()-MOD(ROW()-ROW($C$2),3),ROW($C:$C),0))+(B39-INDEX($B:$B,MATCH(ROW()-MOD(ROW()-ROW($C$2),3),ROW($C:$C),0)))/(INDEX($B:$B,MATCH(ROW()-MOD(ROW()-ROW($C$2),3),ROW($C:$C),0)+3)-INDEX($B:$B,MATCH(ROW()-MOD(ROW()-ROW($C$2),3),ROW($C:$C),0)))*(INDEX($C:$C,MATCH(ROW()-MOD(ROW()-ROW($C$2),3),ROW($C:$C),0)+3)-INDEX($C:$C,MATCH(ROW()-MOD(ROW()-ROW($C$2),3),ROW($C:$C),0)))} -> 262741.29
A40: =EDATE(A39,1) -> 38777 | B40: =TEXT(A40,"yyyy-mm-01") -> 2006-03-01 | C40: {=INDEX($C:$C,MATCH(ROW()-MOD(ROW()-ROW($C$2),3),ROW($C:$C),0))+(B40-INDEX($B:$B,MATCH(ROW()-MOD(ROW()-ROW($C$2),3),ROW($C:$C),0)))/(INDEX($B:$B,MATCH(ROW()-MOD(ROW()-ROW($C$2),3),ROW($C:$C),0)+3)-INDEX($B:$B,MATCH(ROW()-MOD(ROW()-ROW($C$2),3),ROW($C:$C),0)))*(INDEX($C:$C,MATCH(ROW()-MOD(ROW()-ROW($C$2),3),ROW($C:$C),0)+3)-INDEX($C:$C,MATCH(ROW()-MOD(ROW()-ROW($C$2),3),ROW($C:$C),0)))} -> 267742.71
...

Sheet Final Cleaned
A1: date | B1: ru_extdebt_m
A2: =Sheet1!B2 -> 2003-01-01 | B2: =Sheet1!C2 -> 151302
A3: =Sheet1!B3 -> 2003-02-01 | B3: =Sheet1!C3 -> 151960.92
A4: =Sheet1!B4 -> 2003-03-01 | B4: =Sheet1!C4 -> 152556.08
A5: =Sheet1!B5 -> 2003-04-01 | B5: =Sheet1!C5 -> 153215
A6: =Sheet1!B6 -> 2003-05-01 | B6: =Sheet1!C6 -> 154847.2
A7: =Sheet1!B7 -> 2003-06-01 | B7: =Sheet1!C7 -> 156533.8
A8: =Sheet1!B8 -> 2003-07-01 | B8: =Sheet1!C8 -> 158166
A9: =Sheet1!B9 -> 2003-08-01 | B9: =Sheet1!C9 -> 160749.78
A10: =Sheet1!B10 -> 2003-09-01 | B10: =Sheet1!C10 -> 163333.57
A11: =Sheet1!B11 -> 2003-10-01 | B11: =Sheet1!C11 -> 165834
A12: =Sheet1!B12 -> 2003-11-01 | B12: =Sheet1!C12 -> 172276.95
A13: =Sheet1!B13 -> 2003-12-01 | B13: =Sheet1!C13 -> 178512.05
... A281: =Sheet1!B281 -> 2026-04-01 | B281: =Sheet1!C281 -> 299063.74
