Workbook

Sheet RC
A1: DT | B1: ruo | C1: vol | D1: T | E1: C | F1: MinRate | G1: Percentile25 | H1: Percentile75 | I1: MaxRate | J1: StatusXML | K1: DateUpdate
A2: 46247 | B2: 13.98 | C2: 677.71 | D2: 63 | E2: 21 | F2: 12.8 | G2: 13.75 | H2: 14 | I2: 14.15 | J2: 0 | K2: 46248.596
A3: 46246 | B3: 13.87 | C3: 688 | D3: 63 | E3: 20 | F3: 12.8 | G3: 13.6 | H3: 13.95 | I3: 14 | J3: 0 | K3: 46247.597
A4: 46245 | B4: 13.59 | C4: 857.05 | D4: 77 | E4: 22 | F4: 12.8 | G4: 13.4 | H4: 13.65 | I4: 13.9 | J4: 0 | K4: 46246.595
A5: 46244 | B5: 13.57 | C5: 724.74 | D5: 67 | E5: 24 | F5: 12.8 | G5: 13.4 | H5: 13.6 | I5: 13.7 | J5: 0 | K5: 46245.597
A6: 46241 | B6: 13.71 | C6: 646.82 | D6: 62 | E6: 24 | F6: 12.8 | G6: 13.4 | H6: 13.75 | I6: 13.9 | J6: 0 | K6: 46244.597
A7: 46240 | B7: 13.57 | C7: 811.83 | D7: 72 | E7: 23 | F7: 12.8 | G7: 13.4 | H7: 13.6 | I7: 13.75 | J7: 0 | K7: 46241.596
A8: 46239 | B8: 13.68 | C8: 826.11 | D8: 75 | E8: 21 | F8: 13.4 | G8: 13.57 | H8: 13.75 | I8: 13.9 | J8: 0 | K8: 46240.595
A9: 46238 | B9: 13.84 | C9: 823.9 | D9: 72 | E9: 20 | F9: 13.4 | G9: 13.61 | H9: 13.85 | I9: 14 | J9: 0 | K9: 46239.6
A10: 46237 | B10: 13.86 | C10: 892.28 | D10: 72 | E10: 20 | F10: 13.5 | G10: 13.7 | H10: 13.9 | I10: 14.1 | J10: 0 | K10: 46238.598
A11: 46234 | B11: 13.95 | C11: 619.1 | D11: 65 | E11: 19 | F11: 13.69 | G11: 13.75 | H11: 14 | I11: 14.15 | J11: 0 | K11: 46237.601
A12: 46233 | B12: 13.99 | C12: 694.28 | D12: 63 | E12: 23 | F12: 13.25 | G12: 13.75 | H12: 14 | I12: 14.1 | J12: 0 | K12: 46234.596
A13: 46232 | B13: 13.9 | C13: 739.15 | D13: 71 | E13: 24 | F13: 13.25 | G13: 13.7 | H13: 13.98 | I13: 14.15 | J13: 0 | K13: 46233.597
... A579: 45392 | B579: 15.61 | C579: 400.84 | D579: 47 | E579: 21 | F579: 15.1 | G579: 15.43 | H579: 15.75 | I579: 16.35 | J579: 0 | K579: 45393.588
A580: 45391 | B580: 15.9 | J580: 1 | K580: 45392.589
A581: 45390 | B581: 15.86 | C581: 794.59 | D581: 64 | E581: 22 | F581: 15.05 | G581: 15.54 | H581: 15.85 | I581: 16.15 | J581: 0 | K581: 45391.588
A582: 45387 | B582: 15.72 | C582: 789.86 | D582: 68 | E582: 24 | F582: 15.1 | G582: 15.5 | H582: 15.75 | I582: 16.25 | J582: 0 | K582: 45390.589
A583: 45386 | B583: 15.67 | C583: 909.18 | D583: 75 | E583: 23 | F583: 15.05 | G583: 15.21 | H583: 15.74 | I583: 16.25 | J583: 0 | K583: 45387.589
A584: 45385 | B584: 15.7 | C584: 628.75 | D584: 86 | E584: 25 | F584: 15.05 | G584: 15.3 | H584: 15.85 | I584: 16.25 | J584: 0 | K584: 45386.589
A585: 45384 | B585: 15.49 | C585: 438.68 | D585: 60 | E585: 25 | F585: 15.05 | G585: 15.29 | H585: 15.8 | I585: 16.25 | J585: 0 | K585: 45385.589
A586: 45383 | B586: 15.63 | C586: 438.09 | D586: 62 | E586: 23 | F586: 15.1 | G586: 15.5 | H586: 15.75 | I586: 16.3 | J586: 0 | K586: 45384.589
A587: 45380 | B587: 15.99 | C587: 526.63 | D587: 75 | E587: 18 | F587: 15.1 | G587: 15.71 | H587: 16.25 | I587: 17.1 | J587: 0 | K587: 45383.587
A588: 45379 | B588: 15.42 | C588: 362.04 | D588: 48 | E588: 23 | F588: 15.07 | G588: 15.35 | H588: 15.75 | I588: 16.1 | J588: 0 | K588: 45380.588
A589: 45378 | B589: 15.25 | C589: 359.69 | D589: 37 | E589: 19 | F589: 15.05 | G589: 15.25 | H589: 15.4 | I589: 15.75 | J589: 0 | K589: 45379.59
A590: 45377 | B590: 15.5 | C590: 296 | D590: 29 | E590: 16 | F590: 15.15 | G590: 15.5 | H590: 15.5 | I590: 16.45 | J590: 0 | K590: 45378.589
A591: 45376 | B591: 15.29 | C591: 318.3 | D591: 39 | E591: 18 | F591: 15.1 | G591: 15.25 | H591: 15.35 | I591: 15.5 | J591: 0 | K591: 45377.589
A592: 45373 | B592: 15.35 | C592: 299.3 | D592: 38 | E592: 18 | F592: 15.1 | G592: 15.25 | H592: 15.5 | I592: 15.75 | J592: 0 | K592: 45376.589
A593: 45372 | B593: 15.54 | J593: 1 | K593: 45373.59
A594: 45371 | B594: 15.7 | C594: 406.5 | D594: 48 | E594: 18 | F594: 15.1 | G594: 15.48 | H594: 15.75 | I594: 15.9 | J594: 0 | K594: 45372.595
A595: 45370 | B595: 15.68 | C595: 500.96 | D595: 59 | E595: 20 | F595: 15.1 | G595: 15.36 | H595: 15.75 | I595: 16 | J595: 0 | K595: 45371.589
A596: 45369 | B596: 15.72 | C596: 582.16 | D596: 63 | E596: 23 | F596: 15.1 | G596: 15.4 | H596: 15.75 | I596: 16 | J596: 0 | K596: 45370.59
A597: 45366 | B597: 15.74 | C597: 546.82 | D597: 63 | E597: 23 | F597: 15.15 | G597: 15.5 | H597: 15.75 | I597: 15.9 | J597: 0 | K597: 45369.59
A598: 45365 | B598: 15.75 | C598: 478.58 | D598: 57 | E598: 20 | F598: 15.1 | G598: 15.7 | H598: 15.75 | I598: 16 | J598: 0 | K598: 45366.588
A599: 45364 | B599: 15.75 | C599: 397.9 | D599: 47 | E599: 20 | F599: 15.1 | G599: 15.54 | H599: 15.75 | I599: 15.8 | J599: 0 | K599: 45365.589
A600: 45363 | B600: 16 | C600: 509.82 | D600: 55 | E600: 17 | F600: 15.45 | G600: 15.75 | H600: 16 | I600: 16.25 | J600: 0 | K600: 45364.692
A601: 45362 | B601: 15.89 | C601: 469.48 | D601: 54 | E601: 22 | F601: 15.1 | G601: 15.75 | H601: 16 | I601: 16.45 | J601: 0 | K601: 45363.589
A602: 45358 | B602: 15.67 | C602: 438.39 | D602: 55 | E602: 23 | F602: 15.05 | G602: 15.5 | H602: 16 | I602: 16.3 | J602: 0 | K602: 45362.589
A603: 45357 | B603: 15.4 | C603: 296.31 | D603: 41 | E603: 17 | F603: 15.25 | G603: 15.33 | H603: 15.5 | I603: 16 | J603: 0 | K603: 45358.589
A604: 45356 | B604: 15.34 | C604: 503.14 | D604: 58 | E604: 21 | F604: 15 | G604: 15.15 | H604: 15.4 | I604: 15.55 | J604: 0 | K604: 45357.59
A605: 45355 | B605: 15.46 | C605: 609.11 | D605: 62 | E605: 19 | F605: 15.1 | G605: 15.25 | H605: 15.5 | I605: 15.55 | J605: 0 | K605: 45356.592
...

Sheet TRANSFORM
A1: DATE | B1: MONTHS | C1: RUONIA_AVERAGE | D1: RUONIA
A2: ='RC'!A2 -> 46247 | B2: =TEXT(A2,"yyyy-mm-01") -> 2026-08-01 | C2: =AVERAGEIF(B:B,B2,D:D) -> 13.741111 | D2: ='RC'!B2 -> 13.98
A3: ='RC'!A3 -> 46246 | B3: =TEXT(A3,"yyyy-mm-01") -> 2026-08-01 | C3: =AVERAGEIF(B:B,B3,D:D) -> 13.741111 | D3: ='RC'!B3 -> 13.87
A4: ='RC'!A4 -> 46245 | B4: =TEXT(A4,"yyyy-mm-01") -> 2026-08-01 | C4: =AVERAGEIF(B:B,B4,D:D) -> 13.741111 | D4: ='RC'!B4 -> 13.59
A5: ='RC'!A5 -> 46244 | B5: =TEXT(A5,"yyyy-mm-01") -> 2026-08-01 | C5: =AVERAGEIF(B:B,B5,D:D) -> 13.741111 | D5: ='RC'!B5 -> 13.57
A6: ='RC'!A6 -> 46241 | B6: =TEXT(A6,"yyyy-mm-01") -> 2026-08-01 | C6: =AVERAGEIF(B:B,B6,D:D) -> 13.741111 | D6: ='RC'!B6 -> 13.71
A7: ='RC'!A7 -> 46240 | B7: =TEXT(A7,"yyyy-mm-01") -> 2026-08-01 | C7: =AVERAGEIF(B:B,B7,D:D) -> 13.741111 | D7: ='RC'!B7 -> 13.57
A8: ='RC'!A8 -> 46239 | B8: =TEXT(A8,"yyyy-mm-01") -> 2026-08-01 | C8: =AVERAGEIF(B:B,B8,D:D) -> 13.741111 | D8: ='RC'!B8 -> 13.68
A9: ='RC'!A9 -> 46238 | B9: =TEXT(A9,"yyyy-mm-01") -> 2026-08-01 | C9: =AVERAGEIF(B:B,B9,D:D) -> 13.741111 | D9: ='RC'!B9 -> 13.84
A10: ='RC'!A10 -> 46237 | B10: =TEXT(A10,"yyyy-mm-01") -> 2026-08-01 | C10: =AVERAGEIF(B:B,B10,D:D) -> 13.741111 | D10: ='RC'!B10 -> 13.86
A11: ='RC'!A11 -> 46234 | B11: =TEXT(A11,"yyyy-mm-01") -> 2026-07-01 | C11: =AVERAGEIF(B:B,B11,D:D) -> 14.282609 | D11: ='RC'!B11 -> 13.95
A12: ='RC'!A12 -> 46233 | B12: =TEXT(A12,"yyyy-mm-01") -> 2026-07-01 | C12: =AVERAGEIF(B:B,B12,D:D) -> 14.282609 | D12: ='RC'!B12 -> 13.99
A13: ='RC'!A13 -> 46232 | B13: =TEXT(A13,"yyyy-mm-01") -> 2026-07-01 | C13: =AVERAGEIF(B:B,B13,D:D) -> 14.282609 | D13: ='RC'!B13 -> 13.9
... A3947: ='RC'!A3947 -> 40392 | B3947: =TEXT(A3947,"yyyy-mm-01") -> 2010-08-01 | C3947: =AVERAGEIF(B:B,B3947,D:D) -> 2.54 | D3947: ='RC'!B3947 -> 2.22

Sheet Final Cleaned
A1: date | B1: ru_ruonia_m
A2: {=_xlfn.UNIQUE(TRANSFORM!B2:C3947)} -> 2026-08-01 | B2: 13.741111
A3: 2026-07-01 | B3: 14.282609
A4: 2026-06-01 | B4: 14.031429
A5: 2026-05-01 | B5: 14.170526
A6: 2026-04-01 | B6: 14.638636
A7: 2026-03-01 | B7: 14.974762
A8: 2026-02-01 | B8: 15.325263
A9: 2026-01-01 | B9: 15.692667
A10: 2025-12-01 | B10: 16.04
A11: 2025-11-01 | B11: 16.323684
A12: 2025-10-01 | B12: 16.494783
A13: 2025-09-01 | B13: 17.198636
A14: 2025-08-01 | B14: 17.733333
... A194: 2010-08-01 | B194: 2.54
