Workbook

Sheet 2013-2018
A1: /data/@id | B1: /data/metadata/columns/column/@bytes | C1: /data/metadata/columns/column/@max_size | D1: /data/metadata/columns/column/@name | E1: /data/metadata/columns/column/@type | F1: /data/rows/row/@BOARDID | G1: /data/rows/row/@CAPITALIZATION | H1: /data/rows/row/@CLOSE | I1: /data/rows/row/@CURRENCYID | J1: /data/rows/row/@DECIMALS | K1: /data/rows/row/@DIVISOR | L1: /data/rows/row/@DURATION | M1: /data/rows/row/@HIGH | N1: /data/rows/row/@LOW | O1: /data/rows/row/@NAME | P1: /data/rows/row/@OPEN | Q1: /data/rows/row/@RECALC_DATE | R1: /data/rows/row/@SECID | S1: /data/rows/row/@SHORTNAME | T1: /data/rows/row/@TRADE_SESSION_DATE | U1: /data/rows/row/@TRADEDATE | V1: /data/rows/row/@TRADINGSESSION | W1: /data/rows/row/@VALUE | X1: /data/rows/row/@VOLUME | Y1: /data/rows/row/@YIELD
A2: history | B2: 12 | C2: 0 | D2: BOARDID | E2: string
A3: history | B3: 36 | C3: 0 | D3: SECID | E3: string
A4: history | B4: 10 | C4: 0 | D4: TRADEDATE | E4: date
A5: history | B5: 189 | C5: 0 | D5: SHORTNAME | E5: string
A6: history | B6: 765 | C6: 0 | D6: NAME | E6: string
A7: history | D7: CLOSE | E7: double
A8: history | D8: OPEN | E8: double
A9: history | D9: HIGH | E9: double
A10: history | D10: LOW | E10: double
A11: history | D11: VALUE | E11: double
A12: history | D12: DURATION | E12: int32
A13: history | D13: YIELD | E13: double
A14: history | D14: DECIMALS | E14: int32
A15: history | D15: CAPITALIZATION | E15: double
A16: history | B16: 9 | C16: 0 | D16: CURRENCYID | E16: string
A17: history | D17: DIVISOR | E17: double
A18: history | B18: 3 | C18: 0 | D18: TRADINGSESSION | E18: string
A19: history | D19: VOLUME | E19: double
A20: history | B20: 10 | C20: 0 | D20: TRADE_SESSION_DATE | E20: date
A21: history | B21: 10 | C21: 0 | D21: RECALC_DATE | E21: date
A22: history | F22: SNDX | G22: 715338000000 | H22: 224.55 | I22: RUB | J22: 2 | L22: 856 | M22: 224.6 | N22: 224.54 | O22: Индекс Мосбиржи корпоративных облигаций | P22: 224.6 | R22: RUCBITR | S22: Индекс Мосбиржи корп обл CBITR | T22: 41282 | U22: 41282 | V22: 3 | W22: 784691 | Y22: 8.63
A23: history | F23: SNDX | G23: 715389000000 | H23: 224.57 | I23: RUB | J23: 2 | L23: 855 | M23: 224.61 | N23: 224.55 | O23: Индекс Мосбиржи корпоративных облигаций | P23: 224.55 | R23: RUCBITR | S23: Индекс Мосбиржи корп обл CBITR | T23: 41283 | U23: 41283 | V23: 3 | W23: 7721771992 | Y23: 8.64
A24: history | F24: SNDX | G24: 715402000000 | H24: 224.71 | I24: RUB | J24: 2 | L24: 854 | M24: 224.77 | N24: 224.6 | O24: Индекс Мосбиржи корпоративных облигаций | P24: 224.63 | R24: RUCBITR | S24: Индекс Мосбиржи корп обл CBITR | T24: 41284 | U24: 41284 | V24: 3 | W24: 2202431535 | Y24: 8.63
A25: history | F25: SNDX | G25: 716326000000 | H25: 225 | I25: RUB | J25: 2 | L25: 854 | M25: 225 | N25: 224.74 | O25: Индекс Мосбиржи корпоративных облигаций | P25: 224.76 | R25: RUCBITR | S25: Индекс Мосбиржи корп обл CBITR | T25: 41285 | U25: 41285 | V25: 3 | W25: 1384848720 | Y25: 8.57
A26: history | F26: SNDX | G26: 717339000000 | H26: 225.32 | I26: RUB | J26: 2 | L26: 851 | M26: 225.33 | N26: 225.16 | O26: Индекс Мосбиржи корпоративных облигаций | P26: 225.16 | R26: RUCBITR | S26: Индекс Мосбиржи корп обл CBITR | T26: 41288 | U26: 41288 | V26: 3 | W26: 3523676317 | Y26: 8.54
A27: history | F27: SNDX | G27: 717484000000 | H27: 225.41 | I27: RUB | J27: 2 | L27: 850 | M27: 225.43 | N27: 225.32 | O27: Индекс Мосбиржи корпоративных облигаций | P27: 225.32 | R27: RUCBITR | S27: Индекс Мосбиржи корп обл CBITR | T27: 41289 | U27: 41289 | V27: 3 | W27: 14041423077 | Y27: 8.53
A28: history | F28: SNDX | G28: 718187000000 | H28: 225.63 | I28: RUB | J28: 2 | L28: 850 | M28: 225.64 | N28: 225.46 | O28: Индекс Мосбиржи корпоративных облигаций | P28: 225.46 | R28: RUCBITR | S28: Индекс Мосбиржи корп обл CBITR | T28: 41290 | U28: 41290 | V28: 3 | W28: 6301051476 | Y28: 8.49
A29: history | F29: SNDX | G29: 717538000000 | H29: 225.76 | I29: RUB | J29: 2 | L29: 851 | M29: 225.77 | N29: 225.63 | O29: Индекс Мосбиржи корпоративных облигаций | P29: 225.63 | R29: RUCBITR | S29: Индекс Мосбиржи корп обл CBITR | T29: 41291 | U29: 41291 | V29: 3 | W29: 7711976257 | Y29: 8.48
A30: history | F30: SNDX | G30: 717922000000 | H30: 225.88 | I30: RUB | J30: 2 | L30: 850 | M30: 225.89 | N30: 225.79 | O30: Индекс Мосбиржи корпоративных облигаций | P30: 225.81 | R30: RUCBITR | S30: Индекс Мосбиржи корп обл CBITR | T30: 41292 | U30: 41292 | V30: 3 | W30: 5228747117 | Y30: 8.47
A31: history | F31: SNDX | G31: 718335000000 | H31: 226.01 | I31: RUB | J31: 2 | L31: 847 | M31: 226.08 | N31: 225.88 | O31: Индекс Мосбиржи корпоративных облигаций | P31: 225.88 | R31: RUCBITR | S31: Индекс Мосбиржи корп обл CBITR | T31: 41295 | U31: 41295 | V31: 3 | W31: 5045771151 | Y31: 8.46
A32: history | F32: SNDX | G32: 718728000000 | H32: 226.13 | I32: RUB | J32: 2 | L32: 846 | M32: 226.14 | N32: 226.06 | O32: Индекс Мосбиржи корпоративных облигаций | P32: 226.06 | R32: RUCBITR | S32: Индекс Мосбиржи корп обл CBITR | T32: 41296 | U32: 41296 | V32: 3 | W32: 7805498182 | Y32: 8.45
A33: history | F33: SNDX | G33: 719320000000 | H33: 226.32 | I33: RUB | J33: 2 | L33: 845 | M33: 226.32 | N33: 226.13 | O33: Индекс Мосбиржи корпоративных облигаций | P33: 226.13 | R33: RUCBITR | S33: Индекс Мосбиржи корп обл CBITR | T33: 41297 | U33: 41297 | V33: 3 | W33: 2556914952 | Y33: 8.41
... A1250: history | F1250: SNDX | G1250: 455972000000 | H1250: 349.73 | I1250: RUB | J1250: 2 | L1250: 968 | M1250: 350.06 | N1250: 349.73 | O1250: Индекс Мосбиржи корпоративных облигаций | P1250: 349.84 | R1250: RUCBITR | S1250: Индекс Мосбиржи корп обл CBITR | T1250: 43063 | U1250: 43063 | V1250: 3 | W1250: 727502268 | Y1250: 8.49
A1251: history | F1251: SNDX | G1251: 455488000000 | H1251: 349.36 | I1251: RUB | J1251: 2 | K1251: 1 | L1251: 964 | M1251: 349.86 | N1251: 349.31 | O1251: Индекс Мосбиржи корпоративных облигаций | P1251: 349.86 | R1251: RUCBITR | S1251: Индекс Мосбиржи корп обл CBITR | T1251: 43066 | U1251: 43066 | V1251: 3 | W1251: 7.179891e+08 | Y1251: 8.46
A1252: history | F1252: SNDX | G1252: 455847000000 | H1252: 349.64 | I1252: RUB | J1252: 2 | K1252: 1 | L1252: 964 | M1252: 349.88 | N1252: 349.59 | O1252: Индекс Мосбиржи корпоративных облигаций | P1252: 349.63 | R1252: RUCBITR | S1252: Индекс Мосбиржи корп обл CBITR | T1252: 43067 | U1252: 43067 | V1252: 3 | W1252: 1729843757 | Y1252: 8.44
A1253: history | F1253: SNDX | G1253: 456029000000 | H1253: 349.78 | I1253: RUB | J1253: 2 | K1253: 1 | L1253: 964 | M1253: 351.36 | N1253: 349.73 | O1253: Индекс Мосбиржи корпоративных облигаций | P1253: 349.73 | R1253: RUCBITR | S1253: Индекс Мосбиржи корп обл CBITR | T1253: 43068 | U1253: 43068 | V1253: 3 | W1253: 1131227676 | Y1253: 8.43
A1254: history | F1254: SNDX | G1254: 456181000000 | H1254: 349.9 | I1254: RUB | J1254: 2 | K1254: 1 | L1254: 962 | M1254: 350.08 | N1254: 349.85 | O1254: Индекс Мосбиржи корпоративных облигаций | P1254: 349.88 | R1254: RUCBITR | S1254: Индекс Мосбиржи корп обл CBITR | T1254: 43069 | U1254: 43069 | V1254: 3 | W1254: 8.3443746e+08 | Y1254: 8.43
A1255: history | F1255: SNDX | G1255: 575378000000 | H1255: 350.13 | I1255: RUB | J1255: 2 | K1255: 1 | L1255: 1031 | M1255: 350.21 | N1255: 349.73 | O1255: Индекс Мосбиржи корпоративных облигаций | P1255: 349.98 | R1255: RUCBITR | S1255: Индекс Мосбиржи корп обл CBITR | T1255: 43070 | U1255: 43070 | V1255: 3 | W1255: 1872887263 | Y1255: 8.54
A1256: history | F1256: SNDX | G1256: 575443000000 | H1256: 350.17 | I1256: RUB | J1256: 2 | K1256: 1 | L1256: 1028 | M1256: 350.39 | N1256: 347.8 | O1256: Индекс Мосбиржи корпоративных облигаций | P1256: 350.39 | R1256: RUCBITR | S1256: Индекс Мосбиржи корп обл CBITR | T1256: 43073 | U1256: 43073 | V1256: 3 | W1256: 2421790780 | Y1256: 8.56
...

Sheet 2018-2026
A1: /data/@id | B1: /data/metadata/columns/column/@bytes | C1: /data/metadata/columns/column/@max_size | D1: /data/metadata/columns/column/@name | E1: /data/metadata/columns/column/@type | F1: /data/rows/row/@BOARDID | G1: /data/rows/row/@CAPITALIZATION | H1: /data/rows/row/@CLOSE | I1: /data/rows/row/@CURRENCYID | J1: /data/rows/row/@DECIMALS | K1: /data/rows/row/@DIVISOR | L1: /data/rows/row/@DURATION | M1: /data/rows/row/@HIGH | N1: /data/rows/row/@LOW | O1: /data/rows/row/@NAME | P1: /data/rows/row/@OPEN | Q1: /data/rows/row/@RECALC_DATE | R1: /data/rows/row/@SECID | S1: /data/rows/row/@SHORTNAME | T1: /data/rows/row/@TRADE_SESSION_DATE | U1: /data/rows/row/@TRADEDATE | V1: /data/rows/row/@TRADINGSESSION | W1: /data/rows/row/@VALUE | X1: /data/rows/row/@VOLUME | Y1: /data/rows/row/@YIELD
A2: history | B2: 12 | C2: 0 | D2: BOARDID | E2: string
A3: history | B3: 36 | C3: 0 | D3: SECID | E3: string
A4: history | B4: 10 | C4: 0 | D4: TRADEDATE | E4: date
A5: history | B5: 189 | C5: 0 | D5: SHORTNAME | E5: string
A6: history | B6: 765 | C6: 0 | D6: NAME | E6: string
A7: history | D7: CLOSE | E7: double
A8: history | D8: OPEN | E8: double
A9: history | D9: HIGH | E9: double
A10: history | D10: LOW | E10: double
A11: history | D11: VALUE | E11: double
A12: history | D12: DURATION | E12: int32
A13: history | D13: YIELD | E13: double
A14: history | D14: DECIMALS | E14: int32
A15: history | D15: CAPITALIZATION | E15: double
A16: history | B16: 9 | C16: 0 | D16: CURRENCYID | E16: string
A17: history | D17: DIVISOR | E17: double
A18: history | B18: 3 | C18: 0 | D18: TRADINGSESSION | E18: string
A19: history | D19: VOLUME | E19: double
A20: history | B20: 10 | C20: 0 | D20: TRADE_SESSION_DATE | E20: date
A21: history | B21: 10 | C21: 0 | D21: RECALC_DATE | E21: date
A22: history | F22: RTSI | H22: 100 | I22: RUB | J22: 2 | M22: 100 | N22: 100 | O22: Индекс МосБиржи Корпоративных Облигаций RUCBTRNS | P22: 100 | R22: RUCBTRNS | S22: RUCBTRNS | T22: 43463 | U22: 43463 | V22: 3 | Y22: =VLOOKUP(U22,'2020 Gap'!$S$20:$W$3790,5,FALSE) -> 8.96
A23: history | F23: RTSI | H23: 100.32 | I23: RUB | J23: 2 | M23: 100.32 | N23: 100.32 | O23: Индекс МосБиржи Корпоративных Облигаций RUCBTRNS | P23: 100.32 | R23: RUCBTRNS | S23: RUCBTRNS | T23: 43468 | U23: 43468 | V23: 3 | Y23: =VLOOKUP(U23,'2020 Gap'!$S$20:$W$3790,5,FALSE) -> 8.86
A24: history | F24: RTSI | H24: 100.51 | I24: RUB | J24: 2 | M24: 100.51 | N24: 100.51 | O24: Индекс МосБиржи Корпоративных Облигаций RUCBTRNS | P24: 100.51 | R24: RUCBTRNS | S24: RUCBTRNS | T24: 43469 | U24: 43469 | V24: 3 | Y24: =VLOOKUP(U24,'2020 Gap'!$S$20:$W$3790,5,FALSE) -> 8.81
A25: history | F25: RTSI | H25: 100.46 | I25: RUB | J25: 2 | M25: 100.46 | N25: 100.46 | O25: Индекс МосБиржи Корпоративных Облигаций RUCBTRNS | P25: 100.46 | R25: RUCBTRNS | S25: RUCBTRNS | T25: 43473 | U25: 43473 | V25: 3 | Y25: =VLOOKUP(U25,'2020 Gap'!$S$20:$W$3790,5,FALSE) -> 8.86
A26: history | F26: RTSI | H26: 100.49 | I26: RUB | J26: 2 | M26: 100.49 | N26: 100.49 | O26: Индекс МосБиржи Корпоративных Облигаций RUCBTRNS | P26: 100.49 | R26: RUCBTRNS | S26: RUCBTRNS | T26: 43474 | U26: 43474 | V26: 3 | Y26: =VLOOKUP(U26,'2020 Gap'!$S$20:$W$3790,5,FALSE) -> 8.87
A27: history | F27: RTSI | H27: 100.63 | I27: RUB | J27: 2 | M27: 100.63 | N27: 100.63 | O27: Индекс МосБиржи Корпоративных Облигаций RUCBTRNS | P27: 100.63 | R27: RUCBTRNS | S27: RUCBTRNS | T27: 43475 | U27: 43475 | V27: 3 | Y27: =VLOOKUP(U27,'2020 Gap'!$S$20:$W$3790,5,FALSE) -> 8.83
A28: history | F28: RTSI | H28: 100.82 | I28: RUB | J28: 2 | M28: 100.82 | N28: 100.82 | O28: Индекс МосБиржи Корпоративных Облигаций RUCBTRNS | P28: 100.82 | R28: RUCBTRNS | S28: RUCBTRNS | T28: 43476 | U28: 43476 | V28: 3 | Y28: =VLOOKUP(U28,'2020 Gap'!$S$20:$W$3790,5,FALSE) -> 8.78
A29: history | F29: RTSI | H29: 100.87 | I29: RUB | J29: 2 | M29: 100.87 | N29: 100.87 | O29: Индекс МосБиржи Корпоративных Облигаций RUCBTRNS | P29: 100.87 | R29: RUCBTRNS | S29: RUCBTRNS | T29: 43479 | U29: 43479 | V29: 3 | Y29: =VLOOKUP(U29,'2020 Gap'!$S$20:$W$3790,5,FALSE) -> 8.79
A30: history | F30: RTSI | H30: 100.88 | I30: RUB | J30: 2 | M30: 100.88 | N30: 100.88 | O30: Индекс МосБиржи Корпоративных Облигаций RUCBTRNS | P30: 100.88 | R30: RUCBTRNS | S30: RUCBTRNS | T30: 43480 | U30: 43480 | V30: 3 | Y30: =VLOOKUP(U30,'2020 Gap'!$S$20:$W$3790,5,FALSE) -> 8.8
A31: history | F31: RTSI | H31: 100.98 | I31: RUB | J31: 2 | M31: 100.98 | N31: 100.98 | O31: Индекс МосБиржи Корпоративных Облигаций RUCBTRNS | P31: 100.98 | R31: RUCBTRNS | S31: RUCBTRNS | T31: 43481 | U31: 43481 | V31: 3 | Y31: =VLOOKUP(U31,'2020 Gap'!$S$20:$W$3790,5,FALSE) -> 8.78
A32: history | F32: RTSI | H32: 100.99 | I32: RUB | J32: 2 | M32: 100.99 | N32: 100.99 | O32: Индекс МосБиржи Корпоративных Облигаций RUCBTRNS | P32: 100.99 | R32: RUCBTRNS | S32: RUCBTRNS | T32: 43482 | U32: 43482 | V32: 3 | Y32: =VLOOKUP(U32,'2020 Gap'!$S$20:$W$3790,5,FALSE) -> 8.78
A33: history | F33: RTSI | H33: 100.98 | I33: RUB | J33: 2 | M33: 100.98 | N33: 100.98 | O33: Индекс МосБиржи Корпоративных Облигаций RUCBTRNS | P33: 100.98 | R33: RUCBTRNS | S33: RUCBTRNS | T33: 43483 | U33: 43483 | V33: 3 | Y33: =VLOOKUP(U33,'2020 Gap'!$S$20:$W$3790,5,FALSE) -> 8.8
... A502: history | F502: RTSI | H502: 127.62 | I502: RUB | J502: 2 | M502: 127.62 | N502: 127.62 | O502: Индекс МосБиржи Корпоративных Облигаций RUCBTRNS | P502: 127.62 | R502: RUCBTRNS | S502: RUCBTRNS | T502: 44165 | U502: 44165 | V502: 3 | Y502: =VLOOKUP(U502,'2020 Gap'!$S$20:$W$3790,5,FALSE) -> 6.06
A503: history | F503: RTSI | G503: 1.3745127e+12 | H503: 127.6 | I503: RUB | J503: 2 | L503: 0 | M503: 127.6 | N503: 127.6 | O503: Индекс МосБиржи Корпоративных Облигаций RUCBTRNS | P503: 127.6 | R503: RUCBTRNS | S503: RUCBTRNS | T503: 44167 | U503: 44167 | V503: 3 | W503: 0 | Y503: =VLOOKUP(U503,'2020 Gap'!$S$20:$W$3790,5,FALSE) -> 6.05
A504: history | F504: RTSI | G504: 1.3727007e+12 | H504: 127.47 | I504: RUB | J504: 2 | L504: 0 | M504: 127.47 | N504: 127.47 | O504: Индекс МосБиржи Корпоративных Облигаций RUCBTRNS | P504: 127.47 | R504: RUCBTRNS | S504: RUCBTRNS | T504: 44168 | U504: 44168 | V504: 3 | W504: 0 | Y504: =VLOOKUP(U504,'2020 Gap'!$S$20:$W$3790,5,FALSE) -> 6.05
A505: history | F505: RTSI | G505: 1.3755318e+12 | H505: 127.74 | I505: RUB | J505: 2 | L505: 0 | M505: 127.74 | N505: 127.74 | O505: Индекс МосБиржи Корпоративных Облигаций RUCBTRNS | P505: 127.74 | R505: RUCBTRNS | S505: RUCBTRNS | T505: 44169 | U505: 44169 | V505: 3 | W505: 0 | Y505: =VLOOKUP(U505,'2020 Gap'!$S$20:$W$3790,5,FALSE) -> 6.05
A506: history | F506: RTSI | G506: 1.3750583e+12 | H506: 127.7 | I506: RUB | J506: 2 | L506: 0 | M506: 127.7 | N506: 127.7 | O506: Индекс МосБиржи Корпоративных Облигаций RUCBTRNS | P506: 127.7 | R506: RUCBTRNS | S506: RUCBTRNS | T506: 44172 | U506: 44172 | V506: 3 | W506: 0 | Y506: =VLOOKUP(U506,'2020 Gap'!$S$20:$W$3790,5,FALSE) -> 6.11
A507: history | F507: RTSI | G507: 1.3732768e+12 | H507: 127.53 | I507: RUB | J507: 2 | L507: 0 | M507: 127.53 | N507: 127.53 | O507: Индекс МосБиржи Корпоративных Облигаций RUCBTRNS | P507: 127.53 | R507: RUCBTRNS | S507: RUCBTRNS | T507: 44173 | U507: 44173 | V507: 3 | W507: 0 | Y507: =VLOOKUP(U507,'2020 Gap'!$S$20:$W$3790,5,FALSE) -> 6.13
A508: history | F508: RTSI | G508: 1.3739337e+12 | H508: 127.59 | I508: RUB | J508: 2 | L508: 0 | M508: 127.59 | N508: 127.59 | O508: Индекс МосБиржи Корпоративных Облигаций RUCBTRNS | P508: 127.59 | R508: RUCBTRNS | S508: RUCBTRNS | T508: 44174 | U508: 44174 | V508: 3 | W508: 0 | Y508: =VLOOKUP(U508,'2020 Gap'!$S$20:$W$3790,5,FALSE) -> 6.11
...

Sheet 2020 Gap
A1: /data/@id | B1: /data/metadata/columns/column/@bytes | C1: /data/metadata/columns/column/@max_size | D1: /data/metadata/columns/column/@name | E1: /data/metadata/columns/column/@type | F1: /data/rows/row/@BOARDID | G1: /data/rows/row/@CAPITALIZATION | H1: /data/rows/row/@CLOSE | I1: /data/rows/row/@CURRENCYID | J1: /data/rows/row/@DECIMALS | K1: /data/rows/row/@DIVISOR | L1: /data/rows/row/@DURATION | M1: /data/rows/row/@HIGH | N1: /data/rows/row/@LOW | O1: /data/rows/row/@NAME | P1: /data/rows/row/@OPEN | Q1: /data/rows/row/@SECID | R1: /data/rows/row/@SHORTNAME | S1: /data/rows/row/@TRADEDATE | T1: /data/rows/row/@TRADINGSESSION | U1: /data/rows/row/@VALUE | V1: /data/rows/row/@VOLUME | W1: /data/rows/row/@YIELD
A2: history | B2: 12 | C2: 0 | D2: BOARDID | E2: string
A3: history | B3: 36 | C3: 0 | D3: SECID | E3: string
A4: history | B4: 10 | C4: 0 | D4: TRADEDATE | E4: date
A5: history | B5: 189 | C5: 0 | D5: SHORTNAME | E5: string
A6: history | B6: 765 | C6: 0 | D6: NAME | E6: string
A7: history | D7: CLOSE | E7: double
A8: history | D8: OPEN | E8: double
A9: history | D9: HIGH | E9: double
A10: history | D10: LOW | E10: double
A11: history | D11: VALUE | E11: double
A12: history | D12: DURATION | E12: int32
A13: history | D13: YIELD | E13: double
A14: history | D14: DECIMALS | E14: int32
A15: history | D15: CAPITALIZATION | E15: double
A16: history | B16: 9 | C16: 0 | D16: CURRENCYID | E16: string
A17: history | D17: DIVISOR | E17: double
A18: history | B18: 3 | C18: 0 | D18: TRADINGSESSION | E18: string
A19: history | D19: VOLUME | E19: double
A20: history | F20: SNDX | H20: 159.96 | I20: RUB | J20: 2 | L20: 951 | M20: 160.16 | N20: 159.94 | O20: Индекс Мосбиржи корпоративных облигаций | P20: 160.04 | Q20: RUCBITR | R20: Индекс Мосбиржи корп обл CBITR | S20: 39572 | T20: 3 | U20: 2.5535837e+08 | W20: 8.36
A21: history | F21: SNDX | H21: 160 | I21: RUB | J21: 2 | L21: 950 | M21: 160 | N21: 159.89 | O21: Индекс Мосбиржи корпоративных облигаций | P21: 159.99 | Q21: RUCBITR | R21: Индекс Мосбиржи корп обл CBITR | S21: 39573 | T21: 3 | U21: 8.676638e+08 | W21: 8.46
A22: history | F22: SNDX | H22: 160.37 | I22: RUB | J22: 2 | L22: 949 | M22: 160.37 | N22: 160 | O22: Индекс Мосбиржи корпоративных облигаций | P22: 160.04 | Q22: RUCBITR | R22: Индекс Мосбиржи корп обл CBITR | S22: 39574 | T22: 3 | U22: 1795505107 | W22: 8.32
A23: history | F23: SNDX | H23: 160.41 | I23: RUB | J23: 2 | L23: 948 | M23: 160.43 | N23: 160.36 | O23: Индекс Мосбиржи корпоративных облигаций | P23: 160.41 | Q23: RUCBITR | R23: Индекс Мосбиржи корп обл CBITR | S23: 39575 | T23: 3 | U23: 1221129503 | W23: 8.31
A24: history | F24: SNDX | H24: 160.42 | I24: RUB | J24: 2 | L24: 947 | M24: 160.5 | N24: 160.32 | O24: Индекс Мосбиржи корпоративных облигаций | P24: 160.45 | Q24: RUCBITR | R24: Индекс Мосбиржи корп обл CBITR | S24: 39576 | T24: 3 | U24: 1357969518 | W24: 8.26
A25: history | F25: SNDX | H25: 160.54 | I25: RUB | J25: 2 | L25: 943 | M25: 160.59 | N25: 160.42 | O25: Индекс Мосбиржи корпоративных облигаций | P25: 160.56 | Q25: RUCBITR | R25: Индекс Мосбиржи корп обл CBITR | S25: 39580 | T25: 3 | U25: 8.2109585e+08 | W25: 8.27
A26: history | F26: SNDX | H26: 160.65 | I26: RUB | J26: 2 | L26: 942 | M26: 160.68 | N26: 160.54 | O26: Индекс Мосбиржи корпоративных облигаций | P26: 160.54 | Q26: RUCBITR | R26: Индекс Мосбиржи корп обл CBITR | S26: 39581 | T26: 3 | U26: 2373466520 | W26: 8.3
A27: history | F27: SNDX | H27: 160.68 | I27: RUB | J27: 2 | L27: 944 | M27: 160.71 | N27: 160.65 | O27: Индекс Мосбиржи корпоративных облигаций | P27: 160.65 | Q27: RUCBITR | R27: Индекс Мосбиржи корп обл CBITR | S27: 39582 | T27: 3 | U27: 1388316645 | W27: 8.3
A28: history | F28: SNDX | H28: 160.72 | I28: RUB | J28: 2 | L28: 946 | M28: 160.75 | N28: 160.68 | O28: Индекс Мосбиржи корпоративных облигаций | P28: 160.68 | Q28: RUCBITR | R28: Индекс Мосбиржи корп обл CBITR | S28: 39583 | T28: 3 | U28: 2230241850 | W28: 8.3
A29: history | F29: SNDX | H29: 160.68 | I29: RUB | J29: 2 | L29: 945 | M29: 160.76 | N29: 160.67 | O29: Индекс Мосбиржи корпоративных облигаций | P29: 160.76 | Q29: RUCBITR | R29: Индекс Мосбиржи корп обл CBITR | S29: 39584 | T29: 3 | U29: 8.5392302e+08 | W29: 8.33
A30: history | F30: SNDX | H30: 160.83 | I30: RUB | J30: 2 | L30: 942 | M30: 160.83 | N30: 160.68 | O30: Индекс Мосбиржи корпоративных облигаций | P30: 160.68 | Q30: RUCBITR | R30: Индекс Мосбиржи корп обл CBITR | S30: 39587 | T30: 3 | U30: 1197040717 | W30: 8.34
A31: history | F31: SNDX | H31: 160.82 | I31: RUB | J31: 2 | L31: 942 | M31: 160.91 | N31: 160.81 | O31: Индекс Мосбиржи корпоративных облигаций | P31: 160.83 | Q31: RUCBITR | R31: Индекс Мосбиржи корп обл CBITR | S31: 39588 | T31: 3 | U31: 2457531123 | W31: 8.32
... A923: history | F923: SNDX | H923: 206.3 | I923: RUB | J923: 2 | L923: 954 | M923: 206.33 | N923: 205.95 | O923: Индекс Мосбиржи корпоративных облигаций | P923: 206.12 | Q923: RUCBITR | R923: Индекс Мосбиржи корп обл CBITR | S923: 40891 | T923: 3 | U923: 2107144474 | W923: 8.47
A924: history | F924: SNDX | G924: 721684000000 | H924: 205.81 | I924: RUB | J924: 2 | L924: 953 | M924: 206.35 | N924: 205.81 | O924: Индекс Мосбиржи корпоративных облигаций | P924: 206.35 | Q924: RUCBITR | R924: Индекс Мосбиржи корп обл CBITR | S924: 40892 | T924: 3 | U924: 4467205637 | W924: 8.61
A925: history | F925: SNDX | G925: 723456000000 | H925: 206.37 | I925: RUB | J925: 2 | L925: 960 | M925: 206.37 | N925: 205.73 | O925: Индекс Мосбиржи корпоративных облигаций | P925: 205.86 | Q925: RUCBITR | R925: Индекс Мосбиржи корп обл CBITR | S925: 40893 | T925: 3 | U925: 4094993547 | W925: 8.61
A926: history | F926: SNDX | G926: 723680000000 | H926: 206.43 | I926: RUB | J926: 2 | L926: 952 | M926: 206.67 | N926: 206.43 | O926: Индекс Мосбиржи корпоративных облигаций | P926: 206.51 | Q926: RUCBITR | R926: Индекс Мосбиржи корп обл CBITR | S926: 40896 | T926: 3 | U926: 3208145140 | W926: 8.57
A927: history | F927: SNDX | G927: 722892000000 | H927: 206.32 | I927: RUB | J927: 2 | L927: 951 | M927: 206.49 | N927: 206.29 | O927: Индекс Мосбиржи корпоративных облигаций | P927: 206.48 | Q927: RUCBITR | R927: Индекс Мосбиржи корп обл CBITR | S927: 40897 | T927: 3 | U927: 2441561158 | W927: 8.61
A928: history | F928: SNDX | G928: 721604000000 | H928: 205.95 | I928: RUB | J928: 2 | L928: 949 | M928: 206.4 | N928: 205.94 | O928: Индекс Мосбиржи корпоративных облигаций | P928: 206.37 | Q928: RUCBITR | R928: Индекс Мосбиржи корп обл CBITR | S928: 40898 | T928: 3 | U928: 3109555826 | W928: 8.73
A929: history | F929: SNDX | G929: 721437000000 | H929: 205.99 | I929: RUB | J929: 2 | L929: 949 | M929: 206 | N929: 205.75 | O929: Индекс Мосбиржи корпоративных облигаций | P929: 205.95 | Q929: RUCBITR | R929: Индекс Мосбиржи корп обл CBITR | S929: 40899 | T929: 3 | U929: 3033441038 | W929: 8.7
A930: history | F930: SNDX | G930: 720238000000 | H930: 205.77 | I930: RUB | J930: 2 | L930: 947 | M930: 206.07 | N930: 205.69 | O930: Индекс Мосбиржи корпоративных облигаций | P930: 206.04 | Q930: RUCBITR | R930: Индекс Мосбиржи корп обл CBITR | S930: 40900 | T930: 3 | U930: 1366452375 | W930: 8.74
A931: history | F931: SNDX | G931: 719872000000 | H931: 205.67 | I931: RUB | J931: 2 | L931: 944 | M931: 206.11 | N931: 205.67 | O931: Индекс Мосбиржи корпоративных облигаций | P931: 205.91 | Q931: RUCBITR | R931: Индекс Мосбиржи корп обл CBITR | S931: 40903 | T931: 3 | U931: 2948292155 | W931: 8.77
...

Sheet Combined
A1: date | B1: Yield | C1: Date Modified | D1: Corporate Yield Russian
A2: ='2013-2018'!U22 -> 41282 | B2: ='2013-2018'!Y22 -> 8.63 | C2: =TEXT(A2,"yyyy-mm-01") -> 2013-01-01 | D2: =AVERAGEIF($C$2:$C$3413,C2,$B$2:$B$3413) -> 8.4594444
A3: ='2013-2018'!U23 -> 41283 | B3: ='2013-2018'!Y23 -> 8.64 | C3: =TEXT(A3,"yyyy-mm-01") -> 2013-01-01 | D3: =AVERAGEIF($C$2:$C$3413,C3,$B$2:$B$3413) -> 8.4594444
A4: ='2013-2018'!U24 -> 41284 | B4: ='2013-2018'!Y24 -> 8.63 | C4: =TEXT(A4,"yyyy-mm-01") -> 2013-01-01 | D4: =AVERAGEIF($C$2:$C$3413,C4,$B$2:$B$3413) -> 8.4594444
A5: ='2013-2018'!U25 -> 41285 | B5: ='2013-2018'!Y25 -> 8.57 | C5: =TEXT(A5,"yyyy-mm-01") -> 2013-01-01 | D5: =AVERAGEIF($C$2:$C$3413,C5,$B$2:$B$3413) -> 8.4594444
A6: ='2013-2018'!U26 -> 41288 | B6: ='2013-2018'!Y26 -> 8.54 | C6: =TEXT(A6,"yyyy-mm-01") -> 2013-01-01 | D6: =AVERAGEIF($C$2:$C$3413,C6,$B$2:$B$3413) -> 8.4594444
A7: ='2013-2018'!U27 -> 41289 | B7: ='2013-2018'!Y27 -> 8.53 | C7: =TEXT(A7,"yyyy-mm-01") -> 2013-01-01 | D7: =AVERAGEIF($C$2:$C$3413,C7,$B$2:$B$3413) -> 8.4594444
A8: ='2013-2018'!U28 -> 41290 | B8: ='2013-2018'!Y28 -> 8.49 | C8: =TEXT(A8,"yyyy-mm-01") -> 2013-01-01 | D8: =AVERAGEIF($C$2:$C$3413,C8,$B$2:$B$3413) -> 8.4594444
A9: ='2013-2018'!U29 -> 41291 | B9: ='2013-2018'!Y29 -> 8.48 | C9: =TEXT(A9,"yyyy-mm-01") -> 2013-01-01 | D9: =AVERAGEIF($C$2:$C$3413,C9,$B$2:$B$3413) -> 8.4594444
A10: ='2013-2018'!U30 -> 41292 | B10: ='2013-2018'!Y30 -> 8.47 | C10: =TEXT(A10,"yyyy-mm-01") -> 2013-01-01 | D10: =AVERAGEIF($C$2:$C$3413,C10,$B$2:$B$3413) -> 8.4594444
A11: ='2013-2018'!U31 -> 41295 | B11: ='2013-2018'!Y31 -> 8.46 | C11: =TEXT(A11,"yyyy-mm-01") -> 2013-01-01 | D11: =AVERAGEIF($C$2:$C$3413,C11,$B$2:$B$3413) -> 8.4594444
A12: ='2013-2018'!U32 -> 41296 | B12: ='2013-2018'!Y32 -> 8.45 | C12: =TEXT(A12,"yyyy-mm-01") -> 2013-01-01 | D12: =AVERAGEIF($C$2:$C$3413,C12,$B$2:$B$3413) -> 8.4594444
A13: ='2013-2018'!U33 -> 41297 | B13: ='2013-2018'!Y33 -> 8.41 | C13: =TEXT(A13,"yyyy-mm-01") -> 2013-01-01 | D13: =AVERAGEIF($C$2:$C$3413,C13,$B$2:$B$3413) -> 8.4594444
... A1509: ='2013-2018'!U1529 -> 43463 | B1509: ='2013-2018'!Y1529 -> 8.96 | C1509: =TEXT(A1509,"yyyy-mm-01") -> 2018-12-01 | D1509: =AVERAGEIF($C$2:$C$3413,C1509,$B$2:$B$3413) -> 9.0063636
A1510: ='2018-2026'!U22 -> 43463 | B1510: ='2018-2026'!Y22 -> 8.96 | C1510: =TEXT(A1510,"yyyy-mm-01") -> 2018-12-01 | D1510: =AVERAGEIF($C$2:$C$3413,C1510,$B$2:$B$3413) -> 9.0063636
A1511: ='2018-2026'!U23 -> 43468 | B1511: ='2018-2026'!Y23 -> 8.86 | C1511: =TEXT(A1511,"yyyy-mm-01") -> 2019-01-01 | D1511: =AVERAGEIF($C$2:$C$3413,C1511,$B$2:$B$3413) -> 8.805
A1512: ='2018-2026'!U24 -> 43469 | B1512: ='2018-2026'!Y24 -> 8.81 | C1512: =TEXT(A1512,"yyyy-mm-01") -> 2019-01-01 | D1512: =AVERAGEIF($C$2:$C$3413,C1512,$B$2:$B$3413) -> 8.805
A1513: ='2018-2026'!U25 -> 43473 | B1513: ='2018-2026'!Y25 -> 8.86 | C1513: =TEXT(A1513,"yyyy-mm-01") -> 2019-01-01 | D1513: =AVERAGEIF($C$2:$C$3413,C1513,$B$2:$B$3413) -> 8.805
A1514: ='2018-2026'!U26 -> 43474 | B1514: ='2018-2026'!Y26 -> 8.87 | C1514: =TEXT(A1514,"yyyy-mm-01") -> 2019-01-01 | D1514: =AVERAGEIF($C$2:$C$3413,C1514,$B$2:$B$3413) -> 8.805
A1515: ='2018-2026'!U27 -> 43475 | B1515: ='2018-2026'!Y27 -> 8.83 | C1515: =TEXT(A1515,"yyyy-mm-01") -> 2019-01-01 | D1515: =AVERAGEIF($C$2:$C$3413,C1515,$B$2:$B$3413) -> 8.805
A1516: ='2018-2026'!U28 -> 43476 | B1516: ='2018-2026'!Y28 -> 8.78 | C1516: =TEXT(A1516,"yyyy-mm-01") -> 2019-01-01 | D1516: =AVERAGEIF($C$2:$C$3413,C1516,$B$2:$B$3413) -> 8.805
A1517: ='2018-2026'!U29 -> 43479 | B1517: ='2018-2026'!Y29 -> 8.79 | C1517: =TEXT(A1517,"yyyy-mm-01") -> 2019-01-01 | D1517: =AVERAGEIF($C$2:$C$3413,C1517,$B$2:$B$3413) -> 8.805
A1518: ='2018-2026'!U30 -> 43480 | B1518: ='2018-2026'!Y30 -> 8.8 | C1518: =TEXT(A1518,"yyyy-mm-01") -> 2019-01-01 | D1518: =AVERAGEIF($C$2:$C$3413,C1518,$B$2:$B$3413) -> 8.805
A1519: ='2018-2026'!U31 -> 43481 | B1519: ='2018-2026'!Y31 -> 8.78 | C1519: =TEXT(A1519,"yyyy-mm-01") -> 2019-01-01 | D1519: =AVERAGEIF($C$2:$C$3413,C1519,$B$2:$B$3413) -> 8.805
A1520: ='2018-2026'!U32 -> 43482 | B1520: ='2018-2026'!Y32 -> 8.78 | C1520: =TEXT(A1520,"yyyy-mm-01") -> 2019-01-01 | D1520: =AVERAGEIF($C$2:$C$3413,C1520,$B$2:$B$3413) -> 8.805
A1521: ='2018-2026'!U33 -> 43483 | B1521: ='2018-2026'!Y33 -> 8.8 | C1521: =TEXT(A1521,"yyyy-mm-01") -> 2019-01-01 | D1521: =AVERAGEIF($C$2:$C$3413,C1521,$B$2:$B$3413) -> 8.805
... A3413: ='2018-2026'!U1925 -> 46241 | B3413: ='2018-2026'!Y1925 -> 15.7 | C3413: =TEXT(A3413,"yyyy-mm-01") -> 2026-08-01 | D3413: =AVERAGEIF($C$2:$C$3413,C3413,$B$2:$B$3413) -> 15.748

Sheet Final Cleaned
A1: date | B1: ru_corp_yield_m
A2: {=_xlfn.UNIQUE(Combined!$C$2:$D$3413)} -> 2013-01-01 | B2: 8.4594444
A3: 2013-02-01 | B3: 8.067
A4: 2013-03-01 | B4: 8.076
A5: 2013-04-01 | B5: 7.9963636
A6: 2013-05-01 | B6: 7.8771429
A7: 2013-06-01 | B7: 8.1036842
A8: 2013-07-01 | B8: 8.0504348
A9: 2013-08-01 | B9: 7.8368182
A10: 2013-09-01 | B10: 7.7947619
A11: 2013-10-01 | B11: 7.6926087
A12: 2013-11-01 | B12: 7.504
A13: 2013-12-01 | B13: 7.7566667
A14: 2014-01-01 | B14: 8.3752632
... A165: 2026-08-01 | B165: 15.748
